Workbook

Sheet Sheet1
A1: CAPM
A2: Rf | B2: 0.0749 | AU2: Budget | AV2: 406.912
A3: Nbr of business days | B3: 252
A4: this year's average profit | B4: =AVERAGE(E525:E708) -> 0.00046947728 | F4: =AVERAGE(I525:I708) -> 0.0016194764 | J4: =AVERAGE(M525:M708) -> 0.0028950748 | N4: =AVERAGE(Q525:Q708) -> 0.00095958501 | R4: =AVERAGE(U525:U708) -> 0.0014405738 | V4: =AVERAGE(Y525:Y708) -> 0.0019498991 | Z4: =AVERAGE(AC525:AC708) -> -0.00071362666 | AD4: =AVERAGE(AG525:AG708) -> 0.0031807927 | AH4: =AVERAGE(AK525:AK708) -> 0.0013275705 | AL4: =AVERAGE(#REF!) -> #REF!
A5: this year's expected profit | B5: =B4*$B$3 -> 0.11830827 | F5: =F4*$B$3 -> 0.40810804 | J5: =J4*$B$3 -> 0.72955885 | N5: =N4*$B$3 -> 0.24181542 | R5: =R4*$B$3 -> 0.3630246 | V5: =V4*$B$3 -> 0.49137457 | Z5: =Z4*$B$3 -> -0.17983392 | AD5: =AD4*$B$3 -> 0.80155976 | AH5: =AH4*$B$3 -> 0.33454777 | AL5: =AL4*$B$3 -> #REF! | AU5: Companies | AV5: Tawasol GH | AW5: Smart Tunisie | AX5: Attijari Bank | AY5: Euro-cycles | AZ5: UNIMED | BA5: AMV | BB5: Carthage Cement | BC5: Poulina | BD5: One Tech Holding | BE5: Essoukna | BF5: Total
A6: daily mean | B6: =AVERAGE(E22:E708) -> 0.00039868121 | F6: =AVERAGE(I22:I708) -> 0.0003658944 | J6: =AVERAGE(M22:M708) -> 0.0015609576 | N6: =AVERAGE(Q22:Q708) -> -0.00061599051 | R6: =AVERAGE(U22:U708) -> 0.00055002268 | V6: =AVERAGE(Y22:Y708) -> 0.00067225621 | Z6: =AVERAGE(AC22:AC708) -> 6.5584023e-05 | AD6: =AVERAGE(AG22:AG708) -> 0.0011190722 | AH6: =AVERAGE(AK22:AK708) -> 0.00073565 | AL6: =AVERAGE(AO22:AO708) -> 0.00058957759 | AP6: =AVERAGE(AR22:AR708) -> 0.00062863802 | AU6: Nber of stock to purchase | AV6: 0 | AW6: 1 | AX6: 2 | AY6: 0 | AZ6: 1 | BA6: 6 | BB6: 0 | BC6: 5 | BD6: 9 | BE6: 1
A7: yearly mean | B7: =B6*$B$3 -> 0.10046766 | F7: =F6*$B$3 -> 0.09220539 | J7: =J6*$B$3 -> 0.39336133 | N7: =N6*$B$3 -> -0.15522961 | R7: =R6*$B$3 -> 0.13860572 | V7: =V6*$B$3 -> 0.16940857 | Z7: =Z6*$B$3 -> 0.016527174 | AD7: =AD6*$B$3 -> 0.28200621 | AH7: =AH6*$B$3 -> 0.1853838 | AL7: =AL6*$B$3 -> 0.14857355 | AP7: =AP6*252 -> 0.15841678 | AU7: Stock's price | AV7: 0.83 | AW7: 18.2 | AX7: 66.9 | AY7: 12.9 | BA7: 6.75 | BB7: 1.94 | BC7: 18.1 | BD7: 8.88 | BE7: 3.06
A8: daily standard dev | B8: =_xlfn.STDEV.S(E22:E708) -> 0.024813956 | F8: =_xlfn.STDEV.S(I22:I708) -> 0.014429516 | J8: =_xlfn.STDEV.S(M22:M708) -> 0.012438879 | N8: =_xlfn.STDEV.S(Q22:Q708) -> 0.017036611 | R8: =_xlfn.STDEV.S(U22:U708) -> 0.012325324 | V8: =_xlfn.STDEV.S(Y22:Y708) -> 0.015101286 | Z8: =_xlfn.STDEV.S(AC22:AC708) -> 0.01149778 | AD8: =_xlfn.STDEV.S(AG22:AG708) -> 0.015041479 | AH8: =_xlfn.STDEV.S(AK22:AK708) -> 0.0099647581 | AL8: =_xlfn.STDEV.S(AO22:AO708) -> 0.02426467 | AP8: =_xlfn.STDEV.S(AR22:AR708) -> 0.0035118497 | AU8: weights | AV8: =AV11 -> 0 | AW8: =AW11 -> 0.013199817 | AX8: =AX11 -> 0.4884895 | AY8: =AY11 -> 0 | AZ8: =AZ11 -> 0.0073089633 | BA8: =BA11 -> 0.085870171 | BB8: =BB11 -> 0 | BC8: =BC11 -> 0.21113046 | ... BE8: =BE11 -> 0.0025737994
A9: yearly standard dev | B9: =B8*SQRT($B$3) -> 0.39390935 | F9: =F8*SQRT($B$3) -> 0.22906146 | J9: =J8*SQRT($B$3) -> 0.19746108 | N9: =N8*SQRT($B$3) -> 0.27044781 | R9: =R8*SQRT($B$3) -> 0.19565846 | V9: =V8*SQRT($B$3) -> 0.23972548 | Z9: =Z8*SQRT($B$3) -> 0.18252161 | AD9: =AD8*SQRT($B$3) -> 0.23877607 | AH9: =AH8*SQRT($B$3) -> 0.15818563 | AL9: =AL8*SQRT($B$3) -> 0.38518969 | AP9: =AP8*SQRT(252) -> 0.055748886 | AU9: Money invested | AV9: =AV6*AV7 -> 0 | AW9: =AW6*AW7 -> 18.2 | AX9: =AX6*AX7 -> 133.8 | AY9: =AY6*AY7 -> 0 | AZ9: =AZ6*AZ7 -> 0 | BA9: =BA6*BA7 -> 40.5 | BB9: =BB6*BB7 -> 0 | BC9: =BC6*BC7 -> 90.5 | ... BE9: =BE6*BE7 -> 3.06 | BF9: =SUM(AV9:BE9) -> 365.98
A10: sharpe ratio | B10: =(B7-$B$2)/B9 -> 0.064907482 | F10: =(F7-$B$2)/F9 -> 0.075549109 | J10: =(J7-$B$2)/J9 -> 1.6127802 | N10: =(N7-$B$2)/N9 -> -0.85092059 | R10: =(R7-$B$2)/R9 -> 0.32559653 | V10: =(V7-$B$2)/V9 -> 0.39423664 | Z10: =(Z7-$B$2)/Z9 -> -0.31981324 | AD10: =(AD7-$B$2)/AD9 -> 0.86736584 | AH10: =(AH7-$B$2)/AH9 -> 0.69844396 | AL10: =(AL7-$B$2)/AL9 -> 0.19126563 | AP10: =(AP7-7.49%)/AP9 -> 1.4980888 | AU10: constraint | AV10: =AV9/$BF$9 -> 0 | AW10: =AW9/$BF$9 -> 0.049729493 | AX10: =AX9/$BF$9 -> 0.36559375 | AY10: =AY9/$BF$9 -> 0 | AZ10: =AZ9/$BF$9 -> 0 | BA10: =BA9/$BF$9 -> 0.11066178 | BB10: =BB9/$BF$9 -> 0 | BC10: =BC9/$BF$9 -> 0.24728127 | ... BE10: =BE9/$BF$9 -> 0.0083611126
A11: covariance | B11: =_xlfn.COVARIANCE.S(E22:E708,$AR$22:$AR$708)*$B$3 -> 0.0011719083 | F11: =_xlfn.COVARIANCE.S(I22:I708,$AR$22:$AR$708)*$B$3 -> 0.0010663529 | J11: =_xlfn.COVARIANCE.S(M22:M708,$AR$22:$AR$708)*$B$3 -> 0.0060735132 | N11: =_xlfn.COVARIANCE.S(Q22:Q708,$AR$22:$AR$708)*$B$3 -> 0.0024738866 | R11: =_xlfn.COVARIANCE.S(U22:U708,$AR$22:$AR$708)*$B$3 -> 0.0016752724 | V11: =_xlfn.COVARIANCE.S(Y22:Y708,AR22:AR708)*$B$3 -> 0.0014119965 | Z11: =_xlfn.COVARIANCE.S(AC22:AC708,$AR$22:$AR$708)*$B$3 -> 0.0023773733 | AD11: =_xlfn.COVARIANCE.S(AG22:AG708,$AR$22:$AR$708)*$B$3 -> 0.002687287 | AH11: =_xlfn.COVARIANCE.S(AK22:AK708,$AR$22:$AR$708)*$B$3 -> 0.0026040982 | AL11: =_xlfn.COVARIANCE.S(AO22:AO708,$AR$22:$AR$708)*$B$3 -> 0.0025701315 | AT11: Weights | AV11: =AT13 -> 0 | AW11: =AT14 -> 0.013199817 | AX11: =AT15 -> 0.4884895 | AY11: =AT16 -> 0 | AZ11: =AT17 -> 0.0073089633 | BA11: =AT18 -> 0.085870171 | BB11: =AT19 -> 0 | BC11: =AT20 -> 0.21113046 | BD11: =AT21 -> 0.19142729 | BE11: =AT22 -> 0.0025737994
A12: beta | B12: =B11/$AP$9^2 -> 0.37706936 | F12: =F11/$AP$9^2 -> 0.3431062 | J12: =J11/$AP$9^2 -> 1.9541936 | N12: =N11/$AP$9^2 -> 0.79598963 | R12: =R11/$AP$9^2 -> 0.53903015 | V12: =V11/$AP$9^2 -> 0.45431936 | Z12: =Z11/$AP$9^2 -> 0.76493581 | AD12: =AD11/$AP$9^2 -> 0.86465263 | AH12: =AH11/$AP$9^2 -> 0.83788606 | AL12: =AL11/$AP$9^2 -> 0.82695707 | AV12: Tawasol GH | AW12: Smart Tunisie | AX12: Attijari Bank | AY12: Euro-cycles | AZ12: UNIMED | BA12: AMV | BB12: Carthage Cement | BC12: Poulina | BD12: One Tech Holding | BE12: Essoukna
AT13: 0 | AU13: Tawasol GH | AV13: =VARP(Sheet2!$A$3:$A$688) -> 0.00061483487 | AW13: 8.4193824e-06 | AX13: 5.0376465e-06 | AY13: 1.4862964e-06 | AZ13: -8.0487406e-06 | BA13: 3.271657e-06 | BB13: 3.6547178e-07 | BC13: 9.1149964e-07 | BD13: 2.4113683e-05 | BE13: -4.6351158e-06
AT14: 0.013199817 | AU14: Smart Tunisie | AV14: 8.4193824e-06 | AW14: =VARP(Sheet2!$B$3:$B$688) -> 0.00020790742 | AX14: -6.525042e-07 | AY14: -1.1754641e-06 | AZ14: 6.0257957e-06 | BA14: -7.520089e-07 | BB14: -2.9940598e-07 | BC14: 2.3912874e-06 | BD14: 8.0255938e-06 | BE14: 4.0085751e-06
AT15: 0.4884895 | AU15: Attijari Bank | AV15: 5.0376465e-06 | AW15: -6.525042e-07 | AX15: =VARP(Sheet2!$C$3:$C$688) -> 0.00015450016 | AY15: 8.941829e-06 | AZ15: 1.732876e-05 | BA15: 8.8511638e-06 | BB15: 1.3101995e-05 | BC15: 1.1273361e-05 | BD15: 1.7037604e-05 | BE15: 3.002134e-05
AT16: 0 | AU16: Euro-cycles | AV16: 1.4862964e-06 | AW16: -1.1754641e-06 | AX16: 8.941829e-06 | AY16: =VARP(Sheet2!$D$3:$D$688) -> 0.000289823 | AZ16: 2.8234252e-06 | BA16: -2.7647058e-06 | BB16: 9.4564557e-06 | BC16: 2.4021564e-06 | BD16: 2.1337185e-06 | BE16: 1.757721e-05
AT17: 0.0073089633 | AU17: UNIMED | AV17: -8.0487406e-06 | AW17: 6.0257957e-06 | AX17: 1.732876e-05 | AY17: 2.8234252e-06 | AZ17: =VARP(Sheet2!$E$3:$E$688) -> 0.00015169217 | BA17: 4.2896617e-06 | BB17: -2.6383546e-07 | BC17: 2.1478978e-05 | BD17: 9.4837469e-06 | BE17: 2.5469313e-05
AT18: 0.085870171 | AU18: AMV | AV18: 3.271657e-06 | AW18: -7.520089e-07 | AX18: 8.8511638e-06 | AY18: -2.7647058e-06 | AZ18: 4.2896617e-06 | BA18: =VARP(Sheet2!$F$3:$F$688) -> 0.00022771639 | BB18: 8.9588515e-06 | BC18: -4.1192155e-06 | BD18: 7.0175593e-06 | BE18: -1.0684985e-05
AT19: 0 | AU19: Carthage Cement | AV19: 3.6547178e-07 | AW19: -2.9940598e-07 | AX19: 1.3101995e-05 | AY19: 9.4564557e-06 | AZ19: -2.6383546e-07 | BA19: 8.9588515e-06 | BB19: =VARP(Sheet2!$G$3:$G$688) -> 0.00013200624 | BC19: -9.0133091e-07 | BD19: 1.9287745e-06 | BE19: 1.373486e-05
B20: TAWASOL | F20: SMART TUNISIE | J20: ATTIJARI BANK | N20: EURO CYCLE | R20: UNIMED | V20: AMV | Z20: CARTHAGE CEMENT | AD20: POULINA | AH20: ONE TECH HOLDING | AL20: ESSOUKNA | AP20: TUNINDEX | AT20: 0.21113046 | AU20: Poulina | AV20: 9.1149964e-07 | AW20: 2.3912874e-06 | AX20: 1.1273361e-05 | AY20: 2.4021564e-06 | AZ20: 2.1478978e-05 | BA20: -4.1192155e-06 | BB20: -9.0133091e-07 | BC20: =VARP(Sheet2!$H$3:$H$688) -> 0.00022591627 | BD20: 1.6704339e-06 | BE20: 2.0210158e-06
B21: Date | C21: Cours | D21: Cours Ajusté | E21: Daily return | F21: Date | G21: Cours | H21: Cours Ajusté | I21: Daily return | J21: Date | K21: Cours | L21: Cours Ajusté | M21: Daily return | N21: Date | O21: Cours | P21: Cours Ajusté | Q21: Daily return | R21: Date | S21: Cours | T21: Cours Ajusté | U21: Daily return | V21: Date | W21: Cours | X21: Cours Ajusté | Y21: Daily return | Z21: Date | AA21: Cours | AB21: Cours Ajusté | AC21: Daily return | AD21: Date | AE21: Cours | AF21: Cours Ajusté | AG21: Daily return | AH21: Date | AI21: Cours | AJ21: Cours Ajusté | AK21: Daily return | AL21: Date | AM21: Cours | AN21: Cours Ajusté | AO21: Daily return | AP21: Date | AQ21: Cours Ajusté | AR21: Daily return | AT21: 0.19142729 | AU21: One Tech Holding | AV21: 2.4113683e-05 | AW21: 8.0255938e-06 | AX21: 1.7037604e-05 | AY21: 2.1337185e-06 | AZ21: 9.4837469e-06 | BA21: 7.0175593e-06 | BB21: 1.9287745e-06 | BC21: 1.6704339e-06 | BD21: =VARP(Sheet2!$I$3:$I$688) -> 9.9151658e-05 | BE21: 1.5957746e-05
B22: 44928 | C22: 0.62 | D22: 0.62 | F22: 44928 | G22: 23.9 | H22: 14.071 | J22: 44928 | K22: 37.4 | L22: 22.4835 | N22: 44928 | O22: 25.2 | P22: 22.1577 | R22: 44928 | S22: 6.99 | T22: 6.1743 | V22: 44928 | W22: 6.36 | X22: 5.402 | Z22: 44928 | AA22: 1.9 | AB22: 1.9 | AD22: 44928 | AE22: 8.26 | AF22: 7.471 | AH22: 44928 | AI22: 8.93 | AJ22: 7.8072 | AL22: 44928 | AM22: 2.09 | AN22: 1.96 | AP22: 02/01/23 | AQ22: 8094.2 | AT22: 0.0025737994 | AU22: Essoukna | AV22: -4.6351158e-06 | AW22: 4.0085751e-06 | AX22: 3.002134e-05 | AY22: 1.757721e-05 | AZ22: 2.5469313e-05 | BA22: -1.0684985e-05 | BB22: 1.373486e-05 | BC22: 2.0210158e-06 | BD22: 1.5957746e-05 | BE22: =VARP(Sheet2!$J$3:$J$688) -> 0.00058791594
B23: 44929 | C23: 0.62 | D23: 0.62 | E23: =(D23/D22)-1 -> 0 | F23: 44929 | G23: 23.8 | H23: 14.0121 | I23: =(H23/H22)-1 -> -0.0041859143 | J23: 44929 | K23: 37 | L23: 22.2431 | M23: =(L23/L22)-1 -> -0.010692285 | N23: 44929 | O23: 25 | P23: 21.9819 | Q23: =(P23/P22)-1 -> -0.0079340365 | R23: 44929 | S23: 6.9 | T23: 6.0948 | U23: =(T23/T22)-1 -> -0.012875954 | V23: 44929 | W23: 6.32 | X23: 5.368 | Y23: =(X23/X22)-1 -> -0.0062939652 | Z23: 44929 | AA23: 1.9 | AB23: 1.9 | AC23: =(AB23/AB22)-1 -> 0 | AD23: 44929 | AE23: 8.17 | AF23: 7.3896 | AG23: =(AF23/AF22)-1 -> -0.010895462 | AH23: 44929 | AI23: 8.84 | AJ23: 7.7286 | AK23: =(AJ23/AJ22)-1 -> -0.01006763 | AL23: 44929 | AM23: 2 | AN23: 1.8756 | AO23: -0.043061224 | AP23: 03/01/23 | AQ23: 8069.25 | AR23: -0.0030824541
B24: 44930 | C24: 0.6 | D24: 0.6 | E24: =(D24/D23)-1 -> -0.032258065 | F24: 44930 | G24: 23.5 | H24: 13.8355 | I24: =(H24/H23)-1 -> -0.012603393 | J24: 44930 | K24: 37.88 | L24: 22.7721 | M24: =(L24/L23)-1 -> 0.023782656 | N24: 44930 | O24: 24.9 | P24: 21.8939 | Q24: =(P24/P23)-1 -> -0.0040032936 | R24: 44930 | S24: 6.8 | T24: 6.0065 | U24: =(T24/T23)-1 -> -0.01448776 | V24: 44930 | W24: 6.35 | X24: 5.394 | Y24: =(X24/X23)-1 -> 0.0048435171 | Z24: 44930 | AA24: 1.91 | AB24: 1.91 | AC24: =(AB24/AB23)-1 -> 0.0052631579 | AD24: 44930 | AE24: 8 | AF24: 7.2358 | AG24: =(AF24/AF23)-1 -> -0.020813035 | AH24: 44930 | AI24: 8.75 | AJ24: 7.6499 | AK24: =(AJ24/AJ23)-1 -> -0.010182957 | AL24: 44930 | AM24: 1.91 | AN24: 1.7912 | AO24: -0.044998934 | AP24: 04/01/23 | AQ24: 8048.7 | AR24: -0.0025467051
B25: 44931 | C25: 0.6 | D25: 0.6 | E25: =(D25/D24)-1 -> 0 | F25: 44931 | G25: 22.52 | H25: 13.2585 | I25: =(H25/H24)-1 -> -0.041704311 | J25: 44931 | K25: 37.8 | L25: 22.724 | M25: =(L25/L24)-1 -> -0.0021122338 | N25: 44931 | O25: 24.98 | P25: 21.9643 | Q25: =(P25/P24)-1 -> 0.0032155075 | R25: 44931 | S25: 6.77 | T25: 5.98 | U25: =(T25/T24)-1 -> -0.0044118871 | V25: 44931 | W25: 6.2 | X25: 5.266 | Y25: =(X25/X24)-1 -> -0.02373007 | Z25: 44931 | AA25: 1.91 | AB25: 1.91 | AC25: =(AB25/AB24)-1 -> 0 | AD25: 44931 | AE25: 8 | AF25: 7.2358 | AG25: =(AF25/AF24)-1 -> 0 | AH25: 44931 | AI25: 8.73 | AJ25: 7.6324 | AK25: =(AJ25/AJ24)-1 -> -0.0022876116 | AL25: 44931 | AM25: 1.99 | AN25: 1.8662 | AO25: 0.041871371 | AP25: 05/01/23 | AQ25: 8087.56 | AR25: 0.0048281089 | AU25: Portfolio daily Variance | AV25: {=MMULT(MMULT(AV8:BE8,AV13:BE22),TRANSPOSE(AV8:BE8))} -> 5.9125745e-05
B26: 44932 | C26: 0.6 | D26: 0.6 | E26: =(D26/D25)-1 -> 0 | F26: 44932 | G26: 22.52 | H26: 13.2585 | I26: =(H26/H25)-1 -> 0 | J26: 44932 | K26: 39 | L26: 23.4454 | M26: =(L26/L25)-1 -> 0.031746171 | N26: 44932 | O26: 24.84 | P26: 21.8412 | Q26: =(P26/P25)-1 -> -0.0056045492 | R26: 44932 | S26: 6.7 | T26: 5.9182 | U26: =(T26/T25)-1 -> -0.010334448 | V26: 44932 | W26: 6.3 | X26: 5.351 | Y26: =(X26/X25)-1 -> 0.016141284 | Z26: 44932 | AA26: 1.92 | AB26: 1.92 | AC26: =(AB26/AB25)-1 -> 0.0052356021 | AD26: 44932 | AE26: 8 | AF26: 7.2358 | AG26: =(AF26/AF25)-1 -> 0 | AH26: 44932 | AI26: 8.78 | AJ26: 7.6761 | AK26: =(AJ26/AJ25)-1 -> 0.0057255909 | AL26: 44932 | AM26: 2.07 | AN26: 1.9412 | AO26: 0.040188619 | AP26: 06/01/23 | AQ26: 8105.78 | AR26: 0.0022528426 | AU26: Portfolio mean yearly return | AV26: =AVERAGE(Sheet2!K3:K688)*Sheet1!B3 -> 0.30434019
B27: 44935 | C27: 0.6 | D27: 0.6 | E27: =(D27/D26)-1 -> 0 | F27: 44935 | G27: 22.52 | H27: 13.2585 | I27: =(H27/H26)-1 -> 0 | J27: 44935 | K27: 38.8 | L27: 23.3252 | M27: =(L27/L26)-1 -> -0.0051268053 | N27: 44935 | O27: 24.82 | P27: 21.8236 | Q27: =(P27/P26)-1 -> -0.00080581653 | R27: 44935 | S27: 6.79 | T27: 5.9977 | U27: =(T27/T26)-1 -> 0.013433138 | V27: 44935 | W27: 6.3 | X27: 5.351 | Y27: =(X27/X26)-1 -> 0 | Z27: 44935 | AA27: 1.91 | AB27: 1.91 | AC27: =(AB27/AB26)-1 -> -0.0052083333 | AD27: 44935 | AE27: 7.8 | AF27: 7.0549 | AG27: =(AF27/AF26)-1 -> -0.025000691 | AH27: 44935 | AI27: 8.68 | AJ27: 7.5887 | AK27: =(AJ27/AJ26)-1 -> -0.01138599 | AL27: 44935 | AM27: 1.98 | AN27: 1.8568 | AO27: -0.043478261 | AP27: 09/01/23 | AQ27: 8106.59 | AR27: 9.9928693e-05 | AU27: portfolio yearly std | AV27: =SQRT(AV25*$B$3) -> 0.12206428
B28: 44936 | C28: 0.63 | D28: 0.63 | E28: =(D28/D27)-1 -> 0.05 | F28: 44936 | G28: 22.52 | H28: 13.2585 | I28: =(H28/H27)-1 -> 0 | J28: 44936 | K28: 39.59 | L28: 23.8001 | M28: =(L28/L27)-1 -> 0.020359954 | N28: 44936 | O28: 24.13 | P28: 21.2169 | Q28: =(P28/P27)-1 -> -0.02780018 | R28: 44936 | S28: 6.78 | T28: 5.9888 | U28: =(T28/T27)-1 -> -0.0014839022 | V28: 44936 | W28: 6.26 | X28: 5.317 | Y28: =(X28/X27)-1 -> -0.0063539525 | Z28: 44936 | AA28: 1.91 | AB28: 1.91 | AC28: =(AB28/AB27)-1 -> 0 | AD28: 44936 | AE28: 7.75 | AF28: 7.0097 | AG28: =(AF28/AF27)-1 -> -0.0064068945 | AH28: 44936 | AI28: 8.69 | AJ28: 7.5974 | AK28: =(AJ28/AJ27)-1 -> 0.0011464414 | AL28: 44936 | AM28: 1.91 | AN28: 1.7912 | AO28: -0.035329599 | AP28: 10/01/23 | AQ28: 8105.9 | AR28: -8.5115937e-05 | AU28: Sharpe Ratio | AV28: =(AV26-$B$2)/AV27 -> 1.879667
B29: 44937 | C29: 0.66 | D29: 0.66 | E29: =(D29/D28)-1 -> 0.047619048 | F29: 44937 | G29: 22.52 | H29: 13.2585 | I29: =(H29/H28)-1 -> 0 | J29: 44937 | K29: 39.99 | L29: 24.0406 | M29: =(L29/L28)-1 -> 0.010105 | N29: 44937 | O29: 24.13 | P29: 21.2169 | Q29: =(P29/P28)-1 -> 0 | R29: 44937 | S29: 6.7 | T29: 5.9182 | U29: =(T29/T28)-1 -> -0.011788672 | V29: 44937 | W29: 6.2 | X29: 5.266 | Y29: =(X29/X28)-1 -> -0.0095918751 | Z29: 44937 | AA29: 1.88 | AB29: 1.88 | AC29: =(AB29/AB28)-1 -> -0.015706806 | AD29: 44937 | AE29: 7.55 | AF29: 6.8288 | AG29: =(AF29/AF28)-1 -> -0.025807096 | AH29: 44937 | AI29: 8.6 | AJ29: 7.5187 | AK29: =(AJ29/AJ28)-1 -> -0.010358807 | AL29: 44937 | AM29: 1.99 | AN29: 1.8662 | AO29: 0.041871371 | AP29: 11/01/23 | AQ29: 8116.31 | AR29: 0.0012842497 | AU29: Weights constraint | AV29: =SUM(AV8:BE8) -> 1 | AW29: = | AX29: 1
B30: 44938 | C30: 0.66 | D30: 0.66 | E30: =(D30/D29)-1 -> 0 | F30: 44938 | G30: 21.9 | H30: 12.8935 | I30: =(H30/H29)-1 -> -0.027529509 | J30: 44938 | K30: 41.56 | L30: 24.9844 | M30: =(L30/L29)-1 -> 0.039258588 | N30: 44938 | O30: 24 | P30: 21.1026 | Q30: =(P30/P29)-1 -> -0.0053872149 | R30: 44938 | S30: 6.66 | T30: 5.8828 | U30: =(T30/T29)-1 -> -0.0059815484 | V30: 44938 | W30: 6.25 | X30: 5.309 | Y30: =(X30/X29)-1 -> 0.0081655906 | Z30: 44938 | AA30: 1.89 | AB30: 1.89 | AC30: =(AB30/AB29)-1 -> 0.0053191489 | AD30: 44938 | AE30: 7.85 | AF30: 7.1001 | AG30: =(AF30/AF29)-1 -> 0.039728796 | AH30: 44938 | AI30: 8.6 | AJ30: 7.5187 | AK30: =(AJ30/AJ29)-1 -> 0 | AL30: 44938 | AM30: 1.91 | AN30: 1.7912 | AO30: -0.040188619 | AP30: 12/01/23 | AQ30: 8237.83 | AR30: 0.014972321
B31: 44939 | C31: 0.67 | D31: 0.67 | E31: =(D31/D30)-1 -> 0.015151515 | F31: 44939 | G31: 22.29 | H31: 13.1231 | I31: =(H31/H30)-1 -> 0.017807422 | J31: 44939 | K31: 42.6 | L31: 25.6096 | M31: =(L31/L30)-1 -> 0.025023615 | N31: 44939 | O31: 24 | P31: 21.1026 | Q31: =(P31/P30)-1 -> 0 | R31: 44939 | S31: 6.94 | T31: 6.1302 | U31: =(T31/T30)-1 -> 0.042054804 | V31: 44939 | W31: 6.1 | X31: 5.181 | Y31: =(X31/X30)-1 -> -0.024110002 | Z31: 44939 | AA31: 1.87 | AB31: 1.87 | AC31: =(AB31/AB30)-1 -> -0.010582011 | AD31: 44939 | AE31: 8.29 | AF31: 7.4981 | AG31: =(AF31/AF30)-1 -> 0.056055549 | AH31: 44939 | AI31: 8.68 | AJ31: 7.5887 | AK31: =(AJ31/AJ30)-1 -> 0.0093101201 | AL31: 44939 | AM31: 1.97 | AN31: 1.8475 | AO31: 0.031431443 | AP31: 13/01/23 | AQ31: 8287.21 | AR31: 0.005994297
B32: 44942 | C32: 0.66 | D32: 0.66 | E32: =(D32/D31)-1 -> -0.014925373 | F32: 44942 | G32: 22 | H32: 12.9524 | I32: =(H32/H31)-1 -> -0.013007597 | J32: 44942 | K32: 42.79 | L32: 25.7238 | M32: =(L32/L31)-1 -> 0.0044592653 | N32: 44942 | O32: 23.8 | P32: 20.9267 | Q32: =(P32/P31)-1 -> -0.0083354658 | R32: 44942 | S32: 6.89 | T32: 6.086 | U32: =(T32/T31)-1 -> -0.0072102052 | V32: 44942 | W32: 6.38 | X32: 5.419 | Y32: =(X32/X31)-1 -> 0.045937078 | Z32: 44942 | AA32: 1.87 | AB32: 1.87 | AC32: =(AB32/AB31)-1 -> 0 | AD32: 44942 | AE32: 8.11 | AF32: 7.3353 | AG32: =(AF32/AF31)-1 -> -0.021712167 | AH32: 44942 | AI32: 8.62 | AJ32: 7.5362 | AK32: =(AJ32/AJ31)-1 -> -0.006918181 | AL32: 44942 | AM32: 1.9 | AN32: 1.7818 | AO32: -0.03556157 | AP32: 16/01/23 | AQ32: 8302.2 | AR32: 0.0018088114
B33: 44943 | C33: 0.67 | D33: 0.67 | E33: =(D33/D32)-1 -> 0.015151515 | F33: 44943 | G33: 22 | H33: 12.9524 | I33: =(H33/H32)-1 -> 0 | J33: 44943 | K33: 42.55 | L33: 25.5795 | M33: =(L33/L32)-1 -> -0.0056095911 | N33: 44943 | O33: 24.49 | P33: 21.5334 | Q33: =(P33/P32)-1 -> 0.028991671 | R33: 44943 | S33: 6.87 | T33: 6.0683 | U33: =(T33/T32)-1 -> -0.0029083142 | V33: 44943 | W33: 6.44 | X33: 5.47 | Y33: =(X33/X32)-1 -> 0.0094113305 | Z33: 44943 | AA33: 1.9 | AB33: 1.9 | AC33: =(AB33/AB32)-1 -> 0.016042781 | AD33: 44943 | AE33: 8.18 | AF33: 7.3986 | AG33: =(AF33/AF32)-1 -> 0.0086295039 | AH33: 44943 | AI33: 8.88 | AJ33: 7.7635 | AK33: =(AJ33/AJ32)-1 -> 0.030161089 | AL33: 44943 | AM33: 1.83 | AN33: 1.7162 | AO33: -0.036816702 | AP33: 17/01/23 | AQ33: 8282.31 | AR33: -0.0023957505
B34: 44944 | C34: 0.66 | D34: 0.66 | E34: =(D34/D33)-1 -> -0.014925373 | F34: 44944 | G34: 21.99 | H34: 12.9465 | I34: =(H34/H33)-1 -> -0.00045551404 | J34: 44944 | K34: 41.9 | L34: 25.1888 | M34: =(L34/L33)-1 -> -0.01527395 | N34: 44944 | O34: 24.15 | P34: 21.2345 | Q34: =(P34/P33)-1 -> -0.013880762 | R34: 44944 | S34: 6.8 | T34: 6.0065 | U34: =(T34/T33)-1 -> -0.010184071 | V34: 44944 | W34: 6.4 | X34: 5.436 | Y34: =(X34/X33)-1 -> -0.0062157221 | Z34: 44944 | AA34: 1.9 | AB34: 1.9 | AC34: =(AB34/AB33)-1 -> 0 | AD34: 44944 | AE34: 7.75 | AF34: 7.0097 | AG34: =(AF34/AF33)-1 -> -0.052563999 | AH34: 44944 | AI34: 8.7 | AJ34: 7.6062 | AK34: =(AJ34/AJ33)-1 -> -0.02026148 | AL34: 44944 | AM34: 1.75 | AN34: 1.6412 | AO34: -0.0437012 | AP34: 18/01/23 | AQ34: 8230.55 | AR34: -0.0062494642
B35: 44945 | C35: 0.67 | D35: 0.67 | E35: =(D35/D34)-1 -> 0.015151515 | F35: 44945 | G35: 22.3 | H35: 13.129 | I35: =(H35/H34)-1 -> 0.014096474 | J35: 44945 | K35: 41.47 | L35: 24.9303 | M35: =(L35/L34)-1 -> -0.010262498 | N35: 44945 | O35: 24.46 | P35: 21.507 | Q35: =(P35/P34)-1 -> 0.01283289 | R35: 44945 | S35: 6.7 | T35: 5.9182 | U35: =(T35/T34)-1 -> -0.014700741 | V35: 44945 | W35: 6.43 | X35: 5.462 | Y35: =(X35/X34)-1 -> 0.0047829286 | Z35: 44945 | AA35: 1.91 | AB35: 1.91 | AC35: =(AB35/AB34)-1 -> 0.0052631579 | AD35: 44945 | AE35: 8 | AF35: 7.2358 | AG35: =(AF35/AF34)-1 -> 0.032255303 | AH35: 44945 | AI35: 8.68 | AJ35: 7.5887 | AK35: =(AJ35/AJ34)-1 -> -0.0023007546 | AL35: 44945 | AM35: 1.82 | AN35: 1.7068 | AO35: 0.039970753 | AP35: 19/01/23 | AQ35: 8229.79 | AR35: -9.2338908e-05
B36: 44946 | C36: 0.66 | D36: 0.66 | E36: =(D36/D35)-1 -> -0.014925373 | F36: 44946 | G36: 22 | H36: 12.9524 | I36: =(H36/H35)-1 -> -0.013451139 | J36: 44946 | K36: 41.7 | L36: 25.0685 | M36: =(L36/L35)-1 -> 0.0055434552 | N36: 44946 | O36: 24.5 | P36: 21.5422 | Q36: =(P36/P35)-1 -> 0.0016366764 | R36: 44946 | S36: 6.79 | T36: 5.9977 | U36: =(T36/T35)-1 -> 0.013433138 | V36: 44946 | W36: 6.43 | X36: 5.462 | Y36: =(X36/X35)-1 -> 0 | Z36: 44946 | AA36: 1.89 | AB36: 1.89 | AC36: =(AB36/AB35)-1 -> -0.010471204 | AD36: 44946 | AE36: 8.11 | AF36: 7.3353 | AG36: =(AF36/AF35)-1 -> 0.013751071 | AH36: 44946 | AI36: 8.65 | AJ36: 7.5624 | AK36: =(AJ36/AJ35)-1 -> -0.0034656792 | AL36: 44946 | AM36: 1.74 | AN36: 1.6318 | AO36: -0.04394188 | AP36: 20/01/23 | AQ36: 8248.48 | AR36: 0.0022710179
B37: 44949 | C37: 0.66 | D37: 0.66 | E37: =(D37/D36)-1 -> 0 | F37: 44949 | G37: 22.3 | H37: 13.129 | I37: =(H37/H36)-1 -> 0.013634539 | J37: 44949 | K37: 41.3 | L37: 24.8281 | M37: =(L37/L36)-1 -> -0.0095897242 | N37: 44949 | O37: 24.4 | P37: 21.4543 | Q37: =(P37/P36)-1 -> -0.0040803632 | R37: 44949 | S37: 6.79 | T37: 5.9977 | U37: =(T37/T36)-1 -> 0 | V37: 44949 | W37: 6.4 | X37: 5.436 | Y37: =(X37/X36)-1 -> -0.0047601611 | Z37: 44949 | AA37: 1.87 | AB37: 1.87 | AC37: =(AB37/AB36)-1 -> -0.010582011 | AD37: 44949 | AE37: 8.1 | AF37: 7.3263 | AG37: =(AF37/AF36)-1 -> -0.0012269437 | AH37: 44949 | AI37: 8.59 | AJ37: 7.51 | AK37: =(AJ37/AJ36)-1 -> -0.0069290172 | AL37: 44949 | AM37: 1.74 | AN37: 1.6318 | AO37: 0 | AP37: 23/01/23 | AQ37: 8203.97 | AR37: -0.0053961457
B38: 44950 | C38: 0.66 | D38: 0.66 | E38: =(D38/D37)-1 -> 0 | F38: 44950 | G38: 22.25 | H38: 13.0996 | I38: =(H38/H37)-1 -> -0.0022393175 | J38: 44950 | K38: 41.61 | L38: 25.0144 | M38: =(L38/L37)-1 -> 0.0075035947 | N38: 44950 | O38: 24.4 | P38: 21.4543 | Q38: =(P38/P37)-1 -> 0 | R38: 44950 | S38: 7.08 | T38: 6.2538 | U38: =(T38/T37)-1 -> 0.042699702 | V38: 44950 | W38: 6.35 | X38: 5.394 | Y38: =(X38/X37)-1 -> -0.0077262693 | Z38: 44950 | AA38: 1.85 | AB38: 1.85 | AC38: =(AB38/AB37)-1 -> -0.010695187 | AD38: 44950 | AE38: 8 | AF38: 7.2358 | AG38: =(AF38/AF37)-1 -> -0.012352757 | AH38: 44950 | AI38: 8.66 | AJ38: 7.5712 | AK38: =(AJ38/AJ37)-1 -> 0.0081491345 | AL38: 44950 | AM38: 1.8 | AN38: 1.688 | AO38: 0.034440495 | AP38: 24/01/23 | AQ38: 8235.56 | AR38: 0.0038505748
B39: 44951 | C39: 0.67 | D39: 0.67 | E39: =(D39/D38)-1 -> 0.015151515 | F39: 44951 | G39: 22.19 | H39: 13.0642 | I39: =(H39/H38)-1 -> -0.0027023726 | J39: 44951 | K39: 41.54 | L39: 24.9724 | M39: =(L39/L38)-1 -> -0.0016790329 | N39: 44951 | O39: 24 | P39: 21.1026 | Q39: =(P39/P38)-1 -> -0.016392984 | R39: 44951 | S39: 7.08 | T39: 6.2538 | U39: =(T39/T38)-1 -> 0 | V39: 44951 | W39: 6.38 | X39: 5.419 | Y39: =(X39/X38)-1 -> 0.0046347794 | Z39: 44951 | AA39: 1.86 | AB39: 1.86 | AC39: =(AB39/AB38)-1 -> 0.0054054054 | AD39: 44951 | AE39: 7.82 | AF39: 7.073 | AG39: =(AF39/AF38)-1 -> -0.02249924 | AH39: 44951 | AI39: 8.64 | AJ39: 7.5537 | AK39: =(AJ39/AJ38)-1 -> -0.0023113905 | AL39: 44951 | AM39: 1.74 | AN39: 1.6318 | AO39: -0.033293839 | AP39: 25/01/23 | AQ39: 8223.82 | AR39: -0.0014255254
B40: 44952 | C40: 0.69 | D40: 0.69 | E40: =(D40/D39)-1 -> 0.029850746 | F40: 44952 | G40: 22.19 | H40: 13.0642 | I40: =(H40/H39)-1 -> 0 | J40: 44952 | K40: 41 | L40: 24.6477 | M40: =(L40/L39)-1 -> -0.013002355 | N40: 44952 | O40: 24 | P40: 21.1026 | Q40: =(P40/P39)-1 -> 0 | R40: 44952 | S40: 7.09 | T40: 6.2626 | U40: =(T40/T39)-1 -> 0.0014071445 | V40: 44952 | W40: 6.27 | X40: 5.326 | Y40: =(X40/X39)-1 -> -0.017161838 | Z40: 44952 | AA40: 1.86 | AB40: 1.86 | AC40: =(AB40/AB39)-1 -> 0 | AD40: 44952 | AE40: 7.8 | AF40: 7.0549 | AG40: =(AF40/AF39)-1 -> -0.0025590273 | AH40: 44952 | AI40: 8.6 | AJ40: 7.5187 | AK40: =(AJ40/AJ39)-1 -> -0.0046334909 | AL40: 44952 | AM40: 1.8 | AN40: 1.688 | AO40: 0.034440495 | AP40: 26/01/23 | AQ40: 8271.98 | AR40: 0.0058561593
...

Sheet Sheet2
A1: Adjusted Return
A2: Tawasol GH | B2: Smart Tunisie | C2: Attijari Bank | D2: Euro-cycles | E2: UNIMED | F2: AMV | G2: Carthage Cement | H2: Poulina | I2: One Tech Holding | J2: Essoukna | K2: Portfolio Return
A3: 0 | B3: -0.0041859143 | C3: -0.010692285 | D3: -0.0079340365 | E3: -0.012875954 | F3: -0.0062939652 | G3: 0 | H3: -0.010895462 | I3: -0.01006763 | J3: -0.043061224 | K3: =SUMPRODUCT(Sheet1!$AV$8:$BE$8,Sheet2!A3:J3) -> -0.01025131 | N3: Tawasol GH | O3: Smart Tunisie | P3: Attijari Bank | Q3: Euro-cycles | R3: UNIMED | S3: AMV | T3: Carthage Cement | U3: Poulina | V3: One Tech Holding | W3: Essoukna
A4: -0.032258065 | B4: -0.012603393 | C4: 0.023782656 | D4: -0.0040032936 | E4: -0.01448776 | F4: 0.0048435171 | G4: 0.0052631579 | H4: -0.020813035 | I4: -0.010182957 | J4: -0.044998934 | K4: =SUMPRODUCT(Sheet1!$AV$8:$BE$8,Sheet2!A4:J4) -> 0.0053018588 | M4: Tawasol GH | N4: =VARP(Sheet2!$A$3:$A$688) -> 0.00061483487 | O4: 8.4193824e-06 | P4: 5.0376465e-06 | Q4: 1.4862964e-06 | R4: -8.0487406e-06 | S4: 3.271657e-06 | T4: 3.6547178e-07 | U4: 9.1149964e-07 | V4: 2.4113683e-05 | W4: -4.6351158e-06
A5: 0 | B5: -0.041704311 | C5: -0.0021122338 | D5: 0.0032155075 | E5: -0.0044118871 | F5: -0.02373007 | G5: 0 | H5: 0 | I5: -0.0022876116 | J5: 0.041871371 | K5: =SUMPRODUCT(Sheet1!$AV$8:$BE$8,Sheet2!A5:J5) -> -0.0039823876 | M5: Smart Tunisie | N5: 8.4193824e-06 | O5: =VARP(Sheet2!$B$3:$B$688) -> 0.00020790742 | P5: -6.525042e-07 | Q5: -1.1754641e-06 | R5: 6.0257957e-06 | S5: -7.520089e-07 | T5: -2.9940598e-07 | U5: 2.3912874e-06 | V5: 8.0255938e-06 | W5: 4.0085751e-06
A6: 0 | B6: 0 | C6: 0.031746171 | D6: -0.0056045492 | E6: -0.010334448 | F6: 0.016141284 | G6: 0.0052356021 | H6: 0 | I6: 0.0057255909 | J6: 0.040188619 | K6: =SUMPRODUCT(Sheet1!$AV$8:$BE$8,Sheet2!A6:J6) -> 0.018017664 | M6: Attijari Bank | N6: 5.0376465e-06 | O6: -6.525042e-07 | P6: =VARP(Sheet2!$C$3:$C$688) -> 0.00015450016 | Q6: 8.941829e-06 | R6: 1.732876e-05 | S6: 8.8511638e-06 | T6: 1.3101995e-05 | U6: 1.1273361e-05 | V6: 1.7037604e-05 | W6: 3.002134e-05
A7: 0 | B7: 0 | C7: -0.0051268053 | D7: -0.00080581653 | E7: 0.013433138 | F7: 0 | G7: -0.0052083333 | H7: -0.025000691 | I7: -0.01138599 | J7: -0.043478261 | K7: =SUMPRODUCT(Sheet1!$AV$8:$BE$8,Sheet2!A7:J7) -> -0.0099761092 | M7: Euro-cycles | N7: 1.4862964e-06 | O7: -1.1754641e-06 | P7: 8.941829e-06 | Q7: =VARP(Sheet2!$D$3:$D$688) -> 0.000289823 | R7: 2.8234252e-06 | S7: -2.7647058e-06 | T7: 9.4564557e-06 | U7: 2.4021564e-06 | V7: 2.1337185e-06 | W7: 1.757721e-05
A8: 0.05 | B8: 0 | C8: 0.020359954 | D8: -0.02780018 | E8: -0.0014839022 | F8: -0.0063539525 | G8: 0 | H8: -0.0064068945 | I8: 0.0011464414 | J8: -0.035329599 | K8: =SUMPRODUCT(Sheet1!$AV$8:$BE$8,Sheet2!A8:J8) -> 0.0081650012 | M8: UNIMED | N8: -8.0487406e-06 | O8: 6.0257957e-06 | P8: 1.732876e-05 | Q8: 2.8234252e-06 | R8: =VARP(Sheet2!$E$3:$E$688) -> 0.00015169217 | S8: 4.2896617e-06 | T8: -2.6383546e-07 | U8: 2.1478978e-05 | V8: 9.4837469e-06 | W8: 2.5469313e-05
A9: 0.047619048 | B9: 0 | C9: 0.010105 | D9: 0 | E9: -0.011788672 | F9: -0.0095918751 | G9: -0.015706806 | H9: -0.025807096 | I9: -0.010358807 | J9: 0.041871371 | K9: =SUMPRODUCT(Sheet1!$AV$8:$BE$8,Sheet2!A9:J9) -> -0.0032974866 | M9: AMV | N9: 3.271657e-06 | O9: -7.520089e-07 | P9: 8.8511638e-06 | Q9: -2.7647058e-06 | R9: 4.2896617e-06 | S9: =VARP(Sheet2!$F$3:$F$688) -> 0.00022771639 | T9: 8.9588515e-06 | U9: -4.1192155e-06 | V9: 7.0175593e-06 | W9: -1.0684985e-05
A10: 0 | B10: -0.027529509 | C10: 0.039258588 | D10: -0.0053872149 | E10: -0.0059815484 | F10: 0.0081655906 | G10: 0.0053191489 | H10: 0.039728796 | I10: 0 | J10: -0.040188619 | K10: =SUMPRODUCT(Sheet1!$AV$8:$BE$8,Sheet2!A10:J10) -> 0.027756006 | M10: Carthage Cement | N10: 3.6547178e-07 | O10: -2.9940598e-07 | P10: 1.3101995e-05 | Q10: 9.4564557e-06 | R10: -2.6383546e-07 | S10: 8.9588515e-06 | T10: =VARP(Sheet2!$G$3:$G$688) -> 0.00013200624 | U10: -9.0133091e-07 | V10: 1.9287745e-06 | W10: 1.373486e-05
A11: 0.015151515 | B11: 0.017807422 | C11: 0.025023615 | D11: 0 | E11: 0.042054804 | F11: -0.024110002 | G11: -0.010582011 | H11: 0.056055549 | I11: 0.0093101201 | J11: 0.031431443 | K11: =SUMPRODUCT(Sheet1!$AV$8:$BE$8,Sheet2!A11:J11) -> 0.024394018 | M11: Poulina | N11: 9.1149964e-07 | O11: 2.3912874e-06 | P11: 1.1273361e-05 | Q11: 2.4021564e-06 | R11: 2.1478978e-05 | S11: -4.1192155e-06 | T11: -9.0133091e-07 | U11: =VARP(Sheet2!$H$3:$H$688) -> 0.00022591627 | V11: 1.6704339e-06 | W11: 2.0210158e-06
A12: -0.014925373 | B12: -0.013007597 | C12: 0.0044592653 | D12: -0.0083354658 | E12: -0.0072102052 | F12: 0.045937078 | G12: 0 | H12: -0.021712167 | I12: -0.006918181 | J12: -0.03556157 | K12: =SUMPRODUCT(Sheet1!$AV$8:$BE$8,Sheet2!A12:J12) -> -0.00010142486 | M12: One Tech Holding | N12: 2.4113683e-05 | O12: 8.0255938e-06 | P12: 1.7037604e-05 | Q12: 2.1337185e-06 | R12: 9.4837469e-06 | S12: 7.0175593e-06 | T12: 1.9287745e-06 | U12: 1.6704339e-06 | V12: =VARP(Sheet2!$I$3:$I$688) -> 9.9151658e-05 | W12: 1.5957746e-05
A13: 0.015151515 | B13: 0 | C13: -0.0056095911 | D13: 0.028991671 | E13: -0.0029083142 | F13: 0.0094113305 | G13: 0.016042781 | H13: 0.0086295039 | I13: 0.030161089 | J13: -0.036816702 | K13: =SUMPRODUCT(Sheet1!$AV$8:$BE$8,Sheet2!A13:J13) -> 0.0055475175 | M13: Essoukna | N13: -4.6351158e-06 | O13: 4.0085751e-06 | P13: 3.002134e-05 | Q13: 1.757721e-05 | R13: 2.5469313e-05 | S13: -1.0684985e-05 | T13: 1.373486e-05 | U13: 2.0210158e-06 | V13: 1.5957746e-05 | W13: =VARP(Sheet2!$J$3:$J$688) -> 0.00058791594
A14: -0.014925373 | B14: -0.00045551404 | C14: -0.01527395 | D14: -0.013880762 | E14: -0.010184071 | F14: -0.0062157221 | G14: 0 | H14: -0.052563999 | I14: -0.02026148 | J14: -0.0437012 | K14: =SUMPRODUCT(Sheet1!$AV$8:$BE$8,Sheet2!A14:J14) -> -0.023164296
A15: 0.015151515 | B15: 0.014096474 | C15: -0.010262498 | D15: 0.01283289 | E15: -0.014700741 | F15: 0.0047829286 | G15: 0.0052631579 | H15: 0.032255303 | I15: -0.0023007546 | J15: 0.039970753 | K15: =SUMPRODUCT(Sheet1!$AV$8:$BE$8,Sheet2!A15:J15) -> 0.0019487387 | N15: Tawasol GH | O15: Smart Tunisie | P15: Attijari Bank | Q15: Euro-cycles | R15: UNIMED | S15: AMV | T15: Carthage Cement | U15: Poulina | V15: One Tech Holding | W15: Essoukna
A16: -0.014925373 | B16: -0.013451139 | C16: 0.0055434552 | D16: 0.0016366764 | E16: 0.013433138 | F16: 0 | G16: -0.010471204 | H16: 0.013751071 | I16: -0.0034656792 | J16: -0.04394188 | K16: =SUMPRODUCT(Sheet1!$AV$8:$BE$8,Sheet2!A16:J16) -> 0.0047552961 | M16: Tawasol GH | N16: =VARP(Sheet2!$A$3:$A$688) -> 0.00061483487 | O16: 8.4193824e-06 | P16: 5.0376465e-06 | Q16: 1.4862964e-06 | R16: -8.0487406e-06 | S16: 3.271657e-06 | T16: 3.6547178e-07 | U16: 9.1149964e-07 | V16: 2.4113683e-05 | W16: -4.6351158e-06
A17: 0 | B17: 0.013634539 | C17: -0.0095897242 | D17: -0.0040803632 | E17: 0 | F17: -0.0047601611 | G17: -0.010582011 | H17: -0.0012269437 | I17: -0.0069290172 | J17: 0 | K17: =SUMPRODUCT(Sheet1!$AV$8:$BE$8,Sheet2!A17:J17) -> -0.0064987102 | M17: Smart Tunisie | O17: =VARP(Sheet2!$B$3:$B$688) -> 0.00020790742 | P17: -6.525042e-07 | Q17: -1.1754641e-06 | R17: 6.0257957e-06 | S17: -7.520089e-07 | T17: -2.9940598e-07 | U17: 2.3912874e-06 | V17: 8.0255938e-06 | W17: 4.0085751e-06
A18: 0 | B18: -0.0022393175 | C18: 0.0075035947 | D18: 0 | E18: 0.042699702 | F18: -0.0077262693 | G18: -0.010695187 | H18: -0.012352757 | I18: 0.0081491345 | J18: 0.034440495 | K18: =SUMPRODUCT(Sheet1!$AV$8:$BE$8,Sheet2!A18:J18) -> 0.0023250697 | M18: Attijari Bank | P18: =VARP(Sheet2!$C$3:$C$688) -> 0.00015450016 | Q18: 8.941829e-06 | R18: 1.732876e-05 | S18: 8.8511638e-06 | T18: 1.3101995e-05 | U18: 1.1273361e-05 | V18: 1.7037604e-05 | W18: 3.002134e-05
A19: 0.015151515 | B19: -0.0027023726 | C19: -0.0016790329 | D19: -0.016392984 | E19: 0 | F19: 0.0046347794 | G19: 0.0054054054 | H19: -0.02249924 | I19: -0.0023113905 | J19: -0.033293839 | K19: =SUMPRODUCT(Sheet1!$AV$8:$BE$8,Sheet2!A19:J19) -> -0.0057363012 | M19: Euro-cycles | Q19: =VARP(Sheet2!$D$3:$D$688) -> 0.000289823 | R19: 2.8234252e-06 | S19: -2.7647058e-06 | T19: 9.4564557e-06 | U19: 2.4021564e-06 | V19: 2.1337185e-06 | W19: 1.757721e-05
A20: 0.029850746 | B20: 0 | C20: -0.013002355 | D20: 0 | E20: 0.0014071445 | F20: -0.017161838 | G20: 0 | H20: -0.0025590273 | I20: -0.0046334909 | J20: 0.034440495 | K20: =SUMPRODUCT(Sheet1!$AV$8:$BE$8,Sheet2!A20:J20) -> -0.0091535411 | M20: UNIMED | R20: =VARP(Sheet2!$E$3:$E$688) -> 0.00015169217 | S20: 4.2896617e-06 | T20: -2.6383546e-07 | U20: 2.1478978e-05 | V20: 9.4837469e-06 | W20: 2.5469313e-05
A21: 0.043478261 | B21: -0.00044396136 | C21: 0 | D21: 0.016249183 | E21: -0.0098681059 | F21: 0.0046939542 | G21: 0.010752688 | H21: 0 | I21: 0 | J21: 0.044490521 | K21: =SUMPRODUCT(Sheet1!$AV$8:$BE$8,Sheet2!A21:J21) -> 0.00043959449 | M21: AMV | S21: =VARP(Sheet2!$F$3:$F$688) -> 0.00022771639 | T21: 8.9588515e-06 | U21: -4.1192155e-06 | V21: 7.0175593e-06 | W21: -1.0684985e-05
A22: -0.027777778 | B22: -0.017138394 | C22: -0.017072587 | D22: -0.0036884195 | E22: 0.01851374 | F22: 0.0095309288 | G22: -0.0053191489 | H22: -0.0025655927 | I22: -0.0011571149 | J22: 0.010606318 | K22: =SUMPRODUCT(Sheet1!$AV$8:$BE$8,Sheet2!A22:J22) -> -0.0083481439 | M22: Carthage Cement | T22: =VARP(Sheet2!$G$3:$G$688) -> 0.00013200624 | U22: -9.0133091e-07 | V22: 1.9287745e-06 | W22: 1.373486e-05
A23: -0.014285714 | B23: -0.0091705234 | C23: -0.00024765859 | D23: -0.0078206904 | E23: -0.0013933751 | F23: 0.0048130322 | G23: -0.0053475936 | H23: 0 | I23: -0.0081491345 | J23: 0.010551128 | K23: =SUMPRODUCT(Sheet1!$AV$8:$BE$8,Sheet2!A23:J23) -> -0.0013717264 | M23: Poulina | U23: =VARP(Sheet2!$H$3:$H$688) -> 0.00022591627 | V23: 1.6704339e-06 | W23: 2.0210158e-06
A24: -0.028985507 | B24: 0 | C24: 0.0052145048 | D24: 0.0058067955 | E24: 0 | F24: 0 | G24: -0.0053763441 | H24: 0 | I24: 0.0035173451 | J24: 0 | K24: =SUMPRODUCT(Sheet1!$AV$8:$BE$8,Sheet2!A24:J24) -> 0.0032205467 | M24: One Tech Holding | V24: =VARP(Sheet2!$I$3:$I$688) -> 9.9151658e-05 | W24: 1.5957746e-05
A25: -0.029850746 | B25: -0.0046316319 | C25: -0.0098779326 | D25: -0.0045351368 | E25: -0.0013953193 | F25: 0 | G25: 0.0054054054 | H25: -0.0038511824 | I25: -0.0070100334 | J25: 0 | K25: =SUMPRODUCT(Sheet1!$AV$8:$BE$8,Sheet2!A25:J25) -> -0.007051615 | M25: Essoukna | W25: =VARP(Sheet2!$J$3:$J$688) -> 0.00058791594
A26: -0.015384615 | B26: 0 | C26: 0.0099764796 | D26: 0.041836076 | E26: 0.035058749 | F26: 0 | G26: -0.0053763441 | H26: 0.027091031 | I26: -0.0058874249 | J26: 0 | K26: =SUMPRODUCT(Sheet1!$AV$8:$BE$8,Sheet2!A26:J26) -> 0.0097223765
A27: -0.046875 | B27: 0 | C27: 0.003454196 | D27: 0.059646283 | E27: -0.0013499417 | F27: -0.0062638172 | G27: 0.0054054054 | H27: -0.0012500694 | I27: -0.010665546 | J27: 0.0052204821 | K27: =SUMPRODUCT(Sheet1!$AV$8:$BE$8,Sheet2!A27:J27) -> -0.0011525712
A28: 0.049180328 | B28: 0 | C28: -0.010826276 | D28: 0.013131223 | E28: -0.0040706605 | F28: -0.0016685206 | G28: 0 | H28: -0.0037827163 | I28: 0.023944549 | J28: 0 | K28: =SUMPRODUCT(Sheet1!$AV$8:$BE$8,Sheet2!A28:J28) -> -0.0016765569
A29: 0 | B29: -0.013951651 | C29: -0.0014937849 | D29: -0.012223888 | E29: -0.0013727154 | F29: -0.015784587 | G29: -0.010752688 | H29: 0.0037970796 | I29: 0 | J29: -0.0051933702 | K29: =SUMPRODUCT(Sheet1!$AV$8:$BE$8,Sheet2!A29:J29) -> -0.0014910033
A30: 0 | B30: 0 | C30: -0.0037338328 | D30: -0.025121321 | E30: -0.030009576 | F30: -0.02245283 | G30: -0.0054347826 | H30: -0.031443829 | I30: 0.010528428 | J30: 0.0052204821 | K30: =SUMPRODUCT(Sheet1!$AV$8:$BE$8,Sheet2!A30:J30) -> -0.0085811905
A31: -0.015625 | B31: 0.014149054 | C31: 0.0024999376 | D31: -0.019229171 | E31: 0.030938013 | F31: 0.0065624397 | G31: 0 | H31: 0.018177902 | I31: 0 | J31: -0.041491713 | K31: =SUMPRODUCT(Sheet1!$AV$8:$BE$8,Sheet2!A31:J31) -> 0.0059287183
A32: -0.015873016 | B32: 0 | C32: -0.0072363043 | D32: -0.012550454 | E32: -0.0040929169 | F32: -0.0015340364 | G32: -0.0054644809 | H32: 0.0012691966 | I32: 0.012735481 | J32: 0.043287798 | K32: =SUMPRODUCT(Sheet1!$AV$8:$BE$8,Sheet2!A32:J32) -> -0.00087920284
A33: 0 | B33: 0 | C33: 0.0082921304 | D33: 0.00079493769 | E33: 0 | F33: -0.0049932783 | G33: 0 | H33: -0.025478514 | I33: 0.0354253 | J33: -0.0051933702 | K33: =SUMPRODUCT(Sheet1!$AV$8:$BE$8,Sheet2!A33:J33) -> 0.0050105572
A34: -0.048387097 | B34: 0.0046531838 | C34: -0.003237346 | D34: 0.023811136 | E34: -0.027387913 | F34: -0.0015441035 | G34: 0 | H34: 0 | I34: -0.022080824 | J34: 0 | K34: =SUMPRODUCT(Sheet1!$AV$8:$BE$8,Sheet2!A34:J34) -> -0.0060796304
A35: 0 | B35: -0.0046316319 | C35: 0 | D35: 0.0077495118 | E35: 0.019708204 | F35: -0.0017398028 | G35: -0.010989011 | H35: 0.0065469997 | I35: 0.020320165 | J35: 0.0052204821 | K35: =SUMPRODUCT(Sheet1!$AV$8:$BE$8,Sheet2!A35:J35) -> 0.0052190545
A36: 0.016949153 | B36: -0.0046531838 | C36: 0 | D36: -0.0073049853 | E36: -0.019327297 | F36: 0.0032920217 | G36: 0.011111111 | H36: 0.01947017 | I36: -0.0044284738 | J36: 0 | K36: =SUMPRODUCT(Sheet1!$AV$8:$BE$8,Sheet2!A36:J36) -> 0.0033430179
A37: -0.016666667 | B37: 0.0093498742 | C37: -0.0024993138 | D37: 0.0065832089 | E37: 0.0070318106 | F37: -0.0032812198 | G37: 0 | H37: -0.031844622 | I37: 0 | J37: 0 | K37: =SUMPRODUCT(Sheet1!$AV$8:$BE$8,Sheet2!A37:J37) -> -0.0080512052
... A688: 0 | B688: 0 | C688: -0.0016051364 | D688: -0.002276176 | E688: -0.0034965035 | F688: 0 | G688: 0 | H688: 0.010854817 | I688: -0.0079365079 | J688: -0.020408163 | K688: =SUMPRODUCT(Sheet1!$AV$8:$BE$8,Sheet2!A688:J688) -> -8.9656426e-05
