Workbook

Sheet Data 
A1: *All figures in TND | C1: Net income | H1: Total revenues | M1: Liabilities | R1: Equity
A2: Name | B2: shares | C2: 2020 | D2: 2021 | E2: 2022 | F2: 2023 | G2: 2024 | H2: 2020 | I2: 2021 | J2: 2022 | K2: 2023 | L2: 2024 | M2: 2020 | N2: 2021 | O2: 2022 | P2: 2023 | Q2: 2024 | R2: 2020 | S2: 2021 | T2: 2022 | U2: 2023 | V2: 2024
A3: société de fabrication des boissons de tunisie | B3: 268125000 | C3: 210586454 | D3: 251025666 | E3: 257026776 | F3: 281681042 | G3: 282951677 | H3: 1202858757 | I3: 1197117395 | J3: 1329913407 | K3: 1369328653 | L3: 1396203653 | M3: 605198771 | N3: 582089575 | O3: 663900702 | P3: 674204914 | Q3: 702784435 | R3: 1044895289 | S3: 1128462280 | T3: 1214081074 | U3: 1330442193 | V3: 1419478330
A4: Banque Attijari De Tunisie | B4: 42000000 | C4: 275188000 | D4: 283034000 | E4: 332403000 | F4: 366478000 | G4: 356943000 | H4: 543892000 | I4: 601056000 | J4: 664428000 | K4: 692133000 | L4: 739756000 | M4: 9404191000 | N4: 10014188000 | O4: 10671334000 | P4: 10761871000 | Q4: 11218431000 | R4: 885704000 | S4: 944291000 | T4: 1012474000 | U4: 1119719000 | V4: 1182999000
A5: Poulina Group Holding | B5: 180003600 | C5: 74937220 | D5: 93285368 | E5: 65769556 | F5: 129654069 | G5: 162090645 | H5: 2293947835 | I5: 2882599824 | J5: 3164460391 | K5: 3477502364 | L5: 3447451207 | M5: 2811485344 | N5: 3996369427 | O5: 4270526977 | P5: 3367995642 | Q5: 3249814754 | R5: 942307377 | S5: 979707603 | T5: 978293945 | U5: 1062563406 | V5: 1151954920
A6: Societe Delice Holding | B6: 54907262 | C6: 57816018 | D6: 70352493 | E6: 78543635 | F6: 97781367 | G6: 101013371 | H6: 1046727484 | I6: 1164933467 | J6: 1266872997 | K6: 1388767638 | L6: 1442665250 | M6: 421245165 | N6: 404261860 | O6: 450915549 | P6: 522155650 | Q6: 564831339 | R6: 241147799 | S6: 304147184 | T6: 364189269 | U6: 422934128 | V6: 489797529
A7: One Tech Holding | B7: 80400000 | C7: 19769312 | D7: 30744092 | E7: 13791941 | F7: 38332438 | G7: 30197705 | H7: 718581103 | I7: 905056057 | J7: 1046772970 | K7: 1104751430 | L7: 1048199298 | M7: 310101478 | N7: 335686674 | O7: 366593922 | P7: 349239677 | Q7: 298618444 | R7: 346534054 | S7: 362643559 | T7: 354158354 | U7: 386546573 | V7: 394399831
A8: Carthage Cement | B8: 343624940 | C8: 19364586 | D8: 31509188 | E8: 35650372 | F8: 55193147 | G8: 70256035 | H8: 252976021 | I8: 325968814 | J8: 366979942 | K8: 431588146 | L8: 421573245 | M8: 708595935 | N8: 640245531 | O8: 658953060 | P8: 615719080 | Q8: 544934512 | R8: 135979012 | S8: 167488200 | T8: 203138572 | U8: 258331719 | V8: 328587754
A9: SOTUVER | B9: 39254475 | C9: 10651279 | D9: 19985560 | E9: 29905517 | F9: 46641768 | G9: 41791733 | H9: 91090533 | I9: 104902769 | J9: 156191940 | K9: 262355892 | L9: 235107783 | M9: 91956837 | N9: 170267584 | O9: 264579385 | P9: 334927249 | Q9: 401543583 | R9: 75018410 | S9: 85484294 | T9: 101921247 | U9: 130270434 | V9: 150579061
A10: Societe Tunisie Profiles Aluminium | B10: 50000000 | C10: 21220962 | D10: 19059221 | E10: 28965394 | F10: 41345385 | G10: 48271762 | H10: 180466964 | I10: 214886191 | J10: 284773841 | K10: 287981082 | L10: 340361979 | M10: 131432591 | N10: 155341106 | O10: 167089348 | P10: 160005488 | Q10: 208765994 | R10: 136745685 | S10: 137213594 | T10: 148247471 | U10: 180629473 | V10: 210685434
A11: SPDIT-SICAF | B11: 28000000 | C11: 16915587 | D11: 17431933 | E11: 21767036 | F11: 26798947 | G11: 31978317 | H11: 19682665 | I11: 20489302 | J11: 23671906 | K11: 31146141 | L11: 34548651 | M11: 2782823 | N11: 1921585 | O11: 2792929 | P11: 4279120 | Q11: 4487488 | R11: 70761043 | S11: 71392976 | T11: 76360012 | U11: 83558959 | V11: 91737276
A12: Automobile Reseau Tunisien Et Service SA | B12: 38250000 | C12: 33238344 | D12: 41292326 | E12: 29181541 | F12: 42191994 | G12: 42191994 | H12: 212270266 | I12: 270149720 | J12: 175328865 | K12: 307457210 | L12: 307457210 | M12: 83515129 | N12: 47123113 | O12: 69394960 | P12: 147330366 | Q12: 157502369 | R12: 202470049 | S12: 213751115 | T12: 212324796 | U12: 140945761 | V12: 223222609
A13: City Cars | B13: 18000000 | C13: 20997476 | D13: 33354791 | E13: 30325763 | F13: 31718596 | G13: 29518791 | H13: 236557895 | I13: 343752648 | J13: 343102459 | K13: 375037265 | L13: 378411694 | M13: 94479452 | N13: 125141075 | O13: 156681418 | P13: 178709683 | Q13: 188626944 | R13: 57993863 | S13: 75777791 | T13: 84264584 | U13: 93488979 | V13: 100515697
A14: Ste Assurances Magrebia SA | B14: 4500000 | C14: 53498963 | D14: 77138663 | E14: 81214552 | F14: 82043544 | G14: 100657148 | H14: 39437994 | I14: 25824239 | J14: 28099216 | K14: 58872202 | L14: 69462727 | M14: 705324780 | N14: 748804044 | O14: 818450849 | P14: 925960837 | Q14: 1000685399 | R14: =45000000+64915188 -> 109915188 | S14: 154247479 | T14: 180502400 | U14: 202661534 | V14: 222179266
A15: Tunisie Leasing | B15: 10800000 | C15: 8979580 | D15: 7219162 | E15: 20706291 | F15: 28217472 | G15: 37470534 | H15: 144274295 | I15: 135140038 | J15: 150119991 | K15: 159079516 | L15: 195436341 | M15: 1796491353 | N15: 1775948425 | O15: 1776253794 | P15: 1982538258 | Q15: 2701941948 | R15: 223423406 | S15: 219991497 | T15: 239740658 | U15: 262109131 | V15: 289189747
A16: Compagnie Internationale De Leasing | B16: 7000000 | C16: 12447280 | D16: 15554485 | E16: 17229686 | F16: 19604550 | G16: 20182707 | H16: 30371293 | I16: 37117968 | J16: 42675715 | K16: 43823948 | L16: 46075652 | M16: 519445701 | N16: 538160372 | O16: 526021032 | P16: 573586678 | Q16: 591321795 | R16: 102953690 | S16: 109669667 | T16: 117583196 | U16: 127006909 | V16: 134157467
A17: Tunis RE | B17: 20000000 | C17: 739837 | D17: 334289 | E17: 440431 | F17: 114589 | G17: 3559600 | H17: 26770378 | I17: 23989023 | J17: 26689229 | K17: 31460523 | L17: 34087211 | M17: 707669341 | N17: 688447995 | O17: 707235919 | P17: 679956517 | Q17: 764975240 | R17: 212407678 | S17: 223916077 | T17: 236382079 | U17: 246462733 | V17: 258375216
A18: Assurances Maghrebia Vie SA | B18: 25000000 | C18: 12061819 | D18: 13614231 | E18: 13631045 | F18: 14999019 | G18: 26535372 | H18: 15282744 | I18: 17646440 | J18: 19923333 | K18: 22261847 | L18: 24899687 | M18: 369823362 | N18: 433230835 | O18: 496111565 | P18: 695019447 | Q18: 776430083 | R18: 62863953 | S18: 72697316 | T18: 115471809 | U18: 127870307 | V18: 142842908
A19: SAH | B19: =84015979 -> 84015979 | C19: 33389210 | D19: 16220997 | E19: 35323742 | F19: 35650047 | G19: 61608801 | H19: 631666504 | I19: 673903901 | J19: 880620421 | K19: 901985011 | L19: 981989853 | M19: 571148278 | N19: 669145153 | O19: 715018763 | P19: 760318382 | Q19: 882318491 | R19: 314215854 | S19: 295909720 | T19: 312143492 | U19: 319267092 | V19: 353488673
A20: Arab Tunisian Lease | B20: 32500000 | C20: 5279696 | D20: 11132156 | E20: 16270427 | F20: 19975764 | G20: 22111702 | H20: 30224741 | I20: 39917653 | J20: 46605128 | K20: 51196690 | L20: 58431579 | M20: 101586485 | N20: 550778433 | O20: 511992456 | P20: 555632129 | Q20: 577991444 | R20: 529216961 | S20: 110283583 | T20: 120054439 | U20: 131251766 | V20: 143613469
A21: Societe Tunisienne des Marches de Gros SA | B21: 13200000 | C21: 4635285 | D21: 5846000 | E21: 6221525 | F21: 7650860 | G21: 7058807 | H21: 14953062 | I21: 15429133 | J21: 16508737 | K21: 17707272 | L21: 18543742 | M21: 4661439 | N21: 4534835 | O21: 5959719 | P21: 6392678 | Q21: 6362805 | R21: 29054683 | S21: 31809716 | T21: 32624556 | U21: 34528357 | V21: 34496586
A22: Hannibal Lease | B22: 11000000 | C22: -3178572 | D22: 5908464 | E22: 7977572 | F22: 13065086 | G22: 12638444 | H22: 18642707 | I22: 32461319 | J22: 43826623 | K22: 46219616 | L22: 48837921 | M22: 609669899 | N22: 546064460 | O22: 537406584 | P22: 567056088 | Q22: 636933102 | R22: 70402866 | S22: 76174587 | T22: 81775841 | U22: 91419671 | V22: 99902831
A23: ATB | B23: 128000000 | C23: 12458000 | D23: -61435000 | E23: 29600000 | F23: -158000 | G23: 31285000 | H23: 297547000 | I23: 333106000 | J23: 365930000 | K23: 406023000 | L23: 436785000 | M23: 7371459000 | N23: 7630042000 | O23: 7744312000 | P23: 7600100000 | Q23: 8360359000 | R23: 585655000 | S23: 594128000 | T23: 618059000 | U23: 617788000 | V23: 649326000
A24: BIAT | B24: 40800000 | C24: 277480000 | D24: 283431000 | E24: 312402000 | F24: 358591000 | G24: 379406000 | H24: 1034036000 | I24: 1134600000 | J24: 1415147000 | K24: 1603909000 | L24: 1750286000 | M24: 16106196000 | N24: 17356171000 | O24: 18948687000 | P24: 20633250000 | Q24: 22776769000 | R24: 1771111000 | S24: 1877408000 | T24: 2000681000 | U24: 2158755000 | V24: 2314276000
A25: BNA | B25: 64000000 | C25: 107639000 | D25: 173366000 | E25: 169910000 | F25: 212043000 | G25: 210906000 | H25: 691244000 | I25: 912190000 | J25: 946380000 | K25: 1047026000 | L25: 1044281000 | M25: 12684441000 | N25: 17590365000 | O25: 20071667000 | P25: 21323167000 | Q25: 20576496000 | R25: 1650596000 | S25: 1761097000 | T25: 1865475000 | U25: 2035541000 | V25: 2188321000
A26: BT | B26: 270000000 | C26: 94411000 | D26: 152124000 | E26: 168562000 | F26: 182322000 | G26: 199437000 | H26: 380424000 | I26: 385983000 | J26: 428815000 | K26: 493636000 | L26: 518336000 | M26: 5566025000 | N26: 5851368000 | O26: 6387792000 | P26: 6918575000 | Q26: 7783177000 | R26: 1089048000 | S26: 1163594000 | T26: 1281121000 | U26: 1385289000 | V26: 1457011000
A27: AMEN BANK | B27: 30264000 | C27: 98440000 | D27: 136147000 | E27: 152578000 | F27: 216546000 | G27: 243545000 | H27: 395028000 | I27: 453158000 | J27: 488396000 | K27: 538309000 | L27: 562660000 | M27: 7895119000 | N27: 8163618000 | O27: 8871857000 | P27: 9384043000 | Q27: 10072285000 | R27: 1169511000 | S27: 1241864000 | T27: 1366659000 | U27: 1564603000 | V27: 1703741000
A28: EURO-CYCLES | B28: 9801000 | C28: 16610924 | D28: 26619458 | E28: 16628745 | F28: 4959031.8 | G28: 10976341 | H28: 1.1983366e+08 | I28: 1.4913271e+08 | J28: 1.6271355e+08 | K28: 1.1321541e+08 | L28: 1.2225003e+08 | M28: 67110276 | N28: 1.5820675e+08 | O28: 1.6156741e+08 | P28: 1.1142387e+08 | Q28: 99591114 | R28: 46724056 | S28: =59646348.181-1616.184 -> 59644732 | T28: =61351391.438-1493.16 -> 61349898 | U28: =56259856.585-402.38 -> 56259454 | V28: =64094899.424-1105.968 -> 64093793
A29: ICF | B29: 2100000 | C29: -11366764 | D29: 9015089 | E29: 31090040 | F29: 7320560 | G29: 21453470 | H29: 117519304 | I29: 148047650 | J29: 230831878 | K29: 146579725 | L29: 169862009 | M29: 25293660 | N29: 47481668 | O29: 51268475 | P29: 25129700 | Q29: 55599127 | R29: 87466518 | S29: 93052722 | T29: 116093876 | U29: 107403020 | V29: 121626025
A30: STB | B30: 155375000 | C30: 72159000 | D30: 117019000 | E30: 87878000 | F30: 86035000 | G30: 102331000 | H30: 625657000 | I30: 650447000 | J30: 697492000 | K30: 714678000 | L30: 689336000 | M30: 11149312000 | N30: 12304641000 | O30: 13396948000 | P30: 13232421000 | Q30: 13480669000 | R30: 1100124000 | S30: 1267335000 | T30: 1356233000 | U30: 1323092000 | V30: 1419547000
A31: UIB | B31: 32560000 | C31: 65171000 | D31: 82782000 | E31: 132539000 | F31: 124983000 | G31: 71861000 | H31: 403016000 | I31: 444415000 | J31: 493246000 | K31: 522981000 | L31: 539825000 | M31: 5761185000 | N31: 6044581000 | O31: 6366819000 | P31: 6732963000 | Q31: 7268244000 | R31: 721311000 | S31: 780025000 | T31: 889994000 | U31: 987375000 | V31: 1030162000
A32: ENNAKL AUTOMOBILES | B32: 30000000 | C32: 14083691 | D32: 36056125 | E32: 43211101 | F32: 52798417 | G32: 55526338 | H32: 448683874 | I32: 538114892 | J32: 568542801 | K32: 348209795 | L32: 352118840 | M32: 202955633 | N32: 165667191 | O32: 291923651 | P32: 224228380 | Q32: 286727611 | R32: 163243575 | S32: 179686332 | T32: 203382280 | U32: 302335851 | V32: 331462189
A33: ASTREE | B33: 6000000 | C33: 25524992 | D33: 21056249 | E33: 17103870 | F33: 22678287 | G33: 28985751 | H33: =25863627+10533472+25395777 -> 61792876 | I33: =7762313+4208100+25190756 -> 37161169 | J33: =6846173+6959655+24305395 -> 38111223 | K33: =14782595+14560216+31466266 -> 60809077 | L33: =15541709+16950863+35701976 -> 68194548 | M33: =630810375-R33 -> 477472991 | N33: =686764477-S33 -> 529170844 | O33: =764430352-T33 -> 606532849 | P33: =864062717-U33 -> 695486928 | Q33: =817830616-V32 -> 486368427 | R33: 153337384 | S33: 157593633 | T33: 157897503 | U33: 168575789 | V33: 184361541
A34: BH LEASING | B34: 7000000 | C34: -513135 | D34: 1140342 | E34: 1961523 | F34: 3149573 | G34: 3898695 | H34: 8500405 | I34: 13704752 | J34: 15733748 | K34: 14960151 | L34: 18535404 | M34: 282858023 | N34: 254182700 | O34: 263947305 | P34: 251831404 | Q34: 270253037 | R34: 29189001 | S34: 30315318 | T34: 32265200 | U34: 35402071 | V34: 39285275
A35: CIMENTS DE BIZERTE | B35: 44047290 | C35: -421318 | D35: -6153262 | E35: -28950468 | F35: -34355944 | G35: -44790355 | H35: 111057228 | I35: 125207539 | J35: 120080846 | K35: 91323675 | L35: 27838606 | M35: 214816606 | N35: 201740080 | O35: 225797912 | P35: 219922350 | Q35: 245366150 | R35: 30569803 | S35: 85919313 | T35: 56754210 | U35: 21742193 | V35: 143302286
A36: ESSOUKNA | B36: 5050500 | C36: -172078 | D36: -952432 | E36: 672754 | F36: -2846051 | G36: -2501388 | H36: 17253957 | I36: 12015612 | J36: 17480481 | K36: 6652987 | L36: 389696 | M36: 34790177 | N36: 31046730 | O36: 23462088 | P36: 27128831 | Q36: 48126294 | R36: 34104440 | S36: 33606766 | T36: 34235231 | U36: 30336199 | V36: 28340886
A37: LAND'OR | B37: 13784285 | C37: 6980368 | D37: 9631470 | E37: -9932649 | F37: 6840834 | G37: 12631257 | H37: 133756032 | I37: 160856608 | J37: 192456617 | K37: 257094946 | L37: 261556427 | M37: 59383985 | N37: 103705103 | O37: 128463976 | P37: 134953183 | Q37: 129227282 | R37: 68431213 | S37: 77673850 | T37: 88613806 | U37: 97538786 | V37: 110868117
A38: MONOPRIX | B38: 25345736 | C38: -9586617 | D38: -3117449 | E38: -8392666 | F38: 1013684 | G38: 6872913 | H38: 649624978 | I38: 657548597 | J38: 665523304 | K38: 724783677 | L38: 775277935 | M38: 314223680 | N38: 323651502 | O38: 338300600 | P38: 298077011 | Q38: 299295661 | R38: 50037812 | S38: 46812093 | T38: 37261685 | U38: 44697377 | V38: 49423396
A39: NEW BODY LINE | B39: 4250400 | C39: 1216170 | D39: 2167848 | E39: 1135336 | F39: 1136892 | G39: -6120768 | H39: 4947403 | I39: 6843886 | J39: 5466474 | K39: 13057296 | L39: 8932846 | M39: 555272 | N39: 1334010 | O39: 1351167 | P39: 1719857 | Q39: 2016622 | R39: 12068397 | S39: 12687912 | T39: 12200418 | U39: 13120762 | V39: 5073268
A40: SIMPAR | B40: 1100000 | C40: -9375293 | D40: -8961870 | E40: -3341071 | F40: -5512252 | G40: -7700174 | H40: 44960783 | I40: 39563223 | J40: 66860622 | K40: 44448221 | L40: 17984310 | M40: 165713904 | N40: 166207065 | O40: 153733055 | P40: 169671737 | Q40: 230817868 | R40: 61794177 | S40: 52622689 | T40: 49084912 | U40: 48480225 | V40: 37809397
...

Sheet Ratios and Scoring System
A1: Name | B1: EPS | H1: EPS Growth | M1: Net profit margin | S1: ROE | Y1: D/E ratio (for banks LCR) | AE1: P/E
B2: 2020 | C2: 2021 | D2: 2022 | E2: 2023 | F2: 2024 | H2: 2021 | I2: 2022 | J2: 2023 | K2: 2024 | M2: 2020 | N2: 2021 | O2: 2022 | P2: 2023 | Q2: 2024 | S2: 2020 | T2: 2021 | U2: 2022 | V2: 2023 | W2: 2024 | Y2: 2020 | Z2: 2021 | AA2: 2022 | AB2: 2023 | AC2: 2024 | AE2: CURRENT
A3: Societe Frigorifique Et Brasserie | B3: ='Data '!C3/'Data '!$B$3 -> 0.78540402 | C3: ='Data '!D3/'Data '!$B$3 -> 0.93622626 | D3: ='Data '!E3/'Data '!$B$3 -> 0.95860802 | E3: ='Data '!F3/'Data '!$B$3 -> 1.0505587 | F3: ='Data '!G3/'Data '!$B$3 -> 1.0552976 | H3: =((C3-B3)/ABS(B3)) -> 0.1920314 | I3: =((D3-C3)/ABS(C3)) -> 0.02390636 | J3: =((E3-D3)/ABS(D3)) -> 0.095921002 | K3: =((F3-E3)/ABS(E3)) -> 0.0045109 | M3: ='Data '!C3/'Data '!H3 -> 0.17507164 | N3: ='Data '!D3/'Data '!I3 -> 0.20969177 | O3: ='Data '!E3/'Data '!J3 -> 0.1932658 | P3: ='Data '!F3/'Data '!K3 -> 0.2057074 | Q3: ='Data '!G3/'Data '!L3 -> 0.20265788 | S3: ='Data '!C3/'Data '!R3 -> 0.20153833 | T3: ='Data '!D3/'Data '!S3 -> 0.22244932 | U3: ='Data '!E3/'Data '!T3 -> 0.21170479 | V3: ='Data '!F3/'Data '!U3 -> 0.21171987 | W3: ='Data '!G3/'Data '!V3 -> 0.19933497 | Y3: ='Data '!M3/'Data '!R3 -> 0.57919562 | Z3: ='Data '!N3/'Data '!S3 -> 0.51582546 | AA3: ='Data '!O3/'Data '!T3 -> 0.54683391 | AB3: ='Data '!P3/'Data '!U3 -> 0.5067525 | AC3: ='Data '!Q3/'Data '!V3 -> 0.4951005 | AE3: 11.26
A4: Banque Attijari De Tunisie | B4: ='Data '!C4/'Data '!$B$4 -> 6.5520952 | C4: ='Data '!D4/'Data '!$B$4 -> 6.7389048 | D4: ='Data '!J4/'Data '!$B$4 -> 15.819714 | E4: ='Data '!F4/'Data '!$B$4 -> 8.7256667 | F4: ='Data '!G4/'Data '!$B$4 -> 8.4986429 | H4: =((C4-B4)/ABS(B4)) -> 0.028511418 | I4: =((D4-C4)/ABS(C4)) -> 1.3475201 | J4: =((E4-D4)/ABS(D4)) -> -0.44843083 | K4: =((F4-E4)/ABS(E4)) -> -0.026017933 | M4: ='Data '!C4/'Data '!H4 -> 0.50596074 | N4: ='Data '!D4/'Data '!I4 -> 0.47089456 | O4: ='Data '!E4/'Data '!J4 -> 0.50028446 | P4: ='Data '!F4/'Data '!K4 -> 0.52949072 | Q4: ='Data '!G4/'Data '!L4 -> 0.4825145 | S4: ='Data '!C4/'Data '!R4 -> 0.31069974 | T4: ='Data '!D4/'Data '!S4 -> 0.29973176 | U4: ='Data '!J4/'Data '!T4 -> 0.65624204 | V4: ='Data '!F4/'Data '!U4 -> 0.32729462 | W4: ='Data '!G4/'Data '!V4 -> 0.30172722 | Y4: 2.056 | Z4: 3.545 | AA4: 3.59 | AB4: 6.91 | AC4: ='Data '!Q4/'Data '!V4 -> 9.4830435 | AE4: 11.44
A5: Poulina Group Holding | B5: ='Data '!G5/'Data '!$B$5 -> 0.90048557 | C5: ='Data '!D5/'Data '!$B$5 -> 0.51824168 | D5: ='Data '!E5/'Data '!$B$5 -> 0.36537911 | E5: ='Data '!F5/'Data '!$B$5 -> 0.72028598 | F5: ='Data '!G5/'Data '!$B$5 -> 0.90048557 | H5: =((C5-B5)/ABS(B5)) -> -0.42448642 | I5: =((D5-C5)/ABS(C5)) -> -0.29496386 | J5: =((E5-D5)/ABS(D5)) -> 0.97133867 | K5: =((F5-E5)/ABS(E5)) -> 0.25017785 | M5: ='Data '!G5/'Data '!H5 -> 0.070660127 | N5: ='Data '!D5/'Data '!I5 -> 0.032361539 | O5: ='Data '!E5/'Data '!J5 -> 0.020783814 | P5: ='Data '!F5/'Data '!K5 -> 0.037283675 | Q5: ='Data '!G5/'Data '!L5 -> 0.047017531 | S5: ='Data '!G5/'Data '!R5 -> 0.17201462 | T5: ='Data '!D5/'Data '!S5 -> 0.095217561 | U5: ='Data '!E5/'Data '!T5 -> 0.067228829 | V5: ='Data '!F5/'Data '!U5 -> 0.12202008 | W5: ='Data '!G5/'Data '!V5 -> 0.14070919 | Y5: ='Data '!M5/'Data '!R5 -> 2.9836181 | Z5: ='Data '!N5/'Data '!S5 -> 4.0791451 | AA5: ='Data '!O5/'Data '!T5 -> 4.36528 | AB5: ='Data '!P5/'Data '!U5 -> 3.1696891 | AC5: ='Data '!Q5/'Data '!V5 -> 2.8211301 | AE5: 20.14
A6: Societe Delice Holding | B6: ='Data '!C6/'Data '!$B$6 -> 1.0529758 | C6: ='Data '!D6/'Data '!$B$6 -> 1.2812967 | D6: ='Data '!E6/'Data '!$B$6 -> 1.4304781 | E6: ='Data '!F6/'Data '!$B$6 -> 1.7808458 | F6: ='Data '!G6/'Data '!$B$6 -> 1.8397088 | H6: =((C6-B6)/ABS(B6)) -> 0.21683394 | I6: =((D6-C6)/ABS(C6)) -> 0.11643002 | J6: =((E6-D6)/ABS(D6)) -> 0.2449305 | K6: =((F6-E6)/ABS(E6)) -> 0.033053373 | M6: ='Data '!C6/'Data '!H6 -> 0.055235024 | N6: ='Data '!D6/'Data '!I6 -> 0.060391855 | O6: ='Data '!E6/'Data '!J6 -> 0.061998034 | P6: ='Data '!F6/'Data '!K6 -> 0.070408731 | Q6: ='Data '!G6/'Data '!L6 -> 0.070018579 | S6: ='Data '!C6/'Data '!R6 -> 0.23975346 | T6: ='Data '!D6/'Data '!S6 -> 0.23131068 | U6: ='Data '!E6/'Data '!T6 -> 0.21566708 | V6: ='Data '!F6/'Data '!U6 -> 0.23119763 | W6: ='Data '!G6/'Data '!V6 -> 0.20623495 | Y6: ='Data '!M6/'Data '!R6 -> 1.746834 | Z6: ='Data '!N6/'Data '!S6 -> 1.3291652 | AA6: ='Data '!O6/'Data '!T6 -> 1.2381352 | AB6: ='Data '!P6/'Data '!U6 -> 1.2346028 | AC6: ='Data '!Q6/'Data '!V6 -> 1.1531935 | AE6: 6.79
A7: One Tech Ho | B7: ='Data '!C7/'Data '!$B$7 -> 0.24588697 | C7: ='Data '!D7/'Data '!$B$7 -> 0.3823892 | D7: ='Data '!E7/'Data '!$B$7 -> 0.17154155 | E7: ='Data '!F7/'Data '!$B$7 -> 0.47677162 | F7: ='Data '!G7/'Data '!$B$7 -> 0.37559335 | H7: =((C7-B7)/ABS(B7)) -> 0.55514223 | I7: =((D7-C7)/ABS(C7)) -> -0.5513954 | J7: =((E7-D7)/ABS(D7)) -> 1.779336 | K7: =((F7-E7)/ABS(E7)) -> -0.21221538 | M7: ='Data '!C7/'Data '!H7 -> 0.027511595 | N7: ='Data '!D7/'Data '!I7 -> 0.033969268 | O7: ='Data '!E7/'Data '!J7 -> 0.013175676 | P7: ='Data '!F7/'Data '!K7 -> 0.034697794 | Q7: ='Data '!G7/'Data '!L7 -> 0.028809125 | S7: ='Data '!C7/'Data '!R7 -> 0.057048685 | T7: ='Data '!D7/'Data '!S7 -> 0.084777714 | U7: ='Data '!E7/'Data '!T7 -> 0.038942865 | V7: ='Data '!F7/'Data '!U7 -> 0.099166415 | W7: ='Data '!G7/'Data '!V7 -> 0.076566222 | Y7: ='Data '!M7/'Data '!R7 -> 0.89486581 | Z7: ='Data '!N7/'Data '!S7 -> 0.92566562 | AA7: ='Data '!O7/'Data '!T7 -> 1.035113 | AB7: ='Data '!P7/'Data '!U7 -> 0.90348667 | AC7: ='Data '!Q7/'Data '!V7 -> 0.75714648 | AE7: 24.26
A8: Carthage Cement | B8: ='Data '!C8/'Data '!$B$8 -> 0.056353843 | C8: ='Data '!D8/'Data '!$B$8 -> 0.091696453 | D8: ='Data '!E8/'Data '!$B$8 -> 0.10374792 | E8: ='Data '!F8/'Data '!$B$8 -> 0.16062032 | F8: ='Data '!G8/'Data '!$B$8 -> 0.20445558 | H8: =((C8-B8)/ABS(B8)) -> 0.62715526 | I8: =((D8-C8)/ABS(C8)) -> 0.13142782 | J8: =((E8-D8)/ABS(D8)) -> 0.54817871 | K8: =((F8-E8)/ABS(E8)) -> 0.27291229 | M8: ='Data '!C8/'Data '!H8 -> 0.076547121 | N8: ='Data '!D8/'Data '!I8 -> 0.096663198 | O8: ='Data '!E8/'Data '!J8 -> 0.097145288 | P8: ='Data '!F8/'Data '!K8 -> 0.12788383 | Q8: ='Data '!G8/'Data '!L8 -> 0.16665203 | S8: ='Data '!C8/'Data '!R8 -> 0.14240864 | T8: ='Data '!D8/'Data '!S8 -> 0.18812781 | U8: ='Data '!E8/'Data '!T8 -> 0.1754978 | V8: ='Data '!F8/'Data '!U8 -> 0.21365223 | W8: ='Data '!G8/'Data '!V8 -> 0.21381209 | Y8: ='Data '!M8/'Data '!R8 -> 5.2110684 | Z8: ='Data '!N8/'Data '!S8 -> 3.8226307 | AA8: ='Data '!O8/'Data '!T8 -> 3.2438599 | AB8: ='Data '!P8/'Data '!U8 -> 2.3834436 | AC8: ='Data '!Q8/'Data '!V8 -> 1.6584139 | AE8: 8.87
A9: Societe Tunisienne De Verreries | B9: ='Data '!C9/'Data '!$B$9 -> 0.27133923 | C9: ='Data '!D9/'Data '!$B$9 -> 0.50912819 | D9: ='Data '!E9/'Data '!$B$9 -> 0.76183714 | E9: ='Data '!F9/'Data '!$B$9 -> 1.1881898 | F9: ='Data '!G9/'Data '!$B$9 -> 1.0646361 | H9: =((C9-B9)/ABS(B9)) -> 0.87635307 | I9: =((D9-C9)/ABS(C9)) -> 0.49635622 | J9: =((E9-D9)/ABS(D9)) -> 0.55963757 | K9: =((F9-E9)/ABS(E9)) -> -0.1039848 | M9: ='Data '!C9/'Data '!H9 -> 0.11693069 | N9: ='Data '!D9/'Data '!I9 -> 0.19051509 | O9: ='Data '!E9/'Data '!J9 -> 0.19146645 | P9: ='Data '!F9/'Data '!K9 -> 0.17778052 | Q9: ='Data '!G9/'Data '!L9 -> 0.17775563 | S9: ='Data '!C9/'Data '!R9 -> 0.1419822 | T9: ='Data '!D9/'Data '!S9 -> 0.23379219 | U9: ='Data '!E9/'Data '!T9 -> 0.29341789 | V9: ='Data '!F9/'Data '!U9 -> 0.35803802 | W9: ='Data '!G9/'Data '!V9 -> 0.27754014 | Y9: ='Data '!M9/'Data '!R9 -> 1.2257903 | Z9: ='Data '!N9/'Data '!S9 -> 1.9917996 | AA9: ='Data '!O9/'Data '!T9 -> 2.5959198 | AB9: ='Data '!P9/'Data '!U9 -> 2.5710151 | AC9: ='Data '!Q9/'Data '!V9 -> 2.6666628 | AE9: 12.44
A10: Societe Tunisie Profiles Aluminium | B10: ='Data '!C10/'Data '!$B$10 -> 0.42441924 | C10: ='Data '!D10/'Data '!$B$10 -> 0.38118442 | D10: ='Data '!E10/'Data '!$B$10 -> 0.57930788 | E10: ='Data '!F10/'Data '!$B$10 -> 0.8269077 | F10: ='Data '!G10/'Data '!$B$10 -> 0.96543524 | H10: =((C10-B10)/ABS(B10)) -> -0.10186819 | I10: =((D10-C10)/ABS(C10)) -> 0.5197575 | J10: =((E10-D10)/ABS(D10)) -> 0.42740627 | K10: =((F10-E10)/ABS(E10)) -> 0.16752479 | M10: ='Data '!C10/'Data '!H10 -> 0.11758918 | N10: ='Data '!D10/'Data '!I10 -> 0.088694489 | O10: ='Data '!E10/'Data '!J10 -> 0.10171368 | P10: ='Data '!F10/'Data '!K10 -> 0.1435698 | Q10: ='Data '!G10/'Data '!L10 -> 0.14182478 | S10: ='Data '!C10/'Data '!R10 -> 0.15518561 | T10: ='Data '!D10/'Data '!S10 -> 0.13890184 | U10: ='Data '!E10/'Data '!T10 -> 0.19538542 | V10: ='Data '!F10/'Data '!U10 -> 0.22889612 | W10: ='Data '!G10/'Data '!V10 -> 0.2291177 | Y10: ='Data '!M10/'Data '!R10 -> 0.96114617 | Z10: ='Data '!N10/'Data '!S10 -> 1.1321116 | AA10: ='Data '!O10/'Data '!T10 -> 1.1270975 | AB10: ='Data '!P10/'Data '!U10 -> 0.8858216 | AC10: ='Data '!Q10/'Data '!V10 -> 0.99088955 | AE10: 10.56
A11: SPDIT-SICAF | B11: ='Data '!C11/'Data '!$B$11 -> 0.60412811 | C11: ='Data '!D11/'Data '!$B$11 -> 0.62256904 | D11: ='Data '!E11/'Data '!$B$11 -> 0.77739414 | E11: ='Data '!F11/'Data '!$B$11 -> 0.95710525 | F11: ='Data '!G11/'Data '!$B$11 -> 1.1420827 | H11: =((C11-B11)/ABS(B11)) -> 0.030524864 | I11: =((D11-C11)/ABS(C11)) -> 0.24868745 | J11: =((E11-D11)/ABS(D11)) -> 0.23117116 | K11: =((F11-E11)/ABS(E11)) -> 0.19326767 | M11: ='Data '!C11/'Data '!H11 -> 0.85941548 | N11: ='Data '!D11/'Data '!I11 -> 0.85078218 | O11: ='Data '!E11/'Data '!J11 -> 0.91953035 | P11: ='Data '!F11/'Data '!K11 -> 0.86042592 | Q11: ='Data '!G11/'Data '!L11 -> 0.92560248 | S11: ='Data '!C11/'Data '!R11 -> 0.23905226 | T11: ='Data '!D11/'Data '!S11 -> 0.24416874 | U11: ='Data '!E11/'Data '!T11 -> 0.28505805 | V11: ='Data '!F11/'Data '!U11 -> 0.32071901 | W11: ='Data '!G11/'Data '!V11 -> 0.34858586 | Y11: ='Data '!M11/'Data '!R11 -> 0.039327049 | Z11: ='Data '!N11/'Data '!S11 -> 0.026915603 | AA11: ='Data '!O11/'Data '!T11 -> 0.036575806 | AB11: ='Data '!P11/'Data '!U11 -> 0.051210786 | AC11: ='Data '!Q11/'Data '!V11 -> 0.048916735 | AE11: 11.27
A12: Automobile Reseau Tunisien Et Service SA | B12: ='Data '!C12/'Data '!$B$12 -> 0.86897631 | C12: ='Data '!H12/'Data '!$B$12 -> 5.5495494 | D12: ='Data '!E12/'Data '!$B$12 -> 0.7629161 | E12: ='Data '!F12/'Data '!$B$12 -> 1.1030587 | F12: ='Data '!G12/'Data '!$B$12 -> 1.1030587 | H12: =((C12-B12)/ABS(B12)) -> 5.3863069 | I12: =((D12-C12)/ABS(C12)) -> -0.86252648 | J12: =((E12-D12)/ABS(D12)) -> 0.4458453 | K12: =((F12-E12)/ABS(E12)) -> 0 | M12: ='Data '!C12/'Data '!H12 -> 0.15658502 | N12: ='Data '!H12/'Data '!I12 -> 0.78575046 | O12: ='Data '!E12/'Data '!J12 -> 0.16643889 | P12: ='Data '!F12/'Data '!K12 -> 0.13722883 | Q12: ='Data '!G12/'Data '!L12 -> 0.13722883 | S12: ='Data '!C12/'Data '!R12 -> 0.16416425 | T12: ='Data '!H12/'Data '!S12 -> 0.99307209 | U12: ='Data '!E12/'Data '!T12 -> 0.13743822 | V12: ='Data '!F12/'Data '!U12 -> 0.29934915 | W12: ='Data '!G12/'Data '!V12 -> 0.18901309 | Y12: ='Data '!M12/'Data '!R12 -> 0.4124814 | Z12: ='Data '!N12/'Data '!S12 -> 0.22045786 | AA12: ='Data '!O12/'Data '!T12 -> 0.32683399 | AB12: ='Data '!P12/'Data '!U12 -> 1.0452983 | AC12: ='Data '!Q12/'Data '!V12 -> 0.7055843 | AE12: 10.79
A13: City Cars | B13: ='Data '!C13/'Data '!$B$13 -> 1.1665264 | C13: ='Data '!D13/'Data '!$B$13 -> 1.8530439 | D13: ='Data '!E13/'Data '!$B$13 -> 1.6847646 | E13: ='Data '!F13/'Data '!$B$13 -> 1.7621442 | F13: ='Data '!G13/'Data '!$B$13 -> 1.6399328 | H13: =((C13-B13)/ABS(B13)) -> 0.58851431 | I13: =((D13-C13)/ABS(C13)) -> -0.090812381 | J13: =((E13-D13)/ABS(D13)) -> 0.045929034 | K13: =((F13-E13)/ABS(E13)) -> -0.069353795 | M13: ='Data '!C13/'Data '!H13 -> 0.088762525 | N13: ='Data '!D13/'Data '!I13 -> 0.097031372 | O13: ='Data '!E13/'Data '!J13 -> 0.088386901 | P13: ='Data '!F13/'Data '!K13 -> 0.084574518 | Q13: ='Data '!G13/'Data '!L13 -> 0.078007079 | S13: ='Data '!C13/'Data '!R13 -> 0.36206376 | T13: ='Data '!D13/'Data '!S13 -> 0.44016579 | U13: ='Data '!E13/'Data '!T13 -> 0.35988741 | V13: ='Data '!F13/'Data '!U13 -> 0.33927631 | W13: ='Data '!G13/'Data '!V13 -> 0.29367344 | Y13: ='Data '!M12/'Data '!R13 -> 1.4400684 | Z13: ='Data '!N13/'Data '!S13 -> 1.6514215 | AA13: ='Data '!O13/'Data '!T13 -> 1.8593982 | AB13: ='Data '!P13/'Data '!U13 -> 1.9115588 | AC13: ='Data '!Q13/'Data '!V13 -> 1.8765919 | AE13: 11.88
A14: Ste Assurances Maghrebia SA | B14: ='Data '!C14/'Data '!$B$14 -> 11.888658 | C14: ='Data '!D14/'Data '!$B$14 -> 17.141925 | D14: ='Data '!E14/'Data '!$B$14 -> 18.047678 | E14: ='Data '!F14/'Data '!$B$14 -> 18.231899 | F14: ='Data '!G14/'Data '!$B$14 -> 22.368255 | H14: =((C14-B14)/ABS(B14)) -> 0.44187212 | I14: =((D14-C14)/ABS(C14)) -> 0.052838471 | J14: =((E14-D14)/ABS(D14)) -> 0.010207432 | K14: =((F14-E14)/ABS(E14)) -> 0.22687469 | M14: ='Data '!C14/'Data '!H14 -> 1.3565336 | N14: ='Data '!D14/'Data '!I14 -> 2.9870643 | O14: ='Data '!E14/'Data '!J14 -> 2.8902782 | P14: ='Data '!F14/'Data '!K14 -> 1.3935871 | Q14: ='Data '!G14/'Data '!L14 -> 1.4490814 | S14: ='Data '!C14/'Data '!R14 -> 0.48672949 | T14: ='Data '!D14/'Data '!S14 -> 0.50009675 | U14: ='Data '!E14/'Data '!T14 -> 0.44993613 | V14: ='Data '!F14/'Data '!U14 -> 0.40483037 | W14: ='Data '!G14/'Data '!V14 -> 0.45304474 | Y14: 0.7492 | Z14: 0.7708 | AA14: 0.7725 | AB14: 0.8038 | AC14: ='Data '!Q14/'Data '!V14 -> 4.5039549 | AE14: 8.66
A15: Tunisie Leasing | B15: ='Data '!C15/'Data '!$B$15 -> 0.83144259 | C15: ='Data '!D15/'Data '!$B$15 -> 0.66844093 | D15: ='Data '!E15/'Data '!$B$15 -> 1.9172492 | E15: ='Data '!F15/'Data '!$B$15 -> 2.6127289 | F15: ='Data '!G15/'Data '!$B$15 -> 3.4694939 | H15: =((C15-B15)/ABS(B15)) -> -0.19604681 | I15: =((D15-C15)/ABS(C15)) -> 1.8682402 | J15: =((E15-D15)/ABS(D15)) -> 0.36274874 | K15: =((F15-E15)/ABS(E15)) -> 0.3279196 | M15: ='Data '!C15/'Data '!H15 -> 0.062239639 | N15: ='Data '!D15/'Data '!I15 -> 0.053419861 | O15: ='Data '!E15/'Data '!J15 -> 0.1379316 | P15: ='Data '!F15/'Data '!K15 -> 0.17737967 | Q15: ='Data '!G15/'Data '!L15 -> 0.19172757 | S15: ='Data '!C15/'Data '!R15 -> 0.040190865 | T15: ='Data '!D15/'Data '!S15 -> 0.032815641 | U15: ='Data '!E15/'Data '!T15 -> 0.086369543 | V15: ='Data '!F15/'Data '!U15 -> 0.10765543 | W15: ='Data '!G15/'Data '!V15 -> 0.12957076 | Y15: ='Data '!M15/'Data '!R15 -> 8.0407482 | Z15: ='Data '!N15/'Data '!S15 -> 8.0728049 | AA15: ='Data '!O15/'Data '!T15 -> 7.4090636 | AB15: ='Data '!P15/'Data '!U15 -> 7.5637894 | AC15: ='Data '!Q15/'Data '!V15 -> 9.3431457 | AE15: 9.22
A16: Compagnie Internationale De Leasing | B16: 2.616 | C16: 3.185 | D16: 2.59 | E16: 2.884 | F16: 3.884 | H16: =((C16-B16)/ABS(B16)) -> 0.21750765 | I16: =((D16-C16)/ABS(C16)) -> -0.18681319 | J16: =((E16-D16)/ABS(D16)) -> 0.11351351 | K16: =((F16-E16)/ABS(E16)) -> 0.34674064 | M16: ='Data '!C16/'Data '!H16 -> 0.40983701 | N16: ='Data '!D16/'Data '!I16 -> 0.4190554 | O16: ='Data '!E16/'Data '!J16 -> 0.40373515 | P16: ='Data '!F16/'Data '!K16 -> 0.44734787 | Q16: ='Data '!G16/'Data '!L16 -> 0.43803411 | S16: ='Data '!C16/'Data '!R16 -> 0.12090174 | T16: ='Data '!D16/'Data '!S16 -> 0.14183033 | U16: ='Data '!E16/'Data '!O16 -> 0.032754747 | V16: ='Data '!F16/'Data '!U16 -> 0.15435814 | W16: ='Data '!G16/'Data '!V16 -> 0.15044043 | Y16: ='Data '!M16/'Data '!R16 -> 5.0454306 | Z16: ='Data '!N16/'Data '!S16 -> 4.9071032 | AA16: ='Data '!T16/'Data '!O16 -> 0.22353326 | AB16: ='Data '!P16/'Data '!U16 -> 4.5161848 | AC16: ='Data '!Q16/'Data '!V16 -> 4.4076696 | AE16: 9.38
A17: Tunis Re | B17: ='Data '!C17/'Data '!$B$17 -> 0.03699185 | C17: ='Data '!D17/'Data '!$B$17 -> 0.01671445 | D17: ='Data '!E17/'Data '!$B$17 -> 0.02202155 | E17: ='Data '!F17/'Data '!$B$17 -> 0.00572945 | F17: ='Data '!G17/'Data '!$B$17 -> 0.17798 | H17: =((C17-B17)/ABS(B17)) -> -0.54815858 | I17: =((D17-C17)/ABS(C17)) -> 0.31751568 | J17: =((E17-D17)/ABS(D17)) -> -0.73982531 | K17: =((F17-E17)/ABS(E17)) -> 30.064064 | M17: ='Data '!C17/'Data '!H17 -> 0.027636405 | N17: ='Data '!D17/'Data '!I17 -> 0.013935082 | O17: ='Data '!E17/'Data '!J17 -> 0.0165022 | P17: ='Data '!F17/'Data '!K17 -> 0.0036423107 | Q17: ='Data '!G17/'Data '!L17 -> 0.10442626 | S17: ='Data '!C17/'Data '!R17 -> 0.0034830991 | T17: ='Data '!D17/'Data '!S17 -> 0.0014929209 | U17: ='Data '!E17/'Data '!T17 -> 0.0018632165 | V17: ='Data '!F17/'Data '!U17 -> 0.00046493439 | W17: ='Data '!G17/'Data '!V17 -> 0.013776863 | Y17: ='Data '!M17/'Data '!R17 -> 3.3316561 | Z17: ='Data '!N17/'Data '!S17 -> 3.0745805 | AA17: ='Data '!T17/'Data '!O17 -> 0.3342337 | AB17: ='Data '!P17/'Data '!U17 -> 2.7588614 | AC17: ='Data '!Q17/'Data '!V17 -> 2.9607145 | AE17: 8.4
A18: Assurances Maghrebia Vie SA | B18: ='Data '!C18/'Data '!$B$18 -> 0.48247276 | C18: ='Data '!I18/'Data '!$B$18 -> 0.7058576 | D18: ='Data '!J18/'Data '!$B$18 -> 0.79693332 | E18: ='Data '!F18/'Data '!$B$18 -> 0.59996076 | F18: ='Data '!G18/'Data '!$B$18 -> 1.0614149 | H18: =((C18-B18)/ABS(B18)) -> 0.4629999 | I18: =((D18-C18)/ABS(C18)) -> 0.12902846 | J18: =((E18-D18)/ABS(D18)) -> -0.24716316 | K18: =((F18-E18)/ABS(E18)) -> 0.7691405 | M18: ='Data '!C18/'Data '!H18 -> 0.78924433 | N18: ='Data '!D18/'Data '!I18 -> 0.77150014 | O18: ='Data '!E18/'Data '!J18 -> 0.68417493 | P18: ='Data '!F18/'Data '!K18 -> 0.67375447 | Q18: ='Data '!G18/'Data '!L18 -> 1.065691 | S18: ='Data '!C18/'Data '!R18 -> 0.19187179 | T18: ='Data '!I18/'Data '!S18 -> 0.24273854 | U18: ='Data '!J18/'Data '!T18 -> 0.1725385 | V18: ='Data '!F18/'Data '!U18 -> 0.11729869 | W18: ='Data '!G18/'Data '!V18 -> 0.18576611 | Y18: 0.52836501 | Z18: 0.61652507 | AA18: 0.65330327 | AB18: 0.61603615 | AC18: ='Data '!Q18/'Data '!V18 -> 5.4355522 | AE18: 0.7
A19: SAH | B19: ='Data '!C19/'Data '!$B$19 -> 0.397415 | C19: ='Data '!D19/'Data '!$B$19 -> 0.19307038 | D19: ='Data '!E19/'Data '!$B$19 -> 0.42044076 | E19: ='Data '!F19/'Data '!$B$19 -> 0.4243246 | F19: ='Data '!G19/'Data '!$B$19 -> 0.73329861 | H19: =((C19-B19)/ABS(B19)) -> -0.51418446 | I19: =((D19-C19)/ABS(C19)) -> 1.1776554 | J19: =((E19-D19)/ABS(D19)) -> 0.0092375547 | K19: =((F19-E19)/ABS(E19)) -> 0.72815483 | M19: ='Data '!C19/'Data '!H19 -> 0.052858921 | N19: ='Data '!D19/'Data '!I19 -> 0.024070193 | O19: ='Data '!E19/'Data '!J19 -> 0.040112336 | P19: ='Data '!F19/'Data '!K19 -> 0.03952399 | Q19: ='Data '!G19/'Data '!L19 -> 0.062738735 | S19: ='Data '!C19/'Data '!R19 -> 0.10626202 | T19: ='Data '!D19/'Data '!S19 -> 0.054817385 | U19: ='Data '!E19/'Data '!T19 -> 0.11316508 | V19: ='Data '!F19/'Data '!U19 -> 0.11166214 | W19: ='Data '!G19/'Data '!V19 -> 0.17428791 | Y19: ='Data '!M19/'Data '!R19 -> 1.817694 | Z19: ='Data '!N19/'Data '!S19 -> 2.2613152 | AA19: ='Data '!O19/'Data '!T19 -> 2.2906733 | AB19: ='Data '!P19/'Data '!U19 -> 2.3814493 | AC19: ='Data '!Q19/'Data '!V19 -> 2.4960304 | AE19: 18.83
A20: Arab Tunisian Lease | B20: ='Data '!C20/'Data '!$B$20 -> 0.16245218 | C20: ='Data '!D20/'Data '!$B$20 -> 0.34252788 | D20: ='Data '!E20/'Data '!$B$20 -> 0.50062852 | E20: ='Data '!F20/'Data '!$B$20 -> 0.61463889 | F20: ='Data '!G20/'Data '!$B$20 -> 0.68036006 | H20: =((C20-B20)/ABS(B20)) -> 1.1084843 | I20: =((D20-C20)/ABS(C20)) -> 0.46157016 | J20: =((E20-D20)/ABS(D20)) -> 0.22773447 | K20: =((F20-E20)/ABS(E20)) -> 0.10692647 | M20: ='Data '!C20/'Data '!H20 -> 0.17468127 | N20: ='Data '!D20/'Data '!I20 -> 0.27887802 | O20: ='Data '!E20/'Data '!J20 -> 0.34911238 | P20: ='Data '!F20/'Data '!K20 -> 0.39017686 | Q20: ='Data '!G20/'Data '!L20 -> 0.37842041 | S20: ='Data '!C20/'Data '!R20 -> 0.0099764301 | T20: ='Data '!D20/'Data '!S20 -> 0.10094119 | U20: ='Data '!E20/'Data '!T20 -> 0.13552541 | V20: ='Data '!F20/'Data '!U20 -> 0.15219425 | W20: ='Data '!G20/'Data '!V20 -> 0.15396677 | Y20: ='Data '!M20/'Data '!R20 -> 0.19195622 | Z20: ='Data '!N20/'Data '!S20 -> 4.9942015 | AA20: ='Data '!O20/'Data '!T20 -> 4.2646691 | AB20: ='Data '!P20/'Data '!U20 -> 4.2333307 | AC20: ='Data '!Q20/'Data '!V20 -> 4.0246326 | AE20: 8.69
A21: Societe Tunisienne des Marches de Gros SA | B21: ='Data '!C21/'Data '!$B$21 -> 0.35115795 | C21: ='Data '!D21/'Data '!$B$21 -> 0.44287879 | D21: ='Data '!E21/'Data '!$B$21 -> 0.47132765 | E21: ='Data '!F21/'Data '!$B$21 -> 0.57961061 | F21: ='Data '!G21/'Data '!$B$21 -> 0.53475811 | H21: =((C21-B21)/ABS(B21)) -> 0.26119537 | I21: =((D21-C21)/ABS(C21)) -> 0.06423623 | J21: =((E21-D21)/ABS(D21)) -> 0.2297403 | K21: =((F21-E21)/ABS(E21)) -> -0.07738385 | M21: ='Data '!C21/'Data '!H21 -> 0.30998902 | N21: ='Data '!D21/'Data '!I21 -> 0.37889362 | O21: ='Data '!E21/'Data '!J21 -> 0.37686257 | P21: ='Data '!F21/'Data '!K21 -> 0.43207446 | Q21: ='Data '!G21/'Data '!L21 -> 0.3806571 | S21: ='Data '!C21/'Data '!R21 -> 0.15953659 | T21: ='Data '!D21/'Data '!S21 -> 0.18378033 | U21: ='Data '!E21/'Data '!T21 -> 0.19070068 | V21: ='Data '!F21/'Data '!U21 -> 0.22158193 | W21: ='Data '!G21/'Data '!V21 -> 0.20462335 | Y21: ='Data '!M21/'Data '!R21 -> 0.16043675 | Z21: ='Data '!N21/'Data '!S21 -> 0.14256132 | AA21: ='Data '!O21/'Data '!T21 -> 0.18267587 | AB21: ='Data '!P21/'Data '!U21 -> 0.18514284 | AC21: ='Data '!Q21/'Data '!V21 -> 0.18444738 | AE21: 17.01
A22: Hannibal Lease | B22: ='Data '!C22/'Data '!$B$22 -> -0.28896109 | C22: ='Data '!D22/'Data '!$B$22 -> 0.53713309 | D22: ='Data '!E22/'Data '!$B$22 -> 0.72523382 | E22: ='Data '!K22/'Data '!$B$22 -> 4.2017833 | F22: ='Data '!L22/'Data '!$B$22 -> 4.439811 | H22: =((C22-B22)/ABS(B22)) -> 2.8588423 | I22: =((D22-C22)/ABS(C22)) -> 0.35019389 | J22: =((E22-D22)/ABS(D22)) -> 4.7936946 | K22: =((F22-E22)/ABS(E22)) -> 0.056649216 | M22: ='Data '!C22/'Data '!H22 -> -0.17049949 | N22: ='Data '!D22/'Data '!I22 -> 0.18201552 | O22: ='Data '!E22/'Data '!J22 -> 0.18202571 | P22: ='Data '!F22/'Data '!K22 -> 0.28267405 | Q22: ='Data '!G22/'Data '!L22 -> 0.25878342 | S22: ='Data '!C22/'Data '!R22 -> -0.045148332 | T22: ='Data '!D22/'Data '!S22 -> 0.077564766 | U22: ='Data '!E22/'Data '!T22 -> 0.097554142 | V22: ='Data '!K22/'Data '!U22 -> 0.50557627 | W22: ='Data '!G22/'Data '!V22 -> 0.12650737 | Y22: ='Data '!M22/'Data '!R22 -> 8.6597313 | Z22: ='Data '!N22/'Data '!S22 -> 7.168591 | AA22: ='Data '!O22/'Data '!T22 -> 6.5717035 | AB22: ='Data '!P22/'Data '!U22 -> 6.2027798 | AC22: ='Data '!Q22/'Data '!V22 -> 6.3755261 | AE22: 6.61
A23: ATB | B23: ='Data '!C23/'Data '!$B$22 -> 1.1325455 | C23: ='Data '!D23/'Data '!$B$22 -> -5.585 | D23: ='Data '!E23/'Data '!$B$22 -> 2.6909091 | E23: ='Data '!K23/'Data '!$B$22 -> 36.911182 | F23: ='Data '!L23/'Data '!$B$22 -> 39.707727 | H23: =((C23-B23)/ABS(B23)) -> -5.9313694 | I23: =((D23-C23)/ABS(C23)) -> 1.48181 | J23: =((E23-D23)/ABS(D23)) -> 12.716993 | K23: =((F23-E23)/ABS(E23)) -> 0.075764181 | M23: ='Data '!C23/'Data '!H23 -> 0.041869016 | N23: ='Data '!D23/'Data '!I23 -> -0.18443078 | O23: ='Data '!E23/'Data '!J23 -> 0.080889788 | P23: ='Data '!F23/'Data '!K23 -> -0.00038914052 | Q23: ='Data '!G23/'Data '!L23 -> 0.071625628 | S23: ='Data '!C23/'Data '!R23 -> 0.021271909 | T23: ='Data '!D23/'Data '!S23 -> -0.10340364 | U23: ='Data '!E23/'Data '!T23 -> 0.047891868 | V23: ='Data '!K23/'Data '!U23 -> 0.6572206 | W23: ='Data '!G23/'Data '!V23 -> 0.048180729 | Y23: ='Data '!M23/'Data '!R23 -> 12.586692 | Z23: ='Data '!N23/'Data '!S23 -> 12.842421 | AA23: ='Data '!O23/'Data '!T23 -> 12.530053 | AB23: ='Data '!P23/'Data '!U23 -> 12.302117 | AC23: ='Data '!Q23/'Data '!V23 -> 12.875442 | AE23: 14.96
A24: BIAT | B24: ='Data '!C24/'Data '!$B$22 -> 25.225455 | C24: ='Data '!D24/'Data '!$B$22 -> 25.766455 | D24: ='Data '!E24/'Data '!$B$22 -> 28.400182 | E24: ='Data '!K24/'Data '!$B$22 -> 145.80991 | F24: ='Data '!L24/'Data '!$B$22 -> 159.11691 | H24: =((C24-B24)/ABS(B24)) -> 0.021446591 | I24: =((D24-C24)/ABS(C24)) -> 0.10221535 | J24: =((E24-D24)/ABS(D24)) -> 4.1341189 | K24: =((F24-E24)/ABS(E24)) -> 0.091262659 | M24: ='Data '!C24/'Data '!H24 -> 0.26834656 | N24: ='Data '!D24/'Data '!I24 -> 0.24980698 | O24: ='Data '!E24/'Data '!J24 -> 0.22075586 | P24: ='Data '!F24/'Data '!K24 -> 0.22357316 | Q24: ='Data '!G24/'Data '!L24 -> 0.216768 | S24: ='Data '!C24/'Data '!R24 -> 0.15667002 | T24: ='Data '!D24/'Data '!S24 -> 0.15096932 | U24: ='Data '!E24/'Data '!T24 -> 0.15614783 | V24: ='Data '!K24/'Data '!U24 -> 0.74297871 | W24: ='Data '!G24/'Data '!V24 -> 0.16394155 | Y24: ='Data '!M24/'Data '!R24 -> 9.0938377 | Z24: ='Data '!N24/'Data '!S24 -> 9.2447518 | AA24: ='Data '!O24/'Data '!T24 -> 9.4711186 | AB24: ='Data '!P24/'Data '!U24 -> 9.5579396 | AC24: ='Data '!Q24/'Data '!V24 -> 9.8418551 | AE24: 5.18
A25: BNA | B25: ='Data '!C25/'Data '!$B$22 -> 9.7853636 | C25: ='Data '!D25/'Data '!$B$22 -> 15.760545 | D25: ='Data '!E25/'Data '!$B$22 -> 15.446364 | E25: ='Data '!K25/'Data '!$B$22 -> 95.184182 | F25: ='Data '!L25/'Data '!$B$22 -> 94.934636 | H25: =((C25-B25)/ABS(B25)) -> 0.6106244 | I25: =((D25-C25)/ABS(C25)) -> -0.019934705 | J25: =((E25-D25)/ABS(D25)) -> 5.1622388 | K25: =((F25-E25)/ABS(E25)) -> -0.0026217114 | M25: ='Data '!C25/'Data '!H25 -> 0.15571781 | N25: ='Data '!D25/'Data '!I25 -> 0.1900547 | O25: ='Data '!E25/'Data '!J25 -> 0.17953676 | P25: ='Data '!F25/'Data '!K25 -> 0.20251933 | Q25: ='Data '!G25/'Data '!L25 -> 0.20196288 | S25: ='Data '!C25/'Data '!R25 -> 0.065212202 | T25: ='Data '!D25/'Data '!S25 -> 0.098442051 | U25: ='Data '!E25/'Data '!T25 -> 0.09108136 | V25: ='Data '!K25/'Data '!U25 -> 0.51437235 | W25: ='Data '!G25/'Data '!V25 -> 0.096377999 | Y25: ='Data '!M25/'Data '!R25 -> 7.6847642 | Z25: ='Data '!N25/'Data '!S25 -> 9.9882999 | AA25: ='Data '!O25/'Data '!T25 -> 10.759548 | AB25: ='Data '!P25/'Data '!U25 -> 10.47543 | AC25: ='Data '!Q25/'Data '!V25 -> 9.4028691 | AE25: 3.11
A26: BT | B26: ='Data '!C26/'Data '!$B$22 -> 8.5828182 | C26: ='Data '!D26/'Data '!$B$22 -> 13.829455 | D26: ='Data '!E26/'Data '!$B$22 -> 15.323818 | E26: ='Data '!K26/'Data '!$B$22 -> 44.876 | F26: ='Data '!L26/'Data '!$B$22 -> 47.121455 | H26: =((C26-B26)/ABS(B26)) -> 0.61129529 | I26: =((D26-C26)/ABS(C26)) -> 0.10805659 | J26: =((E26-D26)/ABS(D26)) -> 1.928513 | K26: =((F26-E26)/ABS(E26)) -> 0.050036869 | M26: ='Data '!C26/'Data '!H26 -> 0.24817309 | N26: ='Data '!D26/'Data '!I26 -> 0.39412098 | O26: ='Data '!E26/'Data '!J26 -> 0.39308793 | P26: ='Data '!F26/'Data '!K26 -> 0.36934502 | Q26: ='Data '!G26/'Data '!L26 -> 0.38476394 | S26: ='Data '!C26/'Data '!R26 -> 0.086691312 | T26: ='Data '!D26/'Data '!S26 -> 0.13073632 | U26: ='Data '!E26/'Data '!T26 -> 0.13157383 | V26: ='Data '!K26/'Data '!U26 -> 0.35634153 | W26: ='Data '!G26/'Data '!V26 -> 0.13688092 | Y26: ='Data '!M26/'Data '!R26 -> 5.1109088 | Z26: ='Data '!N26/'Data '!S26 -> 5.0287025 | AA26: ='Data '!O26/'Data '!T26 -> 4.9860958 | AB26: ='Data '!P26/'Data '!U26 -> 4.9943189 | AC26: ='Data '!Q26/'Data '!V26 -> 5.3418794 | AE26: 9.01
A27: AMEN BANK | B27: ='Data '!C27/'Data '!$B$22 -> 8.9490909 | C27: ='Data '!D27/'Data '!$B$22 -> 12.377 | D27: ='Data '!E27/'Data '!$B$22 -> 13.870727 | E27: ='Data '!K27/'Data '!$B$22 -> 48.937182 | F27: ='Data '!L27/'Data '!$B$22 -> 51.150909 | H27: =((C27-B27)/ABS(B27)) -> 0.38304551 | I27: =((D27-C27)/ABS(C27)) -> 0.12068573 | J27: =((E27-D27)/ABS(D27)) -> 2.5280906 | K27: =((F27-E27)/ABS(E27)) -> 0.0452361 | M27: ='Data '!C27/'Data '!H27 -> 0.24919753 | N27: ='Data '!D27/'Data '!I27 -> 0.30044046 | O27: ='Data '!E27/'Data '!J27 -> 0.31240633 | P27: ='Data '!F27/'Data '!K27 -> 0.40227081 | Q27: ='Data '!G27/'Data '!L27 -> 0.43284577 | S27: ='Data '!C27/'Data '!R27 -> 0.084171932 | T27: ='Data '!D27/'Data '!S27 -> 0.10963117 | U27: ='Data '!E27/'Data '!T27 -> 0.11164307 | V27: ='Data '!K27/'Data '!U27 -> 0.34405469 | W27: ='Data '!G27/'Data '!V27 -> 0.1429472 | Y27: ='Data '!M27/'Data '!R27 -> 6.7507864 | Z27: ='Data '!N27/'Data '!S27 -> 6.5736812 | AA27: ='Data '!O27/'Data '!T27 -> 6.4916391 | AB27: ='Data '!P27/'Data '!U27 -> 5.9977151 | AC27: ='Data '!Q27/'Data '!V27 -> 5.911864 | AE27: 6.81
A28: EURO-CYCLES | B28: ='Data '!C28/'Data '!$B$22 -> 1.510084 | C28: ='Data '!D28/'Data '!$B$22 -> 2.4199508 | D28: ='Data '!E28/'Data '!$B$22 -> 1.5117041 | E28: ='Data '!K28/'Data '!$B$22 -> 10.29231 | F28: ='Data '!L28/'Data '!$B$22 -> 11.113639 | H28: =((C28-B28)/ABS(B28)) -> 0.60252725 | I28: =((D28-C28)/ABS(C28)) -> -0.37531616 | J28: =((E28-D28)/ABS(D28)) -> 5.8084155 | K28: =((F28-E28)/ABS(E28)) -> 0.079800263 | M28: ='Data '!C28/'Data '!H28 -> 0.13861651 | N28: ='Data '!D28/'Data '!I28 -> 0.1784951 | O28: ='Data '!E28/'Data '!J28 -> 0.10219644 | P28: ='Data '!F28/'Data '!K28 -> 0.04380174 | Q28: ='Data '!G28/'Data '!L28 -> 0.089786001 | S28: ='Data '!C28/'Data '!R28 -> 0.35551118 | T28: ='Data '!D28/'Data '!S28 -> 0.44630024 | U28: ='Data '!E28/'Data '!T28 -> 0.27104764 | V28: ='Data '!K28/'Data '!U28 -> 2.0123801 | W28: ='Data '!G28/'Data '!V28 -> 0.17125435 | Y28: ='Data '!M28/'Data '!R28 -> 1.436311 | Z28: ='Data '!N28/'Data '!S28 -> 2.652485 | AA28: ='Data '!O28/'Data '!T28 -> 2.63354 | AB28: ='Data '!P28/'Data '!U28 -> 1.9805358 | AC28: ='Data '!Q28/'Data '!V28 -> 1.553834 | AE28: 10.97
A29: ICF | B29: ='Data '!C29/'Data '!$B$22 -> -1.0333422 | C29: ='Data '!D29/'Data '!$B$22 -> 0.81955355 | D29: ='Data '!E29/'Data '!$B$22 -> 2.8263673 | E29: ='Data '!K29/'Data '!$B$22 -> 13.32543 | F29: ='Data '!L29/'Data '!$B$22 -> 15.442001 | H29: =((C29-B29)/ABS(B29)) -> 1.7931095 | I29: =((D29-C29)/ABS(C29)) -> 2.448667 | J29: =((E29-D29)/ABS(D29)) -> 3.7146843 | K29: =((F29-E29)/ABS(E29)) -> 0.158837 | M29: ='Data '!C29/'Data '!H29 -> -0.096722527 | N29: ='Data '!D29/'Data '!I29 -> 0.060893158 | O29: ='Data '!E29/'Data '!J29 -> 0.13468694 | P29: ='Data '!F29/'Data '!K29 -> 0.049942514 | Q29: ='Data '!G29/'Data '!L29 -> 0.1262994 | S29: ='Data '!C29/'Data '!R29 -> -0.1299556 | T29: ='Data '!D29/'Data '!S29 -> 0.096881518 | U29: ='Data '!E29/'Data '!T29 -> 0.26780086 | V29: ='Data '!K29/'Data '!U29 -> 1.3647635 | W29: ='Data '!G29/'Data '!V29 -> 0.17638881 | Y29: ='Data '!M29/'Data '!R29 -> 0.28918106 | Z29: ='Data '!N29/'Data '!S29 -> 0.5102663 | AA29: ='Data '!O29/'Data '!T29 -> 0.44161223 | AB29: ='Data '!P29/'Data '!U29 -> 0.23397573 | AC29: ='Data '!Q29/'Data '!V29 -> 0.45713183 | AE29: 8.13
A30: STB | B30: ='Data '!C30/'Data '!$B$22 -> 6.5599091 | C30: ='Data '!D30/'Data '!$B$22 -> 10.638091 | D30: ='Data '!E30/'Data '!$B$22 -> 7.9889091 | E30: ='Data '!K30/'Data '!$B$22 -> 64.970727 | F30: ='Data '!L30/'Data '!$B$22 -> 62.666909 | H30: =((C30-B30)/ABS(B30)) -> 0.62168267 | I30: =((D30-C30)/ABS(C30)) -> -0.24902794 | J30: =((E30-D30)/ABS(D30)) -> 7.1326157 | K30: =((F30-E30)/ABS(E30)) -> -0.035459326 | M30: ='Data '!C30/'Data '!H30 -> 0.11533316 | N30: ='Data '!D30/'Data '!I30 -> 0.17990551 | O30: ='Data '!E30/'Data '!J30 -> 0.12599141 | P30: ='Data '!F30/'Data '!K30 -> 0.12038289 | Q30: ='Data '!G30/'Data '!L30 -> 0.14844865 | S30: ='Data '!C30/'Data '!R30 -> 0.065591697 | T30: ='Data '!D30/'Data '!S30 -> 0.092334702 | U30: ='Data '!E30/'Data '!T30 -> 0.064795651 | V30: ='Data '!K30/'Data '!U30 -> 0.54015745 | W30: ='Data '!G30/'Data '!V30 -> 0.072087081 | Y30: ='Data '!M30/'Data '!R30 -> 10.134596 | Z30: ='Data '!N30/'Data '!S30 -> 9.7090675 | AA30: ='Data '!O30/'Data '!T30 -> 9.8780578 | AB30: ='Data '!P30/'Data '!U30 -> 10.001134 | AC30: ='Data '!Q30/'Data '!V30 -> 9.4964584 | AE30: 6.29
A31: UIB | B31: ='Data '!C31/'Data '!$B$22 -> 5.9246364 | C31: ='Data '!D31/'Data '!$B$22 -> 7.5256364 | D31: ='Data '!E31/'Data '!$B$22 -> 12.049 | E31: ='Data '!K31/'Data '!$B$22 -> 47.543727 | F31: ='Data '!L31/'Data '!$B$22 -> 49.075 | H31: =((C31-B31)/ABS(B31)) -> 0.27022756 | I31: =((D31-C31)/ABS(C31)) -> 0.60106062 | J31: =((E31-D31)/ABS(D31)) -> 2.945865 | K31: =((F31-E31)/ABS(E31)) -> 0.032207671 | M31: ='Data '!C31/'Data '!H31 -> 0.16170822 | N31: ='Data '!D31/'Data '!I31 -> 0.18627184 | O31: ='Data '!E31/'Data '!J31 -> 0.2687077 | P31: ='Data '!F31/'Data '!K31 -> 0.23898191 | Q31: ='Data '!G31/'Data '!L31 -> 0.13311907 | S31: ='Data '!C31/'Data '!R31 -> 0.090350764 | T31: ='Data '!D31/'Data '!S31 -> 0.10612737 | U31: ='Data '!E31/'Data '!T31 -> 0.14892123 | V31: ='Data '!K31/'Data '!U31 -> 0.52966806 | W31: ='Data '!G31/'Data '!V31 -> 0.06975699 | Y31: ='Data '!M31/'Data '!R31 -> 7.9871027 | Z31: ='Data '!N31/'Data '!S31 -> 7.7492144 | AA31: ='Data '!O31/'Data '!T31 -> 7.1537774 | AB31: ='Data '!P31/'Data '!U31 -> 6.8190536 | AC31: ='Data '!Q31/'Data '!V31 -> 7.0554379 | AE31: 11.78
A32: ENNAKL AUTOMOBILES | B32: ='Data '!C32/'Data '!$B$22 -> 1.2803355 | C32: ='Data '!D32/'Data '!$B$22 -> 3.2778295 | D32: ='Data '!E32/'Data '!$B$22 -> 3.9282819 | E32: ='Data '!K32/'Data '!$B$22 -> 31.655436 | F32: ='Data '!L32/'Data '!$B$22 -> 32.010804 | H32: =((C32-B32)/ABS(B32)) -> 1.5601332 | I32: =((D32-C32)/ABS(C32)) -> 0.19843996 | J32: =((E32-D32)/ABS(D32)) -> 7.0583412 | K32: =((F32-E32)/ABS(E32)) -> 0.01122612 | M32: ='Data '!C32/'Data '!H32 -> 0.031388895 | N32: ='Data '!D32/'Data '!I32 -> 0.067004511 | O32: ='Data '!E32/'Data '!J32 -> 0.076003251 | P32: ='Data '!F32/'Data '!K32 -> 0.15162818 | Q32: ='Data '!G32/'Data '!L32 -> 0.15769204 | S32: ='Data '!C32/'Data '!R32 -> 0.086274091 | T32: ='Data '!D32/'Data '!S32 -> 0.20066148 | U32: ='Data '!E32/'Data '!T32 -> 0.21246247 | V32: ='Data '!K32/'Data '!U32 -> 1.1517317 | W32: ='Data '!G32/'Data '!V32 -> 0.16751937 | Y32: ='Data '!M32/'Data '!R32 -> 1.2432687 | Z32: ='Data '!N32/'Data '!S32 -> 0.92197993 | AA32: ='Data '!O32/'Data '!T32 -> 1.4353446 | AB32: ='Data '!P32/'Data '!U32 -> 0.74165329 | AC32: ='Data '!Q32/'Data '!V32 -> 0.86503867 | AE32: 9.16
A33: ASTREE | B33: ='Data '!C33/'Data '!$B$22 -> 2.3204538 | C33: ='Data '!D33/'Data '!$B$22 -> 1.9142045 | D33: ='Data '!E33/'Data '!$B$22 -> 1.5548973 | E33: ='Data '!K33/'Data '!$B$22 -> 5.5280979 | F33: ='Data '!L33/'Data '!$B$22 -> 6.1995044 | H33: =((C33-B33)/ABS(B33)) -> -0.17507324 | I33: =((D33-C33)/ABS(C33)) -> -0.18770575 | J33: =((E33-D33)/ABS(D33)) -> 2.5552818 | K33: =((F33-E33)/ABS(E33)) -> 0.12145343 | M33: ='Data '!C33/'Data '!H33 -> 0.41307338 | N33: ='Data '!D33/'Data '!I33 -> 0.56661966 | O33: ='Data '!E33/'Data '!J33 -> 0.44878827 | P33: ='Data '!F33/'Data '!K33 -> 0.37294246 | Q33: ='Data '!G33/'Data '!L33 -> 0.42504499 | S33: ='Data '!C33/'Data '!R33 -> 0.16646294 | T33: ='Data '!D33/'Data '!S33 -> 0.13361104 | U33: ='Data '!E33/'Data '!T33 -> 0.10832261 | V33: ='Data '!K33/'Data '!U33 -> 0.36072248 | W33: ='Data '!G33/'Data '!V33 -> 0.15722233 | Y33: ='Data '!M33/'Data '!R33 -> 3.113872 | Z33: ='Data '!N33/'Data '!S33 -> 3.3578187 | AA33: ='Data '!O33/'Data '!T33 -> 3.8413074 | AB33: ='Data '!P33/'Data '!U33 -> 4.1256632 | AC33: ='Data '!Q33/'Data '!V33 -> 2.638123 | AE33: 8.06
A34: BH LEASING | B34: ='Data '!C34/'Data '!$B$22 -> -0.046648636 | C34: ='Data '!D34/'Data '!$B$22 -> 0.10366745 | D34: ='Data '!E34/'Data '!$B$22 -> 0.17832027 | E34: ='Data '!K34/'Data '!$B$22 -> 1.3600137 | F34: ='Data '!L34/'Data '!$B$22 -> 1.6850367 | H34: =((C34-B34)/ABS(B34)) -> 3.2223041 | I34: =((D34-C34)/ABS(C34)) -> 0.72011818 | J34: =((E34-D34)/ABS(D34)) -> 6.6268038 | K34: =((F34-E34)/ABS(E34)) -> 0.23898509 | M34: ='Data '!C34/'Data '!H34 -> -0.060365947 | N34: ='Data '!D34/'Data '!I34 -> 0.083207781 | O34: ='Data '!E34/'Data '!J34 -> 0.12466979 | P34: ='Data '!F34/'Data '!K34 -> 0.21053083 | Q34: ='Data '!G34/'Data '!L34 -> 0.21033774 | S34: ='Data '!C34/'Data '!R34 -> -0.017579738 | T34: ='Data '!D34/'Data '!S34 -> 0.037616033 | U34: ='Data '!E34/'Data '!T34 -> 0.060793765 | V34: ='Data '!K34/'Data '!U34 -> 0.42257841 | W34: ='Data '!G34/'Data '!V34 -> 0.099240619 | Y34: ='Data '!M34/'Data '!R34 -> 9.6905688 | Z34: ='Data '!N34/'Data '!S34 -> 8.3846292 | AA34: ='Data '!O34/'Data '!T34 -> 8.1805569 | AB34: ='Data '!P34/'Data '!U34 -> 7.1134653 | AC34: ='Data '!Q34/'Data '!V34 -> 6.8792451 | AE34: 7.13
A35: CIMENTS DE BIZERTE | B35: ='Data '!C35/'Data '!$B$22 -> -0.038301636 | C35: ='Data '!D35/'Data '!$B$22 -> -0.55938745 | D35: ='Data '!E35/'Data '!$B$22 -> -2.6318607 | E35: ='Data '!K35/'Data '!$B$22 -> 8.3021523 | F35: ='Data '!L35/'Data '!$B$22 -> 2.5307824 | H35: =((C35-B35)/ABS(B35)) -> -13.604793 | I35: =((D35-C35)/ABS(C35)) -> -3.7048977 | J35: =((E35-D35)/ABS(D35)) -> 4.1544801 | K35: =((F35-E35)/ABS(E35)) -> -0.69516551 | M35: ='Data '!C35/'Data '!H35 -> -0.0037937017 | N35: ='Data '!D35/'Data '!I35 -> -0.049144501 | O35: ='Data '!E35/'Data '!J35 -> -0.24109147 | P35: ='Data '!F35/'Data '!K35 -> -0.37619975 | Q35: ='Data '!G35/'Data '!L35 -> -1.6089295 | S35: ='Data '!C35/'Data '!R35 -> -0.013782163 | T35: ='Data '!D35/'Data '!S35 -> -0.07161675 | U35: ='Data '!E35/'Data '!T35 -> -0.51010256 | V35: ='Data '!K35/'Data '!U35 -> 4.2002973 | W35: ='Data '!G35/'Data '!V35 -> -0.31255855 | Y35: ='Data '!M35/'Data '!R35 -> 7.0270851 | Z35: ='Data '!N35/'Data '!S35 -> 2.3480178 | AA35: ='Data '!O35/'Data '!T35 -> 3.9785227 | AB35: ='Data '!P35/'Data '!U35 -> 10.115003 | AC35: ='Data '!Q35/'Data '!V35 -> 1.7122277
A36: ESSOUKNA | B36: ='Data '!C36/'Data '!$B$22 -> -0.015643455 | C36: ='Data '!D36/'Data '!$B$22 -> -0.086584727 | D36: ='Data '!E36/'Data '!$B$22 -> 0.061159455 | E36: ='Data '!K36/'Data '!$B$22 -> 0.604817 | F36: ='Data '!L36/'Data '!$B$22 -> 0.035426909 | H36: =((C36-B36)/ABS(B36)) -> -4.5348853 | I36: =((D36-C36)/ABS(C36)) -> 1.7063538 | J36: =((E36-D36)/ABS(D36)) -> 8.8891824 | K36: =((F36-E36)/ABS(E36)) -> -0.94142541 | M36: ='Data '!C36/'Data '!H36 -> -0.0099732485 | N36: ='Data '!D36/'Data '!I36 -> -0.079266208 | O36: ='Data '!E36/'Data '!J36 -> 0.038486012 | P36: ='Data '!F36/'Data '!K36 -> -0.42778544 | Q36: ='Data '!G36/'Data '!L36 -> -6.4188188 | S36: ='Data '!C36/'Data '!R36 -> -0.0050456187 | T36: ='Data '!D36/'Data '!S36 -> -0.028340484 | U36: ='Data '!E36/'Data '!T36 -> 0.019650926 | V36: ='Data '!K36/'Data '!U36 -> 0.21930852 | W36: ='Data '!G36/'Data '!V36 -> -0.088260755 | Y36: ='Data '!M36/'Data '!R36 -> 1.020107 | Z36: ='Data '!N36/'Data '!S36 -> 0.92382379 | AA36: ='Data '!O36/'Data '!T36 -> 0.68531999 | AB36: ='Data '!P36/'Data '!U36 -> 0.89427258 | AC36: ='Data '!Q36/'Data '!V36 -> 1.6981224
A37: LAND'OR | B37: ='Data '!C37/'Data '!$B$22 -> 0.63457891 | C37: ='Data '!D37/'Data '!$B$22 -> 0.87558818 | D37: ='Data '!E37/'Data '!$B$22 -> -0.90296809 | E37: ='Data '!K37/'Data '!$B$22 -> 23.372268 | F37: ='Data '!L37/'Data '!$B$22 -> 23.777857 | H37: =((C37-B37)/ABS(B37)) -> 0.37979402 | I37: =((D37-C37)/ABS(C37)) -> -2.0312703 | J37: =((E37-D37)/ABS(D37)) -> 26.883825 | K37: =((F37-E37)/ABS(E37)) -> 0.017353437 | M37: ='Data '!C37/'Data '!H37 -> 0.052187314 | N37: ='Data '!D37/'Data '!I37 -> 0.059876123 | O37: ='Data '!E37/'Data '!J37 -> -0.051609808 | P37: ='Data '!F37/'Data '!K37 -> 0.026608201 | Q37: ='Data '!G37/'Data '!L37 -> 0.048292665 | S37: ='Data '!C37/'Data '!R37 -> 0.10200562 | T37: ='Data '!D37/'Data '!S37 -> 0.12399887 | U37: ='Data '!E37/'Data '!T37 -> -0.11208918 | V37: ='Data '!K37/'Data '!U37 -> 2.6358227 | W37: ='Data '!G37/'Data '!V37 -> 0.11393047 | Y37: ='Data '!M37/'Data '!R37 -> 0.86779092 | Z37: ='Data '!N37/'Data '!S37 -> 1.3351354 | AA37: ='Data '!O37/'Data '!T37 -> 1.4497061 | AB37: ='Data '!P37/'Data '!U37 -> 1.3835848 | AC37: ='Data '!Q37/'Data '!V37 -> 1.1655946 | AE37: 15.67
A38: MONOPRIX | B38: ='Data '!C38/'Data '!$B$22 -> -0.87151064 | C38: ='Data '!D38/'Data '!$B$22 -> -0.28340445 | D38: ='Data '!E38/'Data '!$B$22 -> -0.76296964 | E38: ='Data '!K38/'Data '!$B$22 -> 65.889425 | F38: ='Data '!L38/'Data '!$B$22 -> 70.479812 | H38: =((C38-B38)/ABS(B38)) -> 0.6748124 | I38: =((D38-C38)/ABS(C38)) -> -1.6921582 | J38: =((E38-D38)/ABS(D38)) -> 87.359171 | K38: =((F38-E38)/ABS(E38)) -> 0.06966804 | M38: ='Data '!C38/'Data '!H38 -> -0.014757156 | N38: ='Data '!D38/'Data '!I38 -> -0.0047410169 | O38: ='Data '!E38/'Data '!J38 -> -0.012610627 | P38: ='Data '!F38/'Data '!K38 -> 0.0013986021 | Q38: ='Data '!G38/'Data '!L38 -> 0.0088650956 | S38: ='Data '!C38/'Data '!R38 -> -0.19158745 | T38: ='Data '!D38/'Data '!S38 -> -0.06659495 | U38: ='Data '!E38/'Data '!T38 -> -0.22523582 | V38: ='Data '!K38/'Data '!U38 -> 16.215351 | W38: ='Data '!G38/'Data '!V38 -> 0.13906193 | Y38: ='Data '!M38/'Data '!R38 -> 6.2797246 | Z38: ='Data '!N38/'Data '!S38 -> 6.9138439 | AA38: ='Data '!O38/'Data '!T38 -> 9.0790473 | AB38: ='Data '!P38/'Data '!U38 -> 6.6687808 | AC38: ='Data '!Q38/'Data '!V38 -> 6.0557486 | AE38: 23.21
A39: NEW BODY LINE | B39: ='Data '!C39/'Data '!$B$22 -> 0.11056091 | C39: ='Data '!D39/'Data '!$B$22 -> 0.19707709 | D39: ='Data '!E39/'Data '!$B$22 -> 0.10321236 | E39: ='Data '!K39/'Data '!$B$22 -> 1.1870269 | F39: ='Data '!L39/'Data '!$B$22 -> 0.81207691 | H39: =((C39-B39)/ABS(B39)) -> 0.78252054 | I39: =((D39-C39)/ABS(C39)) -> -0.47628432 | J39: =((E39-D39)/ABS(D39)) -> 10.500821 | K39: =((F39-E39)/ABS(E39)) -> -0.31587321 | M39: ='Data '!C39/'Data '!H39 -> 0.24581988 | N39: ='Data '!D39/'Data '!I39 -> 0.31675688 | O39: ='Data '!E39/'Data '!J39 -> 0.20769073 | P39: ='Data '!F39/'Data '!K39 -> 0.087069482 | Q39: ='Data '!G39/'Data '!L39 -> -0.68519798 | S39: ='Data '!C39/'Data '!R39 -> 0.10077312 | T39: ='Data '!D39/'Data '!S39 -> 0.17085932 | U39: ='Data '!E39/'Data '!T39 -> 0.09305714 | V39: ='Data '!K39/'Data '!U39 -> 0.99516293 | W39: ='Data '!G39/'Data '!V39 -> -1.2064744 | Y39: ='Data '!M39/'Data '!R39 -> 0.046010419 | Z39: ='Data '!N39/'Data '!S39 -> 0.10514023 | AA39: ='Data '!O39/'Data '!T39 -> 0.1107476 | AB39: ='Data '!P39/'Data '!U39 -> 0.13107905 | AC39: ='Data '!Q39/'Data '!V39 -> 0.3974996
A40: SIMPAR | B40: ='Data '!C40/'Data '!$B$22 -> -0.85229936 | C40: ='Data '!D40/'Data '!$B$22 -> -0.81471545 | D40: ='Data '!E40/'Data '!$B$22 -> -0.30373373 | E40: ='Data '!K40/'Data '!$B$22 -> 4.0407474 | F40: ='Data '!L40/'Data '!$B$22 -> 1.6349373 | H40: =((C40-B40)/ABS(B40)) -> 0.044097075 | I40: =((D40-C40)/ABS(C40)) -> 0.62719042 | J40: =((E40-D40)/ABS(D40)) -> 14.303585 | K40: =((F40-E40)/ABS(E40)) -> -0.59538741 | M40: ='Data '!C40/'Data '!H40 -> -0.20852157 | N40: ='Data '!D40/'Data '!I40 -> -0.22652022 | O40: ='Data '!E40/'Data '!J40 -> -0.049970684 | P40: ='Data '!F40/'Data '!K40 -> -0.12401513 | Q40: ='Data '!G40/'Data '!L40 -> -0.42816066 | S40: ='Data '!C40/'Data '!R40 -> -0.15171807 | T40: ='Data '!D40/'Data '!S40 -> -0.1703043 | U40: ='Data '!E40/'Data '!T40 -> -0.068067169 | V40: ='Data '!K40/'Data '!U40 -> 0.91683199 | W40: ='Data '!G40/'Data '!V40 -> -0.20365768 | Y40: ='Data '!M40/'Data '!R40 -> 2.6817074 | Z40: ='Data '!N40/'Data '!S40 -> 3.1584677 | AA40: ='Data '!O40/'Data '!T40 -> 3.1319819 | AB40: ='Data '!P40/'Data '!U40 -> 3.4998133 | AC40: ='Data '!Q40/'Data '!V40 -> 6.1047752
...

Sheet Sheet1
A1: Column1 | B1: average EPS | C1: Average EPS growth | D1: Average NPM | E1: Average ROE | F1: Average D/E | G1: Average P/E | H1: Score
A2: SIAME | B2: 0.18095411 | C2: 4.0840165 | D2: 0.13422944 | E2: 0.34228119 | F2: 0.39291314 | G2: 0.29015966 | H2: =B2*0.1+C2*0.2+D2*0.15+E2*0.25+F2*0.15+G2*0.15 -> 1.0430643
A3: MONOPRIX | B3: 0.68028747 | C3: 1.7587326 | D3: 0.12378351 | E3: 0.97189444 | F3: 0.53077024 | G3: 0.36673183 | H3: 0.77265431
A4: STIP | B4: 0.3767567 | C4: 0.69361322 | D4: 0.28270607 | E4: 0.764241 | F4: 0.63882037 | G4: -0.011404366 | H4: 0.55472502
A5: BIAT | B5: 2.0760906 | C5: 0.62340548 | D5: 0.19643183 | E5: 0.29404215 | F5: 0.5846203 | G5: 0.072987944 | H5: =B5*0.1+C5*0.2+D5*0.15+E5*0.25+F5*0.15+G5*0.15 -> 0.53390671
A6: Ste Assurances Magrebia SA | B6: 0.69187616 | C6: 0.5714986 | D6: 0.75709639 | E6: 0.3453382 | F6: 0.38170011 | G6: 0.12968394 | H6: 0.49275736
A7: SOTETEL | B7: 0.18259524 | C7: 1.3833836 | D7: 0.14023822 | E7: 0.34627939 | F7: 0.40398392 | G7: 0.080645161 | H7: =B7*0.1+C7*0.2+D7*0.15+E7*0.25+F7*0.15+G7*0.15 -> 0.47523619
A8: BNA | B8: 1.3053793 | C8: 0.64408528 | D8: 0.17926778 | E8: 0.26721917 | F8: 0.58447812 | G8: 0.039263604 | H8: =B8*0.1+C8*0.2+D8*0.15+E8*0.25+F8*0.15+G8*0.15 -> 0.44661121
A9: SITS | B9: 0.14620208 | C9: 0.61851477 | D9: 0.21878596 | E9: 0.27509532 | F9: 0.37687933 | G9: 1 | H9: =B9*0.1+C9*0.2+D9*0.15+E9*0.25+F9*0.15+G9*0.15 -> 0.44644679
A10: ASSAD | B10: 0.19819124 | C10: 0.74857693 | D10: 0.10463244 | E10: 0.54133906 | F10: 0.47198891 | G10: 0.33349625 | H10: =B10*0.1+C10*0.2+D10*0.15+E10*0.25+F10*0.15+G10*0.15 -> 0.44138692
A11: TAWASOL GH | B11: 0.19009439 | C11: 1.295241 | D11: 0.10971941 | E11: 0.35248743 | F11: 0.50229457 | G11: -0.011404366 | H11: 0.4408744
A12: SMART TUNISIE | B12: 0.55959311 | C12: 0.9720586 | D12: 0.14098173 | E12: 0.34179525 | F12: 0.33675347 | G12: 0.19322255 | H12: =B12*0.1+C12*0.2+D12*0.15+E12*0.25+F12*0.15+G12*0.15 -> 0.43646351
A13: LAND'OR | B13: 0.33406837 | C13: 0.91351052 | D13: 0.1323981 | E13: 0.36493971 | F13: 0.39134973 | G13: 0.24389052 | H13: =B13*0.1+C13*0.2+D13*0.15+E13*0.25+F13*0.15+G13*0.15 -> 0.42248962
A14: BH | B14: 0.97697974 | C14: 0.64396704 | D14: 0.17872424 | E14: 0.27025737 | F14: 0.60849122 | G14: 0.063049853 | H14: =B14*0.1+C14*0.2+D14*0.15+E14*0.25+F14*0.15+G14*0.15 -> 0.42159552
A15: STB | B15: 0.90698555 | C15: 0.66832241 | D15: 0.1656468 | E15: 0.26694295 | F15: 0.60099154 | G15: 0.09107201 | H15: =B15*0.1+C15*0.2+D15*0.15+E15*0.25+F15*0.15+G15*0.15 -> 0.41975533
A16: MPBS | B16: 0.23593742 | C16: 0.97880694 | D16: 0.13702015 | E16: 0.34435913 | F16: 0.38469603 | G16: 0.15184099 | H16: =B16*0.1+C16*0.2+D16*0.15+E16*0.25+F16*0.15+G16*0.15 -> 0.40647849
