Workbook

Sheet Added Value By Sector
A1: Year | B1: Added value of Agriculture, forestry and fishing sector | C1: Added value of Oil and natural gas extraction sector | D1: Added value of Extraction of mining products sector | E1: Added value of Agrifoods industries sector | F1: Added value of Textile, clothing and leather industry sector | G1: Added value of Oil refinery sector | H1: Added value of Chemical industries sector | I1: Added value of Building materials industry, ceramics and glass sector | J1: Added value of Mechanical and electrical industries sector | K1: Added value of Various industries sector | L1: Added value of Production and distribution of electricity and gas sector | M1: Added value of Water distribution and treatment of wastewater and waste sector | N1: Added value of Construction sector | O1: Added value of Trade, maintenance and repair sector | P1: Added value of Transportation and warehousing services sector | Q1: Added value of Hotel, cafe and restaurant services sector | R1: Added value of Information and communication sector | S1: Added value of Financial activities sector | T1: Added value of Public administration and defense services sector | U1: Added value of Private and public education sector | V1: Added value of Private and public health and social action sector | W1: Added value of Other market services sector | X1: Added value of Other household activities sector | Y1: Added value of Services provided by associative organizations sector | Z1: Added Values of Market activities sector | AA1: Added Values of Nonmarket activities sector
A2: Q4 2010 | B2: 0.059994193 | C2: -0.16577538 | D2: 0.11157135 | E2: -0.015227047 | F2: 0.027219433 | G2: -0.23412152 | H2: 0.066722111 | I2: 0.024739849 | J2: 0.052155646 | K2: 0.019619332 | L2: -0.044615657 | M2: 0.18754026 | N2: 0.11591881 | O2: 0.027506989 | P2: -0.0051114448 | Q2: -0.055389465 | R2: 0.054597987 | S2: -0.014813723 | T2: 0.055922294 | U2: 0.024954572 | V2: -0.0045468807 | W2: -0.041423444 | X2: 8.3778004e-05 | Y2: 0.038332081 | Z2: 0.0033272802 | AA2: 0.040784933
A3: Q4 2011 | B3: 0.11329542 | C3: -0.062364142 | D3: -0.45352155 | E3: 0.070075421 | F3: -0.055979545 | G3: 2.0145093 | H3: -0.23672866 | I3: -0.0094614197 | J3: 0.042108142 | K3: 0.0033615232 | L3: 0.031017104 | M3: -0.068121514 | N3: -0.078424108 | O3: -0.0012704838 | P3: -0.10524702 | Q3: -0.16089633 | R3: 0.038801678 | S3: 0.032649443 | T3: 0.11274506 | U3: 0.049460949 | V3: 0.06144416 | W3: -0.077967234 | X3: 0.023264019 | Y3: 0.062290521 | Z3: -0.027296686 | AA3: 0.078786159
A4: Q4 2012 | B4: 0.07645301 | C4: 0.0715827 | D4: -0.091130511 | E4: 0.040225961 | F4: -0.025056767 | G4: -0.28091999 | H4: 0.16236963 | I4: 0.056704446 | J4: -0.0030201871 | K4: -0.02534443 | L4: 0.11509814 | M4: -0.017177052 | N4: 0.050677975 | O4: 0.050215278 | P4: 0.05961857 | Q4: 0.082138445 | R4: 0.083449573 | S4: 0.070468575 | T4: 0.059033181 | U4: 0.0095878937 | V4: 0.11179522 | W4: 0.06614263 | X4: 0.012404775 | Y4: 0.018717275 | Z4: 0.048913304 | AA4: 0.04342461
A5: Q4 2013 | B5: -0.035729913 | C5: -0.20195816 | D5: 0.51276257 | E5: -0.025911823 | F5: 0.0067807299 | G5: -0.058203759 | H5: 0.12176978 | I5: 0.0071441634 | J5: -0.015246693 | K5: 0.018258572 | L5: 0.049848154 | M5: 0.19806645 | N5: 0.032784292 | O5: 0.039838201 | P5: 0.024767316 | Q5: -0.013829606 | R5: 0.083024547 | S5: 0.016717386 | T5: 0.064492857 | U5: 0.029895115 | V5: 0.077683509 | W5: 0.041806544 | X5: 0.0083181315 | Y5: 0.051779136 | Z5: 0.006620645 | AA5: 0.053427417
A6: Q4 2014 | B6: 0.078973143 | C6: -0.051262347 | D6: -0.088731852 | E6: 0.046567391 | F6: -0.013708488 | G6: -0.046332428 | H6: -0.13005655 | I6: 0.0095820919 | J6: 0.051802938 | K6: -0.0012186574 | L6: -0.0017570776 | M6: 0.03508697 | N6: 0.012102036 | O6: 0.025886863 | P6: 0.00056309055 | Q6: -0.024697864 | R6: 0.037527965 | S6: 0.050808054 | T6: 0.025640178 | U6: 0.046869128 | V6: 0.068546232 | W6: 0.031584643 | X6: 0.015384622 | Y6: 0.052919459 | Z6: 0.020619459 | AA6: 0.03123172
A7: Q4 2015 | B7: 0.060402637 | C7: -0.13790543 | D7: 0.40501208 | E7: -0.0099572301 | F7: -0.041255321 | G7: -0.25111819 | H7: 0.070246515 | I7: -0.00020888804 | J7: -0.0058624394 | K7: -0.019282118 | L7: 0.017694523 | M7: 0.042887111 | N7: -0.0068966107 | O7: 0.011232754 | P7: -0.041215435 | Q7: -0.15245524 | R7: 0.028154998 | S7: 0.031167304 | T7: 0.023308962 | U7: 0.036821954 | V7: 0.042637224 | W7: 0.037222959 | X7: 0.020004784 | Y7: 0.041401841 | Z7: -0.00098807179 | AA7: 0.027053302
A8: Q4 2016 | B8: -0.055476312 | C8: -0.080323809 | D8: 0.12715879 | E8: 0.043951237 | F8: -0.0010989432 | G8: -0.85557448 | H8: 0.0059230561 | I8: -0.022392629 | J8: 0.026290959 | K8: 0.0035925634 | L8: 0.040944243 | M8: 0.00092402706 | N8: -0.0044806284 | O8: 0.021948036 | P8: 0.053280529 | Q8: 0.10851414 | R8: 0.044123168 | S8: 0.041318997 | T8: 0.0050548341 | U8: 0.041254738 | V8: 0.030401758 | W8: 0.035328152 | X8: 0.023576943 | Y8: 0.041456342 | Z8: 0.012475517 | AA8: 0.018453626
A9: Q4 2017 | B9: 0.036950392 | C9: -0.0054887239 | D9: -0.11382816 | E9: 0.067356841 | F9: 0.021392978 | G9: 0.16320268 | H9: 0.022776467 | I9: -0.079123191 | J9: 0.051387856 | K9: -0.0088123213 | L9: 0.039497204 | M9: 0.034088388 | N9: -0.017640436 | O9: 0.011066655 | P9: 0.062650966 | Q9: 0.077444186 | R9: 0.018473683 | S9: 0.11303992 | T9: -0.00013078889 | U9: 0.019372879 | V9: 0.019689014 | W9: 0.020765133 | X9: 0.012868315 | Y9: 0.039805922 | Z9: 0.02799032 | AA9: 0.0025692709
A10: Q4 2018 | B10: 0.065311154 | C10: -0.13010539 | D10: 0.11532848 | E10: -0.015667748 | F10: 0.0091321753 | G10: 0.39924713 | H10: 0.015961428 | I10: 0.014158059 | J10: -0.0029087723 | K10: -3.1362323e-05 | L10: 0.012072638 | M10: 0.027097258 | N10: 0.005401525 | O10: 0.016265634 | P10: 0.030325519 | Q10: 0.050489817 | R10: 0.081250902 | S10: 0.025720339 | T10: 0.0025377928 | U10: 0.012103376 | V10: 0.04360567 | W10: 0.035838971 | X10: 0.027200569 | Y10: 0.039881586 | Z10: 0.023259924 | AA10: 0.0053124555
A11: Q4 2019 | B11: 0.039519365 | C11: -0.077475179 | D11: 0.39493906 | E11: 0.062326477 | F11: -0.058913118 | G11: 0.74670607 | H11: 0.0036820267 | I11: 0.016529514 | J11: -0.029335561 | K11: -0.013785147 | L11: -0.023667187 | M11: 0.046253195 | N11: 0.00016547029 | O11: 0.0055108004 | P11: -0.028872111 | Q11: 0.05299175 | R11: 0.045549087 | S11: 0.0041149009 | T11: 0.013822266 | U11: 0.025888805 | V11: 0.042490461 | W11: -0.0049721169 | X11: 0.013426755 | Y11: 0.0051320531 | Z11: 0.009939922 | AA11: 0.019647681
A12: Q4 2020 | B12: 0.012870884 | C12: 0.051316171 | D12: -0.43382457 | E12: -0.061435286 | F12: 0.17115464 | G12: 0.20715172 | H12: -0.12276883 | I12: 0.17681163 | J12: 0.0048319568 | K12: -0.014669232 | L12: -0.1230768 | M12: 0.096298945 | N12: 0.16195923 | O12: 0.015590124 | P12: -0.044627319 | Q12: 0.33027665 | R12: 0.053629956 | S12: 0.0024216241 | T12: -0.044145442 | U12: -0.01175047 | V12: 0.11097079 | W12: -0.069248944 | X12: -0.018763549 | Y12: -0.087757223 | Z12: -0.045329087 | AA12: -0.0089155346
A13: Q4 2021 | B13: -0.014652997 | C13: 0.18231561 | D13: 0.57522189 | E13: 0.062318341 | F13: 0.028819154 | G13: 1.9787215 | H13: 0.25541252 | I13: -0.018170783 | J13: 0.0006633038 | K13: 0.038939396 | L13: 0.17291781 | M13: 0.11237733 | N13: -0.040379321 | O13: -0.0033272611 | P13: 0.15851725 | Q13: 0.254695 | R13: 0.029285389 | S13: -0.018804832 | T13: 0.014272086 | U13: 0.021568834 | V13: 0.07074806 | W13: -0.00033921634 | X13: 0.016217277 | Y13: 0.003943109 | Z13: 0.038123807 | AA13: 0.0097103168
... A16: Q4 2024 | B16: 0.12230027 | C16: -0.16406656 | D16: 0.26918524 | E16: 0.023746057 | F16: -0.027943685 | G16: -0.32473311 | H16: 0.042605586 | I16: 0.0085369918 | J16: 0.030171647 | K16: -0.004425753 | L16: -0.082983278 | M16: -0.0091767797 | N16: 0.019040965 | O16: 0.026113427 | P16: 0.051612425 | Q16: 0.026039709 | R16: 0.011763263 | S16: -0.021560419 | T16: 0.021898978 | U16: 0.023934031 | V16: 0.014721381 | W16: 0.019468645 | X16: 0.022825744 | Y16: 0.006246006 | Z16: 0.024395035 | AA16: 0.020416884

Sheet National Account By Sector
A1: Quarterly national accounts | B1: Attribute | C1: Constant Prices | D1: QoQ Real GDP | E1: YoY Real GDP | G1: QoQ Real GDP Growth by sector
A2: Added value of Agriculture, forestry and fishing sector | B2: Q4 2024 | C2: 2128.7 | D2: 0.033148903 | E2: 0.12623671 | G2: Sectors | H2: Q1 2025 | I2: Q2 2025
A3: Added value of Oil and natural gas extraction sector | B3: Q4 2024 | C3: 426.9 | D3: 0.0025833725 | E3: -0.17010109 | G3: Agriculture | H3: =D33 -> 0.026260159 | I3: =D64 -> 0.031905154
A4: Added value of Extraction of mining products sector | B4: Q4 2024 | C4: 183.7 | D4: 0.16931891 | E4: 0.24796196 | G4: Industries | H4: =SUMPRODUCT(C3:C16,D34:D47)/SUM(C3:C16) -> -0.0072279133 | I4: =SUMPRODUCT(C34:C47,D65:D78)/SUM(C34:C47) -> 0.026084224
A5: Added value of Agrifoods industries sector | B5: Q4 2024 | C5: 819.3 | D5: -0.0067887017 | E5: 0.023101898 | G5: Services | H5: =SUMPRODUCT(C17:C27,D48:D58)/SUM(C17:C27) -> -0.00027326917 | I5: =SUMPRODUCT(C48:C58,D79:D89)/SUM(C48:C58) -> 0.01580288
A6: Added value of Textile, clothing and leather industry sector | B6: Q4 2024 | C6: 562 | D6: -0.041609823 | E6: -0.030533034
A7: Added value of Oil refinery sector | B7: Q4 2024 | C7: -1.4 | D7: -1.0693069 | E7: -1.1238938
A8: Added value of Chemical industries sector | B8: Q4 2024 | C8: 264.6 | D8: -0.02 | E8: 0.032383925 | G8: YoY Real GDP Growth by sector
A9: Added value of Building materials industry, ceramics and glass sector | B9: Q4 2024 | C9: 204.9 | D9: -0.060522696 | E9: 0.0034280118 | G9: Sectors | H9: Q1 2025 | I9: Q2 2025
A10: Added value of Mechanical and electrical industries sector | B10: Q4 2024 | C10: 1025.2 | D10: 0.020404101 | E10: 0.028904055 | G10: Agriculture | H10: =E33 -> 0.072880856 | I10: =E64 -> 0.098372637
A11: Added value of Various industries sector | B11: Q4 2024 | C11: 401 | D11: -0.0019910403 | E11: -0.0064420218 | G11: Industries | H11: =SUMPRODUCT(C3:C16,E34:E47)/SUM(C3:C16) -> 0.013731089 | I11: =SUMPRODUCT(C34:C47,E65:E78)/SUM(C34:C47) -> 0.039740012
A12: Added value of Production and distribution of electricity and gas sector | B12: Q4 2024 | C12: 238.9 | D12: -0.1483066 | E12: -0.09712774 | G12: Services | H12: =SUMPRODUCT(C17:C27,E48:E58)/SUM(C17:C27) -> 0.014849809 | I12: =SUMPRODUCT(C48:C58,E79:E89)/SUM(C48:C58) -> 0.027746696
A13: Added value of Water distribution and treatment of wastewater and waste sector | B13: Q4 2024 | C13: 187.8 | D13: 0.031301483 | E13: -0.010537408
A14: Added value of Construction sector | B14: Q4 2024 | C14: 1018.8 | D14: 0.024228411 | E14: 0.018596281
A15: Added value of Trade, maintenance and repair sector | B15: Q4 2024 | C15: 2878.6 | D15: 0.015665796 | E15: 0.026238859
A16: Added value of Transportation and warehousing services sector | B16: Q4 2024 | C16: 1405.2 | D16: -0.01644852 | E16: 0.051638976
A17: Added value of Hotel, cafe and restaurant services sector | B17: Q4 2024 | C17: 782.7 | D17: 0.011632416 | E17: 0.02622263
A18: Added value of Information and communication sector | B18: Q4 2024 | C18: 894.9 | D18: 0.0075433461 | E18: 0.011758055
A19: Added value of Financial activities sector | B19: Q4 2024 | C19: 1002.6 | D19: -0.0019908421 | E19: -0.022425897
A20: Added value of Public administration and defense services sector | B20: Q4 2024 | C20: 2237.5 | D20: 0.016721952 | E20: 0.021922813
A21: Added value of Private and public education sector | B21: Q4 2024 | C21: 1608.5 | D21: 0.01106292 | E21: 0.024130905
A22: Added value of Private and public health and social action sector | B22: Q4 2024 | C22: 1075 | D22: 0.01109857 | E22: 0.014725316
A23: Added value of Other market services sector | B23: Q4 2024 | C23: 1476.9 | D23: 0.0025795941 | E23: 0.019606489
A24: Added value of Other household activities sector | B24: Q4 2024 | C24: 1634.1 | D24: 0 | E24: 0.022974834
... A30: Gross domestic product value sector | B30: Q4 2024 | C30: 24355 | D30: 0.0067544106 | E30: 0.024679827
A32: Quarterly national accounts | B32: Attribute | C32: Constant Prices | D32: QoQ Real GDP | E32: YoY Real GDP
A33: Added value of Agriculture, forestry and fishing sector | B33: Q1 2025 | C33: 2184.6 | D33: 0.026260159 | E33: 0.072880856
A34: Added value of Oil and natural gas extraction sector | B34: Q1 2025 | C34: 384.4 | D34: -0.099554931 | E34: -0.072169925
A35: Added value of Extraction of mining products sector | B35: Q1 2025 | C35: 173.1 | D35: -0.057702776 | E35: 0.16880486
A36: Added value of Agrifoods industries sector | B36: Q1 2025 | C36: 890.2 | D36: 0.086537288 | E36: 0.071110576
A37: Added value of Textile, clothing and leather industry sector | B37: Q1 2025 | C37: 571.5 | D37: 0.016903915 | E37: -0.01516457
A38: Added value of Oil refinery sector | B38: Q1 2025 | C38: 1 | D38: -1.7142857 | E38: -0.91150442
A39: Added value of Chemical industries sector | B39: Q1 2025 | C39: 251.2 | D39: -0.050642479 | E39: -0.039020658
A40: Added value of Building materials industry, ceramics and glass sector | B40: Q1 2025 | C40: 207.3 | D40: 0.011713031 | E40: -0.0067081936
A41: Added value of Mechanical and electrical industries sector | B41: Q1 2025 | C41: 968.3 | D41: -0.055501366 | E41: 0.01064607
A42: Added value of Various industries sector | B42: Q1 2025 | C42: 385.3 | D42: -0.03915212 | E42: -0.0018134715
A43: Added value of Production and distribution of electricity and gas sector | B43: Q1 2025 | C43: 247.1 | D43: 0.034323985 | E43: -0.00040453074
A44: Added value of Water distribution and treatment of wastewater and waste sector | B44: Q1 2025 | C44: 189 | D44: 0.0063897764 | E44: 0.029972752
... A61: Gross domestic product value sector | B61: Q1 2025 | C61: 24320.3 | D61: -0.0014247588 | E61: 0.01645449
A63: Quarterly national accounts | B63: Attribute | C63: Constant Prices | D63: QoQ Real GDP | E63: YoY Real GDP
...

Sheet GDP
A1: Quarterly national accounts | B1: Attribute | C1: Constant Prices | D1: QoQ Real GDP | E1: YoY Real GDP | F1: Current Prices | G1: QoQ Nominal GDP | H1: YoY Nominal GDP | I1: index
A2: Added value of Agriculture, forestry and fishing sector | B2: Q1 2010 | C2: 1498.5 | F2: 1098
A3: Added value of Agriculture, forestry and fishing sector | B3: Q2 2010 | C3: 1525.7 | D3: =(Table2_1[[#This Row],[Constant Prices]]-C2)/C2 -> 0.018151485 | F3: 1110.2 | G3: =(Table2_1[[#This Row],[Current Prices]]-F2)/F2 -> 0.011111111
A4: Added value of Agriculture, forestry and fishing sector | B4: Q3 2010 | C4: 1554.3 | D4: =(Table2_1[[#This Row],[Constant Prices]]-C3)/C3 -> 0.018745494 | F4: 1160.9 | G4: =(Table2_1[[#This Row],[Current Prices]]-F3)/F3 -> 0.045667447
A5: Added value of Agriculture, forestry and fishing sector | B5: Q4 2010 | C5: 1590.2 | D5: =(Table2_1[[#This Row],[Constant Prices]]-C4)/C4 -> 0.023097214 | F5: 1158.9 | G5: =(Table2_1[[#This Row],[Current Prices]]-F4)/F4 -> -0.0017228013
A6: Added value of Agriculture, forestry and fishing sector | B6: Q1 2011 | C6: 1659.6 | D6: =(Table2_1[[#This Row],[Constant Prices]]-C5)/C5 -> 0.043642309 | E6: =(Table2_1[[#This Row],[Constant Prices]]-C2)/C2 -> 0.10750751 | F6: 1231.3 | G6: =(Table2_1[[#This Row],[Current Prices]]-F5)/F5 -> 0.062473035 | H6: =(Table2_1[[#This Row],[Current Prices]]-F2)/F2 -> 0.12140255
A7: Added value of Agriculture, forestry and fishing sector | B7: Q2 2011 | C7: 1696.8 | D7: =(Table2_1[[#This Row],[Constant Prices]]-C6)/C6 -> 0.02241504 | E7: =(Table2_1[[#This Row],[Constant Prices]]-C3)/C3 -> 0.11214524 | F7: 1241.5 | G7: =(Table2_1[[#This Row],[Current Prices]]-F6)/F6 -> 0.0082839276 | H7: =(Table2_1[[#This Row],[Current Prices]]-F3)/F3 -> 0.11826698
A8: Added value of Agriculture, forestry and fishing sector | B8: Q3 2011 | C8: 1736.4 | D8: =(Table2_1[[#This Row],[Constant Prices]]-C7)/C7 -> 0.023338048 | E8: =(Table2_1[[#This Row],[Constant Prices]]-C4)/C4 -> 0.11715885 | F8: 1311.5 | G8: =(Table2_1[[#This Row],[Current Prices]]-F7)/F7 -> 0.056383407 | H8: =(Table2_1[[#This Row],[Current Prices]]-F4)/F4 -> 0.12972694
A9: Added value of Agriculture, forestry and fishing sector | B9: Q4 2011 | C9: 1777.9 | D9: =(Table2_1[[#This Row],[Constant Prices]]-C8)/C8 -> 0.023900023 | E9: =(Table2_1[[#This Row],[Constant Prices]]-C5)/C5 -> 0.11803547 | F9: 1348.8 | G9: =(Table2_1[[#This Row],[Current Prices]]-F8)/F8 -> 0.028440717 | H9: =(Table2_1[[#This Row],[Current Prices]]-F5)/F5 -> 0.16386228 | I9: 1
A10: Added value of Agriculture, forestry and fishing sector | B10: Q1 2012 | C10: 1808.4 | D10: =(Table2_1[[#This Row],[Constant Prices]]-C9)/C9 -> 0.017155071 | E10: =(Table2_1[[#This Row],[Constant Prices]]-C6)/C6 -> 0.089660159 | F10: 1472.1 | G10: =(Table2_1[[#This Row],[Current Prices]]-F9)/F9 -> 0.091414591 | H10: =(Table2_1[[#This Row],[Current Prices]]-F6)/F6 -> 0.19556566
A11: Added value of Agriculture, forestry and fishing sector | B11: Q2 2012 | C11: 1855.3 | D11: =(Table2_1[[#This Row],[Constant Prices]]-C10)/C10 -> 0.025934528 | E11: =(Table2_1[[#This Row],[Constant Prices]]-C7)/C7 -> 0.093411127 | F11: 1516.6 | G11: =(Table2_1[[#This Row],[Current Prices]]-F10)/F10 -> 0.030228925 | H11: =(Table2_1[[#This Row],[Current Prices]]-F7)/F7 -> 0.22158679
A12: Added value of Agriculture, forestry and fishing sector | B12: Q3 2012 | C12: 1891.6 | D12: =(Table2_1[[#This Row],[Constant Prices]]-C11)/C11 -> 0.019565569 | E12: =(Table2_1[[#This Row],[Constant Prices]]-C8)/C8 -> 0.089380327 | F12: 1562.1 | G12: =(Table2_1[[#This Row],[Current Prices]]-F11)/F11 -> 0.030001319 | H12: =(Table2_1[[#This Row],[Current Prices]]-F8)/F8 -> 0.19107892
A13: Added value of Agriculture, forestry and fishing sector | B13: Q4 2012 | C13: 1917.7 | D13: =(Table2_1[[#This Row],[Constant Prices]]-C12)/C12 -> 0.013797843 | E13: =(Table2_1[[#This Row],[Constant Prices]]-C9)/C9 -> 0.078632094 | F13: 1582.7 | G13: =(Table2_1[[#This Row],[Current Prices]]-F12)/F12 -> 0.013187376 | H13: =(Table2_1[[#This Row],[Current Prices]]-F9)/F9 -> 0.1734134 | I13: 2
A14: Added value of Agriculture, forestry and fishing sector | B14: Q1 2013 | C14: 1718 | D14: =(Table2_1[[#This Row],[Constant Prices]]-C13)/C13 -> -0.10413516 | E14: =(Table2_1[[#This Row],[Constant Prices]]-C10)/C10 -> -0.04998894 | F14: 1536.6 | G14: =(Table2_1[[#This Row],[Current Prices]]-F13)/F13 -> -0.02912744 | H14: =(Table2_1[[#This Row],[Current Prices]]-F10)/F10 -> 0.043814958
A15: Added value of Agriculture, forestry and fishing sector | B15: Q2 2013 | C15: 1754.5 | D15: =(Table2_1[[#This Row],[Constant Prices]]-C14)/C14 -> 0.021245634 | E15: =(Table2_1[[#This Row],[Constant Prices]]-C11)/C11 -> -0.054330836 | F15: 1556 | G15: =(Table2_1[[#This Row],[Current Prices]]-F14)/F14 -> 0.012625277 | H15: =(Table2_1[[#This Row],[Current Prices]]-F11)/F11 -> 0.025979164
A16: Added value of Agriculture, forestry and fishing sector | B16: Q3 2013 | C16: 1790.4 | D16: =(Table2_1[[#This Row],[Constant Prices]]-C15)/C15 -> 0.02046167 | E16: =(Table2_1[[#This Row],[Constant Prices]]-C12)/C12 -> -0.053499683 | F16: 1585.9 | G16: =(Table2_1[[#This Row],[Current Prices]]-F15)/F15 -> 0.019215938 | H16: =(Table2_1[[#This Row],[Current Prices]]-F12)/F12 -> 0.0152359
A17: Added value of Agriculture, forestry and fishing sector | B17: Q4 2013 | C17: 1838.2 | D17: =(Table2_1[[#This Row],[Constant Prices]]-C16)/C16 -> 0.026697945 | E17: =(Table2_1[[#This Row],[Constant Prices]]-C13)/C13 -> -0.041455911 | F17: 1625 | G17: =(Table2_1[[#This Row],[Current Prices]]-F16)/F16 -> 0.02465477 | H17: =(Table2_1[[#This Row],[Current Prices]]-F13)/F13 -> 0.02672648 | I17: 3
A18: Added value of Agriculture, forestry and fishing sector | B18: Q1 2014 | C18: 1869.7 | D18: =(Table2_1[[#This Row],[Constant Prices]]-C17)/C17 -> 0.017136329 | E18: =(Table2_1[[#This Row],[Constant Prices]]-C14)/C14 -> 0.088300349 | F18: 1747.8 | G18: =(Table2_1[[#This Row],[Current Prices]]-F17)/F17 -> 0.075569231 | H18: =(Table2_1[[#This Row],[Current Prices]]-F14)/F14 -> 0.13744631
A19: Added value of Agriculture, forestry and fishing sector | B19: Q2 2014 | C19: 1932.5 | D19: =(Table2_1[[#This Row],[Constant Prices]]-C18)/C18 -> 0.033588276 | E19: =(Table2_1[[#This Row],[Constant Prices]]-C15)/C15 -> 0.10145341 | F19: 1794 | G19: =(Table2_1[[#This Row],[Current Prices]]-F18)/F18 -> 0.02643323 | H19: =(Table2_1[[#This Row],[Current Prices]]-F15)/F15 -> 0.1529563
A20: Added value of Agriculture, forestry and fishing sector | B20: Q3 2014 | C20: 1971.9 | D20: =(Table2_1[[#This Row],[Constant Prices]]-C19)/C19 -> 0.020388098 | E20: =(Table2_1[[#This Row],[Constant Prices]]-C16)/C16 -> 0.10137399 | F20: 1888.6 | G20: =(Table2_1[[#This Row],[Current Prices]]-F19)/F19 -> 0.052731327 | H20: =(Table2_1[[#This Row],[Current Prices]]-F16)/F16 -> 0.19086954
A21: Added value of Agriculture, forestry and fishing sector | B21: Q4 2014 | C21: 1987.4 | D21: =(Table2_1[[#This Row],[Constant Prices]]-C20)/C20 -> 0.0078604392 | E21: =(Table2_1[[#This Row],[Constant Prices]]-C17)/C17 -> 0.081166358 | F21: 1885.1 | G21: =(Table2_1[[#This Row],[Current Prices]]-F20)/F20 -> -0.0018532246 | H21: =(Table2_1[[#This Row],[Current Prices]]-F17)/F17 -> 0.16006154 | I21: 4
A22: Added value of Agriculture, forestry and fishing sector | B22: Q1 2015 | C22: 2033.7 | D22: =(Table2_1[[#This Row],[Constant Prices]]-C21)/C21 -> 0.02329677 | E22: =(Table2_1[[#This Row],[Constant Prices]]-C18)/C18 -> 0.087714607 | F22: 2006.4 | G22: =(Table2_1[[#This Row],[Current Prices]]-F21)/F21 -> 0.064346719 | H22: =(Table2_1[[#This Row],[Current Prices]]-F18)/F18 -> 0.14795743
A23: Added value of Agriculture, forestry and fishing sector | B23: Q2 2015 | C23: 2043.2 | D23: =(Table2_1[[#This Row],[Constant Prices]]-C22)/C22 -> 0.0046712888 | E23: =(Table2_1[[#This Row],[Constant Prices]]-C19)/C19 -> 0.057283312 | F23: 2006 | G23: =(Table2_1[[#This Row],[Current Prices]]-F22)/F22 -> -0.00019936204 | H23: =(Table2_1[[#This Row],[Current Prices]]-F19)/F19 -> 0.11817168
A24: Added value of Agriculture, forestry and fishing sector | B24: Q3 2015 | C24: 2080.3 | D24: =(Table2_1[[#This Row],[Constant Prices]]-C23)/C23 -> 0.018157792 | E24: =(Table2_1[[#This Row],[Constant Prices]]-C20)/C20 -> 0.054972362 | F24: 2113 | G24: =(Table2_1[[#This Row],[Current Prices]]-F23)/F23 -> 0.05333998 | H24: =(Table2_1[[#This Row],[Current Prices]]-F20)/F20 -> 0.11881817
A25: Added value of Agriculture, forestry and fishing sector | B25: Q4 2015 | C25: 2110 | D25: =(Table2_1[[#This Row],[Constant Prices]]-C24)/C24 -> 0.014276787 | E25: =(Table2_1[[#This Row],[Constant Prices]]-C21)/C21 -> 0.061688638 | F25: 2141.8 | G25: =(Table2_1[[#This Row],[Current Prices]]-F24)/F24 -> 0.01362991 | H25: =(Table2_1[[#This Row],[Current Prices]]-F21)/F21 -> 0.13617315 | I25: 5
A26: Added value of Agriculture, forestry and fishing sector | B26: Q1 2016 | C26: 1848.5 | D26: =(Table2_1[[#This Row],[Constant Prices]]-C25)/C25 -> -0.12393365 | E26: =(Table2_1[[#This Row],[Constant Prices]]-C22)/C22 -> -0.091065546 | F26: 1950.5 | G26: =(Table2_1[[#This Row],[Current Prices]]-F25)/F25 -> -0.089317397 | H26: =(Table2_1[[#This Row],[Current Prices]]-F22)/F22 -> -0.027860845
A27: Added value of Agriculture, forestry and fishing sector | B27: Q2 2016 | C27: 1879.4 | D27: =(Table2_1[[#This Row],[Constant Prices]]-C26)/C26 -> 0.016716256 | E27: =(Table2_1[[#This Row],[Constant Prices]]-C23)/C23 -> -0.080168363 | F27: 1988.8 | G27: =(Table2_1[[#This Row],[Current Prices]]-F26)/F26 -> 0.019635991 | H27: =(Table2_1[[#This Row],[Current Prices]]-F23)/F23 -> -0.0085742772
A28: Added value of Agriculture, forestry and fishing sector | B28: Q3 2016 | C28: 1928.3 | D28: =(Table2_1[[#This Row],[Constant Prices]]-C27)/C27 -> 0.026018942 | E28: =(Table2_1[[#This Row],[Constant Prices]]-C24)/C24 -> -0.073066385 | F28: 2071 | G28: =(Table2_1[[#This Row],[Current Prices]]-F27)/F27 -> 0.041331456 | H28: =(Table2_1[[#This Row],[Current Prices]]-F24)/F24 -> -0.019876952
A29: Added value of Agriculture, forestry and fishing sector | B29: Q4 2016 | C29: 1977.9 | D29: =(Table2_1[[#This Row],[Constant Prices]]-C28)/C28 -> 0.025722139 | E29: =(Table2_1[[#This Row],[Constant Prices]]-C25)/C25 -> -0.062606635 | F29: 2113.4 | G29: =(Table2_1[[#This Row],[Current Prices]]-F28)/F28 -> 0.020473201 | H29: =(Table2_1[[#This Row],[Current Prices]]-F25)/F25 -> -0.013259875 | I29: 6
A30: Added value of Agriculture, forestry and fishing sector | B30: Q1 2017 | C30: 1985.5 | D30: =(Table2_1[[#This Row],[Constant Prices]]-C29)/C29 -> 0.0038424592 | E30: =(Table2_1[[#This Row],[Constant Prices]]-C26)/C26 -> 0.074114147 | F30: 2238.7 | G30: =(Table2_1[[#This Row],[Current Prices]]-F29)/F29 -> 0.059288351 | H30: =(Table2_1[[#This Row],[Current Prices]]-F26)/F26 -> 0.14775699
A31: Added value of Agriculture, forestry and fishing sector | B31: Q2 2017 | C31: 2004.9 | D31: =(Table2_1[[#This Row],[Constant Prices]]-C30)/C30 -> 0.0097708386 | E31: =(Table2_1[[#This Row],[Constant Prices]]-C27)/C27 -> 0.066776631 | F31: 2277.8 | G31: =(Table2_1[[#This Row],[Current Prices]]-F30)/F30 -> 0.017465493 | H31: =(Table2_1[[#This Row],[Current Prices]]-F27)/F27 -> 0.14531376
A32: Added value of Agriculture, forestry and fishing sector | B32: Q3 2017 | C32: 2039.4 | D32: =(Table2_1[[#This Row],[Constant Prices]]-C31)/C31 -> 0.017207841 | E32: =(Table2_1[[#This Row],[Constant Prices]]-C28)/C28 -> 0.057615516 | F32: 2324 | G32: =(Table2_1[[#This Row],[Current Prices]]-F31)/F31 -> 0.020282729 | H32: =(Table2_1[[#This Row],[Current Prices]]-F28)/F28 -> 0.12216321
A33: Added value of Agriculture, forestry and fishing sector | B33: Q4 2017 | C33: 2051.9 | D33: =(Table2_1[[#This Row],[Constant Prices]]-C32)/C32 -> 0.0061292537 | E33: =(Table2_1[[#This Row],[Constant Prices]]-C29)/C29 -> 0.037413418 | F33: 2326.3 | G33: =(Table2_1[[#This Row],[Current Prices]]-F32)/F32 -> 0.00098967298 | H33: =(Table2_1[[#This Row],[Current Prices]]-F29)/F29 -> 0.10073815 | I33: 7
A34: Added value of Agriculture, forestry and fishing sector | B34: Q1 2018 | C34: 2150.9 | D34: =(Table2_1[[#This Row],[Constant Prices]]-C33)/C33 -> 0.048247965 | E34: =(Table2_1[[#This Row],[Constant Prices]]-C30)/C30 -> 0.083303954 | F34: 2844 | G34: =(Table2_1[[#This Row],[Current Prices]]-F33)/F33 -> 0.22254223 | H34: =(Table2_1[[#This Row],[Current Prices]]-F30)/F30 -> 0.27038013
A35: Added value of Agriculture, forestry and fishing sector | B35: Q2 2018 | C35: 2110.6 | D35: =(Table2_1[[#This Row],[Constant Prices]]-C34)/C34 -> -0.018736343 | E35: =(Table2_1[[#This Row],[Constant Prices]]-C31)/C31 -> 0.052720834 | F35: 2756.8 | G35: =(Table2_1[[#This Row],[Current Prices]]-F34)/F34 -> -0.030661041 | H35: =(Table2_1[[#This Row],[Current Prices]]-F31)/F31 -> 0.21029063
A36: Added value of Agriculture, forestry and fishing sector | B36: Q3 2018 | C36: 2109 | D36: =(Table2_1[[#This Row],[Constant Prices]]-C35)/C35 -> -0.00075807827 | E36: =(Table2_1[[#This Row],[Constant Prices]]-C32)/C32 -> 0.034127685 | F36: 2750.1 | G36: =(Table2_1[[#This Row],[Current Prices]]-F35)/F35 -> -0.002430354 | H36: =(Table2_1[[#This Row],[Current Prices]]-F32)/F32 -> 0.18334768
A37: Added value of Agriculture, forestry and fishing sector | B37: Q4 2018 | C37: 2186.1 | D37: =(Table2_1[[#This Row],[Constant Prices]]-C36)/C36 -> 0.03655761 | E37: =(Table2_1[[#This Row],[Constant Prices]]-C33)/C33 -> 0.065402797 | F37: 2821.7 | G37: =(Table2_1[[#This Row],[Current Prices]]-F36)/F36 -> 0.026035417 | H37: =(Table2_1[[#This Row],[Current Prices]]-F33)/F33 -> 0.2129562 | I37: 8
A38: Added value of Agriculture, forestry and fishing sector | B38: Q1 2019 | C38: 2197.2 | D38: =(Table2_1[[#This Row],[Constant Prices]]-C37)/C37 -> 0.0050775353 | E38: =(Table2_1[[#This Row],[Constant Prices]]-C34)/C34 -> 0.021525873 | F38: 2932.7 | G38: =(Table2_1[[#This Row],[Current Prices]]-F37)/F37 -> 0.039337988 | H38: =(Table2_1[[#This Row],[Current Prices]]-F34)/F34 -> 0.031188467
A39: Added value of Agriculture, forestry and fishing sector | B39: Q2 2019 | C39: 2283.6 | D39: =(Table2_1[[#This Row],[Constant Prices]]-C38)/C38 -> 0.039322774 | E39: =(Table2_1[[#This Row],[Constant Prices]]-C35)/C35 -> 0.081967213 | F39: 3007.4 | G39: =(Table2_1[[#This Row],[Current Prices]]-F38)/F38 -> 0.025471409 | H39: =(Table2_1[[#This Row],[Current Prices]]-F35)/F35 -> 0.090902496
A40: Added value of Agriculture, forestry and fishing sector | B40: Q3 2019 | C40: 2310.7 | D40: =(Table2_1[[#This Row],[Constant Prices]]-C39)/C39 -> 0.011867227 | E40: =(Table2_1[[#This Row],[Constant Prices]]-C36)/C36 -> 0.095637743 | F40: 3091 | G40: =(Table2_1[[#This Row],[Current Prices]]-F39)/F39 -> 0.027798098 | H40: =(Table2_1[[#This Row],[Current Prices]]-F36)/F36 -> 0.12395913
...

Sheet Annual General Balance
A1: Annual general balance | B1: Attribute | C1: Value | D1: Ratio | E1: YoY change | H1: Investment Ratio | I1: External Factors
A2: Gross Domestic Product | B2: 2015 | C2: 89802.2 | G2: Years | H2: Total Gross Capital Formation ratio | I2: Net Exports | J2: Openess Ratio | K2: Coverage Ratio
A3: Gross Domestic Product | B3: 2016 | C3: 95286.9 | E3: =(Table1_1[[#This Row],[Value]]-C2)/C2 -> 0.061075341 | G3: 2015 | H3: =(C62+C72)/C2 -> 0.21739 | I3: =(C92-C12)/C2 -> -0.10448853 | J3: =(C92+C12)/C2 -> 0.87248531 | K3: =C92/C12 -> 0.78609759
A4: Gross Domestic Product | B4: 2017 | C4: 102011.5 | E4: =(Table1_1[[#This Row],[Value]]-C3)/C3 -> 0.070572135 | G4: 2016 | H4: =(C63+C73)/C3 -> 0.20475008 | I4: =(C93-C13)/C3 -> -0.10502073 | J4: =(C93+C13)/C3 -> 0.87092664 | K4: =C93/C13 -> 0.78478198
A5: Gross Domestic Product | B5: 2018 | C5: 112985.5 | E5: =(Table1_1[[#This Row],[Value]]-C4)/C4 -> 0.10757611 | G5: 2017 | H5: =(C64+C74)/C4 -> 0.2129456 | I5: =(C94-C14)/C4 -> -0.12367625 | J5: =(C94+C14)/C4 -> 0.95809198 | K5: =C94/C14 -> 0.77134427
A6: Gross Domestic Product | B6: 2019 | C6: 122969.3 | E6: =(Table1_1[[#This Row],[Value]]-C5)/C5 -> 0.088363551 | G6: 2018 | H6: =(C65+C75)/C5 -> 0.22963566 | I6: =(C95-C15)/C5 -> -0.12900328 | J6: =(C95+C15)/C5 -> 1.0387182 | K6: =C95/C15 -> 0.77905129
A7: Gross Domestic Product | B7: 2020 | C7: 119502.1 | E7: =(Table1_1[[#This Row],[Value]]-C6)/C6 -> -0.028195655 | G7: 2019 | H7: =(C66+C76)/C6 -> 0.19803398 | I7: =(C96-C16)/C6 -> -0.10431953 | J7: =(C96+C16)/C6 -> 1.0233261 | K7: =C96/C16 -> 0.81497817
A8: Gross Domestic Product | B8: 2021 | C8: 131544.6 | E8: =(Table1_1[[#This Row],[Value]]-C7)/C7 -> 0.10077229 | G8: 2020 | H8: =(C67+C77)/C7 -> 0.12688229 | I8: =(C97-C17)/C7 -> -0.083497277 | J8: =(C97+C17)/C7 -> 0.8433333 | K8: =C97/C17 -> 0.81982192
A9: Gross Domestic Product | B9: 2022 | C9: 139444.5 | E9: =(Table1_1[[#This Row],[Value]]-C8)/C8 -> 0.060054917 | G9: 2021 | H9: =(C68+C78)/C8 -> 0.1584588 | I9: =(C98-C18)/C8 -> -0.10073009 | J9: =(C98+C18)/C8 -> 0.93633414 | K9: =C98/C18 -> 0.80573991
A10: Gross Domestic Product | B10: 2023 | C10: 149733.8 | E10: =(Table1_1[[#This Row],[Value]]-C9)/C9 -> 0.073787779 | G10: 2022 | H10: =(C69+C79)/C9 -> 0.16673802 | I10: =(C99-C19)/C9 -> -0.13443915 | J10: =(C99+C19)/C9 -> 1.1609579 | K10: =C99/C19 -> 0.79243562
A11: Gross Domestic Product | B11: 2024 | C11: 159760.6 | E11: =(Table1_1[[#This Row],[Value]]-C10)/C10 -> 0.066964172 | G11: 2023 | H11: =(C70+C80)/C10 -> 0.082079664 | I11: =(C100-C20)/C10 -> -0.060500702 | J11: =(C100+C20)/C10 -> 1.1212886 | K11: =C100/C20 -> 0.89761169
A12: Imports | B12: 2015 | C12: 43867.2 | D12: =Table1_1[[#This Row],[Value]]/C2 -> 0.48848692 | G12: 2024 | H12: =(C71+C81)/C11 -> 0.078581953 | I12: =(C101-C21)/C11 -> -0.062951691 | J12: =(C101+C21)/C11 -> 1.0629855 | K12: =C101/C21 -> 0.88817903
A13: Imports | B13: 2016 | C13: 46497.5 | D13: =Table1_1[[#This Row],[Value]]/C3 -> 0.48797369 | E13: =(Table1_1[[#This Row],[Value]]-C12)/C12 -> 0.059960517
A14: Imports | B14: 2017 | C14: 55176.4 | D14: =Table1_1[[#This Row],[Value]]/C4 -> 0.54088412 | E14: =(Table1_1[[#This Row],[Value]]-C13)/C13 -> 0.18665305
A15: Imports | B15: 2018 | C15: 65967.8 | D15: =Table1_1[[#This Row],[Value]]/C5 -> 0.58386076 | E15: =(Table1_1[[#This Row],[Value]]-C14)/C14 -> 0.19557999
A16: Imports | B16: 2019 | C16: 69332.9 | D16: =Table1_1[[#This Row],[Value]]/C6 -> 0.56382284 | E16: =(Table1_1[[#This Row],[Value]]-C15)/C15 -> 0.051011251
A17: Imports | B17: 2020 | C17: 55379.1 | D17: =Table1_1[[#This Row],[Value]]/C7 -> 0.46341529 | E17: =(Table1_1[[#This Row],[Value]]-C16)/C16 -> -0.20125799
A18: Imports | B18: 2021 | C18: 68210.1 | D18: =Table1_1[[#This Row],[Value]]/C8 -> 0.51853212 | E18: =(Table1_1[[#This Row],[Value]]-C17)/C17 -> 0.23169391
A19: Imports | B19: 2022 | C19: 90318 | D19: =Table1_1[[#This Row],[Value]]/C9 -> 0.64769855 | E19: =(Table1_1[[#This Row],[Value]]-C18)/C18 -> 0.32411476
A20: Imports | B20: 2023 | C20: 88476.9 | D20: =Table1_1[[#This Row],[Value]]/C10 -> 0.59089464 | E20: =(Table1_1[[#This Row],[Value]]-C19)/C19 -> -0.020384641
A21: Imports | B21: 2024 | C21: 89940.2 | D21: =Table1_1[[#This Row],[Value]]/C11 -> 0.56296859 | E21: =(Table1_1[[#This Row],[Value]]-C20)/C20 -> 0.01653878
A22: Total Resources - Uses | B22: 2015 | C22: 133669.4 | D22: =Table1_1[[#This Row],[Value]]/C2 -> 1.4884869
A23: Total Resources - Uses | B23: 2016 | C23: 141784.5 | D23: =Table1_1[[#This Row],[Value]]/C3 -> 1.4879747
A24: Total Resources - Uses | B24: 2017 | C24: 157187.9 | D24: =Table1_1[[#This Row],[Value]]/C4 -> 1.5408841
A25: Total Resources - Uses | B25: 2018 | C25: 178953.3 | D25: =Table1_1[[#This Row],[Value]]/C5 -> 1.5838608
A26: Total Resources - Uses | B26: 2019 | C26: 192302.1 | D26: =Table1_1[[#This Row],[Value]]/C6 -> 1.563822
A27: Total Resources - Uses | B27: 2020 | C27: 174881.2 | D27: =Table1_1[[#This Row],[Value]]/C7 -> 1.4634153
A28: Total Resources - Uses | B28: 2021 | C28: 199754.7 | D28: =Table1_1[[#This Row],[Value]]/C8 -> 1.5185321
A29: Total Resources - Uses | B29: 2022 | C29: 229762.5 | D29: =Table1_1[[#This Row],[Value]]/C9 -> 1.6476985
A30: Total Resources - Uses | B30: 2023 | C30: 238210.7 | D30: =Table1_1[[#This Row],[Value]]/C10 -> 1.5908946
A31: Total Resources - Uses | B31: 2024 | C31: 249700.9 | D31: =Table1_1[[#This Row],[Value]]/C11 -> 1.5629692
A32: Final Consumption Expenditure | B32: 2015 | C32: 79663.4 | D32: =Table1_1[[#This Row],[Value]]/C2 -> 0.88709853
A33: Final Consumption Expenditure | B33: 2016 | C33: 85784 | D33: =Table1_1[[#This Row],[Value]]/C3 -> 0.90027066 | E33: =(Table1_1[[#This Row],[Value]]-C32)/C32 -> 0.076830765
A34: Final Consumption Expenditure | B34: 2017 | C34: 92905 | D34: =Table1_1[[#This Row],[Value]]/C4 -> 0.91073065 | E34: =(Table1_1[[#This Row],[Value]]-C33)/C33 -> 0.083010818
A35: Final Consumption Expenditure | B35: 2018 | C35: 101615.5 | D35: =Table1_1[[#This Row],[Value]]/C5 -> 0.89936762 | E35: =(Table1_1[[#This Row],[Value]]-C34)/C34 -> 0.093757064
A36: Final Consumption Expenditure | B36: 2019 | C36: 111445.2 | D36: =Table1_1[[#This Row],[Value]]/C6 -> 0.90628474 | E36: =(Table1_1[[#This Row],[Value]]-C35)/C35 -> 0.096734258
A37: Final Consumption Expenditure | B37: 2020 | C37: 114317.6 | D37: =Table1_1[[#This Row],[Value]]/C7 -> 0.95661583 | E37: =(Table1_1[[#This Row],[Value]]-C36)/C36 -> 0.025774102
A38: Final Consumption Expenditure | B38: 2021 | C38: 123950.6 | D38: =Table1_1[[#This Row],[Value]]/C8 -> 0.94227053 | E38: =(Table1_1[[#This Row],[Value]]-C37)/C37 -> 0.08426524
A39: Final Consumption Expenditure | B39: 2022 | C39: 134940.5 | D39: =Table1_1[[#This Row],[Value]]/C9 -> 0.96770041 | E39: =(Table1_1[[#This Row],[Value]]-C38)/C38 -> 0.088663548
A40: Final Consumption Expenditure | B40: 2023 | C40: 146502.7 | D40: =Table1_1[[#This Row],[Value]]/C10 -> 0.97842104 | E40: =(Table1_1[[#This Row],[Value]]-C39)/C39 -> 0.08568369
...

Sheet Population
A1: Active population | B1: Attribute | C1: Value
A2: Evolution of the active population
A3: Evolution of the active population | B3: Q3 2011 | C3: 3844.6
A4: Evolution of the active population | B4: Q4 2011 | C4: 3909.1
A5: Evolution of the active population | B5: Q1 2012 | C5: 3916.9
A6: Evolution of the active population | B6: Q2 2012 | C6: 3923.2
A7: Evolution of the active population | B7: Q3 2012 | C7: 3907.9
A8: Evolution of the active population | B8: Q4 2012 | C8: 3909.6
A9: Evolution of the active population | B9: Q1 2013 | C9: 3927.3
A10: Evolution of the active population | B10: Q2 2013 | C10: 3943.7
A11: Evolution of the active population | B11: Q3 2013 | C11: 3961.8
A12: Evolution of the active population | B12: Q4 2013 | C12: 3978.6
A13: Evolution of the active population | B13: Q1 2014 | C13: 3998.3
A14: Evolution of the active population | B14: Q2 2014 | C14: 3866.5
... A56: Evolution of the active population | B56: Q1 2025 | C56: 4233.4
A57: Evolution of the active population
A58: Evolution of the male active population | B58: Q3 2011 | C58: 2817.9
A59: Evolution of the male active population | B59: Q4 2011 | C59: 2842.1
A60: Evolution of the male active population | B60: Q1 2012 | C60: 2849.7
A61: Evolution of the male active population | B61: Q2 2012 | C61: 2852.3
A62: Evolution of the male active population | B62: Q3 2012 | C62: 2844.4
A63: Evolution of the male active population | B63: Q4 2012 | C63: 2847.4
A64: Evolution of the male active population | B64: Q1 2013 | C64: 2864.4
A65: Evolution of the male active population | B65: Q2 2013 | C65: 2862
A66: Evolution of the male active population | B66: Q3 2013 | C66: 2870.8
A67: Evolution of the male active population | B67: Q4 2013 | C67: 2872.8
A68: Evolution of the male active population | B68: Q1 2014 | C68: 2879.9
A69: Evolution of the male active population | B69: Q2 2014 | C69: 2654.5
... A111: Evolution of the male active population | B111: Q1 2025 | C111: 2899.7
A112: Evolution of the female active population
A113: Evolution of the female active population | B113: Q3 2011 | C113: 1026.7
A114: Evolution of the female active population | B114: Q4 2011 | C114: 1067
A115: Evolution of the female active population | B115: Q1 2012 | C115: 1067.2
A116: Evolution of the female active population | B116: Q2 2012 | C116: 1070.9
A117: Evolution of the female active population | B117: Q3 2012 | C117: 1063.5
A118: Evolution of the female active population | B118: Q4 2012 | C118: 1062.2
A119: Evolution of the female active population | B119: Q1 2013 | C119: 1062.9
A120: Evolution of the female active population | B120: Q2 2013 | C120: 1081.7
A121: Evolution of the female active population | B121: Q3 2013 | C121: 1091
A122: Evolution of the female active population | B122: Q4 2013 | C122: 1105.8
...

Sheet Unemployment
A1: Unemployment | B1: Attribute | C1: Value | D1: Unemployment rate | E1: Employment rate | F1: Difference in Gender Unemployment Rate
A2: Trends in the unemployed labor force | F2: (Masculin Rate - Feminine Rate)
A3: Trends in the unemployed labor force | B3: Q2 2011 | C3: 704.9 | D3: =Table3_1[[#This Row],[Value]]/Table7_1[[#This Row],[Value]] -> 0.18334807 | E3: =1-Table3_1[[#This Row],[Unemployment rate]] -> 0.81665193 | F3: =D51-D99 -> -0.12339413
A4: Trends in the unemployed labor force | B4: Q4 2011 | C4: 738.4 | D4: =Table3_1[[#This Row],[Value]]/Table7_1[[#This Row],[Value]] -> 0.18889258 | E4: =1-Table3_1[[#This Row],[Unemployment rate]] -> 0.81110742 | F4: =D52-D100 -> -0.12858578
A5: Trends in the unemployed labor force | B5: Q1 2012 | C5: 709.7 | D5: =Table3_1[[#This Row],[Value]]/Table7_1[[#This Row],[Value]] -> 0.18118921 | E5: =1-Table3_1[[#This Row],[Unemployment rate]] -> 0.81881079 | F5: =D53-D101 -> -0.1167328
A6: Trends in the unemployed labor force | B6: Q2 2012 | C6: 691.6 | D6: =Table3_1[[#This Row],[Value]]/Table7_1[[#This Row],[Value]] -> 0.17628467 | E6: =1-Table3_1[[#This Row],[Unemployment rate]] -> 0.82371533 | F6: =D54-D102 -> -0.10970827
A7: Trends in the unemployed labor force | B7: Q3 2012 | C7: 665 | D7: =Table3_1[[#This Row],[Value]]/Table7_1[[#This Row],[Value]] -> 0.17016812 | E7: =1-Table3_1[[#This Row],[Unemployment rate]] -> 0.82983188 | F7: =D55-D103 -> -0.10842086
A8: Trends in the unemployed labor force | B8: Q4 2012 | C8: 653.8 | D8: =Table3_1[[#This Row],[Value]]/Table7_1[[#This Row],[Value]] -> 0.16722938 | E8: =1-Table3_1[[#This Row],[Unemployment rate]] -> 0.83277062 | F8: =D56-D104 -> -0.10311252
A9: Trends in the unemployed labor force | B9: Q1 2013 | C9: 646.1 | D9: =Table3_1[[#This Row],[Value]]/Table7_1[[#This Row],[Value]] -> 0.16451506 | E9: =1-Table3_1[[#This Row],[Unemployment rate]] -> 0.83548494 | F9: =D57-D105 -> -0.093954959
A10: Trends in the unemployed labor force | B10: Q2 2013 | C10: 628.4 | D10: =Table3_1[[#This Row],[Value]]/Table7_1[[#This Row],[Value]] -> 0.15934275 | E10: =1-Table3_1[[#This Row],[Unemployment rate]] -> 0.84065725 | F10: =D58-D106 -> -0.097373799
A11: Trends in the unemployed labor force | B11: Q3 2013 | C11: 620.6 | D11: =Table3_1[[#This Row],[Value]]/Table7_1[[#This Row],[Value]] -> 0.15664597 | E11: =1-Table3_1[[#This Row],[Unemployment rate]] -> 0.84335403 | F11: =D59-D107 -> -0.093856502
A12: Trends in the unemployed labor force | B12: Q4 2013 | C12: 609.9 | D12: =Table3_1[[#This Row],[Value]]/Table7_1[[#This Row],[Value]] -> 0.15329513 | E12: =1-Table3_1[[#This Row],[Unemployment rate]] -> 0.84670487 | F12: =D60-D108 -> -0.091659561
A13: Trends in the unemployed labor force | B13: Q1 2014 | C13: 605.8 | D13: =Table3_1[[#This Row],[Value]]/Table7_1[[#This Row],[Value]] -> 0.15151439 | E13: =1-Table3_1[[#This Row],[Unemployment rate]] -> 0.84848561 | F13: =D61-D109 -> -0.088691207
A14: Trends in the unemployed labor force | B14: Q3 2014 | C14: 602.8 | D14: =Table3_1[[#This Row],[Value]]/Table7_1[[#This Row],[Value]] -> 0.15590327 | E14: =1-Table3_1[[#This Row],[Unemployment rate]] -> 0.84409673 | F14: =D62-D110 -> -0.061226049
... A49: Trends in the unemployed labor force | B49: Q2 2023 | C49: 638.1 | D49: =Table3_1[[#This Row],[Value]]/Table7_1[[#This Row],[Value]] -> 0.15647376 | E49: =1-Table3_1[[#This Row],[Unemployment rate]] -> 0.84352624 | F49: =D97-D145 -> -0.081079085
A50: Male unemployment in the labor force
A51: Male unemployment in the labor force | B51: Q2 2011 | C51: 423.8 | D51: =Table3_1[[#This Row],[Value]]/'[1]Active population 1'!C58 -> 0.15039568 | E51: =1-Table3_1[[#This Row],[Unemployment rate]] -> 0.84960432
A52: Male unemployment in the labor force | B52: Q4 2011 | C52: 437.1 | D52: =Table3_1[[#This Row],[Value]]/'[1]Active population 1'!C59 -> 0.15379473 | E52: =1-Table3_1[[#This Row],[Unemployment rate]] -> 0.84620527
A53: Male unemployment in the labor force | B53: Q1 2012 | C53: 425.7 | D53: =Table3_1[[#This Row],[Value]]/'[1]Active population 1'!C60 -> 0.14938415 | E53: =1-Table3_1[[#This Row],[Unemployment rate]] -> 0.85061585
A54: Male unemployment in the labor force | B54: Q2 2012 | C54: 417.4 | D54: =Table3_1[[#This Row],[Value]]/'[1]Active population 1'!C61 -> 0.14633804 | E54: =1-Table3_1[[#This Row],[Unemployment rate]] -> 0.85366196
A55: Male unemployment in the labor force | B55: Q3 2012 | C55: 400.1 | D55: =Table3_1[[#This Row],[Value]]/'[1]Active population 1'!C62 -> 0.14066235 | E55: =1-Table3_1[[#This Row],[Unemployment rate]] -> 0.85933765
A56: Male unemployment in the labor force | B56: Q4 2012 | C56: 396.4 | D56: =Table3_1[[#This Row],[Value]]/'[1]Active population 1'!C63 -> 0.13921472 | E56: =1-Table3_1[[#This Row],[Unemployment rate]] -> 0.86078528
A57: Male unemployment in the labor force | B57: Q1 2013 | C57: 398.4 | D57: =Table3_1[[#This Row],[Value]]/'[1]Active population 1'!C64 -> 0.13908672 | E57: =1-Table3_1[[#This Row],[Unemployment rate]] -> 0.86091328
A58: Male unemployment in the labor force | B58: Q2 2013 | C58: 379.6 | D58: =Table3_1[[#This Row],[Value]]/'[1]Active population 1'!C65 -> 0.13263452 | E58: =1-Table3_1[[#This Row],[Unemployment rate]] -> 0.86736548
A59: Male unemployment in the labor force | B59: Q3 2013 | C59: 375.5 | D59: =Table3_1[[#This Row],[Value]]/'[1]Active population 1'!C66 -> 0.13079978 | E59: =1-Table3_1[[#This Row],[Unemployment rate]] -> 0.86920022
A60: Male unemployment in the labor force | B60: Q4 2013 | C60: 367.2 | D60: =Table3_1[[#This Row],[Value]]/'[1]Active population 1'!C67 -> 0.12781955 | E60: =1-Table3_1[[#This Row],[Unemployment rate]] -> 0.87218045
A61: Male unemployment in the labor force | B61: Q1 2014 | C61: 364.9 | D61: =Table3_1[[#This Row],[Value]]/'[1]Active population 1'!C68 -> 0.12670579 | E61: =1-Table3_1[[#This Row],[Unemployment rate]] -> 0.87329421
A62: Male unemployment in the labor force | B62: Q3 2014 | C62: 362.9 | D62: =Table3_1[[#This Row],[Value]]/'[1]Active population 1'!C69 -> 0.13671125 | E62: =1-Table3_1[[#This Row],[Unemployment rate]] -> 0.86328875
... A97: Male unemployment in the labor force | B97: Q2 2023 | C97: 377.5 | D97: =Table3_1[[#This Row],[Value]]/'[1]Active population 1'!C104 -> 0.13217787 | E97: =1-Table3_1[[#This Row],[Unemployment rate]] -> 0.86782213
A98: Female unemployed labor force
A99: Female unemployed labor force | B99: Q2 2011 | C99: 281.1 | D99: =Table3_1[[#This Row],[Value]]/'[1]Active population 1'!C113 -> 0.27378981 | E99: =1-Table3_1[[#This Row],[Unemployment rate]] -> 0.72621019
A100: Female unemployed labor force | B100: Q4 2011 | C100: 301.3 | D100: =Table3_1[[#This Row],[Value]]/'[1]Active population 1'!C114 -> 0.28238051 | E100: =1-Table3_1[[#This Row],[Unemployment rate]] -> 0.71761949
A101: Female unemployed labor force | B101: Q1 2012 | C101: 284 | D101: =Table3_1[[#This Row],[Value]]/'[1]Active population 1'!C115 -> 0.26611694 | E101: =1-Table3_1[[#This Row],[Unemployment rate]] -> 0.73388306
A102: Female unemployed labor force | B102: Q2 2012 | C102: 274.2 | D102: =Table3_1[[#This Row],[Value]]/'[1]Active population 1'!C116 -> 0.25604632 | E102: =1-Table3_1[[#This Row],[Unemployment rate]] -> 0.74395368
A103: Female unemployed labor force | B103: Q3 2012 | C103: 264.9 | D103: =Table3_1[[#This Row],[Value]]/'[1]Active population 1'!C117 -> 0.24908322 | E103: =1-Table3_1[[#This Row],[Unemployment rate]] -> 0.75091678
A104: Female unemployed labor force | B104: Q4 2012 | C104: 257.4 | D104: =Table3_1[[#This Row],[Value]]/'[1]Active population 1'!C118 -> 0.24232725 | E104: =1-Table3_1[[#This Row],[Unemployment rate]] -> 0.75767275
A105: Female unemployed labor force | B105: Q1 2013 | C105: 247.7 | D105: =Table3_1[[#This Row],[Value]]/'[1]Active population 1'!C119 -> 0.23304168 | E105: =1-Table3_1[[#This Row],[Unemployment rate]] -> 0.76695832
A106: Female unemployed labor force | B106: Q2 2013 | C106: 248.8 | D106: =Table3_1[[#This Row],[Value]]/'[1]Active population 1'!C120 -> 0.23000832 | E106: =1-Table3_1[[#This Row],[Unemployment rate]] -> 0.76999168
A107: Female unemployed labor force | B107: Q3 2013 | C107: 245.1 | D107: =Table3_1[[#This Row],[Value]]/'[1]Active population 1'!C121 -> 0.22465628 | E107: =1-Table3_1[[#This Row],[Unemployment rate]] -> 0.77534372
A108: Female unemployed labor force | B108: Q4 2013 | C108: 242.7 | D108: =Table3_1[[#This Row],[Value]]/'[1]Active population 1'!C122 -> 0.21947911 | E108: =1-Table3_1[[#This Row],[Unemployment rate]] -> 0.78052089
...

Sheet Interest Rates
A1: money markets | B1: Attribute | C1: Value
A2: Nominal Interest Rate
A3: Nominal Interest Rate | B3: 1994 | C3: 8.81
A4: Nominal Interest Rate | B4: 1995 | C4: 8.81
A5: Nominal Interest Rate | B5: 1996 | C5: 7.81
A6: Nominal Interest Rate | B6: 1997 | C6: 6.88
A7: Nominal Interest Rate | B7: 1998 | C7: 6.88
A8: Nominal Interest Rate | B8: 1999 | C8: 5.88
A9: Nominal Interest Rate | B9: 2000 | C9: 5.88
A10: Nominal Interest Rate | B10: 2001 | C10: 5.94
A11: Nominal Interest Rate | B11: 2002 | C11: 5.91
A12: Nominal Interest Rate | B12: 2003 | C12: 5
A13: Nominal Interest Rate | B13: 2004 | C13: 5
A14: Nominal Interest Rate | B14: 2005 | C14: 5
... A31: Nominal Interest Rate | B31: 2022 | C31: 7.26
A32: Interest Rate on Savings
A33: Interest Rate on Savings | B33: 1994 | C33: 6.88
A34: Interest Rate on Savings | B34: 1995 | C34: 6.88
A35: Interest Rate on Savings | B35: 1996 | C35: 6.13
A36: Interest Rate on Savings | B36: 1997 | C36: 5
A37: Interest Rate on Savings | B37: 1998 | C37: 5
A38: Interest Rate on Savings | B38: 1999 | C38: 3.88
A39: Interest Rate on Savings | B39: 2000 | C39: 3.88
A40: Interest Rate on Savings | B40: 2001 | C40: 4
A41: Interest Rate on Savings | B41: 2002 | C41: 4
A42: Interest Rate on Savings | B42: 2003 | C42: 3
A43: Interest Rate on Savings | B43: 2004 | C43: 3
A44: Interest Rate on Savings | B44: 2005 | C44: 3
... A61: Interest Rate on Savings | B61: 2022 | C61: 6.25
A62: Average Subscription Rate on 5-Year Treasury Bills
A63: Average Subscription Rate on 5-Year Treasury Bills | B63: 1994 | C63: 10.06
A64: Average Subscription Rate on 5-Year Treasury Bills | B64: 1995 | C64: 10.13
A65: Average Subscription Rate on 5-Year Treasury Bills | B65: 1996 | C65: 9.63
A66: Average Subscription Rate on 5-Year Treasury Bills | B66: 1997 | C66: 9.06
A67: Average Subscription Rate on 5-Year Treasury Bills | B67: 1998 | C67: 7.88
A68: Average Subscription Rate on 5-Year Treasury Bills | B68: 1999 | C68: 7.63
A69: Average Subscription Rate on 5-Year Treasury Bills | B69: 2000 | C69: 7.14
A70: Average Subscription Rate on 5-Year Treasury Bills | B70: 2001 | C70: 6.85
A71: Average Subscription Rate on 5-Year Treasury Bills | B71: 2002 | C71: 6.69
A72: Average Subscription Rate on 5-Year Treasury Bills | B72: 2003 | C72: 6.52
...

Sheet Inflation
A1: Consumer Price Indices | J1: Industrial Sales Price Indices
A2: Consumer Price Indices | B2: Attribute | C2: Value | D2: Inflation | E2: Arithmetic Annual Average | F2: 1+Inflation | G2: Product | H2: Geometric Annual Average | I2: Standard Deviation | J2: Industrial Sales Price Indices | K2: Attribute | L2: Value | M2: CPI-to-PPI Ratio
A3: Trends in the Family Consumer Price Index (Base Year: 2015 = 100) | B3: 43466 | C3: 122 | J3: Indices des prix à la vente industriel (IPVI) (2010 = 100) | K3: Jan-19 | L3: 145.6 | M3: =Table3_19[[#This Row],[Value]]/L3 -> 0.83791209
A4: Trends in the Family Consumer Price Index (Base Year: 2015 = 100) | B4: 43497 | C4: 122.1 | J4: Indices des prix à la vente industriel (IPVI) (2010 = 100) | K4: Feb-19 | L4: 146.6 | M4: =Table3_19[[#This Row],[Value]]/L4 -> 0.83287858
A5: Trends in the Family Consumer Price Index (Base Year: 2015 = 100) | B5: 43525 | C5: 122.6 | J5: Indices des prix à la vente industriel (IPVI) (2010 = 100) | K5: Mar-19 | L5: 146.9 | M5: =Table3_19[[#This Row],[Value]]/L5 -> 0.83458135
A6: Trends in the Family Consumer Price Index (Base Year: 2015 = 100) | B6: 43556 | C6: 123.6 | J6: Indices des prix à la vente industriel (IPVI) (2010 = 100) | K6: Apr-19 | L6: 146.9 | M6: =Table3_19[[#This Row],[Value]]/L6 -> 0.8413887
A7: Trends in the Family Consumer Price Index (Base Year: 2015 = 100) | B7: 43586 | C7: 124.2 | J7: Indices des prix à la vente industriel (IPVI) (2010 = 100) | K7: May-19 | L7: 146.9 | M7: =Table3_19[[#This Row],[Value]]/L7 -> 0.84547311
A8: Trends in the Family Consumer Price Index (Base Year: 2015 = 100) | B8: 43617 | C8: 124.6 | J8: Indices des prix à la vente industriel (IPVI) (2010 = 100) | K8: Jun-19 | L8: 147.2 | M8: =Table3_19[[#This Row],[Value]]/L8 -> 0.84646739
A9: Trends in the Family Consumer Price Index (Base Year: 2015 = 100) | B9: 43647 | C9: 124.9 | J9: Indices des prix à la vente industriel (IPVI) (2010 = 100) | K9: Jul-19 | L9: 146.3 | M9: =Table3_19[[#This Row],[Value]]/L9 -> 0.85372522
A10: Trends in the Family Consumer Price Index (Base Year: 2015 = 100) | B10: 43678 | C10: 125.6 | J10: Indices des prix à la vente industriel (IPVI) (2010 = 100) | K10: Aug-19 | L10: 146.6 | M10: =Table3_19[[#This Row],[Value]]/L10 -> 0.85675307
A11: Trends in the Family Consumer Price Index (Base Year: 2015 = 100) | B11: 43709 | C11: 126.4 | J11: Indices des prix à la vente industriel (IPVI) (2010 = 100) | K11: Sep-19 | L11: 147.6 | M11: =Table3_19[[#This Row],[Value]]/L11 -> 0.85636856
A12: Trends in the Family Consumer Price Index (Base Year: 2015 = 100) | B12: 43739 | C12: 127.4 | J12: Indices des prix à la vente industriel (IPVI) (2010 = 100) | K12: Oct-19 | L12: 148.6 | M12: =Table3_19[[#This Row],[Value]]/L12 -> 0.85733513
A13: Trends in the Family Consumer Price Index (Base Year: 2015 = 100) | B13: 43770 | C13: 128 | J13: Indices des prix à la vente industriel (IPVI) (2010 = 100) | K13: Nov-19 | L13: 149.3 | M13: =Table3_19[[#This Row],[Value]]/L13 -> 0.85733423
A14: Trends in the Family Consumer Price Index (Base Year: 2015 = 100) | B14: 43800 | C14: 128.3 | J14: Indices des prix à la vente industriel (IPVI) (2010 = 100) | K14: Dec-19 | L14: 149.3 | M14: =Table3_19[[#This Row],[Value]]/L14 -> 0.8593436
A15: Trends in the Family Consumer Price Index (Base Year: 2015 = 100) | B15: 43831 | C15: 129.1 | D15: =(Table3_19[[#This Row],[Value]]-C3)/C3 -> 0.058196721 | F15: =1+Table3_19[[#This Row],[Inflation]] -> 1.0581967 | G15: =Table3_19[[#This Row],[1+Inflation]] -> 1.0581967 | J15: Indices des prix à la vente industriel (IPVI) (2010 = 100) | K15: Jan-20 | L15: 147.9 | M15: =Table3_19[[#This Row],[Value]]/L15 -> 0.87288709
A16: Trends in the Family Consumer Price Index (Base Year: 2015 = 100) | B16: 43862 | C16: 129.1 | D16: =(Table3_19[[#This Row],[Value]]-C4)/C4 -> 0.057330057 | F16: =1+Table3_19[[#This Row],[Inflation]] -> 1.0573301 | G16: =Table3_19[[#This Row],[1+Inflation]]*F15 -> 1.1188632 | J16: Indices des prix à la vente industriel (IPVI) (2010 = 100) | K16: Feb-20 | L16: 147.7 | M16: =Table3_19[[#This Row],[Value]]/L16 -> 0.87406906
A17: Trends in the Family Consumer Price Index (Base Year: 2015 = 100) | B17: 43891 | C17: 130.2 | D17: =(Table3_19[[#This Row],[Value]]-C5)/C5 -> 0.061990212 | F17: =1+Table3_19[[#This Row],[Inflation]] -> 1.0619902 | G17: =G16*Table3_19[[#This Row],[1+Inflation]] -> 1.1882218 | J17: Indices des prix à la vente industriel (IPVI) (2010 = 100) | K17: Mar-20 | L17: 147.3 | M17: =Table3_19[[#This Row],[Value]]/L17 -> 0.88391039
A18: Trends in the Family Consumer Price Index (Base Year: 2015 = 100) | B18: 43922 | C18: 131.3 | D18: =(Table3_19[[#This Row],[Value]]-C6)/C6 -> 0.062297735 | F18: =1+Table3_19[[#This Row],[Inflation]] -> 1.0622977 | G18: =G17*Table3_19[[#This Row],[1+Inflation]] -> 1.2622453 | J18: Indices des prix à la vente industriel (IPVI) (2010 = 100) | K18: Apr-20 | L18: 149.2 | M18: =Table3_19[[#This Row],[Value]]/L18 -> 0.88002681
A19: Trends in the Family Consumer Price Index (Base Year: 2015 = 100) | B19: 43952 | C19: 132 | D19: =(Table3_19[[#This Row],[Value]]-C7)/C7 -> 0.062801932 | F19: =1+Table3_19[[#This Row],[Inflation]] -> 1.0628019 | G19: =G18*Table3_19[[#This Row],[1+Inflation]] -> 1.3415167 | J19: Indices des prix à la vente industriel (IPVI) (2010 = 100) | K19: May-20 | L19: 149.3 | M19: =Table3_19[[#This Row],[Value]]/L19 -> 0.88412592
A20: Trends in the Family Consumer Price Index (Base Year: 2015 = 100) | B20: 43983 | C20: 131.8 | D20: =(Table3_19[[#This Row],[Value]]-C8)/C8 -> 0.057784912 | F20: =1+Table3_19[[#This Row],[Inflation]] -> 1.0577849 | G20: =G19*Table3_19[[#This Row],[1+Inflation]] -> 1.4190362 | J20: Indices des prix à la vente industriel (IPVI) (2010 = 100) | K20: Jun-20 | L20: 149.9 | M20: =Table3_19[[#This Row],[Value]]/L20 -> 0.87925284
A21: Trends in the Family Consumer Price Index (Base Year: 2015 = 100) | B21: 44013 | C21: 132 | D21: =(Table3_19[[#This Row],[Value]]-C9)/C9 -> 0.056845476 | F21: =1+Table3_19[[#This Row],[Inflation]] -> 1.0568455 | G21: =G20*Table3_19[[#This Row],[1+Inflation]] -> 1.4997019 | J21: Indices des prix à la vente industriel (IPVI) (2010 = 100) | K21: Jul-20 | L21: 151.1 | M21: =Table3_19[[#This Row],[Value]]/L21 -> 0.87359365
A22: Trends in the Family Consumer Price Index (Base Year: 2015 = 100) | B22: 44044 | C22: 132.4 | D22: =(Table3_19[[#This Row],[Value]]-C10)/C10 -> 0.054140127 | F22: =1+Table3_19[[#This Row],[Inflation]] -> 1.0541401 | G22: =G21*Table3_19[[#This Row],[1+Inflation]] -> 1.580896 | J22: Indices des prix à la vente industriel (IPVI) (2010 = 100) | K22: Aug-20 | L22: 151 | M22: =Table3_19[[#This Row],[Value]]/L22 -> 0.87682119
A23: Trends in the Family Consumer Price Index (Base Year: 2015 = 100) | B23: 44075 | C23: 133.2 | D23: =(Table3_19[[#This Row],[Value]]-C11)/C11 -> 0.053797468 | F23: =1+Table3_19[[#This Row],[Inflation]] -> 1.0537975 | G23: =G22*Table3_19[[#This Row],[1+Inflation]] -> 1.6659442 | J23: Indices des prix à la vente industriel (IPVI) (2010 = 100) | K23: Sep-20 | L23: 151.7 | M23: =Table3_19[[#This Row],[Value]]/L23 -> 0.87804878
A24: Trends in the Family Consumer Price Index (Base Year: 2015 = 100) | B24: 44105 | C24: 134.3 | D24: =(Table3_19[[#This Row],[Value]]-C12)/C12 -> 0.054160126 | F24: =1+Table3_19[[#This Row],[Inflation]] -> 1.0541601 | G24: =G23*Table3_19[[#This Row],[1+Inflation]] -> 1.756172 | J24: Indices des prix à la vente industriel (IPVI) (2010 = 100) | K24: Oct-20 | L24: 154.3 | M24: =Table3_19[[#This Row],[Value]]/L24 -> 0.87038237
A25: Trends in the Family Consumer Price Index (Base Year: 2015 = 100) | B25: 44136 | C25: 134.2 | D25: =(Table3_19[[#This Row],[Value]]-C13)/C13 -> 0.0484375 | F25: =1+Table3_19[[#This Row],[Inflation]] -> 1.0484375 | G25: =G24*Table3_19[[#This Row],[1+Inflation]] -> 1.8412365 | J25: Indices des prix à la vente industriel (IPVI) (2010 = 100) | K25: Nov-20 | L25: 154.4 | M25: =Table3_19[[#This Row],[Value]]/L25 -> 0.86917098
A26: Trends in the Family Consumer Price Index (Base Year: 2015 = 100) | B26: 44166 | C26: 134.6 | D26: =(Table3_19[[#This Row],[Value]]-C14)/C14 -> 0.049103663 | E26: =AVERAGE(D15:D26) -> 0.056407161 | F26: =1+Table3_19[[#This Row],[Inflation]] -> 1.0491037 | G26: =G25*Table3_19[[#This Row],[1+Inflation]] -> 1.931648 | H26: =(Table3_19[[#This Row],[Product]]^(1/12))-1 -> 0.056397421 | I26: =_xlfn.STDEV.P(D15:D26) -> 0.0045347058 | J26: Indices des prix à la vente industriel (IPVI) (2010 = 100) | K26: Dec-20 | L26: 154.1 | M26: =Table3_19[[#This Row],[Value]]/L26 -> 0.87345879
A27: Trends in the Family Consumer Price Index (Base Year: 2015 = 100) | B27: 44197 | C27: 135.5 | D27: =(Table3_19[[#This Row],[Value]]-C15)/C15 -> 0.049573974 | F27: =1+Table3_19[[#This Row],[Inflation]] -> 1.049574 | G27: =Table3_19[[#This Row],[1+Inflation]] -> 1.049574 | J27: Indices des prix à la vente industriel (IPVI) (2010 = 100) | K27: Jan-21 | L27: 157.3 | M27: =Table3_19[[#This Row],[Value]]/L27 -> 0.86141132
A28: Trends in the Family Consumer Price Index (Base Year: 2015 = 100) | B28: 44228 | C28: 135.4 | D28: =(Table3_19[[#This Row],[Value]]-C16)/C16 -> 0.04879938 | F28: =1+Table3_19[[#This Row],[Inflation]] -> 1.0487994 | G28: =Table3_19[[#This Row],[1+Inflation]]*F27 -> 1.1007925 | J28: Indices des prix à la vente industriel (IPVI) (2010 = 100) | K28: Feb-21 | L28: 158.3 | M28: =Table3_19[[#This Row],[Value]]/L28 -> 0.85533797
A29: Trends in the Family Consumer Price Index (Base Year: 2015 = 100) | B29: 44256 | C29: 136.4 | D29: =(Table3_19[[#This Row],[Value]]-C17)/C17 -> 0.047619048 | F29: =1+Table3_19[[#This Row],[Inflation]] -> 1.047619 | G29: =G28*Table3_19[[#This Row],[1+Inflation]] -> 1.1532112 | J29: Indices des prix à la vente industriel (IPVI) (2010 = 100) | K29: Mar-21 | L29: 158.6 | M29: =Table3_19[[#This Row],[Value]]/L29 -> 0.86002522
A30: Trends in the Family Consumer Price Index (Base Year: 2015 = 100) | B30: 44287 | C30: 137.9 | D30: =(Table3_19[[#This Row],[Value]]-C18)/C18 -> 0.050266565 | F30: =1+Table3_19[[#This Row],[Inflation]] -> 1.0502666 | G30: =G29*Table3_19[[#This Row],[1+Inflation]] -> 1.2111792 | J30: Indices des prix à la vente industriel (IPVI) (2010 = 100) | K30: Apr-21 | L30: 162.1 | M30: =Table3_19[[#This Row],[Value]]/L30 -> 0.85070944
A31: Trends in the Family Consumer Price Index (Base Year: 2015 = 100) | B31: 44317 | C31: 138.6 | D31: =(Table3_19[[#This Row],[Value]]-C19)/C19 -> 0.05 | F31: =1+Table3_19[[#This Row],[Inflation]] -> 1.05 | G31: =G30*Table3_19[[#This Row],[1+Inflation]] -> 1.2717382 | J31: Indices des prix à la vente industriel (IPVI) (2010 = 100) | K31: May-21 | L31: 165.3 | M31: =Table3_19[[#This Row],[Value]]/L31 -> 0.8384755
