Workbook

Sheet TITRES_STAT
B2: Titre : POULINA G H, Du : 02/01/2015, Au : 17/09/2025
B4: Date | C4: Cours | D4: Cours Ajusté | E4: Qte. Ech. | F4: CMP J | G4: Volume | H4: Daily Return
B5: 42006 | C5: 5.68 | D5: 3.9553 | E5: 642
B6: 42009 | C6: 5.69 | D6: 3.9623 | E6: 1500 | H6: =(D6-D5)/D5 -> 0.0017697773 | J6: Business Days | K6: 252
B7: 42010 | C7: 5.52 | D7: 3.8439 | E7: 614 | H7: =(D7-D6)/D6 -> -0.029881634
B8: 42011 | C8: 5.52 | D8: 3.8439 | E8: 3628 | H8: =(D8-D7)/D7 -> 0 | J8: Daily Mean | K8: =AVERAGE(H6:H2696) -> 0.00060216207
B9: 42012 | C9: 5.5 | D9: 3.83 | E9: 4100 | H9: =(D9-D8)/D8 -> -0.003616119 | J9: Yearly Mean | K9: =K8*K6 -> 0.15174484
B10: 42013 | C10: 5.5 | D10: 3.83 | E10: 4779 | H10: =(D10-D9)/D9 -> 0 | J10: Daily Std Deviation | K10: =STDEV(H6:H2696) -> 0.014813168
B11: 42016 | C11: 5.5 | D11: 3.83 | E11: 3173 | H11: =(D11-D10)/D10 -> 0 | J11: Yearly Std Deviation | K11: =K10*SQRT(K6) -> 0.23515176
B12: 42017 | C12: 5.5 | D12: 3.83 | E12: 7367 | H12: =(D12-D11)/D11 -> 0
B13: 42019 | C13: 5.5 | D13: 3.83 | E13: 19930 | H13: =(D13-D12)/D12 -> 0
B14: 42020 | C14: 5.45 | D14: 3.7952 | E14: 5380 | H14: =(D14-D13)/D13 -> -0.0090861619
B15: 42023 | C15: 5.4 | D15: 3.7603 | E15: 3820 | H15: =(D15-D14)/D14 -> -0.0091958263
B16: 42024 | C16: 5.44 | D16: 3.7882 | E16: 16794 | H16: =(D16-D15)/D15 -> 0.0074196208
B17: 42025 | C17: 5.3 | D17: 3.6907 | E17: 5665 | H17: =(D17-D16)/D16 -> -0.025737817
B18: 42026 | C18: 5.4 | D18: 3.7603 | E18: 15376 | H18: =(D18-D17)/D17 -> 0.018858211
B19: 42027 | C19: 5.4 | D19: 3.7603 | E19: 11236 | H19: =(D19-D18)/D18 -> 0
B20: 42030 | C20: 5.4 | D20: 3.7603 | E20: 23322 | H20: =(D20-D19)/D19 -> 0
B21: 42031 | C21: 5.4 | D21: 3.7603 | E21: 8005 | H21: =(D21-D20)/D20 -> 0
B22: 42032 | C22: 5.4 | D22: 3.7603 | E22: 7780 | H22: =(D22-D21)/D21 -> 0
B23: 42033 | C23: 5.43 | D23: 3.7812 | E23: 20315 | H23: =(D23-D22)/D22 -> 0.0055580672
... B1048: 43528 | C1048: 14.2 | D1048: 11.5682 | E1048: 290 | H1048: =(D1048-D1047)/D1047 -> -0.018654406
B1049: 43529 | C1049: 14.03 | D1049: 11.4297 | E1049: 1118 | F1049: 14.04 | G1049: 15696.72 | H1049: =(D1049-D1048)/D1048 -> -0.011972476
B1050: 43530 | C1050: 13.61 | D1050: 11.0875 | E1050: 568 | F1050: 13.61 | G1050: 7730.48 | H1050: =(D1050-D1049)/D1049 -> -0.029939543
B1051: 43531 | C1051: 13.58 | D1051: 11.0631 | E1051: 263 | F1051: 13.7477 | G1051: 3615.6451 | H1051: =(D1051-D1050)/D1050 -> -0.0022006764
B1052: 43532 | C1052: 12.95 | D1052: 10.5499 | E1052: 6928 | F1052: 12.9879 | G1052: 89980.171 | H1052: =(D1052-D1051)/D1051 -> -0.046388444
B1053: 43535 | C1053: 12.2 | D1053: 9.9389 | E1053: 2579 | F1053: 12.3179 | G1053: 31767.864 | H1053: =(D1053-D1052)/D1052 -> -0.057915241
B1054: 43536 | C1054: 11.49 | D1054: 9.3605 | E1054: 2430 | F1054: 11.5448 | G1054: 28053.864 | H1054: =(D1054-D1053)/D1053 -> -0.058195575
B1055: 43537 | C1055: 11.1 | D1055: 9.0427 | E1055: 7557 | F1055: 11.041 | G1055: 83436.837 | H1055: =(D1055-D1054)/D1054 -> -0.033951178
B1056: 43538 | C1056: 11 | D1056: 8.9613 | E1056: 319 | F1056: 11 | G1056: 3509 | H1056: =(D1056-D1055)/D1055 -> -0.0090017362
B1057: 43539 | C1057: 11 | D1057: 8.9613 | E1057: 942 | F1057: 10.9257 | G1057: 10292.009 | H1057: =(D1057-D1056)/D1056 -> 0
B1058: 43542 | C1058: 11 | D1058: 8.9613 | E1058: 1155 | F1058: 10.8765 | G1058: 12562.358 | H1058: =(D1058-D1057)/D1057 -> 0
B1059: 43543 | C1059: 11.43 | D1059: 9.3116 | E1059: 3890 | F1059: 11.1843 | G1059: 43506.927 | H1059: =(D1059-D1058)/D1058 -> 0.039090311
B1060: 43545 | C1060: 11.5 | D1060: 9.3686 | E1060: 5045 | F1060: 11.4977 | G1060: 58005.897 | H1060: =(D1060-D1059)/D1059 -> 0.006121397
... B2687: 45917 | C2687: 15 | D2687: 15 | E2687: 39584 | F2687: 14.97 | G2687: 592572.48 | H2687: =(D2687-D2686)/D2686 -> 0
B2688: 45918 | C2688: 15 | D2688: 15 | E2688: 21862 | F2688: 14.985 | G2688: =E2688*F2688 -> 327602.07 | H2688: =(D2688-D2687)/D2687 -> 0
B2689: 45919 | C2689: 15 | D2689: 15 | E2689: 11434 | F2689: 14.993 | G2689: =E2689*F2689 -> 171429.96 | H2689: =(D2689-D2688)/D2688 -> 0
B2690: 45922 | C2690: 14.99 | D2690: 14.99 | E2690: 41368 | F2690: 14.982 | G2690: =E2690*F2690 -> 619775.38 | H2690: =(D2690-D2689)/D2689 -> -0.00066666667
B2691: 45923 | C2691: 15 | D2691: 15 | E2691: 24016 | F2691: 14.969 | G2691: =E2691*F2691 -> 359495.5 | H2691: =(D2691-D2690)/D2690 -> 0.00066711141
B2692: 45924 | C2692: 14.98 | D2692: 14.98 | E2692: 34737 | F2692: 14.796 | G2692: =E2692*F2692 -> 513968.65 | H2692: =(D2692-D2691)/D2691 -> -0.0013333333
...

Sheet Moving Avg
A1: =TITRES_STAT!B4 -> Date | B1: =TITRES_STAT!D4 -> Cours Ajusté | C1: Daily Change | D1: Simple Moving Avg (5) | E1: Simple Moving Avg (10) | F1: Simple Moving Avg (20) | G1: Simple Moving Avg (50) | H1: Simple Moving Avg (200) | I1: Wheighted Moving Avg | J1: Exp Moving Avg (20) | K1: Exp Moving Avg (50)
A2: =TITRES_STAT!B5 -> 42006 | B2: =TITRES_STAT!D5 -> 3.9553 | J2: Alpha= | K2: Alpha=
A3: =TITRES_STAT!B6 -> 42009 | B3: =TITRES_STAT!D6 -> 3.9623 | C3: =B3-B2 -> 0.007 | J3: (2/(20+1)) | K3: (2/(50+1))
A4: =TITRES_STAT!B7 -> 42010 | B4: =TITRES_STAT!D7 -> 3.8439 | C4: =B4-B3 -> -0.1184 | J4: =2/21 -> 0.095238095 | K4: =2/51 -> 0.039215686
A5: =TITRES_STAT!B8 -> 42011 | B5: =TITRES_STAT!D8 -> 3.8439 | C5: =B5-B4 -> 0 | D5: =AVERAGE(B1:B5) -> 3.90135
A6: =TITRES_STAT!B9 -> 42012 | B6: =TITRES_STAT!D9 -> 3.83 | C6: =B6-B5 -> -0.0139 | D6: =AVERAGE(B2:B6) -> 3.88708
A7: =TITRES_STAT!B10 -> 42013 | B7: =TITRES_STAT!D10 -> 3.83 | C7: =B7-B6 -> 0 | D7: =AVERAGE(B3:B7) -> 3.86202
A8: =TITRES_STAT!B11 -> 42016 | B8: =TITRES_STAT!D11 -> 3.83 | C8: =B8-B7 -> 0 | D8: =AVERAGE(B4:B8) -> 3.83556
A9: =TITRES_STAT!B12 -> 42017 | B9: =TITRES_STAT!D12 -> 3.83 | C9: =B9-B8 -> 0 | D9: =AVERAGE(B5:B9) -> 3.83278
A10: =TITRES_STAT!B13 -> 42019 | B10: =TITRES_STAT!D13 -> 3.83 | C10: =B10-B9 -> 0 | D10: =AVERAGE(B6:B10) -> 3.83
A11: =TITRES_STAT!B14 -> 42020 | B11: =TITRES_STAT!D14 -> 3.7952 | C11: =B11-B10 -> -0.0348 | D11: =AVERAGE(B7:B11) -> 3.82304 | E11: =AVERAGE(B2:B11) -> 3.85506
A12: =TITRES_STAT!B15 -> 42023 | B12: =TITRES_STAT!D15 -> 3.7603 | C12: =B12-B11 -> -0.0349 | D12: =AVERAGE(B8:B12) -> 3.8091 | E12: =AVERAGE(B3:B12) -> 3.83556
A13: =TITRES_STAT!B16 -> 42024 | B13: =TITRES_STAT!D16 -> 3.7882 | C13: =B13-B12 -> 0.0279 | D13: =AVERAGE(B9:B13) -> 3.80074 | E13: =AVERAGE(B4:B13) -> 3.81815
A14: =TITRES_STAT!B17 -> 42025 | B14: =TITRES_STAT!D17 -> 3.6907 | C14: =B14-B13 -> -0.0975 | D14: =AVERAGE(B10:B14) -> 3.77288 | E14: =AVERAGE(B5:B14) -> 3.80283
A15: =TITRES_STAT!B18 -> 42026 | B15: =TITRES_STAT!D18 -> 3.7603 | C15: =B15-B14 -> 0.0696 | D15: =AVERAGE(B11:B15) -> 3.75894 | E15: =AVERAGE(B6:B15) -> 3.79447
A16: =TITRES_STAT!B19 -> 42027 | B16: =TITRES_STAT!D19 -> 3.7603 | C16: =B16-B15 -> 0 | D16: =AVERAGE(B12:B16) -> 3.75196 | E16: =AVERAGE(B7:B16) -> 3.7875
A17: =TITRES_STAT!B20 -> 42030 | B17: =TITRES_STAT!D20 -> 3.7603 | C17: =B17-B16 -> 0 | D17: =AVERAGE(B13:B17) -> 3.75196 | E17: =AVERAGE(B8:B17) -> 3.78053
A18: =TITRES_STAT!B21 -> 42031 | B18: =TITRES_STAT!D21 -> 3.7603 | C18: =B18-B17 -> 0 | D18: =AVERAGE(B14:B18) -> 3.74638 | E18: =AVERAGE(B9:B18) -> 3.77356 | I18: {=SUMPRODUCT(B2:B21, (ROW(B2:B21)-ROW(B2)+1)) / (20*21/2)} -> 3.7797276
A19: =TITRES_STAT!B22 -> 42032 | B19: =TITRES_STAT!D22 -> 3.7603 | C19: =B19-B18 -> 0 | D19: =AVERAGE(B15:B19) -> 3.7603 | E19: =AVERAGE(B10:B19) -> 3.76659 | I19: {=SUMPRODUCT(B3:B22, (ROW(B3:B22)-ROW(B3)+1)) / (20*21/2)} -> 3.7752476
A20: =TITRES_STAT!B23 -> 42033 | B20: =TITRES_STAT!D23 -> 3.7812 | C20: =B20-B19 -> 0.0209 | D20: =AVERAGE(B16:B20) -> 3.76448 | E20: =AVERAGE(B11:B20) -> 3.76171 | F20: =AVERAGE(B1:B20) -> 3.8090789 | I20: {=SUMPRODUCT(B4:B23, (ROW(B4:B23)-ROW(B4)+1)) / (20*21/2)} -> 3.7716962 | J20: =F20 -> 3.8090789
A21: =TITRES_STAT!B24 -> 42034 | B21: =TITRES_STAT!D24 -> 3.7743 | C21: =B21-B20 -> -0.0069 | D21: =AVERAGE(B17:B21) -> 3.76728 | E21: =AVERAGE(B12:B21) -> 3.75962 | F21: =AVERAGE(B2:B21) -> 3.80734 | I21: {=SUMPRODUCT(B5:B24, (ROW(B5:B24)-ROW(B5)+1)) / (20*21/2)} -> 3.7750781 | J21: =$J$4*B21+J20*(1-$J$4) -> 3.8057667
A22: =TITRES_STAT!B25 -> 42037 | B22: =TITRES_STAT!D25 -> 3.7603 | C22: =B22-B21 -> -0.014 | D22: =AVERAGE(B18:B22) -> 3.76728 | E22: =AVERAGE(B13:B22) -> 3.75962 | F22: =AVERAGE(B3:B22) -> 3.79759 | I22: {=SUMPRODUCT(B6:B25, (ROW(B6:B25)-ROW(B6)+1)) / (20*21/2)} -> 3.7725881 | J22: =$J$4*B22+J21*(1-$J$4) -> 3.8014365
A23: =TITRES_STAT!B26 -> 42038 | B23: =TITRES_STAT!D26 -> 3.7603 | C23: =B23-B22 -> 0 | D23: =AVERAGE(B19:B23) -> 3.76728 | E23: =AVERAGE(B14:B23) -> 3.75683 | F23: =AVERAGE(B4:B23) -> 3.78749 | I23: {=SUMPRODUCT(B7:B26, (ROW(B7:B26)-ROW(B7)+1)) / (20*21/2)} -> 3.7764676 | J23: =$J$4*B23+J22*(1-$J$4) -> 3.7975187
A24: =TITRES_STAT!B27 -> 42039 | B24: =TITRES_STAT!D27 -> 3.823 | C24: =B24-B23 -> 0.0627 | D24: =AVERAGE(B20:B24) -> 3.77982 | E24: =AVERAGE(B15:B24) -> 3.77006 | F24: =AVERAGE(B5:B24) -> 3.786445 | I24: {=SUMPRODUCT(B8:B27, (ROW(B8:B27)-ROW(B8)+1)) / (20*21/2)} -> 3.774409 | J24: =$J$4*B24+J23*(1-$J$4) -> 3.7999455
A25: =TITRES_STAT!B28 -> 42040 | B25: =TITRES_STAT!D28 -> 3.7603 | C25: =B25-B24 -> -0.0627 | D25: =AVERAGE(B21:B25) -> 3.77564 | E25: =AVERAGE(B16:B25) -> 3.77006 | F25: =AVERAGE(B6:B25) -> 3.782265 | I25: {=SUMPRODUCT(B9:B28, (ROW(B9:B28)-ROW(B9)+1)) / (20*21/2)} -> 3.7779871 | J25: =$J$4*B25+J24*(1-$J$4) -> 3.7961698
A26: =TITRES_STAT!B29 -> 42041 | B26: =TITRES_STAT!D29 -> 3.823 | C26: =B26-B25 -> 0.0627 | D26: =AVERAGE(B22:B26) -> 3.78538 | E26: =AVERAGE(B17:B26) -> 3.77633 | F26: =AVERAGE(B7:B26) -> 3.781915 | I26: {=SUMPRODUCT(B10:B29, (ROW(B10:B29)-ROW(B10)+1)) / (20*21/2)} -> 3.7862795 | J26: =$J$4*B26+J25*(1-$J$4) -> 3.798725
A27: =TITRES_STAT!B30 -> 42044 | B27: =TITRES_STAT!D30 -> 3.7603 | C27: =B27-B26 -> -0.0627 | D27: =AVERAGE(B23:B27) -> 3.78538 | E27: =AVERAGE(B18:B27) -> 3.77633 | F27: =AVERAGE(B8:B27) -> 3.77843 | I27: {=SUMPRODUCT(B11:B30, (ROW(B11:B30)-ROW(B11)+1)) / (20*21/2)} -> 3.7844538 | J27: =$J$4*B27+J26*(1-$J$4) -> 3.7950655
A28: =TITRES_STAT!B31 -> 42045 | B28: =TITRES_STAT!D31 -> 3.816 | C28: =B28-B27 -> 0.0557 | D28: =AVERAGE(B24:B28) -> 3.79652 | E28: =AVERAGE(B19:B28) -> 3.7819 | F28: =AVERAGE(B9:B28) -> 3.77773 | I28: {=SUMPRODUCT(B12:B31, (ROW(B12:B31)-ROW(B12)+1)) / (20*21/2)} -> 3.78296 | J28: =$J$4*B28+J27*(1-$J$4) -> 3.7970593
A29: =TITRES_STAT!B32 -> 42046 | B29: =TITRES_STAT!D32 -> 3.8648 | C29: =B29-B28 -> 0.0488 | D29: =AVERAGE(B25:B29) -> 3.80488 | E29: =AVERAGE(B20:B29) -> 3.79235 | F29: =AVERAGE(B10:B29) -> 3.77947 | I29: {=SUMPRODUCT(B13:B32, (ROW(B13:B32)-ROW(B13)+1)) / (20*21/2)} -> 3.7922514 | J29: =$J$4*B29+J28*(1-$J$4) -> 3.8035108
A30: =TITRES_STAT!B33 -> 42047 | B30: =TITRES_STAT!D33 -> 3.7603 | C30: =B30-B29 -> -0.1045 | D30: =AVERAGE(B26:B30) -> 3.80488 | E30: =AVERAGE(B21:B30) -> 3.79026 | F30: =AVERAGE(B11:B30) -> 3.775985 | I30: {=SUMPRODUCT(B14:B33, (ROW(B14:B33)-ROW(B14)+1)) / (20*21/2)} -> 3.8010119 | J30: =$J$4*B30+J29*(1-$J$4) -> 3.7993955
A31: =TITRES_STAT!B34 -> 42048 | B31: =TITRES_STAT!D34 -> 3.7603 | C31: =B31-B30 -> 0 | D31: =AVERAGE(B27:B31) -> 3.79234 | E31: =AVERAGE(B22:B31) -> 3.78886 | F31: =AVERAGE(B12:B31) -> 3.77424 | I31: {=SUMPRODUCT(B15:B34, (ROW(B15:B34)-ROW(B15)+1)) / (20*21/2)} -> 3.8093743 | J31: =$J$4*B31+J30*(1-$J$4) -> 3.7956721
A32: =TITRES_STAT!B35 -> 42051 | B32: =TITRES_STAT!D35 -> 3.8718 | C32: =B32-B31 -> 0.1115 | D32: =AVERAGE(B28:B32) -> 3.81464 | E32: =AVERAGE(B23:B32) -> 3.80001 | F32: =AVERAGE(B13:B32) -> 3.779815 | I32: {=SUMPRODUCT(B16:B35, (ROW(B16:B35)-ROW(B16)+1)) / (20*21/2)} -> 3.8069219 | J32: =$J$4*B32+J31*(1-$J$4) -> 3.8029224
... A49: =TITRES_STAT!B52 -> 42074 | B49: =TITRES_STAT!D52 -> 3.823 | C49: =B49-B48 -> -0.007 | D49: =AVERAGE(B45:B49) -> 3.84112 | E49: =AVERAGE(B40:B49) -> 3.81117 | F49: =AVERAGE(B30:B49) -> 3.8063 | I49: {=SUMPRODUCT(B33:B52, (ROW(B33:B52)-ROW(B33)+1)) / (20*21/2)} -> 3.815689 | J49: =$J$4*B49+J48*(1-$J$4) -> 3.8104794
A50: =TITRES_STAT!B53 -> 42075 | B50: =TITRES_STAT!D53 -> 3.83 | C50: =B50-B49 -> 0.007 | D50: =AVERAGE(B46:B50) -> 3.83416 | E50: =AVERAGE(B41:B50) -> 3.81117 | F50: =AVERAGE(B31:B50) -> 3.809785 | G50: =AVERAGE(B1:B50) -> 3.8055265 | I50: {=SUMPRODUCT(B34:B53, (ROW(B34:B53)-ROW(B34)+1)) / (20*21/2)} -> 3.8174814 | J50: =$J$4*B50+J49*(1-$J$4) -> 3.8123385 | K50: =G50 -> 3.8055265
A51: =TITRES_STAT!B54 -> 42076 | B51: =TITRES_STAT!D54 -> 3.83 | C51: =B51-B50 -> 0 | D51: =AVERAGE(B47:B51) -> 3.83416 | E51: =AVERAGE(B42:B51) -> 3.81814 | F51: =AVERAGE(B32:B51) -> 3.81327 | G51: =AVERAGE(B2:B51) -> 3.806016 | I51: {=SUMPRODUCT(B35:B54, (ROW(B35:B54)-ROW(B35)+1)) / (20*21/2)} -> 3.8194729 | J51: =$J$4*B51+J50*(1-$J$4) -> 3.8140205 | K51: =$K$4*B51+(1-$K$4)*K50 -> 3.8064863
A52: =TITRES_STAT!B55 -> 42079 | B52: =TITRES_STAT!D55 -> 3.83 | C52: =B52-B51 -> 0 | D52: =AVERAGE(B48:B52) -> 3.8286 | E52: =AVERAGE(B43:B52) -> 3.82162 | F52: =AVERAGE(B33:B52) -> 3.81118 | G52: =AVERAGE(B3:B52) -> 3.80351 | I52: {=SUMPRODUCT(B36:B55, (ROW(B36:B55)-ROW(B36)+1)) / (20*21/2)} -> 3.8216633 | J52: =$J$4*B52+J51*(1-$J$4) -> 3.8155424 | K52: =$K$4*B52+(1-$K$4)*K51 -> 3.8074084
A53: =TITRES_STAT!B56 -> 42080 | B53: =TITRES_STAT!D56 -> 3.83 | C53: =B53-B52 -> 0 | D53: =AVERAGE(B49:B53) -> 3.8286 | E53: =AVERAGE(B44:B53) -> 3.82859 | F53: =AVERAGE(B34:B53) -> 3.80909 | G53: =AVERAGE(B4:B53) -> 3.800864 | I53: {=SUMPRODUCT(B37:B56, (ROW(B37:B56)-ROW(B37)+1)) / (20*21/2)} -> 3.8262029 | J53: =$J$4*B53+J52*(1-$J$4) -> 3.8169193 | K53: =$K$4*B53+(1-$K$4)*K52 -> 3.8082943
A54: =TITRES_STAT!B57 -> 42081 | B54: =TITRES_STAT!D57 -> 3.83 | C54: =B54-B53 -> 0 | D54: =AVERAGE(B50:B54) -> 3.83 | E54: =AVERAGE(B45:B54) -> 3.83556 | F54: =AVERAGE(B35:B54) -> 3.807 | G54: =AVERAGE(B5:B54) -> 3.800586 | I54: {=SUMPRODUCT(B38:B57, (ROW(B38:B57)-ROW(B38)+1)) / (20*21/2)} -> 3.8276305 | J54: =$J$4*B54+J53*(1-$J$4) -> 3.8181651 | K54: =$K$4*B54+(1-$K$4)*K53 -> 3.8091455
A55: =TITRES_STAT!B58 -> 42082 | B55: =TITRES_STAT!D58 -> 3.83 | C55: =B55-B54 -> 0 | D55: =AVERAGE(B51:B55) -> 3.83 | E55: =AVERAGE(B46:B55) -> 3.83208 | F55: =AVERAGE(B36:B55) -> 3.810135 | G55: =AVERAGE(B6:B55) -> 3.800308 | I55: {=SUMPRODUCT(B39:B58, (ROW(B39:B58)-ROW(B39)+1)) / (20*21/2)} -> 3.8288924 | J55: =$J$4*B55+J54*(1-$J$4) -> 3.8192922 | K55: =$K$4*B55+(1-$K$4)*K54 -> 3.8099634
A56: =TITRES_STAT!B59 -> 42086 | B56: =TITRES_STAT!D59 -> 3.8578 | C56: =B56-B55 -> 0.0278 | D56: =AVERAGE(B52:B56) -> 3.83556 | E56: =AVERAGE(B47:B56) -> 3.83486 | F56: =AVERAGE(B37:B56) -> 3.81501 | G56: =AVERAGE(B7:B56) -> 3.800864 | I56: {=SUMPRODUCT(B40:B59, (ROW(B40:B59)-ROW(B40)+1)) / (20*21/2)} -> 3.8298224 | J56: =$J$4*B56+J55*(1-$J$4) -> 3.8229596 | K56: =$K$4*B56+(1-$K$4)*K55 -> 3.8118393
...

Sheet RSI
A1: =TITRES_STAT!B4 -> Date | B1: =TITRES_STAT!D4 -> Cours Ajusté | C1: Change | D1: Gain | E1: Loss | F1: Avg Gain | G1: Avg Loss | H1: RS | I1: 14-Day RSI
A2: =TITRES_STAT!B5 -> 42006 | B2: =TITRES_STAT!D5 -> 3.9553
A3: =TITRES_STAT!B6 -> 42009 | B3: =TITRES_STAT!D6 -> 3.9623 | C3: =B3-B2 -> 0.007 | D3: =IF(C3>0,C3,0) -> 0.007 | E3: =IF(C3<0,-C3,0) -> 0
A4: =TITRES_STAT!B7 -> 42010 | B4: =TITRES_STAT!D7 -> 3.8439 | C4: =B4-B3 -> -0.1184 | D4: =IF(C4>0,C4,0) -> 0 | E4: =IF(C4<0,-C4,0) -> 0.1184
A5: =TITRES_STAT!B8 -> 42011 | B5: =TITRES_STAT!D8 -> 3.8439 | C5: =B5-B4 -> 0 | D5: =IF(C5>0,C5,0) -> 0 | E5: =IF(C5<0,-C5,0) -> 0
A6: =TITRES_STAT!B9 -> 42012 | B6: =TITRES_STAT!D9 -> 3.83 | C6: =B6-B5 -> -0.0139 | D6: =IF(C6>0,C6,0) -> 0 | E6: =IF(C6<0,-C6,0) -> 0.0139
A7: =TITRES_STAT!B10 -> 42013 | B7: =TITRES_STAT!D10 -> 3.83 | C7: =B7-B6 -> 0 | D7: =IF(C7>0,C7,0) -> 0 | E7: =IF(C7<0,-C7,0) -> 0
A8: =TITRES_STAT!B11 -> 42016 | B8: =TITRES_STAT!D11 -> 3.83 | C8: =B8-B7 -> 0 | D8: =IF(C8>0,C8,0) -> 0 | E8: =IF(C8<0,-C8,0) -> 0
A9: =TITRES_STAT!B12 -> 42017 | B9: =TITRES_STAT!D12 -> 3.83 | C9: =B9-B8 -> 0 | D9: =IF(C9>0,C9,0) -> 0 | E9: =IF(C9<0,-C9,0) -> 0
A10: =TITRES_STAT!B13 -> 42019 | B10: =TITRES_STAT!D13 -> 3.83 | C10: =B10-B9 -> 0 | D10: =IF(C10>0,C10,0) -> 0 | E10: =IF(C10<0,-C10,0) -> 0
A11: =TITRES_STAT!B14 -> 42020 | B11: =TITRES_STAT!D14 -> 3.7952 | C11: =B11-B10 -> -0.0348 | D11: =IF(C11>0,C11,0) -> 0 | E11: =IF(C11<0,-C11,0) -> 0.0348
A12: =TITRES_STAT!B15 -> 42023 | B12: =TITRES_STAT!D15 -> 3.7603 | C12: =B12-B11 -> -0.0349 | D12: =IF(C12>0,C12,0) -> 0 | E12: =IF(C12<0,-C12,0) -> 0.0349
A13: =TITRES_STAT!B16 -> 42024 | B13: =TITRES_STAT!D16 -> 3.7882 | C13: =B13-B12 -> 0.0279 | D13: =IF(C13>0,C13,0) -> 0.0279 | E13: =IF(C13<0,-C13,0) -> 0
A14: =TITRES_STAT!B17 -> 42025 | B14: =TITRES_STAT!D17 -> 3.6907 | C14: =B14-B13 -> -0.0975 | D14: =IF(C14>0,C14,0) -> 0 | E14: =IF(C14<0,-C14,0) -> 0.0975
A15: =TITRES_STAT!B18 -> 42026 | B15: =TITRES_STAT!D18 -> 3.7603 | C15: =B15-B14 -> 0.0696 | D15: =IF(C15>0,C15,0) -> 0.0696 | E15: =IF(C15<0,-C15,0) -> 0
A16: =TITRES_STAT!B19 -> 42027 | B16: =TITRES_STAT!D19 -> 3.7603 | C16: =B16-B15 -> 0 | D16: =IF(C16>0,C16,0) -> 0 | E16: =IF(C16<0,-C16,0) -> 0 | F16: =(SUM(D3:D16)/14) -> 0.0074642857 | G16: =SUM(E3:E16)/14 -> 0.021392857 | H16: =F16/G16 -> 0.34891486 | I16: =IF(G16=0,100,100-(100/(1+H16))) -> 25.866337
A17: =TITRES_STAT!B20 -> 42030 | B17: =TITRES_STAT!D20 -> 3.7603 | C17: =B17-B16 -> 0 | D17: =IF(C17>0,C17,0) -> 0 | E17: =IF(C17<0,-C17,0) -> 0 | F17: =((F16*13)+D17)/14 -> 0.0069311224 | G17: =((G16*13)+E17)/14 -> 0.019864796 | H17: =F17/G17 -> 0.34891486 | I17: =IF(G17=0,100,100-(100/(1+H17))) -> 25.866337
A18: =TITRES_STAT!B21 -> 42031 | B18: =TITRES_STAT!D21 -> 3.7603 | C18: =B18-B17 -> 0 | D18: =IF(C18>0,C18,0) -> 0 | E18: =IF(C18<0,-C18,0) -> 0 | F18: =((F17*13)+D18)/14 -> 0.0064360423 | G18: =((G17*13)+E18)/14 -> 0.018445882 | H18: =F18/G18 -> 0.34891486 | I18: =IF(G18=0,100,100-(100/(1+H18))) -> 25.866337
A19: =TITRES_STAT!B22 -> 42032 | B19: =TITRES_STAT!D22 -> 3.7603 | C19: =B19-B18 -> 0 | D19: =IF(C19>0,C19,0) -> 0 | E19: =IF(C19<0,-C19,0) -> 0 | F19: =((F18*13)+D19)/14 -> 0.005976325 | G19: =((G18*13)+E19)/14 -> 0.017128319 | H19: =F19/G19 -> 0.34891486 | I19: =IF(G19=0,100,100-(100/(1+H19))) -> 25.866337
A20: =TITRES_STAT!B23 -> 42033 | B20: =TITRES_STAT!D23 -> 3.7812 | C20: =B20-B19 -> 0.0209 | D20: =IF(C20>0,C20,0) -> 0.0209 | E20: =IF(C20<0,-C20,0) -> 0 | F20: =((F19*13)+D20)/14 -> 0.0070423018 | G20: =((G19*13)+E20)/14 -> 0.015904868 | H20: =F20/G20 -> 0.44277651 | I20: =IF(G20=0,100,100-(100/(1+H20))) -> 30.689196
A21: =TITRES_STAT!B24 -> 42034 | B21: =TITRES_STAT!D24 -> 3.7743 | C21: =B21-B20 -> -0.0069 | D21: =IF(C21>0,C21,0) -> 0 | E21: =IF(C21<0,-C21,0) -> 0.0069 | F21: =((F20*13)+D21)/14 -> 0.0065392802 | G21: =((G20*13)+E21)/14 -> 0.015261663 | H21: =F21/G21 -> 0.42847757 | I21: =IF(G21=0,100,100-(100/(1+H21))) -> 29.995401
A22: =TITRES_STAT!B25 -> 42037 | B22: =TITRES_STAT!D25 -> 3.7603 | C22: =B22-B21 -> -0.014 | D22: =IF(C22>0,C22,0) -> 0 | E22: =IF(C22<0,-C22,0) -> 0.014 | F22: =((F21*13)+D22)/14 -> 0.0060721888 | G22: =((G21*13)+E22)/14 -> 0.015171544 | H22: =F22/G22 -> 0.40023539 | I22: =IF(G22=0,100,100-(100/(1+H22))) -> 28.583436
A23: =TITRES_STAT!B26 -> 42038 | B23: =TITRES_STAT!D26 -> 3.7603 | C23: =B23-B22 -> 0 | D23: =IF(C23>0,C23,0) -> 0 | E23: =IF(C23<0,-C23,0) -> 0 | F23: =((F22*13)+D23)/14 -> 0.005638461 | G23: =((G22*13)+E23)/14 -> 0.014087862 | H23: =F23/G23 -> 0.40023539 | I23: =IF(G23=0,100,100-(100/(1+H23))) -> 28.583436
A24: =TITRES_STAT!B27 -> 42039 | B24: =TITRES_STAT!D27 -> 3.823 | C24: =B24-B23 -> 0.0627 | D24: =IF(C24>0,C24,0) -> 0.0627 | E24: =IF(C24<0,-C24,0) -> 0 | F24: =((F23*13)+D24)/14 -> 0.0097142852 | G24: =((G23*13)+E24)/14 -> 0.013081586 | H24: =F24/G24 -> 0.74259229 | I24: =IF(G24=0,100,100-(100/(1+H24))) -> 42.61423
A25: =TITRES_STAT!B28 -> 42040 | B25: =TITRES_STAT!D28 -> 3.7603 | C25: =B25-B24 -> -0.0627 | D25: =IF(C25>0,C25,0) -> 0 | E25: =IF(C25<0,-C25,0) -> 0.0627 | F25: =((F24*13)+D25)/14 -> 0.0090204077 | G25: =((G24*13)+E25)/14 -> 0.016625759 | H25: =F25/G25 -> 0.54255615 | I25: =IF(G25=0,100,100-(100/(1+H25))) -> 35.172538
A26: =TITRES_STAT!B29 -> 42041 | B26: =TITRES_STAT!D29 -> 3.823 | C26: =B26-B25 -> 0.0627 | D26: =IF(C26>0,C26,0) -> 0.0627 | E26: =IF(C26<0,-C26,0) -> 0 | F26: =((F25*13)+D26)/14 -> 0.012854664 | G26: =((G25*13)+E26)/14 -> 0.015438205 | H26: =F26/G26 -> 0.8326528 | I26: =IF(G26=0,100,100-(100/(1+H26))) -> 45.434291
A27: =TITRES_STAT!B30 -> 42044 | B27: =TITRES_STAT!D30 -> 3.7603 | C27: =B27-B26 -> -0.0627 | D27: =IF(C27>0,C27,0) -> 0 | E27: =IF(C27<0,-C27,0) -> 0.0627 | F27: =((F26*13)+D27)/14 -> 0.011936474 | G27: =((G26*13)+E27)/14 -> 0.018814047 | H27: =F27/G27 -> 0.63444478 | I27: =IF(G27=0,100,100-(100/(1+H27))) -> 38.817144
A28: =TITRES_STAT!B31 -> 42045 | B28: =TITRES_STAT!D31 -> 3.816 | C28: =B28-B27 -> 0.0557 | D28: =IF(C28>0,C28,0) -> 0.0557 | E28: =IF(C28<0,-C28,0) -> 0 | F28: =((F27*13)+D28)/14 -> 0.01506244 | G28: =((G27*13)+E28)/14 -> 0.017470187 | H28: =F28/G28 -> 0.86217969 | I28: =IF(G28=0,100,100-(100/(1+H28))) -> 46.29949
... A2693: =TITRES_STAT!B2696 -> 45930 | B2693: =TITRES_STAT!D2696 -> 14.9 | C2693: =B2693-B2692 -> 0.16 | D2693: =IF(C2693>0,C2693,0) -> 0.16 | E2693: =IF(C2693<0,-C2693,0) -> 0 | F2693: =((F2692*13)+D2693)/14 -> 0.025089477 | G2693: =((G2692*13)+E2693)/14 -> 0.036468918 | H2693: =F2693/G2693 -> 0.68796877 | I2693: =IF(G2693=0,100,100-(100/(1+H2693))) -> 40.757198

Sheet MACD
A1: =TITRES_STAT!B4 -> Date | B1: =TITRES_STAT!D4 -> Cours Ajusté | C1: EMA 12-Period | D1: EMA 26-Period | E1: MACD Line | F1: Signal Line | G1: MACD Histogram | H1: Signal
A2: =TITRES_STAT!B5 -> 42006 | B2: =TITRES_STAT!D5 -> 3.9553 | C2: Alpha= | D2: Alpha=
A3: =TITRES_STAT!B6 -> 42009 | B3: =TITRES_STAT!D6 -> 3.9623 | C3: (2/12+1) | D3: (2/26+1)
A4: =TITRES_STAT!B7 -> 42010 | B4: =TITRES_STAT!D7 -> 3.8439 | C4: =2/13 -> 0.15384615 | D4: =2/27 -> 0.074074074
A5: =TITRES_STAT!B8 -> 42011 | B5: =TITRES_STAT!D8 -> 3.8439
A6: =TITRES_STAT!B9 -> 42012 | B6: =TITRES_STAT!D9 -> 3.83
A7: =TITRES_STAT!B10 -> 42013 | B7: =TITRES_STAT!D10 -> 3.83
A8: =TITRES_STAT!B11 -> 42016 | B8: =TITRES_STAT!D11 -> 3.83
A9: =TITRES_STAT!B12 -> 42017 | B9: =TITRES_STAT!D12 -> 3.83
A10: =TITRES_STAT!B13 -> 42019 | B10: =TITRES_STAT!D13 -> 3.83
A11: =TITRES_STAT!B14 -> 42020 | B11: =TITRES_STAT!D14 -> 3.7952
A12: =TITRES_STAT!B15 -> 42023 | B12: =TITRES_STAT!D15 -> 3.7603
A13: =TITRES_STAT!B16 -> 42024 | B13: =TITRES_STAT!D16 -> 3.7882 | C13: =AVERAGE(B2:B13) -> 3.8415917
A14: =TITRES_STAT!B17 -> 42025 | B14: =TITRES_STAT!D17 -> 3.6907 | C14: =$C$4*B4+C13*(1-$C$4) -> 3.8419468
A15: =TITRES_STAT!B18 -> 42026 | B15: =TITRES_STAT!D18 -> 3.7603 | C15: =$C$4*B5+C14*(1-$C$4) -> 3.8422473
A16: =TITRES_STAT!B19 -> 42027 | B16: =TITRES_STAT!D19 -> 3.7603 | C16: =$C$4*B6+C15*(1-$C$4) -> 3.8403631
A17: =TITRES_STAT!B20 -> 42030 | B17: =TITRES_STAT!D20 -> 3.7603 | C17: =$C$4*B7+C16*(1-$C$4) -> 3.8387688
A18: =TITRES_STAT!B21 -> 42031 | B18: =TITRES_STAT!D21 -> 3.7603 | C18: =$C$4*B8+C17*(1-$C$4) -> 3.8374197
A19: =TITRES_STAT!B22 -> 42032 | B19: =TITRES_STAT!D22 -> 3.7603 | C19: =$C$4*B9+C18*(1-$C$4) -> 3.8362782
A20: =TITRES_STAT!B23 -> 42033 | B20: =TITRES_STAT!D23 -> 3.7812 | C20: =$C$4*B10+C19*(1-$C$4) -> 3.8353123
A21: =TITRES_STAT!B24 -> 42034 | B21: =TITRES_STAT!D24 -> 3.7743 | C21: =$C$4*B11+C20*(1-$C$4) -> 3.8291412
A22: =TITRES_STAT!B25 -> 42037 | B22: =TITRES_STAT!D25 -> 3.7603 | C22: =$C$4*B12+C21*(1-$C$4) -> 3.8185503
A23: =TITRES_STAT!B26 -> 42038 | B23: =TITRES_STAT!D26 -> 3.7603 | C23: =$C$4*B13+C22*(1-$C$4) -> 3.813881
A24: =TITRES_STAT!B27 -> 42039 | B24: =TITRES_STAT!D27 -> 3.823 | C24: =$C$4*B14+C23*(1-$C$4) -> 3.7949301
A25: =TITRES_STAT!B28 -> 42040 | B25: =TITRES_STAT!D28 -> 3.7603 | C25: =$C$4*B15+C24*(1-$C$4) -> 3.7896024
A26: =TITRES_STAT!B29 -> 42041 | B26: =TITRES_STAT!D29 -> 3.823 | C26: =$C$4*B16+C25*(1-$C$4) -> 3.7850943
A27: =TITRES_STAT!B30 -> 42044 | B27: =TITRES_STAT!D30 -> 3.7603 | C27: =$C$4*B17+C26*(1-$C$4) -> 3.7812798 | D27: =AVERAGE(B2:B27) -> 3.8013077 | E27: =C27-D27 -> -0.020027892
A28: =TITRES_STAT!B31 -> 42045 | B28: =TITRES_STAT!D31 -> 3.816 | C28: =$C$4*B18+C27*(1-$C$4) -> 3.7780521 | D28: =$D$4*B28+(1-$D$4)*D27 -> 3.802396 | E28: =C28-D28 -> -0.024343872
A29: =TITRES_STAT!B32 -> 42046 | B29: =TITRES_STAT!D32 -> 3.8648 | C29: =$C$4*B19+C28*(1-$C$4) -> 3.775321 | D29: =$D$4*B29+(1-$D$4)*D28 -> 3.8070185 | E29: =C29-D29 -> -0.031697488
A30: =TITRES_STAT!B33 -> 42047 | B30: =TITRES_STAT!D33 -> 3.7603 | C30: =$C$4*B20+C29*(1-$C$4) -> 3.7762255 | D30: =$D$4*B30+(1-$D$4)*D29 -> 3.8035579 | E30: =C30-D30 -> -0.027332401
A31: =TITRES_STAT!B34 -> 42048 | B31: =TITRES_STAT!D34 -> 3.7603 | C31: =$C$4*B21+C30*(1-$C$4) -> 3.7759293 | D31: =$D$4*B31+(1-$D$4)*D30 -> 3.8003536 | E31: =C31-D31 -> -0.024424343
A32: =TITRES_STAT!B35 -> 42051 | B32: =TITRES_STAT!D35 -> 3.8718 | C32: =$C$4*B22+C31*(1-$C$4) -> 3.7735248 | D32: =$D$4*B32+(1-$D$4)*D31 -> 3.8056459 | E32: =C32-D32 -> -0.032121171
A33: =TITRES_STAT!B36 -> 42052 | B33: =TITRES_STAT!D36 -> 3.8718 | C33: =$C$4*B23+C32*(1-$C$4) -> 3.7714902 | D33: =$D$4*B33+(1-$D$4)*D32 -> 3.8105462 | E33: =C33-D33 -> -0.039056051
A34: =TITRES_STAT!B37 -> 42053 | B34: =TITRES_STAT!D37 -> 3.8718 | C34: =$C$4*B24+C33*(1-$C$4) -> 3.7794148 | D34: =$D$4*B34+(1-$D$4)*D33 -> 3.8150836 | E34: =C34-D34 -> -0.03566878
A35: =TITRES_STAT!B38 -> 42054 | B35: =TITRES_STAT!D38 -> 3.7673 | C35: =$C$4*B25+C34*(1-$C$4) -> 3.776474 | D35: =$D$4*B35+(1-$D$4)*D34 -> 3.811544 | E35: =C35-D35 -> -0.035069991 | F35: =AVERAGE(E27:E35) -> -0.029971332 | G35: =E35-F35 -> -0.0050986593 | H35: =IF(G35<0,"Hold","Sell") -> Hold
A36: =TITRES_STAT!B39 -> 42055 | B36: =TITRES_STAT!D39 -> 3.7603 | C36: =$C$4*B26+C35*(1-$C$4) -> 3.7836319 | D36: =$D$4*B36+(1-$D$4)*D35 -> 3.8077482 | E36: =C36-D36 -> -0.024116297 | F36: =(E36*(2/(10)))+((1-(2/10))*F35) -> -0.028800325 | G36: =E36-F36 -> 0.0046840281 | H36: =IF(G36<0,"Hold","Sell") -> Sell
A37: =TITRES_STAT!B40 -> 42058 | B37: =TITRES_STAT!D40 -> 3.7952 | C37: =$C$4*B27+C36*(1-$C$4) -> 3.7800424 | D37: =$D$4*B37+(1-$D$4)*D36 -> 3.8068187 | E37: =C37-D37 -> -0.026776322 | F37: =(E37*(2/(10)))+((1-(2/10))*F36) -> -0.028395525 | G37: =E37-F37 -> 0.0016192023 | H37: =IF(G37<0,"Hold","Sell") -> Sell
A38: =TITRES_STAT!B41 -> 42059 | B38: =TITRES_STAT!D41 -> 3.7603 | C38: =$C$4*B28+C37*(1-$C$4) -> 3.7855743 | D38: =$D$4*B38+(1-$D$4)*D37 -> 3.8033729 | E38: =C38-D38 -> -0.017798549 | F38: =(E38*(2/(10)))+((1-(2/10))*F37) -> -0.026276129 | G38: =E38-F38 -> 0.0084775803 | H38: =IF(G38<0,"Hold","Sell") -> Sell
A39: =TITRES_STAT!B42 -> 42060 | B39: =TITRES_STAT!D42 -> 3.7952 | C39: =$C$4*B29+C38*(1-$C$4) -> 3.7977629 | D39: =$D$4*B39+(1-$D$4)*D38 -> 3.8027675 | E39: =C39-D39 -> -0.0050045839 | F39: =(E39*(2/(10)))+((1-(2/10))*F38) -> -0.02202182 | G39: =E39-F39 -> 0.017017236 | H39: =IF(G39<0,"Hold","Sell") -> Sell
A40: =TITRES_STAT!B43 -> 42061 | B40: =TITRES_STAT!D43 -> 3.83 | C40: =$C$4*B30+C39*(1-$C$4) -> 3.7919994 | D40: =$D$4*B40+(1-$D$4)*D39 -> 3.8047847 | E40: =C40-D40 -> -0.012785328 | F40: =(E40*(2/(10)))+((1-(2/10))*F39) -> -0.020174522 | G40: =E40-F40 -> 0.0073891937 | H40: =IF(G40<0,"Hold","Sell") -> Sell
...

Sheet OBV
A1: =TITRES_STAT!B4 -> Date | B1: =TITRES_STAT!C4 -> Cours | C1: =TITRES_STAT!D4 -> Cours Ajusté | D1: =TITRES_STAT!E4 -> Qte. Ech. | E1: OBV | F1: OBV Trend Signal | G1: OBV Strength | H1: Price-OBV Alignment
A2: =TITRES_STAT!B5 -> 42006 | B2: =TITRES_STAT!C5 -> 5.68 | C2: =TITRES_STAT!D5 -> 3.9553 | D2: =TITRES_STAT!E5 -> 642 | E2: =D2 -> 642
A3: =TITRES_STAT!B6 -> 42009 | B3: =TITRES_STAT!C6 -> 5.69 | C3: =TITRES_STAT!D6 -> 3.9623 | D3: =TITRES_STAT!E6 -> 1500 | E3: =IF(B3>B2, E2+D3, IF(B3<B2, E2-D3, E2)) -> 2142
A4: =TITRES_STAT!B7 -> 42010 | B4: =TITRES_STAT!C7 -> 5.52 | C4: =TITRES_STAT!D7 -> 3.8439 | D4: =TITRES_STAT!E7 -> 614 | E4: =IF(B4>B3, E3+D4, IF(B4<B3, E3-D4, E3)) -> 1528
A5: =TITRES_STAT!B8 -> 42011 | B5: =TITRES_STAT!C8 -> 5.52 | C5: =TITRES_STAT!D8 -> 3.8439 | D5: =TITRES_STAT!E8 -> 3628 | E5: =IF(B5>B4, E4+D5, IF(B5<B4, E4-D5, E4)) -> 1528
A6: =TITRES_STAT!B9 -> 42012 | B6: =TITRES_STAT!C9 -> 5.5 | C6: =TITRES_STAT!D9 -> 3.83 | D6: =TITRES_STAT!E9 -> 4100 | E6: =IF(B6>B5, E5+D6, IF(B6<B5, E5-D6, E5)) -> -2572 | H6: =IF(AND(B6>B1, E6>E1), "CONFIRMED BULLISH", IF(AND(B6<B1, E6<E1), "CONFIRMED BEARISH", IF(AND(B6>B1, E6<E1), "BEARISH DIVERGENCE", IF(AND(B6<B1, E6>E1), "BULLISH DIVERGENCE", "NEUTRAL")))) -> CONFIRMED BEARISH
A7: =TITRES_STAT!B10 -> 42013 | B7: =TITRES_STAT!C10 -> 5.5 | C7: =TITRES_STAT!D10 -> 3.83 | D7: =TITRES_STAT!E10 -> 4779 | E7: =IF(B7>B6, E6+D7, IF(B7<B6, E6-D7, E6)) -> -2572 | F7: =IF(E7>E2,"BULLISH",IF(E7<E2,"BEARISH","NEUTRAL")) -> BEARISH | G7: =IF((E7-E2)/E2 > 0.02, "STRONG", IF((E7-E2)/E2 < -0.02, "WEAK", "NEUTRAL")) -> WEAK | H7: =IF(AND(B7>B2, E7>E2), "CONFIRMED BULLISH", IF(AND(B7<B2, E7<E2), "CONFIRMED BEARISH", IF(AND(B7>B2, E7<E2), "BEARISH DIVERGENCE", IF(AND(B7<B2, E7>E2), "BULLISH DIVERGENCE", "NEUTRAL")))) -> CONFIRMED BEARISH
A8: =TITRES_STAT!B11 -> 42016 | B8: =TITRES_STAT!C11 -> 5.5 | C8: =TITRES_STAT!D11 -> 3.83 | D8: =TITRES_STAT!E11 -> 3173 | E8: =IF(B8>B7, E7+D8, IF(B8<B7, E7-D8, E7)) -> -2572 | F8: =IF(E8>E3,"BULLISH",IF(E8<E3,"BEARISH","NEUTRAL")) -> BEARISH | G8: =IF((E8-E3)/E3 > 0.02, "STRONG", IF((E8-E3)/E3 < -0.02, "WEAK", "NEUTRAL")) -> WEAK | H8: =IF(AND(B8>B3, E8>E3), "CONFIRMED BULLISH", IF(AND(B8<B3, E8<E3), "CONFIRMED BEARISH", IF(AND(B8>B3, E8<E3), "BEARISH DIVERGENCE", IF(AND(B8<B3, E8>E3), "BULLISH DIVERGENCE", "NEUTRAL")))) -> CONFIRMED BEARISH
A9: =TITRES_STAT!B12 -> 42017 | B9: =TITRES_STAT!C12 -> 5.5 | C9: =TITRES_STAT!D12 -> 3.83 | D9: =TITRES_STAT!E12 -> 7367 | E9: =IF(B9>B8, E8+D9, IF(B9<B8, E8-D9, E8)) -> -2572 | F9: =IF(E9>E4,"BULLISH",IF(E9<E4,"BEARISH","NEUTRAL")) -> BEARISH | G9: =IF((E9-E4)/E4 > 0.02, "STRONG", IF((E9-E4)/E4 < -0.02, "WEAK", "NEUTRAL")) -> WEAK | H9: =IF(AND(B9>B4, E9>E4), "CONFIRMED BULLISH", IF(AND(B9<B4, E9<E4), "CONFIRMED BEARISH", IF(AND(B9>B4, E9<E4), "BEARISH DIVERGENCE", IF(AND(B9<B4, E9>E4), "BULLISH DIVERGENCE", "NEUTRAL")))) -> CONFIRMED BEARISH
A10: =TITRES_STAT!B13 -> 42019 | B10: =TITRES_STAT!C13 -> 5.5 | C10: =TITRES_STAT!D13 -> 3.83 | D10: =TITRES_STAT!E13 -> 19930 | E10: =IF(B10>B9, E9+D10, IF(B10<B9, E9-D10, E9)) -> -2572 | F10: =IF(E10>E5,"BULLISH",IF(E10<E5,"BEARISH","NEUTRAL")) -> BEARISH | G10: =IF((E10-E5)/E5 > 0.02, "STRONG", IF((E10-E5)/E5 < -0.02, "WEAK", "NEUTRAL")) -> WEAK | H10: =IF(AND(B10>B5, E10>E5), "CONFIRMED BULLISH", IF(AND(B10<B5, E10<E5), "CONFIRMED BEARISH", IF(AND(B10>B5, E10<E5), "BEARISH DIVERGENCE", IF(AND(B10<B5, E10>E5), "BULLISH DIVERGENCE", "NEUTRAL")))) -> CONFIRMED BEARISH
A11: =TITRES_STAT!B14 -> 42020 | B11: =TITRES_STAT!C14 -> 5.45 | C11: =TITRES_STAT!D14 -> 3.7952 | D11: =TITRES_STAT!E14 -> 5380 | E11: =IF(B11>B10, E10+D11, IF(B11<B10, E10-D11, E10)) -> -7952 | F11: =IF(E11>E6,"BULLISH",IF(E11<E6,"BEARISH","NEUTRAL")) -> BEARISH | G11: =IF((E11-E6)/E6 > 0.02, "STRONG", IF((E11-E6)/E6 < -0.02, "WEAK", "NEUTRAL")) -> STRONG | H11: =IF(AND(B11>B6, E11>E6), "CONFIRMED BULLISH", IF(AND(B11<B6, E11<E6), "CONFIRMED BEARISH", IF(AND(B11>B6, E11<E6), "BEARISH DIVERGENCE", IF(AND(B11<B6, E11>E6), "BULLISH DIVERGENCE", "NEUTRAL")))) -> CONFIRMED BEARISH
A12: =TITRES_STAT!B15 -> 42023 | B12: =TITRES_STAT!C15 -> 5.4 | C12: =TITRES_STAT!D15 -> 3.7603 | D12: =TITRES_STAT!E15 -> 3820 | E12: =IF(B12>B11, E11+D12, IF(B12<B11, E11-D12, E11)) -> -11772 | F12: =IF(E12>E7,"BULLISH",IF(E12<E7,"BEARISH","NEUTRAL")) -> BEARISH | G12: =IF((E12-E7)/E7 > 0.02, "STRONG", IF((E12-E7)/E7 < -0.02, "WEAK", "NEUTRAL")) -> STRONG | H12: =IF(AND(B12>B7, E12>E7), "CONFIRMED BULLISH", IF(AND(B12<B7, E12<E7), "CONFIRMED BEARISH", IF(AND(B12>B7, E12<E7), "BEARISH DIVERGENCE", IF(AND(B12<B7, E12>E7), "BULLISH DIVERGENCE", "NEUTRAL")))) -> CONFIRMED BEARISH
A13: =TITRES_STAT!B16 -> 42024 | B13: =TITRES_STAT!C16 -> 5.44 | C13: =TITRES_STAT!D16 -> 3.7882 | D13: =TITRES_STAT!E16 -> 16794 | E13: =IF(B13>B12, E12+D13, IF(B13<B12, E12-D13, E12)) -> 5022 | F13: =IF(E13>E8,"BULLISH",IF(E13<E8,"BEARISH","NEUTRAL")) -> BULLISH | G13: =IF((E13-E8)/E8 > 0.02, "STRONG", IF((E13-E8)/E8 < -0.02, "WEAK", "NEUTRAL")) -> WEAK | H13: =IF(AND(B13>B8, E13>E8), "CONFIRMED BULLISH", IF(AND(B13<B8, E13<E8), "CONFIRMED BEARISH", IF(AND(B13>B8, E13<E8), "BEARISH DIVERGENCE", IF(AND(B13<B8, E13>E8), "BULLISH DIVERGENCE", "NEUTRAL")))) -> BULLISH DIVERGENCE
A14: =TITRES_STAT!B17 -> 42025 | B14: =TITRES_STAT!C17 -> 5.3 | C14: =TITRES_STAT!D17 -> 3.6907 | D14: =TITRES_STAT!E17 -> 5665 | E14: =IF(B14>B13, E13+D14, IF(B14<B13, E13-D14, E13)) -> -643 | F14: =IF(E14>E9,"BULLISH",IF(E14<E9,"BEARISH","NEUTRAL")) -> BULLISH | G14: =IF((E14-E9)/E9 > 0.02, "STRONG", IF((E14-E9)/E9 < -0.02, "WEAK", "NEUTRAL")) -> WEAK | H14: =IF(AND(B14>B9, E14>E9), "CONFIRMED BULLISH", IF(AND(B14<B9, E14<E9), "CONFIRMED BEARISH", IF(AND(B14>B9, E14<E9), "BEARISH DIVERGENCE", IF(AND(B14<B9, E14>E9), "BULLISH DIVERGENCE", "NEUTRAL")))) -> BULLISH DIVERGENCE
A15: =TITRES_STAT!B18 -> 42026 | B15: =TITRES_STAT!C18 -> 5.4 | C15: =TITRES_STAT!D18 -> 3.7603 | D15: =TITRES_STAT!E18 -> 15376 | E15: =IF(B15>B14, E14+D15, IF(B15<B14, E14-D15, E14)) -> 14733 | F15: =IF(E15>E10,"BULLISH",IF(E15<E10,"BEARISH","NEUTRAL")) -> BULLISH | G15: =IF((E15-E10)/E10 > 0.02, "STRONG", IF((E15-E10)/E10 < -0.02, "WEAK", "NEUTRAL")) -> WEAK | H15: =IF(AND(B15>B10, E15>E10), "CONFIRMED BULLISH", IF(AND(B15<B10, E15<E10), "CONFIRMED BEARISH", IF(AND(B15>B10, E15<E10), "BEARISH DIVERGENCE", IF(AND(B15<B10, E15>E10), "BULLISH DIVERGENCE", "NEUTRAL")))) -> BULLISH DIVERGENCE
A16: =TITRES_STAT!B19 -> 42027 | B16: =TITRES_STAT!C19 -> 5.4 | C16: =TITRES_STAT!D19 -> 3.7603 | D16: =TITRES_STAT!E19 -> 11236 | E16: =IF(B16>B15, E15+D16, IF(B16<B15, E15-D16, E15)) -> 14733 | F16: =IF(E16>E11,"BULLISH",IF(E16<E11,"BEARISH","NEUTRAL")) -> BULLISH | G16: =IF((E16-E11)/E11 > 0.02, "STRONG", IF((E16-E11)/E11 < -0.02, "WEAK", "NEUTRAL")) -> WEAK | H16: =IF(AND(B16>B11, E16>E11), "CONFIRMED BULLISH", IF(AND(B16<B11, E16<E11), "CONFIRMED BEARISH", IF(AND(B16>B11, E16<E11), "BEARISH DIVERGENCE", IF(AND(B16<B11, E16>E11), "BULLISH DIVERGENCE", "NEUTRAL")))) -> BULLISH DIVERGENCE
A17: =TITRES_STAT!B20 -> 42030 | B17: =TITRES_STAT!C20 -> 5.4 | C17: =TITRES_STAT!D20 -> 3.7603 | D17: =TITRES_STAT!E20 -> 23322 | E17: =IF(B17>B16, E16+D17, IF(B17<B16, E16-D17, E16)) -> 14733 | F17: =IF(E17>E12,"BULLISH",IF(E17<E12,"BEARISH","NEUTRAL")) -> BULLISH | G17: =IF((E17-E12)/E12 > 0.02, "STRONG", IF((E17-E12)/E12 < -0.02, "WEAK", "NEUTRAL")) -> WEAK | H17: =IF(AND(B17>B12, E17>E12), "CONFIRMED BULLISH", IF(AND(B17<B12, E17<E12), "CONFIRMED BEARISH", IF(AND(B17>B12, E17<E12), "BEARISH DIVERGENCE", IF(AND(B17<B12, E17>E12), "BULLISH DIVERGENCE", "NEUTRAL")))) -> NEUTRAL
A18: =TITRES_STAT!B21 -> 42031 | B18: =TITRES_STAT!C21 -> 5.4 | C18: =TITRES_STAT!D21 -> 3.7603 | D18: =TITRES_STAT!E21 -> 8005 | E18: =IF(B18>B17, E17+D18, IF(B18<B17, E17-D18, E17)) -> 14733 | F18: =IF(E18>E13,"BULLISH",IF(E18<E13,"BEARISH","NEUTRAL")) -> BULLISH | G18: =IF((E18-E13)/E13 > 0.02, "STRONG", IF((E18-E13)/E13 < -0.02, "WEAK", "NEUTRAL")) -> STRONG | H18: =IF(AND(B18>B13, E18>E13), "CONFIRMED BULLISH", IF(AND(B18<B13, E18<E13), "CONFIRMED BEARISH", IF(AND(B18>B13, E18<E13), "BEARISH DIVERGENCE", IF(AND(B18<B13, E18>E13), "BULLISH DIVERGENCE", "NEUTRAL")))) -> BULLISH DIVERGENCE
... A2692: =TITRES_STAT!B2695 -> 45929 | B2692: =TITRES_STAT!C2695 -> 14.74 | C2692: =TITRES_STAT!D2695 -> 14.74 | D2692: =TITRES_STAT!E2695 -> 782 | E2692: =IF(B2692>B2691, E2691+D2692, IF(B2692<B2691, E2691-D2692, E2691)) -> 1755378 | F2692: =IF(E2692>E2687,"BULLISH",IF(E2692<E2687,"BEARISH","NEUTRAL")) -> BEARISH | G2692: =IF((E2692-E2687)/E2687 > 0.02, "STRONG", IF((E2692-E2687)/E2687 < -0.02, "WEAK", "NEUTRAL")) -> NEUTRAL | H2692: =IF(AND(B2692>B2687, E2692>E2687), "CONFIRMED BULLISH", IF(AND(B2692<B2687, E2692<E2687), "CONFIRMED BEARISH", IF(AND(B2692>B2687, E2692<E2687), "BEARISH DIVERGENCE", IF(AND(B2692<B2687, E2692>E2687), "BULLISH DIVERGENCE", "NEUTRAL")))) -> CONFIRMED BEARISH
A2693: =TITRES_STAT!B2696 -> 45930 | B2693: =TITRES_STAT!C2696 -> 14.9 | C2693: =TITRES_STAT!D2696 -> 14.9 | D2693: =TITRES_STAT!E2696 -> 21054 | E2693: =TITRES_STAT!F2696 -> 14.703 | F2693: =IF(E2693>E2688,"BULLISH",IF(E2693<E2688,"BEARISH","NEUTRAL")) -> BEARISH | G2693: =IF((E2693-E2688)/E2688 > 0.02, "STRONG", IF((E2693-E2688)/E2688 < -0.02, "WEAK", "NEUTRAL")) -> WEAK | H2693: =IF(AND(B2693>B2688, E2693>E2688), "CONFIRMED BULLISH", IF(AND(B2693<B2688, E2693<E2688), "CONFIRMED BEARISH", IF(AND(B2693>B2688, E2693<E2688), "BEARISH DIVERGENCE", IF(AND(B2693<B2688, E2693>E2688), "BULLISH DIVERGENCE", "NEUTRAL")))) -> CONFIRMED BEARISH

Sheet Overall Overview
A1: =RSI!A1 -> Date | B1: =RSI!B1 -> Cours Ajusté | C1: =RSI!I1 -> 14-Day RSI | D1: =MACD!E1 -> MACD Line | E1: =MACD!F1 -> Signal Line | F1: ='Moving Avg'!D1 -> Simple Moving Avg (5) | G1: ='Moving Avg'!F1 -> Simple Moving Avg (20) | H1: ='Moving Avg'!G1 -> Simple Moving Avg (50) | I1: ='Moving Avg'!H1 -> Simple Moving Avg (200) | J1: =OBV!F1 -> OBV Trend Signal | K1: =OBV!G1 -> OBV Strength | L1: =OBV!H1 -> Price-OBV Alignment
A2: =RSI!A2 -> 42006 | B2: =RSI!B2 -> 3.9553 | C2: =RSI!I2 -> 0 | D2: =MACD!E2 -> 0 | E2: =MACD!F2 -> 0 | F2: ='Moving Avg'!D2 -> 0 | G2: ='Moving Avg'!F2 -> 0 | H2: ='Moving Avg'!G2 -> 0 | I2: ='Moving Avg'!H2 -> 0 | J2: =OBV!F2 -> 0 | K2: =OBV!G2 -> 0 | L2: =OBV!H2 -> 0
A3: =RSI!A3 -> 42009 | B3: =RSI!B3 -> 3.9623 | C3: =RSI!I3 -> 0 | D3: =MACD!E3 -> 0 | E3: =MACD!F3 -> 0 | F3: ='Moving Avg'!D3 -> 0 | G3: ='Moving Avg'!F3 -> 0 | H3: ='Moving Avg'!G3 -> 0 | I3: ='Moving Avg'!H3 -> 0 | J3: =OBV!F3 -> 0 | K3: =OBV!G3 -> 0 | L3: =OBV!H3 -> 0
A4: =RSI!A4 -> 42010 | B4: =RSI!B4 -> 3.8439 | C4: =RSI!I4 -> 0 | D4: =MACD!E4 -> 0 | E4: =MACD!F4 -> 0 | F4: ='Moving Avg'!D4 -> 0 | G4: ='Moving Avg'!F4 -> 0 | H4: ='Moving Avg'!G4 -> 0 | I4: ='Moving Avg'!H4 -> 0 | J4: =OBV!F4 -> 0 | K4: =OBV!G4 -> 0 | L4: =OBV!H4 -> 0
A5: =RSI!A5 -> 42011 | B5: =RSI!B5 -> 3.8439 | C5: =RSI!I5 -> 0 | D5: =MACD!E5 -> 0 | E5: =MACD!F5 -> 0 | F5: ='Moving Avg'!D5 -> 3.90135 | G5: ='Moving Avg'!F5 -> 0 | H5: ='Moving Avg'!G5 -> 0 | I5: ='Moving Avg'!H5 -> 0 | J5: =OBV!F5 -> 0 | K5: =OBV!G5 -> 0 | L5: =OBV!H5 -> 0
A6: =RSI!A6 -> 42012 | B6: =RSI!B6 -> 3.83 | C6: =RSI!I6 -> 0 | D6: =MACD!E6 -> 0 | E6: =MACD!F6 -> 0 | F6: ='Moving Avg'!D6 -> 3.88708 | G6: ='Moving Avg'!F6 -> 0 | H6: ='Moving Avg'!G6 -> 0 | I6: ='Moving Avg'!H6 -> 0 | J6: =OBV!F6 -> 0 | K6: =OBV!G6 -> 0 | L6: =OBV!H6 -> CONFIRMED BEARISH
A7: =RSI!A7 -> 42013 | B7: =RSI!B7 -> 3.83 | C7: =RSI!I7 -> 0 | D7: =MACD!E7 -> 0 | E7: =MACD!F7 -> 0 | F7: ='Moving Avg'!D7 -> 3.86202 | G7: ='Moving Avg'!F7 -> 0 | H7: ='Moving Avg'!G7 -> 0 | I7: ='Moving Avg'!H7 -> 0 | J7: =OBV!F7 -> BEARISH | K7: =OBV!G7 -> WEAK | L7: =OBV!H7 -> CONFIRMED BEARISH
A8: =RSI!A8 -> 42016 | B8: =RSI!B8 -> 3.83 | C8: =RSI!I8 -> 0 | D8: =MACD!E8 -> 0 | E8: =MACD!F8 -> 0 | F8: ='Moving Avg'!D8 -> 3.83556 | G8: ='Moving Avg'!F8 -> 0 | H8: ='Moving Avg'!G8 -> 0 | I8: ='Moving Avg'!H8 -> 0 | J8: =OBV!F8 -> BEARISH | K8: =OBV!G8 -> WEAK | L8: =OBV!H8 -> CONFIRMED BEARISH
A9: =RSI!A9 -> 42017 | B9: =RSI!B9 -> 3.83 | C9: =RSI!I9 -> 0 | D9: =MACD!E9 -> 0 | E9: =MACD!F9 -> 0 | F9: ='Moving Avg'!D9 -> 3.83278 | G9: ='Moving Avg'!F9 -> 0 | H9: ='Moving Avg'!G9 -> 0 | I9: ='Moving Avg'!H9 -> 0 | J9: =OBV!F9 -> BEARISH | K9: =OBV!G9 -> WEAK | L9: =OBV!H9 -> CONFIRMED BEARISH
A10: =RSI!A10 -> 42019 | B10: =RSI!B10 -> 3.83 | C10: =RSI!I10 -> 0 | D10: =MACD!E10 -> 0 | E10: =MACD!F10 -> 0 | F10: ='Moving Avg'!D10 -> 3.83 | G10: ='Moving Avg'!F10 -> 0 | H10: ='Moving Avg'!G10 -> 0 | I10: ='Moving Avg'!H10 -> 0 | J10: =OBV!F10 -> BEARISH | K10: =OBV!G10 -> WEAK | L10: =OBV!H10 -> CONFIRMED BEARISH
A11: =RSI!A11 -> 42020 | B11: =RSI!B11 -> 3.7952 | C11: =RSI!I11 -> 0 | D11: =MACD!E11 -> 0 | E11: =MACD!F11 -> 0 | F11: ='Moving Avg'!D11 -> 3.82304 | G11: ='Moving Avg'!F11 -> 0 | H11: ='Moving Avg'!G11 -> 0 | I11: ='Moving Avg'!H11 -> 0 | J11: =OBV!F11 -> BEARISH | K11: =OBV!G11 -> STRONG | L11: =OBV!H11 -> CONFIRMED BEARISH
A12: =RSI!A12 -> 42023 | B12: =RSI!B12 -> 3.7603 | C12: =RSI!I12 -> 0 | D12: =MACD!E12 -> 0 | E12: =MACD!F12 -> 0 | F12: ='Moving Avg'!D12 -> 3.8091 | G12: ='Moving Avg'!F12 -> 0 | H12: ='Moving Avg'!G12 -> 0 | I12: ='Moving Avg'!H12 -> 0 | J12: =OBV!F12 -> BEARISH | K12: =OBV!G12 -> STRONG | L12: =OBV!H12 -> CONFIRMED BEARISH
... A2693: =RSI!A2693 -> 45930 | B2693: =RSI!B2693 -> 14.9 | C2693: =RSI!I2693 -> 40.757198 | D2693: =MACD!E2693 -> 0.046607723 | E2693: =MACD!F2693 -> 0.068509355 | F2693: ='Moving Avg'!D2693 -> 14.894 | G2693: ='Moving Avg'!F2693 -> 15.0155 | H2693: ='Moving Avg'!G2693 -> 15.194 | I2693: ='Moving Avg'!H2693 -> 12.421432 | J2693: =OBV!F2693 -> BEARISH | K2693: =OBV!G2693 -> WEAK | L2693: =OBV!H2693 -> CONFIRMED BEARISH

Sheet Scoring System
A1: =RSI!A1 -> Date | B1: =RSI!B1 -> Cours Ajusté | C1: =RSI!I1 -> 14-Day RSI | D1: =MACD!E1 -> MACD Line | E1: =MACD!F1 -> Signal Line | F1: ='Moving Avg'!D1 -> Simple Moving Avg (5) | G1: ='Moving Avg'!F1 -> Simple Moving Avg (20) | H1: ='Moving Avg'!G1 -> Simple Moving Avg (50) | I1: ='Moving Avg'!H1 -> Simple Moving Avg (200) | J1: =OBV!F1 -> OBV Trend Signal | K1: =OBV!G1 -> OBV Strength | L1: =OBV!H1 -> Price-OBV Alignment | M1: RSI Score | N1: MACD Score | O1: SMA Score | P1: OBV Score | Q1: Score Momentum | R1: Score Trend | S1: Volume Score | T1: Score Equal Weights | U1: Overall Score (3C) | V1: Overall Score (4C)
A2: =RSI!A2 -> 42006 | B2: =RSI!B2 -> 3.9553 | C2: =RSI!I2 -> 0 | D2: =MACD!E2 -> 0 | E2: =MACD!F2 -> 0 | F2: ='Moving Avg'!D2 -> 0 | G2: ='Moving Avg'!F2 -> 0 | H2: ='Moving Avg'!G2 -> 0 | I2: ='Moving Avg'!H2 -> 0 | J2: =OBV!F2 -> 0 | K2: =OBV!G2 -> 0 | L2: =OBV!H2 -> 0 | M2: =IF(C2<30,100, IF(C2>70, 0, 50)) -> 100 | N2: =IF(E2-D2>0.02, 100, IF(E2-D2<0,0,45)) -> 45 | O2: =IF(F2-I2>10,100,IF(F2-I2>5,75, IF(F2-I2>0,50,0))) -> 0 | P2: =IF(L2="confirmed bullish", 34, IF(L2="bullish divergence",17, 0))+IF(J2="bullish",33,IF(J2="bearish",0,16.5))+IF(K2="strong",33,IF(K2="weak",0,16.5)) -> 33 | Q2: =0.35*M2+N2*0.35+O2*0.15+P2*0.15 -> 55.7 | R2: =M2*0.2+N2*0.2+O2*0.35+P2*0.25 -> 37.25 | S2: =M2*0.15+N2*0.15+O2*0.25+P2*0.45 -> 36.6 | T2: =0.25*SUM(M2:P2) -> 44.5 | U2: =SUM(Q2:S2)/3 -> 43.183333 | V2: =SUM(Q2:T2)/4 -> 43.5125
A3: =RSI!A3 -> 42009 | B3: =RSI!B3 -> 3.9623 | C3: =RSI!I3 -> 0 | D3: =MACD!E3 -> 0 | E3: =MACD!F3 -> 0 | F3: ='Moving Avg'!D3 -> 0 | G3: ='Moving Avg'!F3 -> 0 | H3: ='Moving Avg'!G3 -> 0 | I3: ='Moving Avg'!H3 -> 0 | J3: =OBV!F3 -> 0 | K3: =OBV!G3 -> 0 | L3: =OBV!H3 -> 0 | M3: =IF(C3<30,100, IF(C3>70, 0, 50)) -> 100 | N3: =IF(E3-D3>0.02, 100, IF(E3-D3<0,0,45)) -> 45 | O3: =IF(F3-I3>10,100,IF(F3-I3>5,75, IF(F3-I3>0,50,0))) -> 0 | P3: =IF(L3="confirmed bullish", 34, IF(L3="bullish divergence",17, 0))+IF(J3="bullish",33,IF(J3="bearish",0,16.5))+IF(K3="strong",33,IF(K3="weak",0,16.5)) -> 33 | Q3: =0.35*M3+N3*0.35+O3*0.15+P3*0.15 -> 55.7 | R3: =M3*0.2+N3*0.2+O3*0.35+P3*0.25 -> 37.25 | S3: =M3*0.15+N3*0.15+O3*0.25+P3*0.45 -> 36.6 | T3: =0.25*SUM(M3:P3) -> 44.5 | U3: =SUM(Q3:S3)/3 -> 43.183333 | V3: =SUM(Q3:T3)/4 -> 43.5125
A4: =RSI!A4 -> 42010 | B4: =RSI!B4 -> 3.8439 | C4: =RSI!I4 -> 0 | D4: =MACD!E4 -> 0 | E4: =MACD!F4 -> 0 | F4: ='Moving Avg'!D4 -> 0 | G4: ='Moving Avg'!F4 -> 0 | H4: ='Moving Avg'!G4 -> 0 | I4: ='Moving Avg'!H4 -> 0 | J4: =OBV!F4 -> 0 | K4: =OBV!G4 -> 0 | L4: =OBV!H4 -> 0 | M4: =IF(C4<30,100, IF(C4>70, 0, 50)) -> 100 | N4: =IF(E4-D4>0.02, 100, IF(E4-D4<0,0,45)) -> 45 | O4: =IF(F4-I4>10,100,IF(F4-I4>5,75, IF(F4-I4>0,50,0))) -> 0 | P4: =IF(L4="confirmed bullish", 34, IF(L4="bullish divergence",17, 0))+IF(J4="bullish",33,IF(J4="bearish",0,16.5))+IF(K4="strong",33,IF(K4="weak",0,16.5)) -> 33 | Q4: =0.35*M4+N4*0.35+O4*0.15+P4*0.15 -> 55.7 | R4: =M4*0.2+N4*0.2+O4*0.35+P4*0.25 -> 37.25 | S4: =M4*0.15+N4*0.15+O4*0.25+P4*0.45 -> 36.6 | T4: =0.25*SUM(M4:P4) -> 44.5 | U4: =SUM(Q4:S4)/3 -> 43.183333 | V4: =SUM(Q4:T4)/4 -> 43.5125
A5: =RSI!A5 -> 42011 | B5: =RSI!B5 -> 3.8439 | C5: =RSI!I5 -> 0 | D5: =MACD!E5 -> 0 | E5: =MACD!F5 -> 0 | F5: ='Moving Avg'!D5 -> 3.90135 | G5: ='Moving Avg'!F5 -> 0 | H5: ='Moving Avg'!G5 -> 0 | I5: ='Moving Avg'!H5 -> 0 | J5: =OBV!F5 -> 0 | K5: =OBV!G5 -> 0 | L5: =OBV!H5 -> 0 | M5: =IF(C5<30,100, IF(C5>70, 0, 50)) -> 100 | N5: =IF(E5-D5>0.02, 100, IF(E5-D5<0,0,45)) -> 45 | O5: =IF(F5-I5>10,100,IF(F5-I5>5,75, IF(F5-I5>0,50,0))) -> 50 | P5: =IF(L5="confirmed bullish", 34, IF(L5="bullish divergence",17, 0))+IF(J5="bullish",33,IF(J5="bearish",0,16.5))+IF(K5="strong",33,IF(K5="weak",0,16.5)) -> 33 | Q5: =0.35*M5+N5*0.35+O5*0.15+P5*0.15 -> 63.2 | R5: =M5*0.2+N5*0.2+O5*0.35+P5*0.25 -> 54.75 | S5: =M5*0.15+N5*0.15+O5*0.25+P5*0.45 -> 49.1 | T5: =0.25*SUM(M5:P5) -> 57 | U5: =SUM(Q5:S5)/3 -> 55.683333 | V5: =SUM(Q5:T5)/4 -> 56.0125
A6: =RSI!A6 -> 42012 | B6: =RSI!B6 -> 3.83 | C6: =RSI!I6 -> 0 | D6: =MACD!E6 -> 0 | E6: =MACD!F6 -> 0 | F6: ='Moving Avg'!D6 -> 3.88708 | G6: ='Moving Avg'!F6 -> 0 | H6: ='Moving Avg'!G6 -> 0 | I6: ='Moving Avg'!H6 -> 0 | J6: =OBV!F6 -> 0 | K6: =OBV!G6 -> 0 | L6: =OBV!H6 -> CONFIRMED BEARISH | M6: =IF(C6<30,100, IF(C6>70, 0, 50)) -> 100 | N6: =IF(E6-D6>0.02, 100, IF(E6-D6<0,0,45)) -> 45 | O6: =IF(F6-I6>10,100,IF(F6-I6>5,75, IF(F6-I6>0,50,0))) -> 50 | P6: =IF(L6="confirmed bullish", 34, IF(L6="bullish divergence",17, 0))+IF(J6="bullish",33,IF(J6="bearish",0,16.5))+IF(K6="strong",33,IF(K6="weak",0,16.5)) -> 33 | Q6: =0.35*M6+N6*0.35+O6*0.15+P6*0.15 -> 63.2 | R6: =M6*0.2+N6*0.2+O6*0.35+P6*0.25 -> 54.75 | S6: =M6*0.15+N6*0.15+O6*0.25+P6*0.45 -> 49.1 | T6: =0.25*SUM(M6:P6) -> 57 | U6: =SUM(Q6:S6)/3 -> 55.683333 | V6: =SUM(Q6:T6)/4 -> 56.0125
A7: =RSI!A7 -> 42013 | B7: =RSI!B7 -> 3.83 | C7: =RSI!I7 -> 0 | D7: =MACD!E7 -> 0 | E7: =MACD!F7 -> 0 | F7: ='Moving Avg'!D7 -> 3.86202 | G7: ='Moving Avg'!F7 -> 0 | H7: ='Moving Avg'!G7 -> 0 | I7: ='Moving Avg'!H7 -> 0 | J7: =OBV!F7 -> BEARISH | K7: =OBV!G7 -> WEAK | L7: =OBV!H7 -> CONFIRMED BEARISH | M7: =IF(C7<30,100, IF(C7>70, 0, 50)) -> 100 | N7: =IF(E7-D7>0.02, 100, IF(E7-D7<0,0,45)) -> 45 | O7: =IF(F7-I7>10,100,IF(F7-I7>5,75, IF(F7-I7>0,50,0))) -> 50 | P7: =IF(L7="confirmed bullish", 34, IF(L7="bullish divergence",17, 0))+IF(J7="bullish",33,IF(J7="bearish",0,16.5))+IF(K7="strong",33,IF(K7="weak",0,16.5)) -> 0 | Q7: =0.35*M7+N7*0.35+O7*0.15+P7*0.15 -> 58.25 | R7: =M7*0.2+N7*0.2+O7*0.35+P7*0.25 -> 46.5 | S7: =M7*0.15+N7*0.15+O7*0.25+P7*0.45 -> 34.25 | T7: =0.25*SUM(M7:P7) -> 48.75 | U7: =SUM(Q7:S7)/3 -> 46.333333 | V7: =SUM(Q7:T7)/4 -> 46.9375
A8: =RSI!A8 -> 42016 | B8: =RSI!B8 -> 3.83 | C8: =RSI!I8 -> 0 | D8: =MACD!E8 -> 0 | E8: =MACD!F8 -> 0 | F8: ='Moving Avg'!D8 -> 3.83556 | G8: ='Moving Avg'!F8 -> 0 | H8: ='Moving Avg'!G8 -> 0 | I8: ='Moving Avg'!H8 -> 0 | J8: =OBV!F8 -> BEARISH | K8: =OBV!G8 -> WEAK | L8: =OBV!H8 -> CONFIRMED BEARISH | M8: =IF(C8<30,100, IF(C8>70, 0, 50)) -> 100 | N8: =IF(E8-D8>0.02, 100, IF(E8-D8<0,0,45)) -> 45 | O8: =IF(F8-I8>10,100,IF(F8-I8>5,75, IF(F8-I8>0,50,0))) -> 50 | P8: =IF(L8="confirmed bullish", 34, IF(L8="bullish divergence",17, 0))+IF(J8="bullish",33,IF(J8="bearish",0,16.5))+IF(K8="strong",33,IF(K8="weak",0,16.5)) -> 0 | Q8: =0.35*M8+N8*0.35+O8*0.15+P8*0.15 -> 58.25 | R8: =M8*0.2+N8*0.2+O8*0.35+P8*0.25 -> 46.5 | S8: =M8*0.15+N8*0.15+O8*0.25+P8*0.45 -> 34.25 | T8: =0.25*SUM(M8:P8) -> 48.75 | U8: =SUM(Q8:S8)/3 -> 46.333333 | V8: =SUM(Q8:T8)/4 -> 46.9375
A9: =RSI!A9 -> 42017 | B9: =RSI!B9 -> 3.83 | C9: =RSI!I9 -> 0 | D9: =MACD!E9 -> 0 | E9: =MACD!F9 -> 0 | F9: ='Moving Avg'!D9 -> 3.83278 | G9: ='Moving Avg'!F9 -> 0 | H9: ='Moving Avg'!G9 -> 0 | I9: ='Moving Avg'!H9 -> 0 | J9: =OBV!F9 -> BEARISH | K9: =OBV!G9 -> WEAK | L9: =OBV!H9 -> CONFIRMED BEARISH | M9: =IF(C9<30,100, IF(C9>70, 0, 50)) -> 100 | N9: =IF(E9-D9>0.02, 100, IF(E9-D9<0,0,45)) -> 45 | O9: =IF(F9-I9>10,100,IF(F9-I9>5,75, IF(F9-I9>0,50,0))) -> 50 | P9: =IF(L9="confirmed bullish", 34, IF(L9="bullish divergence",17, 0))+IF(J9="bullish",33,IF(J9="bearish",0,16.5))+IF(K9="strong",33,IF(K9="weak",0,16.5)) -> 0 | Q9: =0.35*M9+N9*0.35+O9*0.15+P9*0.15 -> 58.25 | R9: =M9*0.2+N9*0.2+O9*0.35+P9*0.25 -> 46.5 | S9: =M9*0.15+N9*0.15+O9*0.25+P9*0.45 -> 34.25 | T9: =0.25*SUM(M9:P9) -> 48.75 | U9: =SUM(Q9:S9)/3 -> 46.333333 | V9: =SUM(Q9:T9)/4 -> 46.9375
A10: =RSI!A10 -> 42019 | B10: =RSI!B10 -> 3.83 | C10: =RSI!I10 -> 0 | D10: =MACD!E10 -> 0 | E10: =MACD!F10 -> 0 | F10: ='Moving Avg'!D10 -> 3.83 | G10: ='Moving Avg'!F10 -> 0 | H10: ='Moving Avg'!G10 -> 0 | I10: ='Moving Avg'!H10 -> 0 | J10: =OBV!F10 -> BEARISH | K10: =OBV!G10 -> WEAK | L10: =OBV!H10 -> CONFIRMED BEARISH | M10: =IF(C10<30,100, IF(C10>70, 0, 50)) -> 100 | N10: =IF(E10-D10>0.02, 100, IF(E10-D10<0,0,45)) -> 45 | O10: =IF(F10-I10>10,100,IF(F10-I10>5,75, IF(F10-I10>0,50,0))) -> 50 | P10: =IF(L10="confirmed bullish", 34, IF(L10="bullish divergence",17, 0))+IF(J10="bullish",33,IF(J10="bearish",0,16.5))+IF(K10="strong",33,IF(K10="weak",0,16.5)) -> 0 | Q10: =0.35*M10+N10*0.35+O10*0.15+P10*0.15 -> 58.25 | R10: =M10*0.2+N10*0.2+O10*0.35+P10*0.25 -> 46.5 | S10: =M10*0.15+N10*0.15+O10*0.25+P10*0.45 -> 34.25 | T10: =0.25*SUM(M10:P10) -> 48.75 | U10: =SUM(Q10:S10)/3 -> 46.333333 | V10: =SUM(Q10:T10)/4 -> 46.9375
A11: =RSI!A11 -> 42020 | B11: =RSI!B11 -> 3.7952 | C11: =RSI!I11 -> 0 | D11: =MACD!E11 -> 0 | E11: =MACD!F11 -> 0 | F11: ='Moving Avg'!D11 -> 3.82304 | G11: ='Moving Avg'!F11 -> 0 | H11: ='Moving Avg'!G11 -> 0 | I11: ='Moving Avg'!H11 -> 0 | J11: =OBV!F11 -> BEARISH | K11: =OBV!G11 -> STRONG | L11: =OBV!H11 -> CONFIRMED BEARISH | M11: =IF(C11<30,100, IF(C11>70, 0, 50)) -> 100 | N11: =IF(E11-D11>0.02, 100, IF(E11-D11<0,0,45)) -> 45 | O11: =IF(F11-I11>10,100,IF(F11-I11>5,75, IF(F11-I11>0,50,0))) -> 50 | P11: =IF(L11="confirmed bullish", 34, IF(L11="bullish divergence",17, 0))+IF(J11="bullish",33,IF(J11="bearish",0,16.5))+IF(K11="strong",33,IF(K11="weak",0,16.5)) -> 33 | Q11: =0.35*M11+N11*0.35+O11*0.15+P11*0.15 -> 63.2 | R11: =M11*0.2+N11*0.2+O11*0.35+P11*0.25 -> 54.75 | S11: =M11*0.15+N11*0.15+O11*0.25+P11*0.45 -> 49.1 | T11: =0.25*SUM(M11:P11) -> 57 | U11: =SUM(Q11:S11)/3 -> 55.683333 | V11: =SUM(Q11:T11)/4 -> 56.0125
A12: =RSI!A12 -> 42023 | B12: =RSI!B12 -> 3.7603 | C12: =RSI!I12 -> 0 | D12: =MACD!E12 -> 0 | E12: =MACD!F12 -> 0 | F12: ='Moving Avg'!D12 -> 3.8091 | G12: ='Moving Avg'!F12 -> 0 | H12: ='Moving Avg'!G12 -> 0 | I12: ='Moving Avg'!H12 -> 0 | J12: =OBV!F12 -> BEARISH | K12: =OBV!G12 -> STRONG | L12: =OBV!H12 -> CONFIRMED BEARISH | M12: =IF(C12<30,100, IF(C12>70, 0, 50)) -> 100 | N12: =IF(E12-D12>0.02, 100, IF(E12-D12<0,0,45)) -> 45 | O12: =IF(F12-I12>10,100,IF(F12-I12>5,75, IF(F12-I12>0,50,0))) -> 50 | P12: =IF(L12="confirmed bullish", 34, IF(L12="bullish divergence",17, 0))+IF(J12="bullish",33,IF(J12="bearish",0,16.5))+IF(K12="strong",33,IF(K12="weak",0,16.5)) -> 33 | Q12: =0.35*M12+N12*0.35+O12*0.15+P12*0.15 -> 63.2 | R12: =M12*0.2+N12*0.2+O12*0.35+P12*0.25 -> 54.75 | S12: =M12*0.15+N12*0.15+O12*0.25+P12*0.45 -> 49.1 | T12: =0.25*SUM(M12:P12) -> 57 | U12: =SUM(Q12:S12)/3 -> 55.683333 | V12: =SUM(Q12:T12)/4 -> 56.0125
A13: =RSI!A13 -> 42024 | B13: =RSI!B13 -> 3.7882 | C13: =RSI!I13 -> 0 | D13: =MACD!E13 -> 0 | E13: =MACD!F13 -> 0 | F13: ='Moving Avg'!D13 -> 3.80074 | G13: ='Moving Avg'!F13 -> 0 | H13: ='Moving Avg'!G13 -> 0 | I13: ='Moving Avg'!H13 -> 0 | J13: =OBV!F13 -> BULLISH | K13: =OBV!G13 -> WEAK | L13: =OBV!H13 -> BULLISH DIVERGENCE | M13: =IF(C13<30,100, IF(C13>70, 0, 50)) -> 100 | N13: =IF(E13-D13>0.02, 100, IF(E13-D13<0,0,45)) -> 45 | O13: =IF(F13-I13>10,100,IF(F13-I13>5,75, IF(F13-I13>0,50,0))) -> 50 | P13: =IF(L13="confirmed bullish", 34, IF(L13="bullish divergence",17, 0))+IF(J13="bullish",33,IF(J13="bearish",0,16.5))+IF(K13="strong",33,IF(K13="weak",0,16.5)) -> 50 | Q13: =0.35*M13+N13*0.35+O13*0.15+P13*0.15 -> 65.75 | R13: =M13*0.2+N13*0.2+O13*0.35+P13*0.25 -> 59 | S13: =M13*0.15+N13*0.15+O13*0.25+P13*0.45 -> 56.75 | T13: =0.25*SUM(M13:P13) -> 61.25 | U13: =SUM(Q13:S13)/3 -> 60.5 | V13: =SUM(Q13:T13)/4 -> 60.6875
... A2693: =RSI!A2693 -> 45930 | B2693: =RSI!B2693 -> 14.9 | C2693: =RSI!I2693 -> 40.757198 | D2693: =MACD!E2693 -> 0.046607723 | E2693: =MACD!F2693 -> 0.068509355 | F2693: ='Moving Avg'!D2693 -> 14.894 | G2693: ='Moving Avg'!F2693 -> 15.0155 | H2693: ='Moving Avg'!G2693 -> 15.194 | I2693: ='Moving Avg'!H2693 -> 12.421432 | J2693: =OBV!F2693 -> BEARISH | K2693: =OBV!G2693 -> WEAK | L2693: =OBV!H2693 -> CONFIRMED BEARISH | M2693: =IF(C2693<30,100, IF(C2693>70, 0, 50)) -> 50 | N2693: =IF(E2693-D2693>0.02, 100, IF(E2693-D2693<0,0,45)) -> 100 | O2693: =IF(F2693-I2693>10,100,IF(F2693-I2693>5,75, IF(F2693-I2693>0,50,0))) -> 50 | P2693: =IF(L2693="confirmed bullish", 34, IF(L2693="bullish divergence",17, 0))+IF(J2693="bullish",33,IF(J2693="bearish",0,16.5))+IF(K2693="strong",33,IF(K2693="weak",0,16.5)) -> 0 | Q2693: =0.35*M2693+N2693*0.35+O2693*0.15+P2693*0.15 -> 60 | R2693: =M2693*0.2+N2693*0.2+O2693*0.35+P2693*0.25 -> 47.5 | S2693: =M2693*0.15+N2693*0.15+O2693*0.25+P2693*0.45 -> 35 | T2693: =0.25*SUM(M2693:P2693) -> 50 | U2693: =SUM(Q2693:S2693)/3 -> 47.5 | V2693: =SUM(Q2693:T2693)/4 -> 48.125
