Workbook

Sheet TITRES_STAT
B2: Titre : DELICE HOLDING, Du : 02/01/2015, Au : 17/09/2025
B4: Date | C4: Cours | D4: Cours Ajusté | E4: Qte. Ech. | F4: CMP J | G4: Volume | H4: Daily Return
B5: 42006 | C5: 15.15 | D5: 5.3341 | E5: 192
B6: 42009 | C6: 15.05 | D6: 5.2989 | E6: 103 | H6: =(D6-D5)/D5 -> -0.0065990514 | J6: Business Days | K6: 252
B7: 42010 | C7: 15.1 | D7: 5.3165 | E7: 10008 | H7: =(D7-D6)/D6 -> 0.0033214441
B8: 42011 | C8: 15 | D8: 5.2812 | E8: 1445 | H8: =(D8-D7)/D7 -> -0.0066397066 | J8: Daily Mean | K8: =AVERAGE(H6:H2696) -> 0.00038990283
B9: 42012 | C9: 15 | D9: 5.2812 | E9: 5000 | H9: =(D9-D8)/D8 -> 0 | J9: Yearly Mean | K9: =K8*K6 -> 0.098255513
B10: 42013 | C10: 15 | D10: 5.2812 | E10: 21586 | H10: =(D10-D9)/D9 -> 0 | J10: Daily Std Deviation | K10: =STDEV(H6:H2696) -> 0.012641335
B11: 42016 | C11: 15.15 | D11: 5.3341 | E11: 7185 | H11: =(D11-D10)/D10 -> 0.010016663 | J11: Yearly Std Deviation | K11: =K10*SQRT(K6) -> 0.20067498
B12: 42017 | C12: 15.15 | D12: 5.3341 | E12: 2903 | H12: =(D12-D11)/D11 -> 0
B13: 42019 | C13: 15.13 | D13: 5.327 | E13: 1549 | H13: =(D13-D12)/D12 -> -0.0013310587
B14: 42020 | C14: 15.9 | D14: 5.5981 | E14: 721149 | H14: =(D14-D13)/D13 -> 0.050891684
B15: 42023 | C15: 16.4 | D15: 5.7742 | E15: 126687 | H15: =(D15-D14)/D14 -> 0.031457102
B16: 42024 | C16: 16.7 | D16: 5.8798 | E16: 32357 | H16: =(D16-D15)/D15 -> 0.018288248
B17: 42025 | C17: 16.6 | D17: 5.8446 | E17: 38860 | H17: =(D17-D16)/D16 -> -0.0059865982
B18: 42026 | C18: 16.7 | D18: 5.8798 | E18: 77566 | H18: =(D18-D17)/D17 -> 0.0060226534
B19: 42027 | C19: 16.9 | D19: 5.9502 | E19: 21727 | H19: =(D19-D18)/D18 -> 0.011973196
B20: 42030 | C20: 17 | D20: 5.9854 | E20: 20460 | H20: =(D20-D19)/D19 -> 0.0059157675
B21: 42031 | C21: 16.9 | D21: 5.9502 | E21: 2046 | H21: =(D21-D20)/D20 -> -0.005880977
B22: 42032 | C22: 16.64 | D22: 5.8587 | E22: 1755 | H22: =(D22-D21)/D21 -> -0.015377634
B23: 42033 | C23: 17 | D23: 5.9854 | E23: 21984 | H23: =(D23-D22)/D22 -> 0.021625958
... B1048: 43528 | C1048: 11 | D1048: 4.3851 | E1048: 360 | H1048: =(D1048-D1047)/D1047 -> 0
B1049: 43529 | C1049: 11 | D1049: 4.3851 | E1049: 0 | F1049: 0 | G1049: 0 | H1049: =(D1049-D1048)/D1048 -> 0
B1050: 43530 | C1050: 11.29 | D1050: 4.5007 | E1050: 89 | F1050: 11.0092 | G1050: 979.8188 | H1050: =(D1050-D1049)/D1049 -> 0.026361999
B1051: 43531 | C1051: 11 | D1051: 4.3851 | E1051: 3793 | F1051: 11 | G1051: 41723 | H1051: =(D1051-D1050)/D1050 -> -0.025684893
B1052: 43532 | C1052: 11 | D1052: 4.3851 | E1052: 500 | F1052: 10.979 | G1052: 5489.5 | H1052: =(D1052-D1051)/D1051 -> 0
B1053: 43535 | C1053: 11 | D1053: 4.3851 | E1053: 0 | F1053: 0 | G1053: 0 | H1053: =(D1053-D1052)/D1052 -> 0
B1054: 43536 | C1054: 11 | D1054: 4.3851 | E1054: 0 | F1054: 0 | G1054: 0 | H1054: =(D1054-D1053)/D1053 -> 0
B1055: 43537 | C1055: 11 | D1055: 4.3851 | E1055: 0 | F1055: 0 | G1055: 0 | H1055: =(D1055-D1054)/D1054 -> 0
B1056: 43538 | C1056: 11.2 | D1056: 4.4649 | E1056: 100829 | F1056: 10.8169 | G1056: 1090657.2 | H1056: =(D1056-D1055)/D1055 -> 0.018197989
B1057: 43539 | C1057: 11.2 | D1057: 4.4649 | E1057: 280 | F1057: 11.2 | G1057: 3136 | H1057: =(D1057-D1056)/D1056 -> 0
B1058: 43542 | C1058: 11 | D1058: 4.3851 | E1058: 810 | F1058: 11 | G1058: 8910 | H1058: =(D1058-D1057)/D1057 -> -0.017872741
B1059: 43543 | C1059: 11.33 | D1059: 4.5167 | E1059: 319 | F1059: 11.3161 | G1059: 3609.8359 | H1059: =(D1059-D1058)/D1058 -> 0.030010718
B1060: 43545 | C1060: 11.6 | D1060: 4.6243 | E1060: 20 | F1060: 11.6 | G1060: 232 | H1060: =(D1060-D1059)/D1059 -> 0.023822702
... B2687: 45917 | C2687: 12.6 | D2687: 12.6 | E2687: 24213 | F2687: 12.483 | G2687: 302250.88 | H2687: =(D2687-D2686)/D2686 -> 0.020242915
B2688: 45918 | C2688: 12.59 | D2688: 12.59 | E2688: 76589 | F2688: 12.514 | G2688: =E2688*F2688 -> 958434.75 | H2688: =(D2688-D2687)/D2687 -> -0.00079365079
B2689: 45919 | C2689: 12.48 | D2689: 12.48 | E2689: 10521 | F2689: 12.437 | G2689: =E2689*F2689 -> 130849.68 | H2689: =(D2689-D2688)/D2688 -> -0.0087370929
B2690: 45922 | C2690: 12.35 | D2690: 12.35 | E2690: 8880 | F2690: 12.441 | G2690: =E2690*F2690 -> 110476.08 | H2690: =(D2690-D2689)/D2689 -> -0.010416667
B2691: 45923 | C2691: 12.2 | D2691: 12.2 | E2691: 20803 | F2691: 12.239 | G2691: =E2691*F2691 -> 254607.92 | H2691: =(D2691-D2690)/D2690 -> -0.012145749
B2692: 45924 | C2692: 12.2 | D2692: 12.2 | E2692: 33507 | F2692: 12.099 | G2692: =E2692*F2692 -> 405401.19 | H2692: =(D2692-D2691)/D2691 -> 0
...

Sheet Moving Avg
A1: =TITRES_STAT!B4 -> Date | B1: =TITRES_STAT!D4 -> Cours Ajusté | C1: Price(T)-Price(T-1) | D1: Simle Moving Avg (5) | E1: Simle Moving Avg (10) | F1: Simle Moving Avg (20) | G1: Simle Moving Avg (50) | H1: Simle Moving Avg (200) | I1: Wheighted Moving Avg | J1: Exp Moving Avg (20) | K1: Exp Moving Avg (50)
A2: =TITRES_STAT!B5 -> 42006 | B2: =TITRES_STAT!D5 -> 5.3341 | J2: Alpha= | K2: Alpha=
A3: =TITRES_STAT!B6 -> 42009 | B3: =TITRES_STAT!D6 -> 5.2989 | C3: =B3-B2 -> -0.0352 | J3: (2/(20+1)) | K3: (2/(50+1))
A4: =TITRES_STAT!B7 -> 42010 | B4: =TITRES_STAT!D7 -> 5.3165 | C4: =B4-B3 -> 0.0176 | J4: =2/21 -> 0.095238095 | K4: =2/51 -> 0.039215686
A5: =TITRES_STAT!B8 -> 42011 | B5: =TITRES_STAT!D8 -> 5.2812 | C5: =B5-B4 -> -0.0353 | D5: =AVERAGE(B1:B5) -> 5.307675
A6: =TITRES_STAT!B9 -> 42012 | B6: =TITRES_STAT!D9 -> 5.2812 | C6: =B6-B5 -> 0 | D6: =AVERAGE(B2:B6) -> 5.30238
A7: =TITRES_STAT!B10 -> 42013 | B7: =TITRES_STAT!D10 -> 5.2812 | C7: =B7-B6 -> 0 | D7: =AVERAGE(B3:B7) -> 5.2918
A8: =TITRES_STAT!B11 -> 42016 | B8: =TITRES_STAT!D11 -> 5.3341 | C8: =B8-B7 -> 0.0529 | D8: =AVERAGE(B4:B8) -> 5.29884
A9: =TITRES_STAT!B12 -> 42017 | B9: =TITRES_STAT!D12 -> 5.3341 | C9: =B9-B8 -> 0 | D9: =AVERAGE(B5:B9) -> 5.30236
A10: =TITRES_STAT!B13 -> 42019 | B10: =TITRES_STAT!D13 -> 5.327 | C10: =B10-B9 -> -0.0071 | D10: =AVERAGE(B6:B10) -> 5.31152
A11: =TITRES_STAT!B14 -> 42020 | B11: =TITRES_STAT!D14 -> 5.5981 | C11: =B11-B10 -> 0.2711 | D11: =AVERAGE(B7:B11) -> 5.3749 | E11: =AVERAGE(B2:B11) -> 5.33864
A12: =TITRES_STAT!B15 -> 42023 | B12: =TITRES_STAT!D15 -> 5.7742 | C12: =B12-B11 -> 0.1761 | D12: =AVERAGE(B8:B12) -> 5.4735 | E12: =AVERAGE(B3:B12) -> 5.38265
A13: =TITRES_STAT!B16 -> 42024 | B13: =TITRES_STAT!D16 -> 5.8798 | C13: =B13-B12 -> 0.1056 | D13: =AVERAGE(B9:B13) -> 5.58264 | E13: =AVERAGE(B4:B13) -> 5.44074
A14: =TITRES_STAT!B17 -> 42025 | B14: =TITRES_STAT!D17 -> 5.8446 | C14: =B14-B13 -> -0.0352 | D14: =AVERAGE(B10:B14) -> 5.68474 | E14: =AVERAGE(B5:B14) -> 5.49355
A15: =TITRES_STAT!B18 -> 42026 | B15: =TITRES_STAT!D18 -> 5.8798 | C15: =B15-B14 -> 0.0352 | D15: =AVERAGE(B11:B15) -> 5.7953 | E15: =AVERAGE(B6:B15) -> 5.55341
A16: =TITRES_STAT!B19 -> 42027 | B16: =TITRES_STAT!D19 -> 5.9502 | C16: =B16-B15 -> 0.0704 | D16: =AVERAGE(B12:B16) -> 5.86572 | E16: =AVERAGE(B7:B16) -> 5.62031
A17: =TITRES_STAT!B20 -> 42030 | B17: =TITRES_STAT!D20 -> 5.9854 | C17: =B17-B16 -> 0.0352 | D17: =AVERAGE(B13:B17) -> 5.90796 | E17: =AVERAGE(B8:B17) -> 5.69073
A18: =TITRES_STAT!B21 -> 42031 | B18: =TITRES_STAT!D21 -> 5.9502 | C18: =B18-B17 -> -0.0352 | D18: =AVERAGE(B14:B18) -> 5.92204 | E18: =AVERAGE(B9:B18) -> 5.75234 | I18: {=SUMPRODUCT(B2:B21, (ROW(B2:B21)-ROW(B2)+1)) / (20*21/2)} -> 5.7736462
A19: =TITRES_STAT!B22 -> 42032 | B19: =TITRES_STAT!D22 -> 5.8587 | C19: =B19-B18 -> -0.0915 | D19: =AVERAGE(B15:B19) -> 5.92486 | E19: =AVERAGE(B10:B19) -> 5.8048 | I19: {=SUMPRODUCT(B3:B22, (ROW(B3:B22)-ROW(B3)+1)) / (20*21/2)} -> 5.8107505
A20: =TITRES_STAT!B23 -> 42033 | B20: =TITRES_STAT!D23 -> 5.9854 | C20: =B20-B19 -> 0.1267 | D20: =AVERAGE(B16:B20) -> 5.94598 | E20: =AVERAGE(B11:B20) -> 5.87064 | F20: =AVERAGE(B1:B20) -> 5.6049842 | I20: {=SUMPRODUCT(B4:B23, (ROW(B4:B23)-ROW(B4)+1)) / (20*21/2)} -> 5.844619 | J20: =F20 -> 5.6049842
A21: =TITRES_STAT!B24 -> 42034 | B21: =TITRES_STAT!D24 -> 5.9854 | C21: =B21-B20 -> 0 | D21: =AVERAGE(B17:B21) -> 5.95302 | E21: =AVERAGE(B12:B21) -> 5.90937 | F21: =AVERAGE(B2:B21) -> 5.624005 | I21: {=SUMPRODUCT(B5:B24, (ROW(B5:B24)-ROW(B5)+1)) / (20*21/2)} -> 5.8723986 | J21: =$J$4*B21+J20*(1-$J$4) -> 5.6412143
A22: =TITRES_STAT!B25 -> 42037 | B22: =TITRES_STAT!D25 -> 6.0136 | C22: =B22-B21 -> 0.0282 | D22: =AVERAGE(B18:B22) -> 5.95866 | E22: =AVERAGE(B13:B22) -> 5.93331 | F22: =AVERAGE(B3:B22) -> 5.65798 | I22: {=SUMPRODUCT(B6:B25, (ROW(B6:B25)-ROW(B6)+1)) / (20*21/2)} -> 5.8969929 | J22: =$J$4*B22+J21*(1-$J$4) -> 5.6766796
A23: =TITRES_STAT!B26 -> 42038 | B23: =TITRES_STAT!D26 -> 6.0136 | C23: =B23-B22 -> 0 | D23: =AVERAGE(B19:B23) -> 5.97134 | E23: =AVERAGE(B14:B23) -> 5.94669 | F23: =AVERAGE(B4:B23) -> 5.693715 | I23: {=SUMPRODUCT(B7:B26, (ROW(B7:B26)-ROW(B7)+1)) / (20*21/2)} -> 5.9182338 | J23: =$J$4*B23+J22*(1-$J$4) -> 5.7087672
A24: =TITRES_STAT!B27 -> 42039 | B24: =TITRES_STAT!D27 -> 5.9854 | C24: =B24-B23 -> -0.0282 | D24: =AVERAGE(B20:B24) -> 5.99668 | E24: =AVERAGE(B15:B24) -> 5.96077 | F24: =AVERAGE(B5:B24) -> 5.72716 | I24: {=SUMPRODUCT(B8:B27, (ROW(B8:B27)-ROW(B8)+1)) / (20*21/2)} -> 5.9351214 | J24: =$J$4*B24+J23*(1-$J$4) -> 5.7351132
A25: =TITRES_STAT!B28 -> 42040 | B25: =TITRES_STAT!D28 -> 5.9854 | C25: =B25-B24 -> 0 | D25: =AVERAGE(B21:B25) -> 5.99668 | E25: =AVERAGE(B16:B25) -> 5.97133 | F25: =AVERAGE(B6:B25) -> 5.76237 | I25: {=SUMPRODUCT(B9:B28, (ROW(B9:B28)-ROW(B9)+1)) / (20*21/2)} -> 5.9493724 | J25: =$J$4*B25+J24*(1-$J$4) -> 5.7589501
A26: =TITRES_STAT!B29 -> 42041 | B26: =TITRES_STAT!D29 -> 5.9854 | C26: =B26-B25 -> 0 | D26: =AVERAGE(B22:B26) -> 5.99668 | E26: =AVERAGE(B17:B26) -> 5.97485 | F26: =AVERAGE(B7:B26) -> 5.79758 | I26: {=SUMPRODUCT(B10:B29, (ROW(B10:B29)-ROW(B10)+1)) / (20*21/2)} -> 5.9591957 | J26: =$J$4*B26+J25*(1-$J$4) -> 5.7805167
A27: =TITRES_STAT!B30 -> 42044 | B27: =TITRES_STAT!D30 -> 5.9749 | C27: =B27-B26 -> -0.0105 | D27: =AVERAGE(B23:B27) -> 5.98894 | E27: =AVERAGE(B18:B27) -> 5.9738 | F27: =AVERAGE(B8:B27) -> 5.832265 | I27: {=SUMPRODUCT(B11:B30, (ROW(B11:B30)-ROW(B11)+1)) / (20*21/2)} -> 5.9656681 | J27: =$J$4*B27+J26*(1-$J$4) -> 5.7990294
A28: =TITRES_STAT!B31 -> 42045 | B28: =TITRES_STAT!D31 -> 5.9819 | C28: =B28-B27 -> 0.007 | D28: =AVERAGE(B24:B28) -> 5.9826 | E28: =AVERAGE(B19:B28) -> 5.97697 | F28: =AVERAGE(B9:B28) -> 5.864655 | I28: {=SUMPRODUCT(B12:B31, (ROW(B12:B31)-ROW(B12)+1)) / (20*21/2)} -> 5.9677629 | J28: =$J$4*B28+J27*(1-$J$4) -> 5.8164457
A29: =TITRES_STAT!B32 -> 42046 | B29: =TITRES_STAT!D32 -> 5.9678 | C29: =B29-B28 -> -0.0141 | D29: =AVERAGE(B25:B29) -> 5.97908 | E29: =AVERAGE(B20:B29) -> 5.98788 | F29: =AVERAGE(B10:B29) -> 5.89634 | I29: {=SUMPRODUCT(B13:B32, (ROW(B13:B32)-ROW(B13)+1)) / (20*21/2)} -> 5.968181 | J29: =$J$4*B29+J28*(1-$J$4) -> 5.8308604
A30: =TITRES_STAT!B33 -> 42047 | B30: =TITRES_STAT!D33 -> 5.9643 | C30: =B30-B29 -> -0.0035 | D30: =AVERAGE(B26:B30) -> 5.97486 | E30: =AVERAGE(B21:B30) -> 5.98577 | F30: =AVERAGE(B11:B30) -> 5.928205 | I30: {=SUMPRODUCT(B14:B33, (ROW(B14:B33)-ROW(B14)+1)) / (20*21/2)} -> 5.967761 | J30: =$J$4*B30+J29*(1-$J$4) -> 5.8435689
A31: =TITRES_STAT!B34 -> 42048 | B31: =TITRES_STAT!D34 -> 5.9502 | C31: =B31-B30 -> -0.0141 | D31: =AVERAGE(B27:B31) -> 5.96782 | E31: =AVERAGE(B22:B31) -> 5.98225 | F31: =AVERAGE(B12:B31) -> 5.94581 | I31: {=SUMPRODUCT(B15:B34, (ROW(B15:B34)-ROW(B15)+1)) / (20*21/2)} -> 5.9670057 | J31: =$J$4*B31+J30*(1-$J$4) -> 5.8537242
A32: =TITRES_STAT!B35 -> 42051 | B32: =TITRES_STAT!D35 -> 5.9502 | C32: =B32-B31 -> 0 | D32: =AVERAGE(B28:B32) -> 5.96288 | E32: =AVERAGE(B23:B32) -> 5.97591 | F32: =AVERAGE(B13:B32) -> 5.95461 | I32: {=SUMPRODUCT(B16:B35, (ROW(B16:B35)-ROW(B16)+1)) / (20*21/2)} -> 5.9654143 | J32: =$J$4*B32+J31*(1-$J$4) -> 5.8629124
... A49: =TITRES_STAT!B52 -> 42074 | B49: =TITRES_STAT!D52 -> 6.1086 | C49: =B49-B48 -> 0 | D49: =AVERAGE(B45:B49) -> 6.11212 | E49: =AVERAGE(B40:B49) -> 6.11212 | F49: =AVERAGE(B30:B49) -> 6.03275 | I49: {=SUMPRODUCT(B33:B52, (ROW(B33:B52)-ROW(B33)+1)) / (20*21/2)} -> 6.1073571 | J49: =$J$4*B49+J48*(1-$J$4) -> 6.0376196
A50: =TITRES_STAT!B53 -> 42075 | B50: =TITRES_STAT!D53 -> 6.1967 | C50: =B50-B49 -> 0.0881 | D50: =AVERAGE(B46:B50) -> 6.12622 | E50: =AVERAGE(B41:B50) -> 6.12269 | F50: =AVERAGE(B31:B50) -> 6.04437 | G50: =AVERAGE(B1:B50) -> 5.8620367 | I50: {=SUMPRODUCT(B34:B53, (ROW(B34:B53)-ROW(B34)+1)) / (20*21/2)} -> 6.1125057 | J50: =$J$4*B50+J49*(1-$J$4) -> 6.0527701 | K50: =G50 -> 5.8620367
A51: =TITRES_STAT!B54 -> 42076 | B51: =TITRES_STAT!D54 -> 6.1579 | C51: =B51-B50 -> -0.0388 | D51: =AVERAGE(B47:B51) -> 6.13608 | E51: =AVERAGE(B42:B51) -> 6.12938 | F51: =AVERAGE(B32:B51) -> 6.054755 | G51: =AVERAGE(B2:B51) -> 5.867954 | I51: {=SUMPRODUCT(B35:B54, (ROW(B35:B54)-ROW(B35)+1)) / (20*21/2)} -> 6.11584 | J51: =$J$4*B51+J50*(1-$J$4) -> 6.0627825 | K51: =$K$4*B51+(1-$K$4)*K50 -> 5.8736392
A52: =TITRES_STAT!B55 -> 42079 | B52: =TITRES_STAT!D55 -> 6.1579 | C52: =B52-B51 -> 0 | D52: =AVERAGE(B48:B52) -> 6.14594 | E52: =AVERAGE(B43:B52) -> 6.13255 | F52: =AVERAGE(B33:B52) -> 6.06514 | G52: =AVERAGE(B3:B52) -> 5.88443 | I52: {=SUMPRODUCT(B36:B55, (ROW(B36:B55)-ROW(B36)+1)) / (20*21/2)} -> 6.11842 | J52: =$J$4*B52+J51*(1-$J$4) -> 6.0718413 | K52: =$K$4*B52+(1-$K$4)*K51 -> 5.8847867
A53: =TITRES_STAT!B56 -> 42080 | B53: =TITRES_STAT!D56 -> 6.1192 | C53: =B53-B52 -> -0.0387 | D53: =AVERAGE(B49:B53) -> 6.14806 | E53: =AVERAGE(B44:B53) -> 6.13185 | F53: =AVERAGE(B34:B53) -> 6.07359 | G53: =AVERAGE(B4:B53) -> 5.900836 | I53: {=SUMPRODUCT(B37:B56, (ROW(B37:B56)-ROW(B37)+1)) / (20*21/2)} -> 6.120229 | J53: =$J$4*B53+J52*(1-$J$4) -> 6.0763517 | K53: =$K$4*B53+(1-$K$4)*K52 -> 5.8939794
A54: =TITRES_STAT!B57 -> 42081 | B54: =TITRES_STAT!D57 -> 6.1086 | C54: =B54-B53 -> -0.0106 | D54: =AVERAGE(B50:B54) -> 6.14806 | E54: =AVERAGE(B45:B54) -> 6.13009 | F54: =AVERAGE(B35:B54) -> 6.08151 | G54: =AVERAGE(B5:B54) -> 5.916678 | I54: {=SUMPRODUCT(B38:B57, (ROW(B38:B57)-ROW(B38)+1)) / (20*21/2)} -> 6.0894029 | J54: =$J$4*B54+J53*(1-$J$4) -> 6.0794229 | K54: =$K$4*B54+(1-$K$4)*K53 -> 5.9023959
A55: =TITRES_STAT!B58 -> 42082 | B55: =TITRES_STAT!D58 -> 6.1086 | C55: =B55-B54 -> 0 | D55: =AVERAGE(B51:B55) -> 6.13044 | E55: =AVERAGE(B46:B55) -> 6.12833 | F55: =AVERAGE(B36:B55) -> 6.089605 | G55: =AVERAGE(B6:B55) -> 5.933226 | I55: {=SUMPRODUCT(B39:B58, (ROW(B39:B58)-ROW(B39)+1)) / (20*21/2)} -> 6.0751338 | J55: =$J$4*B55+J54*(1-$J$4) -> 6.0822017 | K55: =$K$4*B55+(1-$K$4)*K54 -> 5.9104823
A56: =TITRES_STAT!B59 -> 42086 | B56: =TITRES_STAT!D59 -> 6.1086 | C56: =B56-B55 -> 0 | D56: =AVERAGE(B52:B56) -> 6.12058 | E56: =AVERAGE(B47:B56) -> 6.12833 | F56: =AVERAGE(B37:B56) -> 6.097875 | G56: =AVERAGE(B7:B56) -> 5.949774 | I56: {=SUMPRODUCT(B40:B59, (ROW(B40:B59)-ROW(B40)+1)) / (20*21/2)} -> 6.0620086 | J56: =$J$4*B56+J55*(1-$J$4) -> 6.0847158 | K56: =$K$4*B56+(1-$K$4)*K55 -> 5.9182516
...

Sheet RSI
A1: =TITRES_STAT!B4 -> Date | B1: =TITRES_STAT!D4 -> Cours Ajusté | C1: Change | D1: Gain | E1: Loss | F1: Avg Gain | G1: Avg Loss | H1: RS | I1: 14-Day RSI
A2: =TITRES_STAT!B5 -> 42006 | B2: =TITRES_STAT!D5 -> 5.3341
A3: =TITRES_STAT!B6 -> 42009 | B3: =TITRES_STAT!D6 -> 5.2989 | C3: =B3-B2 -> -0.0352 | D3: =IF(C3>0,C3,0) -> 0 | E3: =IF(C3<0,-C3,0) -> 0.0352
A4: =TITRES_STAT!B7 -> 42010 | B4: =TITRES_STAT!D7 -> 5.3165 | C4: =B4-B3 -> 0.0176 | D4: =IF(C4>0,C4,0) -> 0.0176 | E4: =IF(C4<0,-C4,0) -> 0
A5: =TITRES_STAT!B8 -> 42011 | B5: =TITRES_STAT!D8 -> 5.2812 | C5: =B5-B4 -> -0.0353 | D5: =IF(C5>0,C5,0) -> 0 | E5: =IF(C5<0,-C5,0) -> 0.0353
A6: =TITRES_STAT!B9 -> 42012 | B6: =TITRES_STAT!D9 -> 5.2812 | C6: =B6-B5 -> 0 | D6: =IF(C6>0,C6,0) -> 0 | E6: =IF(C6<0,-C6,0) -> 0
A7: =TITRES_STAT!B10 -> 42013 | B7: =TITRES_STAT!D10 -> 5.2812 | C7: =B7-B6 -> 0 | D7: =IF(C7>0,C7,0) -> 0 | E7: =IF(C7<0,-C7,0) -> 0
A8: =TITRES_STAT!B11 -> 42016 | B8: =TITRES_STAT!D11 -> 5.3341 | C8: =B8-B7 -> 0.0529 | D8: =IF(C8>0,C8,0) -> 0.0529 | E8: =IF(C8<0,-C8,0) -> 0
A9: =TITRES_STAT!B12 -> 42017 | B9: =TITRES_STAT!D12 -> 5.3341 | C9: =B9-B8 -> 0 | D9: =IF(C9>0,C9,0) -> 0 | E9: =IF(C9<0,-C9,0) -> 0
A10: =TITRES_STAT!B13 -> 42019 | B10: =TITRES_STAT!D13 -> 5.327 | C10: =B10-B9 -> -0.0071 | D10: =IF(C10>0,C10,0) -> 0 | E10: =IF(C10<0,-C10,0) -> 0.0071
A11: =TITRES_STAT!B14 -> 42020 | B11: =TITRES_STAT!D14 -> 5.5981 | C11: =B11-B10 -> 0.2711 | D11: =IF(C11>0,C11,0) -> 0.2711 | E11: =IF(C11<0,-C11,0) -> 0
A12: =TITRES_STAT!B15 -> 42023 | B12: =TITRES_STAT!D15 -> 5.7742 | C12: =B12-B11 -> 0.1761 | D12: =IF(C12>0,C12,0) -> 0.1761 | E12: =IF(C12<0,-C12,0) -> 0
A13: =TITRES_STAT!B16 -> 42024 | B13: =TITRES_STAT!D16 -> 5.8798 | C13: =B13-B12 -> 0.1056 | D13: =IF(C13>0,C13,0) -> 0.1056 | E13: =IF(C13<0,-C13,0) -> 0
A14: =TITRES_STAT!B17 -> 42025 | B14: =TITRES_STAT!D17 -> 5.8446 | C14: =B14-B13 -> -0.0352 | D14: =IF(C14>0,C14,0) -> 0 | E14: =IF(C14<0,-C14,0) -> 0.0352
A15: =TITRES_STAT!B18 -> 42026 | B15: =TITRES_STAT!D18 -> 5.8798 | C15: =B15-B14 -> 0.0352 | D15: =IF(C15>0,C15,0) -> 0.0352 | E15: =IF(C15<0,-C15,0) -> 0
A16: =TITRES_STAT!B19 -> 42027 | B16: =TITRES_STAT!D19 -> 5.9502 | C16: =B16-B15 -> 0.0704 | D16: =IF(C16>0,C16,0) -> 0.0704 | E16: =IF(C16<0,-C16,0) -> 0 | F16: =(SUM(D3:D16)/14) -> 0.052064286 | G16: =SUM(E3:E16)/14 -> 0.0080571429 | H16: =F16/G16 -> 6.4618794 | I16: =IF(G16=0,100,100-(100/(1+H16))) -> 86.598551
A17: =TITRES_STAT!B20 -> 42030 | B17: =TITRES_STAT!D20 -> 5.9854 | C17: =B17-B16 -> 0.0352 | D17: =IF(C17>0,C17,0) -> 0.0352 | E17: =IF(C17<0,-C17,0) -> 0 | F17: =((F16*13)+D17)/14 -> 0.050859694 | G17: =((G16*13)+E17)/14 -> 0.0074816327 | H17: =F17/G17 -> 6.7979405 | I17: =IF(G17=0,100,100-(100/(1+H17))) -> 87.176101
A18: =TITRES_STAT!B21 -> 42031 | B18: =TITRES_STAT!D21 -> 5.9502 | C18: =B18-B17 -> -0.0352 | D18: =IF(C18>0,C18,0) -> 0 | E18: =IF(C18<0,-C18,0) -> 0.0352 | F18: =((F17*13)+D18)/14 -> 0.047226859 | G18: =((G17*13)+E18)/14 -> 0.009461516 | H18: =F18/G18 -> 4.9914684 | I18: =IF(G18=0,100,100-(100/(1+H18))) -> 83.309601
A19: =TITRES_STAT!B22 -> 42032 | B19: =TITRES_STAT!D22 -> 5.8587 | C19: =B19-B18 -> -0.0915 | D19: =IF(C19>0,C19,0) -> 0 | E19: =IF(C19<0,-C19,0) -> 0.0915 | F19: =((F18*13)+D19)/14 -> 0.043853512 | G19: =((G18*13)+E19)/14 -> 0.015321408 | H19: =F19/G19 -> 2.8622377 | I19: =IF(G19=0,100,100-(100/(1+H19))) -> 74.108274
A20: =TITRES_STAT!B23 -> 42033 | B20: =TITRES_STAT!D23 -> 5.9854 | C20: =B20-B19 -> 0.1267 | D20: =IF(C20>0,C20,0) -> 0.1267 | E20: =IF(C20<0,-C20,0) -> 0 | F20: =((F19*13)+D20)/14 -> 0.049771118 | G20: =((G19*13)+E20)/14 -> 0.014227021 | H20: =F20/G20 -> 3.4983512 | I20: =IF(G20=0,100,100-(100/(1+H20))) -> 77.769633
A21: =TITRES_STAT!B24 -> 42034 | B21: =TITRES_STAT!D24 -> 5.9854 | C21: =B21-B20 -> 0 | D21: =IF(C21>0,C21,0) -> 0 | E21: =IF(C21<0,-C21,0) -> 0 | F21: =((F20*13)+D21)/14 -> 0.046216038 | G21: =((G20*13)+E21)/14 -> 0.013210806 | H21: =F21/G21 -> 3.4983512 | I21: =IF(G21=0,100,100-(100/(1+H21))) -> 77.769633
A22: =TITRES_STAT!B25 -> 42037 | B22: =TITRES_STAT!D25 -> 6.0136 | C22: =B22-B21 -> 0.0282 | D22: =IF(C22>0,C22,0) -> 0.0282 | E22: =IF(C22<0,-C22,0) -> 0 | F22: =((F21*13)+D22)/14 -> 0.044929178 | G22: =((G21*13)+E22)/14 -> 0.012267177 | H22: =F22/G22 -> 3.6625525 | I22: =IF(G22=0,100,100-(100/(1+H22))) -> 78.55252
A23: =TITRES_STAT!B26 -> 42038 | B23: =TITRES_STAT!D26 -> 6.0136 | C23: =B23-B22 -> 0 | D23: =IF(C23>0,C23,0) -> 0 | E23: =IF(C23<0,-C23,0) -> 0 | F23: =((F22*13)+D23)/14 -> 0.041719951 | G23: =((G22*13)+E23)/14 -> 0.01139095 | H23: =F23/G23 -> 3.6625525 | I23: =IF(G23=0,100,100-(100/(1+H23))) -> 78.55252
A24: =TITRES_STAT!B27 -> 42039 | B24: =TITRES_STAT!D27 -> 5.9854 | C24: =B24-B23 -> -0.0282 | D24: =IF(C24>0,C24,0) -> 0 | E24: =IF(C24<0,-C24,0) -> 0.0282 | F24: =((F23*13)+D24)/14 -> 0.038739955 | G24: =((G23*13)+E24)/14 -> 0.012591596 | H24: =F24/G24 -> 3.0766516 | I24: =IF(G24=0,100,100-(100/(1+H24))) -> 75.470065
A25: =TITRES_STAT!B28 -> 42040 | B25: =TITRES_STAT!D28 -> 5.9854 | C25: =B25-B24 -> 0 | D25: =IF(C25>0,C25,0) -> 0 | E25: =IF(C25<0,-C25,0) -> 0 | F25: =((F24*13)+D25)/14 -> 0.035972815 | G25: =((G24*13)+E25)/14 -> 0.011692196 | H25: =F25/G25 -> 3.0766516 | I25: =IF(G25=0,100,100-(100/(1+H25))) -> 75.470065
A26: =TITRES_STAT!B29 -> 42041 | B26: =TITRES_STAT!D29 -> 5.9854 | C26: =B26-B25 -> 0 | D26: =IF(C26>0,C26,0) -> 0 | E26: =IF(C26<0,-C26,0) -> 0 | F26: =((F25*13)+D26)/14 -> 0.033403328 | G26: =((G25*13)+E26)/14 -> 0.01085704 | H26: =F26/G26 -> 3.0766516 | I26: =IF(G26=0,100,100-(100/(1+H26))) -> 75.470065
A27: =TITRES_STAT!B30 -> 42044 | B27: =TITRES_STAT!D30 -> 5.9749 | C27: =B27-B26 -> -0.0105 | D27: =IF(C27>0,C27,0) -> 0 | E27: =IF(C27<0,-C27,0) -> 0.0105 | F27: =((F26*13)+D27)/14 -> 0.031017376 | G27: =((G26*13)+E27)/14 -> 0.010831537 | H27: =F27/G27 -> 2.8636173 | I27: =IF(G27=0,100,100-(100/(1+H27))) -> 74.117519
A28: =TITRES_STAT!B31 -> 42045 | B28: =TITRES_STAT!D31 -> 5.9819 | C28: =B28-B27 -> 0.007 | D28: =IF(C28>0,C28,0) -> 0.007 | E28: =IF(C28<0,-C28,0) -> 0 | F28: =((F27*13)+D28)/14 -> 0.029301849 | G28: =((G27*13)+E28)/14 -> 0.010057856 | H28: =F28/G28 -> 2.9133297 | I28: =IF(G28=0,100,100-(100/(1+H28))) -> 74.446314
... A2693: =TITRES_STAT!B2696 -> 45930 | B2693: =TITRES_STAT!D2696 -> 12.29 | C2693: =B2693-B2692 -> -0.01 | D2693: =IF(C2693>0,C2693,0) -> 0 | E2693: =IF(C2693<0,-C2693,0) -> 0.01 | F2693: =((F2692*13)+D2693)/14 -> 0.05467133 | G2693: =((G2692*13)+E2693)/14 -> 0.05713523 | H2693: =F2693/G2693 -> 0.95687599 | I2693: =IF(G2693=0,100,100-(100/(1+H2693))) -> 48.898141

Sheet MACD
A1: =TITRES_STAT!B4 -> Date | B1: =TITRES_STAT!D4 -> Cours Ajusté | C1: EMA 12-Period | D1: EMA 26-Period | E1: MACD Line | F1: Signal Line | G1: MACD Histogram | H1: Signal
A2: =TITRES_STAT!B5 -> 42006 | B2: =TITRES_STAT!D5 -> 5.3341 | C2: Alpha= | D2: Alpha=
A3: =TITRES_STAT!B6 -> 42009 | B3: =TITRES_STAT!D6 -> 5.2989 | C3: (2/12+1) | D3: (2/26+1)
A4: =TITRES_STAT!B7 -> 42010 | B4: =TITRES_STAT!D7 -> 5.3165 | C4: =2/13 -> 0.15384615 | D4: =2/27 -> 0.074074074
A5: =TITRES_STAT!B8 -> 42011 | B5: =TITRES_STAT!D8 -> 5.2812
A6: =TITRES_STAT!B9 -> 42012 | B6: =TITRES_STAT!D9 -> 5.2812
A7: =TITRES_STAT!B10 -> 42013 | B7: =TITRES_STAT!D10 -> 5.2812
A8: =TITRES_STAT!B11 -> 42016 | B8: =TITRES_STAT!D11 -> 5.3341
A9: =TITRES_STAT!B12 -> 42017 | B9: =TITRES_STAT!D12 -> 5.3341
A10: =TITRES_STAT!B13 -> 42019 | B10: =TITRES_STAT!D13 -> 5.327
A11: =TITRES_STAT!B14 -> 42020 | B11: =TITRES_STAT!D14 -> 5.5981
A12: =TITRES_STAT!B15 -> 42023 | B12: =TITRES_STAT!D15 -> 5.7742
A13: =TITRES_STAT!B16 -> 42024 | B13: =TITRES_STAT!D16 -> 5.8798 | C13: =AVERAGE(B2:B13) -> 5.4200333
A14: =TITRES_STAT!B17 -> 42025 | B14: =TITRES_STAT!D17 -> 5.8446 | C14: =$C$4*B4+C13*(1-$C$4) -> 5.4041051
A15: =TITRES_STAT!B18 -> 42026 | B15: =TITRES_STAT!D18 -> 5.8798 | C15: =$C$4*B5+C14*(1-$C$4) -> 5.3851966
A16: =TITRES_STAT!B19 -> 42027 | B16: =TITRES_STAT!D19 -> 5.9502 | C16: =$C$4*B6+C15*(1-$C$4) -> 5.3691972
A17: =TITRES_STAT!B20 -> 42030 | B17: =TITRES_STAT!D20 -> 5.9854 | C17: =$C$4*B7+C16*(1-$C$4) -> 5.3556591
A18: =TITRES_STAT!B21 -> 42031 | B18: =TITRES_STAT!D21 -> 5.9502 | C18: =$C$4*B8+C17*(1-$C$4) -> 5.3523423
A19: =TITRES_STAT!B22 -> 42032 | B19: =TITRES_STAT!D22 -> 5.8587 | C19: =$C$4*B9+C18*(1-$C$4) -> 5.3495358
A20: =TITRES_STAT!B23 -> 42033 | B20: =TITRES_STAT!D23 -> 5.9854 | C20: =$C$4*B10+C19*(1-$C$4) -> 5.3460688
A21: =TITRES_STAT!B24 -> 42034 | B21: =TITRES_STAT!D24 -> 5.9854 | C21: =$C$4*B11+C20*(1-$C$4) -> 5.3848428
A22: =TITRES_STAT!B25 -> 42037 | B22: =TITRES_STAT!D25 -> 6.0136 | C22: =$C$4*B12+C21*(1-$C$4) -> 5.4447439
A23: =TITRES_STAT!B26 -> 42038 | B23: =TITRES_STAT!D26 -> 6.0136 | C23: =$C$4*B13+C22*(1-$C$4) -> 5.5116756
A24: =TITRES_STAT!B27 -> 42039 | B24: =TITRES_STAT!D27 -> 5.9854 | C24: =$C$4*B14+C23*(1-$C$4) -> 5.5628948
A25: =TITRES_STAT!B28 -> 42040 | B25: =TITRES_STAT!D28 -> 5.9854 | C25: =$C$4*B15+C24*(1-$C$4) -> 5.6116494
A26: =TITRES_STAT!B29 -> 42041 | B26: =TITRES_STAT!D29 -> 5.9854 | C26: =$C$4*B16+C25*(1-$C$4) -> 5.6637341
A27: =TITRES_STAT!B30 -> 42044 | B27: =TITRES_STAT!D30 -> 5.9749 | C27: =$C$4*B17+C26*(1-$C$4) -> 5.7132212 | D27: =AVERAGE(B2:B27) -> 5.7091692 | E27: =C27-D27 -> 0.0040519458
A28: =TITRES_STAT!B31 -> 42045 | B28: =TITRES_STAT!D31 -> 5.9819 | C28: =$C$4*B18+C27*(1-$C$4) -> 5.7496795 | D28: =$D$4*B28+(1-$D$4)*D27 -> 5.7293715 | E28: =C28-D28 -> 0.020307947
A29: =TITRES_STAT!B32 -> 42046 | B29: =TITRES_STAT!D32 -> 5.9678 | C29: =$C$4*B19+C28*(1-$C$4) -> 5.7664518 | D29: =$D$4*B29+(1-$D$4)*D28 -> 5.7470329 | E29: =C29-D29 -> 0.019418969
A30: =TITRES_STAT!B33 -> 42047 | B30: =TITRES_STAT!D33 -> 5.9643 | C30: =$C$4*B20+C29*(1-$C$4) -> 5.8001362 | D30: =$D$4*B30+(1-$D$4)*D29 -> 5.7631267 | E30: =C30-D30 -> 0.037009439
A31: =TITRES_STAT!B34 -> 42048 | B31: =TITRES_STAT!D34 -> 5.9502 | C31: =$C$4*B21+C30*(1-$C$4) -> 5.8286383 | D31: =$D$4*B31+(1-$D$4)*D30 -> 5.776984 | E31: =C31-D31 -> 0.051654287
A32: =TITRES_STAT!B35 -> 42051 | B32: =TITRES_STAT!D35 -> 5.9502 | C32: =$C$4*B22+C31*(1-$C$4) -> 5.857094 | D32: =$D$4*B32+(1-$D$4)*D31 -> 5.7898148 | E32: =C32-D32 -> 0.067279119
A33: =TITRES_STAT!B36 -> 42052 | B33: =TITRES_STAT!D36 -> 5.9502 | C33: =$C$4*B23+C32*(1-$C$4) -> 5.8811718 | D33: =$D$4*B33+(1-$D$4)*D32 -> 5.8016952 | E33: =C33-D33 -> 0.07947659
A34: =TITRES_STAT!B37 -> 42053 | B34: =TITRES_STAT!D37 -> 5.9502 | C34: =$C$4*B24+C33*(1-$C$4) -> 5.8972069 | D34: =$D$4*B34+(1-$D$4)*D33 -> 5.8126956 | E34: =C34-D34 -> 0.084511342
A35: =TITRES_STAT!B38 -> 42054 | B35: =TITRES_STAT!D38 -> 5.9467 | C35: =$C$4*B25+C34*(1-$C$4) -> 5.9107751 | D35: =$D$4*B35+(1-$D$4)*D34 -> 5.8226218 | E35: =C35-D35 -> 0.088153255 | F35: =AVERAGE(E27:E35) -> 0.050206988 | G35: =E35-F35 -> 0.037946267 | H35: =IF(G35<0,"Hold","Sell") -> Sell
A36: =TITRES_STAT!B39 -> 42055 | B36: =TITRES_STAT!D39 -> 5.9432 | C36: =$C$4*B26+C35*(1-$C$4) -> 5.9222558 | D36: =$D$4*B36+(1-$D$4)*D35 -> 5.8315535 | E36: =C36-D36 -> 0.090702296 | F36: =(E36*(2/(10)))+((1-(2/10))*F35) -> 0.05830605 | G36: =E36-F36 -> 0.032396246 | H36: =IF(G36<0,"Hold","Sell") -> Sell
A37: =TITRES_STAT!B40 -> 42058 | B37: =TITRES_STAT!D40 -> 5.9432 | C37: =$C$4*B27+C36*(1-$C$4) -> 5.9303549 | D37: =$D$4*B37+(1-$D$4)*D36 -> 5.8398236 | E37: =C37-D37 -> 0.09053129 | F37: =(E37*(2/(10)))+((1-(2/10))*F36) -> 0.064751098 | G37: =E37-F37 -> 0.025780192 | H37: =IF(G37<0,"Hold","Sell") -> Sell
A38: =TITRES_STAT!B41 -> 42059 | B38: =TITRES_STAT!D41 -> 5.9678 | C38: =$C$4*B28+C37*(1-$C$4) -> 5.9382849 | D38: =$D$4*B38+(1-$D$4)*D37 -> 5.8493034 | E38: =C38-D38 -> 0.088981569 | F38: =(E38*(2/(10)))+((1-(2/10))*F37) -> 0.069597192 | G38: =E38-F38 -> 0.019384377 | H38: =IF(G38<0,"Hold","Sell") -> Sell
A39: =TITRES_STAT!B42 -> 42060 | B39: =TITRES_STAT!D42 -> 5.9678 | C39: =$C$4*B29+C38*(1-$C$4) -> 5.9428257 | D39: =$D$4*B39+(1-$D$4)*D38 -> 5.8580809 | E39: =C39-D39 -> 0.084744819 | F39: =(E39*(2/(10)))+((1-(2/10))*F38) -> 0.072626717 | G39: =E39-F39 -> 0.012118102 | H39: =IF(G39<0,"Hold","Sell") -> Sell
A40: =TITRES_STAT!B43 -> 42061 | B40: =TITRES_STAT!D43 -> 6.091 | C40: =$C$4*B30+C39*(1-$C$4) -> 5.9461295 | D40: =$D$4*B40+(1-$D$4)*D39 -> 5.8753342 | E40: =C40-D40 -> 0.070795288 | F40: =(E40*(2/(10)))+((1-(2/10))*F39) -> 0.072260431 | G40: =E40-F40 -> -0.0014651439 | H40: =IF(G40<0,"Hold","Sell") -> Hold
...

Sheet OBV
A1: =TITRES_STAT!B4 -> Date | B1: =TITRES_STAT!C4 -> Cours | C1: =TITRES_STAT!D4 -> Cours Ajusté | D1: =TITRES_STAT!E4 -> Qte. Ech. | E1: OBV | F1: OBV Trend Signal | G1: OBV Strength | H1: Price-OBV Alignment
A2: =TITRES_STAT!B5 -> 42006 | B2: =TITRES_STAT!C5 -> 15.15 | C2: =TITRES_STAT!D5 -> 5.3341 | D2: =TITRES_STAT!E5 -> 192 | E2: =D2 -> 192
A3: =TITRES_STAT!B6 -> 42009 | B3: =TITRES_STAT!C6 -> 15.05 | C3: =TITRES_STAT!D6 -> 5.2989 | D3: =TITRES_STAT!E6 -> 103 | E3: =IF(B3>B2, E2+D3, IF(B3<B2, E2-D3, E2)) -> 89
A4: =TITRES_STAT!B7 -> 42010 | B4: =TITRES_STAT!C7 -> 15.1 | C4: =TITRES_STAT!D7 -> 5.3165 | D4: =TITRES_STAT!E7 -> 10008 | E4: =IF(B4>B3, E3+D4, IF(B4<B3, E3-D4, E3)) -> 10097
A5: =TITRES_STAT!B8 -> 42011 | B5: =TITRES_STAT!C8 -> 15 | C5: =TITRES_STAT!D8 -> 5.2812 | D5: =TITRES_STAT!E8 -> 1445 | E5: =IF(B5>B4, E4+D5, IF(B5<B4, E4-D5, E4)) -> 8652
A6: =TITRES_STAT!B9 -> 42012 | B6: =TITRES_STAT!C9 -> 15 | C6: =TITRES_STAT!D9 -> 5.2812 | D6: =TITRES_STAT!E9 -> 5000 | E6: =IF(B6>B5, E5+D6, IF(B6<B5, E5-D6, E5)) -> 8652 | H6: =IF(AND(B6>B1, E6>E1), "CONFIRMED BULLISH", IF(AND(B6<B1, E6<E1), "CONFIRMED BEARISH", IF(AND(B6>B1, E6<E1), "BEARISH DIVERGENCE", IF(AND(B6<B1, E6>E1), "BULLISH DIVERGENCE", "NEUTRAL")))) -> CONFIRMED BEARISH
A7: =TITRES_STAT!B10 -> 42013 | B7: =TITRES_STAT!C10 -> 15 | C7: =TITRES_STAT!D10 -> 5.2812 | D7: =TITRES_STAT!E10 -> 21586 | E7: =IF(B7>B6, E6+D7, IF(B7<B6, E6-D7, E6)) -> 8652 | F7: =IF(E7>E2,"BULLISH",IF(E7<E2,"BEARISH","NEUTRAL")) -> BULLISH | G7: =IF((E7-E2)/E2 > 0.02, "STRONG", IF((E7-E2)/E2 < -0.02, "WEAK", "NEUTRAL")) -> STRONG | H7: =IF(AND(B7>B2, E7>E2), "CONFIRMED BULLISH", IF(AND(B7<B2, E7<E2), "CONFIRMED BEARISH", IF(AND(B7>B2, E7<E2), "BEARISH DIVERGENCE", IF(AND(B7<B2, E7>E2), "BULLISH DIVERGENCE", "NEUTRAL")))) -> BULLISH DIVERGENCE
A8: =TITRES_STAT!B11 -> 42016 | B8: =TITRES_STAT!C11 -> 15.15 | C8: =TITRES_STAT!D11 -> 5.3341 | D8: =TITRES_STAT!E11 -> 7185 | E8: =IF(B8>B7, E7+D8, IF(B8<B7, E7-D8, E7)) -> 15837 | F8: =IF(E8>E3,"BULLISH",IF(E8<E3,"BEARISH","NEUTRAL")) -> BULLISH | G8: =IF((E8-E3)/E3 > 0.02, "STRONG", IF((E8-E3)/E3 < -0.02, "WEAK", "NEUTRAL")) -> STRONG | H8: =IF(AND(B8>B3, E8>E3), "CONFIRMED BULLISH", IF(AND(B8<B3, E8<E3), "CONFIRMED BEARISH", IF(AND(B8>B3, E8<E3), "BEARISH DIVERGENCE", IF(AND(B8<B3, E8>E3), "BULLISH DIVERGENCE", "NEUTRAL")))) -> CONFIRMED BULLISH
A9: =TITRES_STAT!B12 -> 42017 | B9: =TITRES_STAT!C12 -> 15.15 | C9: =TITRES_STAT!D12 -> 5.3341 | D9: =TITRES_STAT!E12 -> 2903 | E9: =IF(B9>B8, E8+D9, IF(B9<B8, E8-D9, E8)) -> 15837 | F9: =IF(E9>E4,"BULLISH",IF(E9<E4,"BEARISH","NEUTRAL")) -> BULLISH | G9: =IF((E9-E4)/E4 > 0.02, "STRONG", IF((E9-E4)/E4 < -0.02, "WEAK", "NEUTRAL")) -> STRONG | H9: =IF(AND(B9>B4, E9>E4), "CONFIRMED BULLISH", IF(AND(B9<B4, E9<E4), "CONFIRMED BEARISH", IF(AND(B9>B4, E9<E4), "BEARISH DIVERGENCE", IF(AND(B9<B4, E9>E4), "BULLISH DIVERGENCE", "NEUTRAL")))) -> CONFIRMED BULLISH
A10: =TITRES_STAT!B13 -> 42019 | B10: =TITRES_STAT!C13 -> 15.13 | C10: =TITRES_STAT!D13 -> 5.327 | D10: =TITRES_STAT!E13 -> 1549 | E10: =IF(B10>B9, E9+D10, IF(B10<B9, E9-D10, E9)) -> 14288 | F10: =IF(E10>E5,"BULLISH",IF(E10<E5,"BEARISH","NEUTRAL")) -> BULLISH | G10: =IF((E10-E5)/E5 > 0.02, "STRONG", IF((E10-E5)/E5 < -0.02, "WEAK", "NEUTRAL")) -> STRONG | H10: =IF(AND(B10>B5, E10>E5), "CONFIRMED BULLISH", IF(AND(B10<B5, E10<E5), "CONFIRMED BEARISH", IF(AND(B10>B5, E10<E5), "BEARISH DIVERGENCE", IF(AND(B10<B5, E10>E5), "BULLISH DIVERGENCE", "NEUTRAL")))) -> CONFIRMED BULLISH
A11: =TITRES_STAT!B14 -> 42020 | B11: =TITRES_STAT!C14 -> 15.9 | C11: =TITRES_STAT!D14 -> 5.5981 | D11: =TITRES_STAT!E14 -> 721149 | E11: =IF(B11>B10, E10+D11, IF(B11<B10, E10-D11, E10)) -> 735437 | F11: =IF(E11>E6,"BULLISH",IF(E11<E6,"BEARISH","NEUTRAL")) -> BULLISH | G11: =IF((E11-E6)/E6 > 0.02, "STRONG", IF((E11-E6)/E6 < -0.02, "WEAK", "NEUTRAL")) -> STRONG | H11: =IF(AND(B11>B6, E11>E6), "CONFIRMED BULLISH", IF(AND(B11<B6, E11<E6), "CONFIRMED BEARISH", IF(AND(B11>B6, E11<E6), "BEARISH DIVERGENCE", IF(AND(B11<B6, E11>E6), "BULLISH DIVERGENCE", "NEUTRAL")))) -> CONFIRMED BULLISH
A12: =TITRES_STAT!B15 -> 42023 | B12: =TITRES_STAT!C15 -> 16.4 | C12: =TITRES_STAT!D15 -> 5.7742 | D12: =TITRES_STAT!E15 -> 126687 | E12: =IF(B12>B11, E11+D12, IF(B12<B11, E11-D12, E11)) -> 862124 | F12: =IF(E12>E7,"BULLISH",IF(E12<E7,"BEARISH","NEUTRAL")) -> BULLISH | G12: =IF((E12-E7)/E7 > 0.02, "STRONG", IF((E12-E7)/E7 < -0.02, "WEAK", "NEUTRAL")) -> STRONG | H12: =IF(AND(B12>B7, E12>E7), "CONFIRMED BULLISH", IF(AND(B12<B7, E12<E7), "CONFIRMED BEARISH", IF(AND(B12>B7, E12<E7), "BEARISH DIVERGENCE", IF(AND(B12<B7, E12>E7), "BULLISH DIVERGENCE", "NEUTRAL")))) -> CONFIRMED BULLISH
A13: =TITRES_STAT!B16 -> 42024 | B13: =TITRES_STAT!C16 -> 16.7 | C13: =TITRES_STAT!D16 -> 5.8798 | D13: =TITRES_STAT!E16 -> 32357 | E13: =IF(B13>B12, E12+D13, IF(B13<B12, E12-D13, E12)) -> 894481 | F13: =IF(E13>E8,"BULLISH",IF(E13<E8,"BEARISH","NEUTRAL")) -> BULLISH | G13: =IF((E13-E8)/E8 > 0.02, "STRONG", IF((E13-E8)/E8 < -0.02, "WEAK", "NEUTRAL")) -> STRONG | H13: =IF(AND(B13>B8, E13>E8), "CONFIRMED BULLISH", IF(AND(B13<B8, E13<E8), "CONFIRMED BEARISH", IF(AND(B13>B8, E13<E8), "BEARISH DIVERGENCE", IF(AND(B13<B8, E13>E8), "BULLISH DIVERGENCE", "NEUTRAL")))) -> CONFIRMED BULLISH
A14: =TITRES_STAT!B17 -> 42025 | B14: =TITRES_STAT!C17 -> 16.6 | C14: =TITRES_STAT!D17 -> 5.8446 | D14: =TITRES_STAT!E17 -> 38860 | E14: =IF(B14>B13, E13+D14, IF(B14<B13, E13-D14, E13)) -> 855621 | F14: =IF(E14>E9,"BULLISH",IF(E14<E9,"BEARISH","NEUTRAL")) -> BULLISH | G14: =IF((E14-E9)/E9 > 0.02, "STRONG", IF((E14-E9)/E9 < -0.02, "WEAK", "NEUTRAL")) -> STRONG | H14: =IF(AND(B14>B9, E14>E9), "CONFIRMED BULLISH", IF(AND(B14<B9, E14<E9), "CONFIRMED BEARISH", IF(AND(B14>B9, E14<E9), "BEARISH DIVERGENCE", IF(AND(B14<B9, E14>E9), "BULLISH DIVERGENCE", "NEUTRAL")))) -> CONFIRMED BULLISH
A15: =TITRES_STAT!B18 -> 42026 | B15: =TITRES_STAT!C18 -> 16.7 | C15: =TITRES_STAT!D18 -> 5.8798 | D15: =TITRES_STAT!E18 -> 77566 | E15: =IF(B15>B14, E14+D15, IF(B15<B14, E14-D15, E14)) -> 933187 | F15: =IF(E15>E10,"BULLISH",IF(E15<E10,"BEARISH","NEUTRAL")) -> BULLISH | G15: =IF((E15-E10)/E10 > 0.02, "STRONG", IF((E15-E10)/E10 < -0.02, "WEAK", "NEUTRAL")) -> STRONG | H15: =IF(AND(B15>B10, E15>E10), "CONFIRMED BULLISH", IF(AND(B15<B10, E15<E10), "CONFIRMED BEARISH", IF(AND(B15>B10, E15<E10), "BEARISH DIVERGENCE", IF(AND(B15<B10, E15>E10), "BULLISH DIVERGENCE", "NEUTRAL")))) -> CONFIRMED BULLISH
A16: =TITRES_STAT!B19 -> 42027 | B16: =TITRES_STAT!C19 -> 16.9 | C16: =TITRES_STAT!D19 -> 5.9502 | D16: =TITRES_STAT!E19 -> 21727 | E16: =IF(B16>B15, E15+D16, IF(B16<B15, E15-D16, E15)) -> 954914 | F16: =IF(E16>E11,"BULLISH",IF(E16<E11,"BEARISH","NEUTRAL")) -> BULLISH | G16: =IF((E16-E11)/E11 > 0.02, "STRONG", IF((E16-E11)/E11 < -0.02, "WEAK", "NEUTRAL")) -> STRONG | H16: =IF(AND(B16>B11, E16>E11), "CONFIRMED BULLISH", IF(AND(B16<B11, E16<E11), "CONFIRMED BEARISH", IF(AND(B16>B11, E16<E11), "BEARISH DIVERGENCE", IF(AND(B16<B11, E16>E11), "BULLISH DIVERGENCE", "NEUTRAL")))) -> CONFIRMED BULLISH
A17: =TITRES_STAT!B20 -> 42030 | B17: =TITRES_STAT!C20 -> 17 | C17: =TITRES_STAT!D20 -> 5.9854 | D17: =TITRES_STAT!E20 -> 20460 | E17: =IF(B17>B16, E16+D17, IF(B17<B16, E16-D17, E16)) -> 975374 | F17: =IF(E17>E12,"BULLISH",IF(E17<E12,"BEARISH","NEUTRAL")) -> BULLISH | G17: =IF((E17-E12)/E12 > 0.02, "STRONG", IF((E17-E12)/E12 < -0.02, "WEAK", "NEUTRAL")) -> STRONG | H17: =IF(AND(B17>B12, E17>E12), "CONFIRMED BULLISH", IF(AND(B17<B12, E17<E12), "CONFIRMED BEARISH", IF(AND(B17>B12, E17<E12), "BEARISH DIVERGENCE", IF(AND(B17<B12, E17>E12), "BULLISH DIVERGENCE", "NEUTRAL")))) -> CONFIRMED BULLISH
A18: =TITRES_STAT!B21 -> 42031 | B18: =TITRES_STAT!C21 -> 16.9 | C18: =TITRES_STAT!D21 -> 5.9502 | D18: =TITRES_STAT!E21 -> 2046 | E18: =IF(B18>B17, E17+D18, IF(B18<B17, E17-D18, E17)) -> 973328 | F18: =IF(E18>E13,"BULLISH",IF(E18<E13,"BEARISH","NEUTRAL")) -> BULLISH | G18: =IF((E18-E13)/E13 > 0.02, "STRONG", IF((E18-E13)/E13 < -0.02, "WEAK", "NEUTRAL")) -> STRONG | H18: =IF(AND(B18>B13, E18>E13), "CONFIRMED BULLISH", IF(AND(B18<B13, E18<E13), "CONFIRMED BEARISH", IF(AND(B18>B13, E18<E13), "BEARISH DIVERGENCE", IF(AND(B18<B13, E18>E13), "BULLISH DIVERGENCE", "NEUTRAL")))) -> CONFIRMED BULLISH
... A2693: =TITRES_STAT!B2696 -> 45930 | B2693: =TITRES_STAT!C2696 -> 12.29 | C2693: =TITRES_STAT!D2696 -> 12.29 | D2693: =TITRES_STAT!E2696 -> 3690 | E2693: =IF(B2693>B2692, E2692+D2693, IF(B2693<B2692, E2692-D2693, E2692)) -> 5948928 | F2693: =IF(E2693>E2688,"BULLISH",IF(E2693<E2688,"BEARISH","NEUTRAL")) -> BULLISH | G2693: =IF((E2693-E2688)/E2688 > 0.02, "STRONG", IF((E2693-E2688)/E2688 < -0.02, "WEAK", "NEUTRAL")) -> NEUTRAL | H2693: =IF(AND(B2693>B2688, E2693>E2688), "CONFIRMED BULLISH", IF(AND(B2693<B2688, E2693<E2688), "CONFIRMED BEARISH", IF(AND(B2693>B2688, E2693<E2688), "BEARISH DIVERGENCE", IF(AND(B2693<B2688, E2693>E2688), "BULLISH DIVERGENCE", "NEUTRAL")))) -> CONFIRMED BULLISH

Sheet Overall Overview
A1: =TITRES_STAT!B4 -> Date | B1: =TITRES_STAT!C4 -> Cours | C1: =RSI!I1 -> 14-Day RSI | D1: =MACD!E1 -> MACD Line | E1: =MACD!F1 -> Signal Line | F1: ='Moving Avg'!D1 -> Simle Moving Avg (5) | G1: ='Moving Avg'!E1 -> Simle Moving Avg (10) | H1: ='Moving Avg'!F1 -> Simle Moving Avg (20) | I1: ='Moving Avg'!G1 -> Simle Moving Avg (50) | J1: ='Moving Avg'!H1 -> Simle Moving Avg (200) | K1: =OBV!F1 -> OBV Trend Signal | L1: =OBV!G1 -> OBV Strength | M1: =OBV!H1 -> Price-OBV Alignment
A2: =TITRES_STAT!B5 -> 42006 | B2: =TITRES_STAT!C5 -> 15.15 | C2: =RSI!I2 -> 0 | D2: =MACD!E2 -> 0 | E2: =MACD!F2 -> 0 | F2: ='Moving Avg'!D2 -> 0 | G2: ='Moving Avg'!E2 -> 0 | H2: ='Moving Avg'!F2 -> 0 | I2: ='Moving Avg'!G2 -> 0 | J2: ='Moving Avg'!H2 -> 0 | K2: =OBV!F2 -> 0 | L2: =OBV!G2 -> 0 | M2: =OBV!H2 -> 0
A3: =TITRES_STAT!B6 -> 42009 | B3: =TITRES_STAT!C6 -> 15.05 | C3: =RSI!I3 -> 0 | D3: =MACD!E3 -> 0 | E3: =MACD!F3 -> 0 | F3: ='Moving Avg'!D3 -> 0 | G3: ='Moving Avg'!E3 -> 0 | H3: ='Moving Avg'!F3 -> 0 | I3: ='Moving Avg'!G3 -> 0 | J3: ='Moving Avg'!H3 -> 0 | K3: =OBV!F3 -> 0 | L3: =OBV!G3 -> 0 | M3: =OBV!H3 -> 0
A4: =TITRES_STAT!B7 -> 42010 | B4: =TITRES_STAT!C7 -> 15.1 | C4: =RSI!I4 -> 0 | D4: =MACD!E4 -> 0 | E4: =MACD!F4 -> 0 | F4: ='Moving Avg'!D4 -> 0 | G4: ='Moving Avg'!E4 -> 0 | H4: ='Moving Avg'!F4 -> 0 | I4: ='Moving Avg'!G4 -> 0 | J4: ='Moving Avg'!H4 -> 0 | K4: =OBV!F4 -> 0 | L4: =OBV!G4 -> 0 | M4: =OBV!H4 -> 0
A5: =TITRES_STAT!B8 -> 42011 | B5: =TITRES_STAT!C8 -> 15 | C5: =RSI!I5 -> 0 | D5: =MACD!E5 -> 0 | E5: =MACD!F5 -> 0 | F5: ='Moving Avg'!D5 -> 5.307675 | G5: ='Moving Avg'!E5 -> 0 | H5: ='Moving Avg'!F5 -> 0 | I5: ='Moving Avg'!G5 -> 0 | J5: ='Moving Avg'!H5 -> 0 | K5: =OBV!F5 -> 0 | L5: =OBV!G5 -> 0 | M5: =OBV!H5 -> 0
A6: =TITRES_STAT!B9 -> 42012 | B6: =TITRES_STAT!C9 -> 15 | C6: =RSI!I6 -> 0 | D6: =MACD!E6 -> 0 | E6: =MACD!F6 -> 0 | F6: ='Moving Avg'!D6 -> 5.30238 | G6: ='Moving Avg'!E6 -> 0 | H6: ='Moving Avg'!F6 -> 0 | I6: ='Moving Avg'!G6 -> 0 | J6: ='Moving Avg'!H6 -> 0 | K6: =OBV!F6 -> 0 | L6: =OBV!G6 -> 0 | M6: =OBV!H6 -> CONFIRMED BEARISH
A7: =TITRES_STAT!B10 -> 42013 | B7: =TITRES_STAT!C10 -> 15 | C7: =RSI!I7 -> 0 | D7: =MACD!E7 -> 0 | E7: =MACD!F7 -> 0 | F7: ='Moving Avg'!D7 -> 5.2918 | G7: ='Moving Avg'!E7 -> 0 | H7: ='Moving Avg'!F7 -> 0 | I7: ='Moving Avg'!G7 -> 0 | J7: ='Moving Avg'!H7 -> 0 | K7: =OBV!F7 -> BULLISH | L7: =OBV!G7 -> STRONG | M7: =OBV!H7 -> BULLISH DIVERGENCE
A8: =TITRES_STAT!B11 -> 42016 | B8: =TITRES_STAT!C11 -> 15.15 | C8: =RSI!I8 -> 0 | D8: =MACD!E8 -> 0 | E8: =MACD!F8 -> 0 | F8: ='Moving Avg'!D8 -> 5.29884 | G8: ='Moving Avg'!E8 -> 0 | H8: ='Moving Avg'!F8 -> 0 | I8: ='Moving Avg'!G8 -> 0 | J8: ='Moving Avg'!H8 -> 0 | K8: =OBV!F8 -> BULLISH | L8: =OBV!G8 -> STRONG | M8: =OBV!H8 -> CONFIRMED BULLISH
A9: =TITRES_STAT!B12 -> 42017 | B9: =TITRES_STAT!C12 -> 15.15 | C9: =RSI!I9 -> 0 | D9: =MACD!E9 -> 0 | E9: =MACD!F9 -> 0 | F9: ='Moving Avg'!D9 -> 5.30236 | G9: ='Moving Avg'!E9 -> 0 | H9: ='Moving Avg'!F9 -> 0 | I9: ='Moving Avg'!G9 -> 0 | J9: ='Moving Avg'!H9 -> 0 | K9: =OBV!F9 -> BULLISH | L9: =OBV!G9 -> STRONG | M9: =OBV!H9 -> CONFIRMED BULLISH
A10: =TITRES_STAT!B13 -> 42019 | B10: =TITRES_STAT!C13 -> 15.13 | C10: =RSI!I10 -> 0 | D10: =MACD!E10 -> 0 | E10: =MACD!F10 -> 0 | F10: ='Moving Avg'!D10 -> 5.31152 | G10: ='Moving Avg'!E10 -> 0 | H10: ='Moving Avg'!F10 -> 0 | I10: ='Moving Avg'!G10 -> 0 | J10: ='Moving Avg'!H10 -> 0 | K10: =OBV!F10 -> BULLISH | L10: =OBV!G10 -> STRONG | M10: =OBV!H10 -> CONFIRMED BULLISH
A11: =TITRES_STAT!B14 -> 42020 | B11: =TITRES_STAT!C14 -> 15.9 | C11: =RSI!I11 -> 0 | D11: =MACD!E11 -> 0 | E11: =MACD!F11 -> 0 | F11: ='Moving Avg'!D11 -> 5.3749 | G11: ='Moving Avg'!E11 -> 5.33864 | H11: ='Moving Avg'!F11 -> 0 | I11: ='Moving Avg'!G11 -> 0 | J11: ='Moving Avg'!H11 -> 0 | K11: =OBV!F11 -> BULLISH | L11: =OBV!G11 -> STRONG | M11: =OBV!H11 -> CONFIRMED BULLISH
A12: =TITRES_STAT!B15 -> 42023 | B12: =TITRES_STAT!C15 -> 16.4 | C12: =RSI!I12 -> 0 | D12: =MACD!E12 -> 0 | E12: =MACD!F12 -> 0 | F12: ='Moving Avg'!D12 -> 5.4735 | G12: ='Moving Avg'!E12 -> 5.38265 | H12: ='Moving Avg'!F12 -> 0 | I12: ='Moving Avg'!G12 -> 0 | J12: ='Moving Avg'!H12 -> 0 | K12: =OBV!F12 -> BULLISH | L12: =OBV!G12 -> STRONG | M12: =OBV!H12 -> CONFIRMED BULLISH
... A2693: =TITRES_STAT!B2696 -> 45930 | B2693: =TITRES_STAT!C2696 -> 12.29 | C2693: =RSI!I2693 -> 48.898141 | D2693: =MACD!E2693 -> -0.11353143 | E2693: =MACD!F2693 -> -0.11391311 | F2693: ='Moving Avg'!D2693 -> 12.232 | G2693: ='Moving Avg'!E2693 -> 12.338 | H2693: ='Moving Avg'!F2693 -> 12.2235 | I2693: ='Moving Avg'!G2693 -> 12.7482 | J2693: ='Moving Avg'!H2693 -> 10.549646 | K2693: =OBV!F2693 -> BULLISH | L2693: =OBV!G2693 -> NEUTRAL | M2693: =OBV!H2693 -> CONFIRMED BULLISH

Sheet Scoring System
A1: =TITRES_STAT!B4 -> Date | B1: =TITRES_STAT!C4 -> Cours | C1: =RSI!I1 -> 14-Day RSI | D1: =MACD!E1 -> MACD Line | E1: =MACD!F1 -> Signal Line | F1: ='Moving Avg'!D1 -> Simle Moving Avg (5) | G1: ='Moving Avg'!E1 -> Simle Moving Avg (10) | H1: ='Moving Avg'!F1 -> Simle Moving Avg (20) | I1: ='Moving Avg'!G1 -> Simle Moving Avg (50) | J1: ='Moving Avg'!H1 -> Simle Moving Avg (200) | K1: =OBV!F1 -> OBV Trend Signal | L1: =OBV!G1 -> OBV Strength | M1: =OBV!H1 -> Price-OBV Alignment | N1: RSI Score | O1: MACD Score | P1: SMA Score | Q1: OBV Score | R1: Score Momentum | S1: Score Trend | T1: Volume Score | U1: Score Equal Weights | V1: Overall Score (3C) | W1: Overall Score (4C)
A2: =TITRES_STAT!B5 -> 42006 | B2: =TITRES_STAT!C5 -> 15.15 | C2: =RSI!I2 -> 0 | D2: =MACD!E2 -> 0 | E2: =MACD!F2 -> 0 | F2: ='Moving Avg'!D2 -> 0 | G2: ='Moving Avg'!E2 -> 0 | H2: ='Moving Avg'!F2 -> 0 | I2: ='Moving Avg'!G2 -> 0 | J2: ='Moving Avg'!H2 -> 0 | K2: =OBV!F2 -> 0 | L2: =OBV!G2 -> 0 | M2: =OBV!H2 -> 0 | N2: =IF(D2<30,50, IF(D2>70, 0, 25)) -> 50 | O2: =IF(F2-E2>0.02, 100, IF(F2-E2<0,0,45)) -> 45 | P2: =IF(G2-J2>10,100,IF(G2-J2>5,75, IF(G2-J2>0,50,0))) -> 0 | Q2: =IF(M2="confirmed bullish", 34, IF(M2="bullish divergence",17, 0))+IF(K2="bullish",33,IF(K2="bearish",0,16.5))+IF(L2="strong",33,IF(L2="weak",0,16.5)) -> 33 | R2: =0.35*N2+O2*0.35+P2*0.15+Q2*0.15 -> 38.2 | S2: =N2*0.2+O2*0.2+P2*0.35+Q2*0.25 -> 27.25 | T2: =N2*0.15+O2*0.15+P2*0.25+Q2*0.45 -> 29.1 | U2: =0.25*SUM(N2:Q2) -> 32 | V2: =SUM(R2:T2)/3 -> 31.516667 | W2: =SUM(R2:U2)/4 -> 31.6375 | X2: Momentum_Score = (D2*0.35) + (E2*0.35) + (F2*0.15) + (G2*0.15)
A3: =TITRES_STAT!B6 -> 42009 | B3: =TITRES_STAT!C6 -> 15.05 | C3: =RSI!I3 -> 0 | D3: =MACD!E3 -> 0 | E3: =MACD!F3 -> 0 | F3: ='Moving Avg'!D3 -> 0 | G3: ='Moving Avg'!E3 -> 0 | H3: ='Moving Avg'!F3 -> 0 | I3: ='Moving Avg'!G3 -> 0 | J3: ='Moving Avg'!H3 -> 0 | K3: =OBV!F3 -> 0 | L3: =OBV!G3 -> 0 | M3: =OBV!H3 -> 0 | N3: =IF(D3<30,50, IF(D3>70, 0, 25)) -> 50 | O3: =IF(F3-E3>0.02, 100, IF(F3-E3<0,0,45)) -> 45 | P3: =IF(G3-J3>10,100,IF(G3-J3>5,75, IF(G3-J3>0,50,0))) -> 0 | Q3: =IF(M3="confirmed bullish", 34, IF(M3="bullish divergence",17, 0))+IF(K3="bullish",33,IF(K3="bearish",0,16.5))+IF(L3="strong",33,IF(L3="weak",0,16.5)) -> 33 | R3: =0.35*N3+O3*0.35+P3*0.15+Q3*0.15 -> 38.2 | S3: =N3*0.2+O3*0.2+P3*0.35+Q3*0.25 -> 27.25 | T3: =N3*0.15+O3*0.15+P3*0.25+Q3*0.45 -> 29.1 | U3: =0.25*SUM(N3:Q3) -> 32 | V3: =SUM(R3:T3)/3 -> 31.516667 | W3: =SUM(R3:U3)/4 -> 31.6375 | X3: Trend_Score = (D2*0.20) + (E2*0.20) + (F2*0.35) + (G2*0.25)
A4: =TITRES_STAT!B7 -> 42010 | B4: =TITRES_STAT!C7 -> 15.1 | C4: =RSI!I4 -> 0 | D4: =MACD!E4 -> 0 | E4: =MACD!F4 -> 0 | F4: ='Moving Avg'!D4 -> 0 | G4: ='Moving Avg'!E4 -> 0 | H4: ='Moving Avg'!F4 -> 0 | I4: ='Moving Avg'!G4 -> 0 | J4: ='Moving Avg'!H4 -> 0 | K4: =OBV!F4 -> 0 | L4: =OBV!G4 -> 0 | M4: =OBV!H4 -> 0 | N4: =IF(D4<30,50, IF(D4>70, 0, 25)) -> 50 | O4: =IF(F4-E4>0.02, 100, IF(F4-E4<0,0,45)) -> 45 | P4: =IF(G4-J4>10,100,IF(G4-J4>5,75, IF(G4-J4>0,50,0))) -> 0 | Q4: =IF(M4="confirmed bullish", 34, IF(M4="bullish divergence",17, 0))+IF(K4="bullish",33,IF(K4="bearish",0,16.5))+IF(L4="strong",33,IF(L4="weak",0,16.5)) -> 33 | R4: =0.35*N4+O4*0.35+P4*0.15+Q4*0.15 -> 38.2 | S4: =N4*0.2+O4*0.2+P4*0.35+Q4*0.25 -> 27.25 | T4: =N4*0.15+O4*0.15+P4*0.25+Q4*0.45 -> 29.1 | U4: =0.25*SUM(N4:Q4) -> 32 | V4: =SUM(R4:T4)/3 -> 31.516667 | W4: =SUM(R4:U4)/4 -> 31.6375 | X4: Volume_Score = (D2*0.15) + (E2*0.15) + (F2*0.25) + (G2*0.45)
A5: =TITRES_STAT!B8 -> 42011 | B5: =TITRES_STAT!C8 -> 15 | C5: =RSI!I5 -> 0 | D5: =MACD!E5 -> 0 | E5: =MACD!F5 -> 0 | F5: ='Moving Avg'!D5 -> 5.307675 | G5: ='Moving Avg'!E5 -> 0 | H5: ='Moving Avg'!F5 -> 0 | I5: ='Moving Avg'!G5 -> 0 | J5: ='Moving Avg'!H5 -> 0 | K5: =OBV!F5 -> 0 | L5: =OBV!G5 -> 0 | M5: =OBV!H5 -> 0 | N5: =IF(D5<30,50, IF(D5>70, 0, 25)) -> 50 | O5: =IF(F5-E5>0.02, 100, IF(F5-E5<0,0,45)) -> 100 | P5: =IF(G5-J5>10,100,IF(G5-J5>5,75, IF(G5-J5>0,50,0))) -> 0 | Q5: =IF(M5="confirmed bullish", 34, IF(M5="bullish divergence",17, 0))+IF(K5="bullish",33,IF(K5="bearish",0,16.5))+IF(L5="strong",33,IF(L5="weak",0,16.5)) -> 33 | R5: =0.35*N5+O5*0.35+P5*0.15+Q5*0.15 -> 57.45 | S5: =N5*0.2+O5*0.2+P5*0.35+Q5*0.25 -> 38.25 | T5: =N5*0.15+O5*0.15+P5*0.25+Q5*0.45 -> 37.35 | U5: =0.25*SUM(N5:Q5) -> 45.75 | V5: =SUM(R5:T5)/3 -> 44.35 | W5: =SUM(R5:U5)/4 -> 44.7 | X5: Composite_Score = (Momentum_Score + Trend_Score + Volume_Score) / 3
A6: =TITRES_STAT!B9 -> 42012 | B6: =TITRES_STAT!C9 -> 15 | C6: =RSI!I6 -> 0 | D6: =MACD!E6 -> 0 | E6: =MACD!F6 -> 0 | F6: ='Moving Avg'!D6 -> 5.30238 | G6: ='Moving Avg'!E6 -> 0 | H6: ='Moving Avg'!F6 -> 0 | I6: ='Moving Avg'!G6 -> 0 | J6: ='Moving Avg'!H6 -> 0 | K6: =OBV!F6 -> 0 | L6: =OBV!G6 -> 0 | M6: =OBV!H6 -> CONFIRMED BEARISH | N6: =IF(D6<30,50, IF(D6>70, 0, 25)) -> 50 | O6: =IF(F6-E6>0.02, 100, IF(F6-E6<0,0,45)) -> 100 | P6: =IF(G6-J6>10,100,IF(G6-J6>5,75, IF(G6-J6>0,50,0))) -> 0 | Q6: =IF(M6="confirmed bullish", 34, IF(M6="bullish divergence",17, 0))+IF(K6="bullish",33,IF(K6="bearish",0,16.5))+IF(L6="strong",33,IF(L6="weak",0,16.5)) -> 33 | R6: =0.35*N6+O6*0.35+P6*0.15+Q6*0.15 -> 57.45 | S6: =N6*0.2+O6*0.2+P6*0.35+Q6*0.25 -> 38.25 | T6: =N6*0.15+O6*0.15+P6*0.25+Q6*0.45 -> 37.35 | U6: =0.25*SUM(N6:Q6) -> 45.75 | V6: =SUM(R6:T6)/3 -> 44.35 | W6: =SUM(R6:U6)/4 -> 44.7
A7: =TITRES_STAT!B10 -> 42013 | B7: =TITRES_STAT!C10 -> 15 | C7: =RSI!I7 -> 0 | D7: =MACD!E7 -> 0 | E7: =MACD!F7 -> 0 | F7: ='Moving Avg'!D7 -> 5.2918 | G7: ='Moving Avg'!E7 -> 0 | H7: ='Moving Avg'!F7 -> 0 | I7: ='Moving Avg'!G7 -> 0 | J7: ='Moving Avg'!H7 -> 0 | K7: =OBV!F7 -> BULLISH | L7: =OBV!G7 -> STRONG | M7: =OBV!H7 -> BULLISH DIVERGENCE | N7: =IF(D7<30,50, IF(D7>70, 0, 25)) -> 50 | O7: =IF(F7-E7>0.02, 100, IF(F7-E7<0,0,45)) -> 100 | P7: =IF(G7-J7>10,100,IF(G7-J7>5,75, IF(G7-J7>0,50,0))) -> 0 | Q7: =IF(M7="confirmed bullish", 34, IF(M7="bullish divergence",17, 0))+IF(K7="bullish",33,IF(K7="bearish",0,16.5))+IF(L7="strong",33,IF(L7="weak",0,16.5)) -> 83 | R7: =0.35*N7+O7*0.35+P7*0.15+Q7*0.15 -> 64.95 | S7: =N7*0.2+O7*0.2+P7*0.35+Q7*0.25 -> 50.75 | T7: =N7*0.15+O7*0.15+P7*0.25+Q7*0.45 -> 59.85 | U7: =0.25*SUM(N7:Q7) -> 58.25 | V7: =SUM(R7:T7)/3 -> 58.516667 | W7: =SUM(R7:U7)/4 -> 58.45
A8: =TITRES_STAT!B11 -> 42016 | B8: =TITRES_STAT!C11 -> 15.15 | C8: =RSI!I8 -> 0 | D8: =MACD!E8 -> 0 | E8: =MACD!F8 -> 0 | F8: ='Moving Avg'!D8 -> 5.29884 | G8: ='Moving Avg'!E8 -> 0 | H8: ='Moving Avg'!F8 -> 0 | I8: ='Moving Avg'!G8 -> 0 | J8: ='Moving Avg'!H8 -> 0 | K8: =OBV!F8 -> BULLISH | L8: =OBV!G8 -> STRONG | M8: =OBV!H8 -> CONFIRMED BULLISH | N8: =IF(D8<30,50, IF(D8>70, 0, 25)) -> 50 | O8: =IF(F8-E8>0.02, 100, IF(F8-E8<0,0,45)) -> 100 | P8: =IF(G8-J8>10,100,IF(G8-J8>5,75, IF(G8-J8>0,50,0))) -> 0 | Q8: =IF(M8="confirmed bullish", 34, IF(M8="bullish divergence",17, 0))+IF(K8="bullish",33,IF(K8="bearish",0,16.5))+IF(L8="strong",33,IF(L8="weak",0,16.5)) -> 100 | R8: =0.35*N8+O8*0.35+P8*0.15+Q8*0.15 -> 67.5 | S8: =N8*0.2+O8*0.2+P8*0.35+Q8*0.25 -> 55 | T8: =N8*0.15+O8*0.15+P8*0.25+Q8*0.45 -> 67.5 | U8: =0.25*SUM(N8:Q8) -> 62.5 | V8: =SUM(R8:T8)/3 -> 63.333333 | W8: =SUM(R8:U8)/4 -> 63.125
A9: =TITRES_STAT!B12 -> 42017 | B9: =TITRES_STAT!C12 -> 15.15 | C9: =RSI!I9 -> 0 | D9: =MACD!E9 -> 0 | E9: =MACD!F9 -> 0 | F9: ='Moving Avg'!D9 -> 5.30236 | G9: ='Moving Avg'!E9 -> 0 | H9: ='Moving Avg'!F9 -> 0 | I9: ='Moving Avg'!G9 -> 0 | J9: ='Moving Avg'!H9 -> 0 | K9: =OBV!F9 -> BULLISH | L9: =OBV!G9 -> STRONG | M9: =OBV!H9 -> CONFIRMED BULLISH | N9: =IF(D9<30,50, IF(D9>70, 0, 25)) -> 50 | O9: =IF(F9-E9>0.02, 100, IF(F9-E9<0,0,45)) -> 100 | P9: =IF(G9-J9>10,100,IF(G9-J9>5,75, IF(G9-J9>0,50,0))) -> 0 | Q9: =IF(M9="confirmed bullish", 34, IF(M9="bullish divergence",17, 0))+IF(K9="bullish",33,IF(K9="bearish",0,16.5))+IF(L9="strong",33,IF(L9="weak",0,16.5)) -> 100 | R9: =0.35*N9+O9*0.35+P9*0.15+Q9*0.15 -> 67.5 | S9: =N9*0.2+O9*0.2+P9*0.35+Q9*0.25 -> 55 | T9: =N9*0.15+O9*0.15+P9*0.25+Q9*0.45 -> 67.5 | U9: =0.25*SUM(N9:Q9) -> 62.5 | V9: =SUM(R9:T9)/3 -> 63.333333 | W9: =SUM(R9:U9)/4 -> 63.125
A10: =TITRES_STAT!B13 -> 42019 | B10: =TITRES_STAT!C13 -> 15.13 | C10: =RSI!I10 -> 0 | D10: =MACD!E10 -> 0 | E10: =MACD!F10 -> 0 | F10: ='Moving Avg'!D10 -> 5.31152 | G10: ='Moving Avg'!E10 -> 0 | H10: ='Moving Avg'!F10 -> 0 | I10: ='Moving Avg'!G10 -> 0 | J10: ='Moving Avg'!H10 -> 0 | K10: =OBV!F10 -> BULLISH | L10: =OBV!G10 -> STRONG | M10: =OBV!H10 -> CONFIRMED BULLISH | N10: =IF(D10<30,50, IF(D10>70, 0, 25)) -> 50 | O10: =IF(F10-E10>0.02, 100, IF(F10-E10<0,0,45)) -> 100 | P10: =IF(G10-J10>10,100,IF(G10-J10>5,75, IF(G10-J10>0,50,0))) -> 0 | Q10: =IF(M10="confirmed bullish", 34, IF(M10="bullish divergence",17, 0))+IF(K10="bullish",33,IF(K10="bearish",0,16.5))+IF(L10="strong",33,IF(L10="weak",0,16.5)) -> 100 | R10: =0.35*N10+O10*0.35+P10*0.15+Q10*0.15 -> 67.5 | S10: =N10*0.2+O10*0.2+P10*0.35+Q10*0.25 -> 55 | T10: =N10*0.15+O10*0.15+P10*0.25+Q10*0.45 -> 67.5 | U10: =0.25*SUM(N10:Q10) -> 62.5 | V10: =SUM(R10:T10)/3 -> 63.333333 | W10: =SUM(R10:U10)/4 -> 63.125
A11: =TITRES_STAT!B14 -> 42020 | B11: =TITRES_STAT!C14 -> 15.9 | C11: =RSI!I11 -> 0 | D11: =MACD!E11 -> 0 | E11: =MACD!F11 -> 0 | F11: ='Moving Avg'!D11 -> 5.3749 | G11: ='Moving Avg'!E11 -> 5.33864 | H11: ='Moving Avg'!F11 -> 0 | I11: ='Moving Avg'!G11 -> 0 | J11: ='Moving Avg'!H11 -> 0 | K11: =OBV!F11 -> BULLISH | L11: =OBV!G11 -> STRONG | M11: =OBV!H11 -> CONFIRMED BULLISH | N11: =IF(D11<30,50, IF(D11>70, 0, 25)) -> 50 | O11: =IF(F11-E11>0.02, 100, IF(F11-E11<0,0,45)) -> 100 | P11: =IF(G11-J11>10,100,IF(G11-J11>5,75, IF(G11-J11>0,50,0))) -> 75 | Q11: =IF(M11="confirmed bullish", 34, IF(M11="bullish divergence",17, 0))+IF(K11="bullish",33,IF(K11="bearish",0,16.5))+IF(L11="strong",33,IF(L11="weak",0,16.5)) -> 100 | R11: =0.35*N11+O11*0.35+P11*0.15+Q11*0.15 -> 78.75 | S11: =N11*0.2+O11*0.2+P11*0.35+Q11*0.25 -> 81.25 | T11: =N11*0.15+O11*0.15+P11*0.25+Q11*0.45 -> 86.25 | U11: =0.25*SUM(N11:Q11) -> 81.25 | V11: =SUM(R11:T11)/3 -> 82.083333 | W11: =SUM(R11:U11)/4 -> 81.875
A12: =TITRES_STAT!B15 -> 42023 | B12: =TITRES_STAT!C15 -> 16.4 | C12: =RSI!I12 -> 0 | D12: =MACD!E12 -> 0 | E12: =MACD!F12 -> 0 | F12: ='Moving Avg'!D12 -> 5.4735 | G12: ='Moving Avg'!E12 -> 5.38265 | H12: ='Moving Avg'!F12 -> 0 | I12: ='Moving Avg'!G12 -> 0 | J12: ='Moving Avg'!H12 -> 0 | K12: =OBV!F12 -> BULLISH | L12: =OBV!G12 -> STRONG | M12: =OBV!H12 -> CONFIRMED BULLISH | N12: =IF(D12<30,50, IF(D12>70, 0, 25)) -> 50 | O12: =IF(F12-E12>0.02, 100, IF(F12-E12<0,0,45)) -> 100 | P12: =IF(G12-J12>10,100,IF(G12-J12>5,75, IF(G12-J12>0,50,0))) -> 75 | Q12: =IF(M12="confirmed bullish", 34, IF(M12="bullish divergence",17, 0))+IF(K12="bullish",33,IF(K12="bearish",0,16.5))+IF(L12="strong",33,IF(L12="weak",0,16.5)) -> 100 | R12: =0.35*N12+O12*0.35+P12*0.15+Q12*0.15 -> 78.75 | S12: =N12*0.2+O12*0.2+P12*0.35+Q12*0.25 -> 81.25 | T12: =N12*0.15+O12*0.15+P12*0.25+Q12*0.45 -> 86.25 | U12: =0.25*SUM(N12:Q12) -> 81.25 | V12: =SUM(R12:T12)/3 -> 82.083333 | W12: =SUM(R12:U12)/4 -> 81.875
A13: =TITRES_STAT!B16 -> 42024 | B13: =TITRES_STAT!C16 -> 16.7 | C13: =RSI!I13 -> 0 | D13: =MACD!E13 -> 0 | E13: =MACD!F13 -> 0 | F13: ='Moving Avg'!D13 -> 5.58264 | G13: ='Moving Avg'!E13 -> 5.44074 | H13: ='Moving Avg'!F13 -> 0 | I13: ='Moving Avg'!G13 -> 0 | J13: ='Moving Avg'!H13 -> 0 | K13: =OBV!F13 -> BULLISH | L13: =OBV!G13 -> STRONG | M13: =OBV!H13 -> CONFIRMED BULLISH | N13: =IF(D13<30,50, IF(D13>70, 0, 25)) -> 50 | O13: =IF(F13-E13>0.02, 100, IF(F13-E13<0,0,45)) -> 100 | P13: =IF(G13-J13>10,100,IF(G13-J13>5,75, IF(G13-J13>0,50,0))) -> 75 | Q13: =IF(M13="confirmed bullish", 34, IF(M13="bullish divergence",17, 0))+IF(K13="bullish",33,IF(K13="bearish",0,16.5))+IF(L13="strong",33,IF(L13="weak",0,16.5)) -> 100 | R13: =0.35*N13+O13*0.35+P13*0.15+Q13*0.15 -> 78.75 | S13: =N13*0.2+O13*0.2+P13*0.35+Q13*0.25 -> 81.25 | T13: =N13*0.15+O13*0.15+P13*0.25+Q13*0.45 -> 86.25 | U13: =0.25*SUM(N13:Q13) -> 81.25 | V13: =SUM(R13:T13)/3 -> 82.083333 | W13: =SUM(R13:U13)/4 -> 81.875
A14: =TITRES_STAT!B17 -> 42025 | B14: =TITRES_STAT!C17 -> 16.6 | C14: =RSI!I14 -> 0 | D14: =MACD!E14 -> 0 | E14: =MACD!F14 -> 0 | F14: ='Moving Avg'!D14 -> 5.68474 | G14: ='Moving Avg'!E14 -> 5.49355 | H14: ='Moving Avg'!F14 -> 0 | I14: ='Moving Avg'!G14 -> 0 | J14: ='Moving Avg'!H14 -> 0 | K14: =OBV!F14 -> BULLISH | L14: =OBV!G14 -> STRONG | M14: =OBV!H14 -> CONFIRMED BULLISH | N14: =IF(D14<30,50, IF(D14>70, 0, 25)) -> 50 | O14: =IF(F14-E14>0.02, 100, IF(F14-E14<0,0,45)) -> 100 | P14: =IF(G14-J14>10,100,IF(G14-J14>5,75, IF(G14-J14>0,50,0))) -> 75 | Q14: =IF(M14="confirmed bullish", 34, IF(M14="bullish divergence",17, 0))+IF(K14="bullish",33,IF(K14="bearish",0,16.5))+IF(L14="strong",33,IF(L14="weak",0,16.5)) -> 100 | R14: =0.35*N14+O14*0.35+P14*0.15+Q14*0.15 -> 78.75 | S14: =N14*0.2+O14*0.2+P14*0.35+Q14*0.25 -> 81.25 | T14: =N14*0.15+O14*0.15+P14*0.25+Q14*0.45 -> 86.25 | U14: =0.25*SUM(N14:Q14) -> 81.25 | V14: =SUM(R14:T14)/3 -> 82.083333 | W14: =SUM(R14:U14)/4 -> 81.875
A15: =TITRES_STAT!B18 -> 42026 | B15: =TITRES_STAT!C18 -> 16.7 | C15: =RSI!I15 -> 0 | D15: =MACD!E15 -> 0 | E15: =MACD!F15 -> 0 | F15: ='Moving Avg'!D15 -> 5.7953 | G15: ='Moving Avg'!E15 -> 5.55341 | H15: ='Moving Avg'!F15 -> 0 | I15: ='Moving Avg'!G15 -> 0 | J15: ='Moving Avg'!H15 -> 0 | K15: =OBV!F15 -> BULLISH | L15: =OBV!G15 -> STRONG | M15: =OBV!H15 -> CONFIRMED BULLISH | N15: =IF(D15<30,50, IF(D15>70, 0, 25)) -> 50 | O15: =IF(F15-E15>0.02, 100, IF(F15-E15<0,0,45)) -> 100 | P15: =IF(G15-J15>10,100,IF(G15-J15>5,75, IF(G15-J15>0,50,0))) -> 75 | Q15: =IF(M15="confirmed bullish", 34, IF(M15="bullish divergence",17, 0))+IF(K15="bullish",33,IF(K15="bearish",0,16.5))+IF(L15="strong",33,IF(L15="weak",0,16.5)) -> 100 | R15: =0.35*N15+O15*0.35+P15*0.15+Q15*0.15 -> 78.75 | S15: =N15*0.2+O15*0.2+P15*0.35+Q15*0.25 -> 81.25 | T15: =N15*0.15+O15*0.15+P15*0.25+Q15*0.45 -> 86.25 | U15: =0.25*SUM(N15:Q15) -> 81.25 | V15: =SUM(R15:T15)/3 -> 82.083333 | W15: =SUM(R15:U15)/4 -> 81.875
A16: =TITRES_STAT!B19 -> 42027 | B16: =TITRES_STAT!C19 -> 16.9 | C16: =RSI!I16 -> 86.598551 | D16: =MACD!E16 -> 0 | E16: =MACD!F16 -> 0 | F16: ='Moving Avg'!D16 -> 5.86572 | G16: ='Moving Avg'!E16 -> 5.62031 | H16: ='Moving Avg'!F16 -> 0 | I16: ='Moving Avg'!G16 -> 0 | J16: ='Moving Avg'!H16 -> 0 | K16: =OBV!F16 -> BULLISH | L16: =OBV!G16 -> STRONG | M16: =OBV!H16 -> CONFIRMED BULLISH | N16: =IF(D16<30,50, IF(D16>70, 0, 25)) -> 50 | O16: =IF(F16-E16>0.02, 100, IF(F16-E16<0,0,45)) -> 100 | P16: =IF(G16-J16>10,100,IF(G16-J16>5,75, IF(G16-J16>0,50,0))) -> 75 | Q16: =IF(M16="confirmed bullish", 34, IF(M16="bullish divergence",17, 0))+IF(K16="bullish",33,IF(K16="bearish",0,16.5))+IF(L16="strong",33,IF(L16="weak",0,16.5)) -> 100 | R16: =0.35*N16+O16*0.35+P16*0.15+Q16*0.15 -> 78.75 | S16: =N16*0.2+O16*0.2+P16*0.35+Q16*0.25 -> 81.25 | T16: =N16*0.15+O16*0.15+P16*0.25+Q16*0.45 -> 86.25 | U16: =0.25*SUM(N16:Q16) -> 81.25 | V16: =SUM(R16:T16)/3 -> 82.083333 | W16: =SUM(R16:U16)/4 -> 81.875
A17: =TITRES_STAT!B20 -> 42030 | B17: =TITRES_STAT!C20 -> 17 | C17: =RSI!I17 -> 87.176101 | D17: =MACD!E17 -> 0 | E17: =MACD!F17 -> 0 | F17: ='Moving Avg'!D17 -> 5.90796 | G17: ='Moving Avg'!E17 -> 5.69073 | H17: ='Moving Avg'!F17 -> 0 | I17: ='Moving Avg'!G17 -> 0 | J17: ='Moving Avg'!H17 -> 0 | K17: =OBV!F17 -> BULLISH | L17: =OBV!G17 -> STRONG | M17: =OBV!H17 -> CONFIRMED BULLISH | N17: =IF(D17<30,50, IF(D17>70, 0, 25)) -> 50 | O17: =IF(F17-E17>0.02, 100, IF(F17-E17<0,0,45)) -> 100 | P17: =IF(G17-J17>10,100,IF(G17-J17>5,75, IF(G17-J17>0,50,0))) -> 75 | Q17: =IF(M17="confirmed bullish", 34, IF(M17="bullish divergence",17, 0))+IF(K17="bullish",33,IF(K17="bearish",0,16.5))+IF(L17="strong",33,IF(L17="weak",0,16.5)) -> 100 | R17: =0.35*N17+O17*0.35+P17*0.15+Q17*0.15 -> 78.75 | S17: =N17*0.2+O17*0.2+P17*0.35+Q17*0.25 -> 81.25 | T17: =N17*0.15+O17*0.15+P17*0.25+Q17*0.45 -> 86.25 | U17: =0.25*SUM(N17:Q17) -> 81.25 | V17: =SUM(R17:T17)/3 -> 82.083333 | W17: =SUM(R17:U17)/4 -> 81.875
... A2693: =TITRES_STAT!B2696 -> 45930 | B2693: =TITRES_STAT!C2696 -> 12.29 | C2693: =RSI!I2693 -> 48.898141 | D2693: =MACD!E2693 -> -0.11353143 | E2693: =MACD!F2693 -> -0.11391311 | F2693: ='Moving Avg'!D2693 -> 12.232 | G2693: ='Moving Avg'!E2693 -> 12.338 | H2693: ='Moving Avg'!F2693 -> 12.2235 | I2693: ='Moving Avg'!G2693 -> 12.7482 | J2693: ='Moving Avg'!H2693 -> 10.549646 | K2693: =OBV!F2693 -> BULLISH | L2693: =OBV!G2693 -> NEUTRAL | M2693: =OBV!H2693 -> CONFIRMED BULLISH | N2693: =IF(D2693<30,50, IF(D2693>70, 0, 25)) -> 50 | O2693: =IF(F2693-E2693>0.02, 100, IF(F2693-E2693<0,0,45)) -> 100 | P2693: =IF(G2693-J2693>10,100,IF(G2693-J2693>5,75, IF(G2693-J2693>0,50,0))) -> 50 | Q2693: =IF(M2693="confirmed bullish", 34, IF(M2693="bullish divergence",17, 0))+IF(K2693="bullish",33,IF(K2693="bearish",0,16.5))+IF(L2693="strong",33,IF(L2693="weak",0,16.5)) -> 83.5 | R2693: =0.35*N2693+O2693*0.35+P2693*0.15+Q2693*0.15 -> 72.525 | S2693: =N2693*0.2+O2693*0.2+P2693*0.35+Q2693*0.25 -> 68.375 | T2693: =N2693*0.15+O2693*0.15+P2693*0.25+Q2693*0.45 -> 72.575 | U2693: =0.25*SUM(N2693:Q2693) -> 70.875 | V2693: =SUM(R2693:T2693)/3 -> 71.158333 | W2693: =SUM(R2693:U2693)/4 -> 71.0875
