Workbook

Sheet TITRES_STAT
B2: Titre : ONE TECH HOLDING, Du : 02/01/2015, Au : 17/09/2025
B4: Date | C4: Cours | D4: Cours Ajusté | E4: Qte. Ech. | F4: CMP J | G4: Volume | H4: Daily Return
B5: 42006 | C5: 7.21 | D5: 3.6229 | E5: 1246
B6: 42009 | C6: 7.36 | D6: 3.6983 | E6: 2070 | H6: =(D6-D5)/D5 -> 0.020812057 | J6: Business Days | K6: 252
B7: 42010 | C7: 7.38 | D7: 3.7083 | E7: 2260 | H7: =(D7-D6)/D6 -> 0.0027039451
B8: 42011 | C8: 7.45 | D8: 3.7435 | E8: 6749 | H8: =(D8-D7)/D7 -> 0.0094922202 | J8: Daily Mean | K8: =AVERAGE(H6:H2696) -> 0.0003970757
B9: 42012 | C9: 7.4 | D9: 3.7184 | E9: 3435 | H9: =(D9-D8)/D8 -> -0.0067049553 | J9: Yearly Mean | K9: =K8*K6 -> 0.10006308
B10: 42013 | C10: 7.4 | D10: 3.7184 | E10: 8780 | H10: =(D10-D9)/D9 -> 0 | J10: Daily Std Deviation | K10: =STDEV(H6:H2696) -> 0.011254807
B11: 42016 | C11: 7.4 | D11: 3.7184 | E11: 3318 | H11: =(D11-D10)/D10 -> 0 | J11: Yearly Std Deviation | K11: =K10*SQRT(K6) -> 0.17866452
B12: 42017 | C12: 7.4 | D12: 3.7184 | E12: 0 | H12: =(D12-D11)/D11 -> 0
B13: 42019 | C13: 7.2 | D13: 3.6179 | E13: 7353 | H13: =(D13-D12)/D12 -> -0.027027754
B14: 42020 | C14: 7.39 | D14: 3.7134 | E14: 2615 | H14: =(D14-D13)/D13 -> 0.026396528
B15: 42023 | C15: 7.39 | D15: 3.7134 | E15: 320 | H15: =(D15-D14)/D14 -> 0
B16: 42024 | C16: 7.39 | D16: 3.7134 | E16: 0 | H16: =(D16-D15)/D15 -> 0
B17: 42025 | C17: 7.3 | D17: 3.6681 | E17: 3395 | H17: =(D17-D16)/D16 -> -0.012199063
B18: 42026 | C18: 7.35 | D18: 3.6933 | E18: 1960 | H18: =(D18-D17)/D17 -> 0.0068700417
B19: 42027 | C19: 7.34 | D19: 3.6882 | E19: 9379 | H19: =(D19-D18)/D18 -> -0.0013808789
B20: 42030 | C20: 7.34 | D20: 3.6882 | E20: 320 | H20: =(D20-D19)/D19 -> 0
B21: 42031 | C21: 7.15 | D21: 3.5928 | E21: 1817 | H21: =(D21-D20)/D20 -> -0.025866276
B22: 42032 | C22: 7.15 | D22: 3.5928 | E22: 710 | H22: =(D22-D21)/D21 -> 0
B23: 42033 | C23: 7.2 | D23: 3.6179 | E23: 494 | H23: =(D23-D22)/D22 -> 0.0069861946
... B1048: 43528 | C1048: 15.65 | D1048: 8.7544 | E1048: 3041 | H1048: =(D1048-D1047)/D1047 -> -0.014488185
B1049: 43529 | C1049: 15.68 | D1049: 8.7712 | E1049: 10443 | F1049: 15.6795 | G1049: 163741.02 | H1049: =(D1049-D1048)/D1048 -> 0.001919035
B1050: 43530 | C1050: 15.86 | D1050: 8.8719 | E1050: 5385 | F1050: 15.6321 | G1050: 84178.859 | H1050: =(D1050-D1049)/D1049 -> 0.011480755
B1051: 43531 | C1051: 15.6 | D1051: 8.7264 | E1051: 8409 | F1051: 15.6 | G1051: 131180.4 | H1051: =(D1051-D1050)/D1050 -> -0.016400095
B1052: 43532 | C1052: 15.6 | D1052: 8.7264 | E1052: 4667 | F1052: 15.5163 | G1052: 72414.572 | H1052: =(D1052-D1051)/D1051 -> 0
B1053: 43535 | C1053: 15.5 | D1053: 8.6705 | E1053: 17607 | F1053: 15.595 | G1053: 274581.16 | H1053: =(D1053-D1052)/D1052 -> -0.0064058489
B1054: 43536 | C1054: 15.47 | D1054: 8.6537 | E1054: 22035 | F1054: 15.4178 | G1054: 339731.22 | H1054: =(D1054-D1053)/D1053 -> -0.0019376045
B1055: 43537 | C1055: 15.25 | D1055: 8.5307 | E1055: 1799 | F1055: 15.2531 | G1055: 27440.327 | H1055: =(D1055-D1054)/D1054 -> -0.014213573
B1056: 43538 | C1056: 15.25 | D1056: 8.5307 | E1056: 2084 | F1056: 15.1212 | G1056: 31512.581 | H1056: =(D1056-D1055)/D1055 -> 0
B1057: 43539 | C1057: 15.3 | D1057: 8.5586 | E1057: 2656 | F1057: 15.2276 | G1057: 40444.506 | H1057: =(D1057-D1056)/D1056 -> 0.0032705405
B1058: 43542 | C1058: 15.25 | D1058: 8.5307 | E1058: 2222 | F1058: 15.2944 | G1058: 33984.157 | H1058: =(D1058-D1057)/D1057 -> -0.003259879
B1059: 43543 | C1059: 15.25 | D1059: 8.5307 | E1059: 1010 | F1059: 15.2322 | G1059: 15384.522 | H1059: =(D1059-D1058)/D1058 -> 0
B1060: 43545 | C1060: 15.13 | D1060: 8.4635 | E1060: 2847 | F1060: 15.1635 | G1060: 43170.484 | H1060: =(D1060-D1059)/D1059 -> -0.0078774309
... B2687: 45917 | C2687: 8.65 | D2687: 8.65 | E2687: 23479 | F2687: 8.643 | G2687: 202929 | H2687: =(D2687-D2686)/D2686 -> -0.017045455
B2688: 45918 | C2688: 8.56 | D2688: 8.56 | E2688: 34600 | F2688: 8.537 | G2688: =E2688*F2688 -> 295380.2 | H2688: =(D2688-D2687)/D2687 -> -0.010404624
B2689: 45919 | C2689: 8.63 | D2689: 8.63 | E2689: 27134 | F2689: 8.843 | G2689: =E2689*F2689 -> 239945.96 | H2689: =(D2689-D2688)/D2688 -> 0.0081775701
B2690: 45922 | C2690: 8.66 | D2690: 8.66 | E2690: 22526 | F2690: 8.788 | G2690: =E2690*F2690 -> 197958.49 | H2690: =(D2690-D2689)/D2689 -> 0.0034762457
B2691: 45923 | C2691: 8.79 | D2691: 8.79 | E2691: 34526 | F2691: 8.764 | G2691: =E2691*F2691 -> 302585.86 | H2691: =(D2691-D2690)/D2690 -> 0.015011547
B2692: 45924 | C2692: 8.67 | D2692: 8.67 | E2692: 18460 | F2692: 8.712 | G2692: =E2692*F2692 -> 160823.52 | H2692: =(D2692-D2691)/D2691 -> -0.013651877
...

Sheet Moving Avg
A1: Date | B1: Cours Ajusté | C1: Daily Change | D1: Simple Moving Avg (5) | E1: Simple Moving Avg (10) | F1: Simple Moving Avg (20) | G1: Simple Moving Avg (50) | H1: Simple Moving Avg (200) | I1: Wheighted Moving Avg | J1: Exp Moving Avg (20) | K1: Exp Moving Avg (50)
A2: 42006 | B2: 3.6229 | J2: Alpha= | K2: Alpha=
A3: 42009 | B3: 3.6983 | C3: =B3-B2 -> 0.0754 | J3: (2/(20+1)) | K3: (2/(50+1))
A4: 42010 | B4: 3.7083 | C4: =B4-B3 -> 0.01 | J4: =2/21 -> 0.095238095 | K4: =2/51 -> 0.039215686
A5: 42011 | B5: 3.7435 | C5: =B5-B4 -> 0.0352 | D5: =AVERAGE(B1:B5) -> 3.69325
A6: 42012 | B6: 3.7184 | C6: =B6-B5 -> -0.0251 | D6: =AVERAGE(B2:B6) -> 3.69828
A7: 42013 | B7: 3.7184 | C7: =B7-B6 -> 0 | D7: =AVERAGE(B3:B7) -> 3.71738
A8: 42016 | B8: 3.7184 | C8: =B8-B7 -> 0 | D8: =AVERAGE(B4:B8) -> 3.7214
A9: 42017 | B9: 3.7184 | C9: =B9-B8 -> 0 | D9: =AVERAGE(B5:B9) -> 3.72342
A10: 42019 | B10: 3.6179 | C10: =B10-B9 -> -0.1005 | D10: =AVERAGE(B6:B10) -> 3.6983
A11: 42020 | B11: 3.7134 | C11: =B11-B10 -> 0.0955 | D11: =AVERAGE(B7:B11) -> 3.6973 | E11: =AVERAGE(B2:B11) -> 3.69779
A12: 42023 | B12: 3.7134 | C12: =B12-B11 -> 0 | D12: =AVERAGE(B8:B12) -> 3.6963 | E12: =AVERAGE(B3:B12) -> 3.70684
A13: 42024 | B13: 3.7134 | C13: =B13-B12 -> 0 | D13: =AVERAGE(B9:B13) -> 3.6953 | E13: =AVERAGE(B4:B13) -> 3.70835
A14: 42025 | B14: 3.6681 | C14: =B14-B13 -> -0.0453 | D14: =AVERAGE(B10:B14) -> 3.68524 | E14: =AVERAGE(B5:B14) -> 3.70433
A15: 42026 | B15: 3.6933 | C15: =B15-B14 -> 0.0252 | D15: =AVERAGE(B11:B15) -> 3.70032 | E15: =AVERAGE(B6:B15) -> 3.69931
A16: 42027 | B16: 3.6882 | C16: =B16-B15 -> -0.0051 | D16: =AVERAGE(B12:B16) -> 3.69528 | E16: =AVERAGE(B7:B16) -> 3.69629
A17: 42030 | B17: 3.6882 | C17: =B17-B16 -> 0 | D17: =AVERAGE(B13:B17) -> 3.69024 | E17: =AVERAGE(B8:B17) -> 3.69327
A18: 42031 | B18: 3.5928 | C18: =B18-B17 -> -0.0954 | D18: =AVERAGE(B14:B18) -> 3.66612 | E18: =AVERAGE(B9:B18) -> 3.68071 | I18: {=SUMPRODUCT(B2:B21, (ROW(B2:B21)-ROW(B2)+1)) / (20*21/2)} -> 3.6737233
A19: 42032 | B19: 3.5928 | C19: =B19-B18 -> 0 | D19: =AVERAGE(B15:B19) -> 3.65106 | E19: =AVERAGE(B10:B19) -> 3.66815 | I19: {=SUMPRODUCT(B3:B22, (ROW(B3:B22)-ROW(B3)+1)) / (20*21/2)} -> 3.6818548
A20: 42033 | B20: 3.6179 | C20: =B20-B19 -> 0.0251 | D20: =AVERAGE(B16:B20) -> 3.63598 | E20: =AVERAGE(B11:B20) -> 3.66815 | F20: =AVERAGE(B1:B20) -> 3.6813684 | I20: {=SUMPRODUCT(B4:B23, (ROW(B4:B23)-ROW(B4)+1)) / (20*21/2)} -> 3.679721 | J20: =F20 -> 3.6813684
A21: 42034 | B21: 3.7184 | C21: =B21-B20 -> 0.1005 | D21: =AVERAGE(B17:B21) -> 3.64202 | E21: =AVERAGE(B12:B21) -> 3.66865 | F21: =AVERAGE(B2:B21) -> 3.68322 | I21: {=SUMPRODUCT(B5:B24, (ROW(B5:B24)-ROW(B5)+1)) / (20*21/2)} -> 3.6753405 | J21: =$J$4*B21+J20*(1-$J$4) -> 3.6848952
A22: 42037 | B22: 3.7686 | C22: =B22-B21 -> 0.0502 | D22: =AVERAGE(B18:B22) -> 3.6581 | E22: =AVERAGE(B13:B22) -> 3.67417 | F22: =AVERAGE(B3:B22) -> 3.690505 | I22: {=SUMPRODUCT(B6:B25, (ROW(B6:B25)-ROW(B6)+1)) / (20*21/2)} -> 3.671271 | J22: =$J$4*B22+J21*(1-$J$4) -> 3.6928671
A23: 42038 | B23: 3.6681 | C23: =B23-B22 -> -0.1005 | D23: =AVERAGE(B19:B23) -> 3.67316 | E23: =AVERAGE(B14:B23) -> 3.66964 | F23: =AVERAGE(B4:B23) -> 3.688995 | I23: {=SUMPRODUCT(B7:B26, (ROW(B7:B26)-ROW(B7)+1)) / (20*21/2)} -> 3.6686419 | J23: =$J$4*B23+J22*(1-$J$4) -> 3.6905083
A24: 42039 | B24: 3.643 | C24: =B24-B23 -> -0.0251 | D24: =AVERAGE(B20:B24) -> 3.6832 | E24: =AVERAGE(B15:B24) -> 3.66713 | F24: =AVERAGE(B5:B24) -> 3.68573 | I24: {=SUMPRODUCT(B8:B27, (ROW(B8:B27)-ROW(B8)+1)) / (20*21/2)} -> 3.6725429 | J24: =$J$4*B24+J23*(1-$J$4) -> 3.6859837
A25: 42040 | B25: 3.643 | C25: =B25-B24 -> 0 | D25: =AVERAGE(B21:B25) -> 3.68822 | E25: =AVERAGE(B16:B25) -> 3.6621 | F25: =AVERAGE(B6:B25) -> 3.680705 | I25: {=SUMPRODUCT(B9:B28, (ROW(B9:B28)-ROW(B9)+1)) / (20*21/2)} -> 3.6812248 | J25: =$J$4*B25+J24*(1-$J$4) -> 3.6818901
A26: 42041 | B26: 3.6531 | C26: =B26-B25 -> 0.0101 | D26: =AVERAGE(B22:B26) -> 3.67516 | E26: =AVERAGE(B17:B26) -> 3.65859 | F26: =AVERAGE(B7:B26) -> 3.67744 | I26: {=SUMPRODUCT(B10:B29, (ROW(B10:B29)-ROW(B10)+1)) / (20*21/2)} -> 3.6906295 | J26: =$J$4*B26+J25*(1-$J$4) -> 3.6791481
A27: 42044 | B27: 3.7184 | C27: =B27-B26 -> 0.0653 | D27: =AVERAGE(B23:B27) -> 3.66512 | E27: =AVERAGE(B18:B27) -> 3.66161 | F27: =AVERAGE(B8:B27) -> 3.67744 | I27: {=SUMPRODUCT(B11:B30, (ROW(B11:B30)-ROW(B11)+1)) / (20*21/2)} -> 3.6997471 | J27: =$J$4*B27+J26*(1-$J$4) -> 3.6828864
A28: 42045 | B28: 3.7686 | C28: =B28-B27 -> 0.0502 | D28: =AVERAGE(B24:B28) -> 3.68522 | E28: =AVERAGE(B19:B28) -> 3.67919 | F28: =AVERAGE(B9:B28) -> 3.67995 | I28: {=SUMPRODUCT(B12:B31, (ROW(B12:B31)-ROW(B12)+1)) / (20*21/2)} -> 3.7119276 | J28: =$J$4*B28+J27*(1-$J$4) -> 3.6910496
A29: 42046 | B29: 3.7787 | C29: =B29-B28 -> 0.0101 | D29: =AVERAGE(B25:B29) -> 3.71236 | E29: =AVERAGE(B20:B29) -> 3.69778 | F29: =AVERAGE(B10:B29) -> 3.682965 | I29: {=SUMPRODUCT(B13:B32, (ROW(B13:B32)-ROW(B13)+1)) / (20*21/2)} -> 3.7236057 | J29: =$J$4*B29+J28*(1-$J$4) -> 3.6993973
A30: 42047 | B30: 3.7787 | C30: =B30-B29 -> 0 | D30: =AVERAGE(B26:B30) -> 3.7395 | E30: =AVERAGE(B21:B30) -> 3.71386 | F30: =AVERAGE(B11:B30) -> 3.691005 | I30: {=SUMPRODUCT(B14:B33, (ROW(B14:B33)-ROW(B14)+1)) / (20*21/2)} -> 3.732391 | J30: =$J$4*B30+J29*(1-$J$4) -> 3.7069499
A31: 42048 | B31: 3.8189 | C31: =B31-B30 -> 0.0402 | D31: =AVERAGE(B27:B31) -> 3.77266 | E31: =AVERAGE(B22:B31) -> 3.72391 | F31: =AVERAGE(B12:B31) -> 3.69628 | I31: {=SUMPRODUCT(B15:B34, (ROW(B15:B34)-ROW(B15)+1)) / (20*21/2)} -> 3.7417457 | J31: =$J$4*B31+J30*(1-$J$4) -> 3.7176118
A32: 42051 | B32: 3.8189 | C32: =B32-B31 -> 0 | D32: =AVERAGE(B28:B32) -> 3.79276 | E32: =AVERAGE(B23:B32) -> 3.72894 | F32: =AVERAGE(B13:B32) -> 3.701555 | I32: {=SUMPRODUCT(B16:B35, (ROW(B16:B35)-ROW(B16)+1)) / (20*21/2)} -> 3.7542829 | J32: =$J$4*B32+J31*(1-$J$4) -> 3.7272583
... A49: 42074 | B49: 3.9746 | C49: =B49-B48 -> 0 | D49: =AVERAGE(B45:B49) -> 3.95754 | E49: =AVERAGE(B40:B49) -> 3.92942 | F49: =AVERAGE(B30:B49) -> 3.87868 | I49: {=SUMPRODUCT(B33:B52, (ROW(B33:B52)-ROW(B33)+1)) / (20*21/2)} -> 3.9457648 | J49: =$J$4*B49+J48*(1-$J$4) -> 3.8824759
A50: 42075 | B50: 3.9947 | C50: =B50-B49 -> 0.0201 | D50: =AVERAGE(B46:B50) -> 3.97662 | E50: =AVERAGE(B41:B50) -> 3.94097 | F50: =AVERAGE(B31:B50) -> 3.88948 | G50: =AVERAGE(B1:B50) -> 3.7729429 | I50: {=SUMPRODUCT(B34:B53, (ROW(B34:B53)-ROW(B34)+1)) / (20*21/2)} -> 3.9557857 | J50: =$J$4*B50+J49*(1-$J$4) -> 3.8931639 | K50: =G50 -> 3.7729429
A51: 42076 | B51: 4.0199 | C51: =B51-B50 -> 0.0252 | D51: =AVERAGE(B47:B51) -> 3.98668 | E51: =AVERAGE(B42:B51) -> 3.95605 | F51: =AVERAGE(B32:B51) -> 3.89953 | G51: =AVERAGE(B2:B51) -> 3.777882 | I51: {=SUMPRODUCT(B35:B54, (ROW(B35:B54)-ROW(B35)+1)) / (20*21/2)} -> 3.9537543 | J51: =$J$4*B51+J50*(1-$J$4) -> 3.905234 | K51: =$K$4*B51+(1-$K$4)*K50 -> 3.7826275
A52: 42079 | B52: 4.0199 | C52: =B52-B51 -> 0 | D52: =AVERAGE(B48:B52) -> 3.99674 | E52: =AVERAGE(B43:B52) -> 3.9661 | F52: =AVERAGE(B33:B52) -> 3.90958 | G52: =AVERAGE(B3:B52) -> 3.785822 | I52: {=SUMPRODUCT(B36:B55, (ROW(B36:B55)-ROW(B36)+1)) / (20*21/2)} -> 3.9603538 | J52: =$J$4*B52+J51*(1-$J$4) -> 3.9161546 | K52: =$K$4*B52+(1-$K$4)*K51 -> 3.7919323
A53: 42080 | B53: 4.0148 | C53: =B53-B52 -> -0.0051 | D53: =AVERAGE(B49:B53) -> 4.00478 | E53: =AVERAGE(B44:B53) -> 3.97564 | F53: =AVERAGE(B34:B53) -> 3.92063 | G53: =AVERAGE(B4:B53) -> 3.792152 | I53: {=SUMPRODUCT(B37:B56, (ROW(B37:B56)-ROW(B37)+1)) / (20*21/2)} -> 3.96815 | J53: =$J$4*B53+J52*(1-$J$4) -> 3.9255494 | K53: =$K$4*B53+(1-$K$4)*K52 -> 3.8006722
A54: 42081 | B54: 3.8993 | C54: =B54-B53 -> -0.1155 | D54: =AVERAGE(B50:B54) -> 3.98972 | E54: =AVERAGE(B45:B54) -> 3.97363 | F54: =AVERAGE(B35:B54) -> 3.925405 | G54: =AVERAGE(B5:B54) -> 3.795972 | I54: {=SUMPRODUCT(B38:B57, (ROW(B38:B57)-ROW(B38)+1)) / (20*21/2)} -> 3.9733862 | J54: =$J$4*B54+J53*(1-$J$4) -> 3.9230494 | K54: =$K$4*B54+(1-$K$4)*K53 -> 3.8045399
A55: 42082 | B55: 3.9947 | C55: =B55-B54 -> 0.0954 | D55: =AVERAGE(B51:B55) -> 3.98972 | E55: =AVERAGE(B46:B55) -> 3.98317 | F55: =AVERAGE(B36:B55) -> 3.93294 | G55: =AVERAGE(B6:B55) -> 3.800996 | I55: {=SUMPRODUCT(B39:B58, (ROW(B39:B58)-ROW(B39)+1)) / (20*21/2)} -> 3.9796995 | J55: =$J$4*B55+J54*(1-$J$4) -> 3.9298733 | K55: =$K$4*B55+(1-$K$4)*K54 -> 3.8119972
A56: 42086 | B56: 4.0148 | C56: =B56-B55 -> 0.0201 | D56: =AVERAGE(B52:B56) -> 3.9887 | E56: =AVERAGE(B47:B56) -> 3.98769 | F56: =AVERAGE(B37:B56) -> 3.93972 | G56: =AVERAGE(B7:B56) -> 3.806924 | I56: {=SUMPRODUCT(B40:B59, (ROW(B40:B59)-ROW(B40)+1)) / (20*21/2)} -> 3.9794567 | J56: =$J$4*B56+J55*(1-$J$4) -> 3.9379616 | K56: =$K$4*B56+(1-$K$4)*K55 -> 3.8199502
...

Sheet RSI
A1: Date | B1: Cours Ajusté | C1: Change | D1: Gain | E1: Loss | F1: Avg Gain | G1: Avg Loss | H1: RS | I1: 14-Day RSI
A2: 42006 | B2: 3.6229
A3: 42009 | B3: 3.6983 | C3: =B3-B2 -> 0.0754 | D3: =IF(C3>0,C3,0) -> 0.0754 | E3: =IF(C3<0,-C3,0) -> 0
A4: 42010 | B4: 3.7083 | C4: =B4-B3 -> 0.01 | D4: =IF(C4>0,C4,0) -> 0.01 | E4: =IF(C4<0,-C4,0) -> 0
A5: 42011 | B5: 3.7435 | C5: =B5-B4 -> 0.0352 | D5: =IF(C5>0,C5,0) -> 0.0352 | E5: =IF(C5<0,-C5,0) -> 0
A6: 42012 | B6: 3.7184 | C6: =B6-B5 -> -0.0251 | D6: =IF(C6>0,C6,0) -> 0 | E6: =IF(C6<0,-C6,0) -> 0.0251
A7: 42013 | B7: 3.7184 | C7: =B7-B6 -> 0 | D7: =IF(C7>0,C7,0) -> 0 | E7: =IF(C7<0,-C7,0) -> 0
A8: 42016 | B8: 3.7184 | C8: =B8-B7 -> 0 | D8: =IF(C8>0,C8,0) -> 0 | E8: =IF(C8<0,-C8,0) -> 0
A9: 42017 | B9: 3.7184 | C9: =B9-B8 -> 0 | D9: =IF(C9>0,C9,0) -> 0 | E9: =IF(C9<0,-C9,0) -> 0
A10: 42019 | B10: 3.6179 | C10: =B10-B9 -> -0.1005 | D10: =IF(C10>0,C10,0) -> 0 | E10: =IF(C10<0,-C10,0) -> 0.1005
A11: 42020 | B11: 3.7134 | C11: =B11-B10 -> 0.0955 | D11: =IF(C11>0,C11,0) -> 0.0955 | E11: =IF(C11<0,-C11,0) -> 0
A12: 42023 | B12: 3.7134 | C12: =B12-B11 -> 0 | D12: =IF(C12>0,C12,0) -> 0 | E12: =IF(C12<0,-C12,0) -> 0
A13: 42024 | B13: 3.7134 | C13: =B13-B12 -> 0 | D13: =IF(C13>0,C13,0) -> 0 | E13: =IF(C13<0,-C13,0) -> 0
A14: 42025 | B14: 3.6681 | C14: =B14-B13 -> -0.0453 | D14: =IF(C14>0,C14,0) -> 0 | E14: =IF(C14<0,-C14,0) -> 0.0453
A15: 42026 | B15: 3.6933 | C15: =B15-B14 -> 0.0252 | D15: =IF(C15>0,C15,0) -> 0.0252 | E15: =IF(C15<0,-C15,0) -> 0
A16: 42027 | B16: 3.6882 | C16: =B16-B15 -> -0.0051 | D16: =IF(C16>0,C16,0) -> 0 | E16: =IF(C16<0,-C16,0) -> 0.0051 | F16: =(SUM(D3:D16)/14) -> 0.017235714 | G16: =SUM(E3:E16)/14 -> 0.012571429 | H16: =F16/G16 -> 1.3710227 | I16: =IF(G16=0,100,100-(100/(1+H16))) -> 57.824107
A17: 42030 | B17: 3.6882 | C17: =B17-B16 -> 0 | D17: =IF(C17>0,C17,0) -> 0 | E17: =IF(C17<0,-C17,0) -> 0 | F17: =((F16*13)+D17)/14 -> 0.016004592 | G17: =((G16*13)+E17)/14 -> 0.011673469 | H17: =F17/G17 -> 1.3710227 | I17: =IF(G17=0,100,100-(100/(1+H17))) -> 57.824107
A18: 42031 | B18: 3.5928 | C18: =B18-B17 -> -0.0954 | D18: =IF(C18>0,C18,0) -> 0 | E18: =IF(C18<0,-C18,0) -> 0.0954 | F18: =((F17*13)+D18)/14 -> 0.014861407 | G18: =((G17*13)+E18)/14 -> 0.017653936 | H18: =F18/G18 -> 0.84181832 | I18: =IF(G18=0,100,100-(100/(1+H18))) -> 45.705828
A19: 42032 | B19: 3.5928 | C19: =B19-B18 -> 0 | D19: =IF(C19>0,C19,0) -> 0 | E19: =IF(C19<0,-C19,0) -> 0 | F19: =((F18*13)+D19)/14 -> 0.013799878 | G19: =((G18*13)+E19)/14 -> 0.01639294 | H19: =F19/G19 -> 0.84181832 | I19: =IF(G19=0,100,100-(100/(1+H19))) -> 45.705828
A20: 42033 | B20: 3.6179 | C20: =B20-B19 -> 0.0251 | D20: =IF(C20>0,C20,0) -> 0.0251 | E20: =IF(C20<0,-C20,0) -> 0 | F20: =((F19*13)+D20)/14 -> 0.014607029 | G20: =((G19*13)+E20)/14 -> 0.015222016 | H20: =F20/G20 -> 0.95959886 | I20: =IF(G20=0,100,100-(100/(1+H20))) -> 48.969148
A21: 42034 | B21: 3.7184 | C21: =B21-B20 -> 0.1005 | D21: =IF(C21>0,C21,0) -> 0.1005 | E21: =IF(C21<0,-C21,0) -> 0 | F21: =((F20*13)+D21)/14 -> 0.020742241 | G21: =((G20*13)+E21)/14 -> 0.014134729 | H21: =F21/G21 -> 1.4674665 | I21: =IF(G21=0,100,100-(100/(1+H21))) -> 59.4726
A22: 42037 | B22: 3.7686 | C22: =B22-B21 -> 0.0502 | D22: =IF(C22>0,C22,0) -> 0.0502 | E22: =IF(C22<0,-C22,0) -> 0 | F22: =((F21*13)+D22)/14 -> 0.022846367 | G22: =((G21*13)+E22)/14 -> 0.013125106 | H22: =F22/G22 -> 1.7406616 | I22: =IF(G22=0,100,100-(100/(1+H22))) -> 63.512459
A23: 42038 | B23: 3.6681 | C23: =B23-B22 -> -0.1005 | D23: =IF(C23>0,C23,0) -> 0 | E23: =IF(C23<0,-C23,0) -> 0.1005 | F23: =((F22*13)+D23)/14 -> 0.021214484 | G23: =((G22*13)+E23)/14 -> 0.01936617 | H23: =F23/G23 -> 1.0954404 | I23: =IF(G23=0,100,100-(100/(1+H23))) -> 52.277334
A24: 42039 | B24: 3.643 | C24: =B24-B23 -> -0.0251 | D24: =IF(C24>0,C24,0) -> 0 | E24: =IF(C24<0,-C24,0) -> 0.0251 | F24: =((F23*13)+D24)/14 -> 0.019699163 | G24: =((G23*13)+E24)/14 -> 0.019775729 | H24: =F24/G24 -> 0.99612831 | I24: =IF(G24=0,100,100-(100/(1+H24))) -> 49.90302
A25: 42040 | B25: 3.643 | C25: =B25-B24 -> 0 | D25: =IF(C25>0,C25,0) -> 0 | E25: =IF(C25<0,-C25,0) -> 0 | F25: =((F24*13)+D25)/14 -> 0.01829208 | G25: =((G24*13)+E25)/14 -> 0.018363177 | H25: =F25/G25 -> 0.99612831 | I25: =IF(G25=0,100,100-(100/(1+H25))) -> 49.90302
A26: 42041 | B26: 3.6531 | C26: =B26-B25 -> 0.0101 | D26: =IF(C26>0,C26,0) -> 0.0101 | E26: =IF(C26<0,-C26,0) -> 0 | F26: =((F25*13)+D26)/14 -> 0.017706932 | G26: =((G25*13)+E26)/14 -> 0.017051521 | H26: =F26/G26 -> 1.0384371 | I26: =IF(G26=0,100,100-(100/(1+H26))) -> 50.942807
A27: 42044 | B27: 3.7184 | C27: =B27-B26 -> 0.0653 | D27: =IF(C27>0,C27,0) -> 0.0653 | E27: =IF(C27<0,-C27,0) -> 0 | F27: =((F26*13)+D27)/14 -> 0.021106437 | G27: =((G26*13)+E27)/14 -> 0.015833556 | H27: =F27/G27 -> 1.3330194 | I27: =IF(G27=0,100,100-(100/(1+H27))) -> 57.13709
A28: 42045 | B28: 3.7686 | C28: =B28-B27 -> 0.0502 | D28: =IF(C28>0,C28,0) -> 0.0502 | E28: =IF(C28<0,-C28,0) -> 0 | F28: =((F27*13)+D28)/14 -> 0.023184548 | G28: =((G27*13)+E28)/14 -> 0.014702587 | H28: =F28/G28 -> 1.5769026 | I28: =IF(G28=0,100,100-(100/(1+H28))) -> 61.193722
... A2693: 45930 | B2693: 8.9 | C2693: =B2693-B2692 -> 0.2 | D2693: =IF(C2693>0,C2693,0) -> 0.2 | E2693: =IF(C2693<0,-C2693,0) -> 0 | F2693: =((F2692*13)+D2693)/14 -> 0.042282098 | G2693: =((G2692*13)+E2693)/14 -> 0.036831939 | H2693: =F2693/G2693 -> 1.1479737 | I2693: =IF(G2693=0,100,100-(100/(1+H2693))) -> 53.444496

Sheet MACD
A1: Date | B1: Cours Ajusté | C1: EMA 12-Period | D1: EMA 26-Period | E1: MACD Line | F1: Signal Line | G1: MACD Histogram | H1: Signal
A2: 42006 | B2: 3.6229 | C2: Alpha= | D2: Alpha=
A3: 42009 | B3: 3.6983 | C3: (2/12+1) | D3: (2/26+1)
A4: 42010 | B4: 3.7083 | C4: =2/13 -> 0.15384615 | D4: =2/27 -> 0.074074074
A5: 42011 | B5: 3.7435
A6: 42012 | B6: 3.7184
A7: 42013 | B7: 3.7184
A8: 42016 | B8: 3.7184
A9: 42017 | B9: 3.7184
A10: 42019 | B10: 3.6179
A11: 42020 | B11: 3.7134
A12: 42023 | B12: 3.7134
A13: 42024 | B13: 3.7134 | C13: =AVERAGE(B2:B13) -> 3.7003917
A14: 42025 | B14: 3.6681 | C14: =$C$4*B4+C13*(1-$C$4) -> 3.7016083
A15: 42026 | B15: 3.6933 | C15: =$C$4*B5+C14*(1-$C$4) -> 3.7080532
A16: 42027 | B16: 3.6882 | C16: =$C$4*B6+C15*(1-$C$4) -> 3.709645
A17: 42030 | B17: 3.6882 | C17: =$C$4*B7+C16*(1-$C$4) -> 3.7109919
A18: 42031 | B18: 3.5928 | C18: =$C$4*B8+C17*(1-$C$4) -> 3.7121316
A19: 42032 | B19: 3.5928 | C19: =$C$4*B9+C18*(1-$C$4) -> 3.713096
A20: 42033 | B20: 3.6179 | C20: =$C$4*B10+C19*(1-$C$4) -> 3.6984505
A21: 42034 | B21: 3.7184 | C21: =$C$4*B11+C20*(1-$C$4) -> 3.7007504
A22: 42037 | B22: 3.7686 | C22: =$C$4*B12+C21*(1-$C$4) -> 3.7026965
A23: 42038 | B23: 3.6681 | C23: =$C$4*B13+C22*(1-$C$4) -> 3.7043432
A24: 42039 | B24: 3.643 | C24: =$C$4*B14+C23*(1-$C$4) -> 3.6987673
A25: 42040 | B25: 3.643 | C25: =$C$4*B15+C24*(1-$C$4) -> 3.6979262
A26: 42041 | B26: 3.6531 | C26: =$C$4*B16+C25*(1-$C$4) -> 3.6964298
A27: 42044 | B27: 3.7184 | C27: =$C$4*B17+C26*(1-$C$4) -> 3.6951637 | D27: =AVERAGE(B2:B27) -> 3.6830231 | E27: =C27-D27 -> 0.01214064
A28: 42045 | B28: 3.7686 | C28: =$C$4*B18+C27*(1-$C$4) -> 3.6794155 | D28: =$D$4*B28+(1-$D$4)*D27 -> 3.6893621 | E28: =C28-D28 -> -0.0099466556
A29: 42046 | B29: 3.7787 | C29: =$C$4*B19+C28*(1-$C$4) -> 3.66609 | D29: =$D$4*B29+(1-$D$4)*D28 -> 3.6959797 | E29: =C29-D29 -> -0.029889731
A30: 42047 | B30: 3.7787 | C30: =$C$4*B20+C29*(1-$C$4) -> 3.6586762 | D30: =$D$4*B30+(1-$D$4)*D29 -> 3.7021072 | E30: =C30-D30 -> -0.043431005
A31: 42048 | B31: 3.8189 | C31: =$C$4*B21+C30*(1-$C$4) -> 3.6678644 | D31: =$D$4*B31+(1-$D$4)*D30 -> 3.7107585 | E31: =C31-D31 -> -0.042894042
A32: 42051 | B32: 3.8189 | C32: =$C$4*B22+C31*(1-$C$4) -> 3.6833622 | D32: =$D$4*B32+(1-$D$4)*D31 -> 3.718769 | E32: =C32-D32 -> -0.035406746
A33: 42052 | B33: 3.7938 | C33: =$C$4*B23+C32*(1-$C$4) -> 3.6810142 | D33: =$D$4*B33+(1-$D$4)*D32 -> 3.7243268 | E33: =C33-D33 -> -0.043312634
A34: 42053 | B34: 3.8038 | C34: =$C$4*B24+C33*(1-$C$4) -> 3.6751658 | D34: =$D$4*B34+(1-$D$4)*D33 -> 3.7302137 | E34: =C34-D34 -> -0.055047872
A35: 42054 | B35: 3.844 | C35: =$C$4*B25+C34*(1-$C$4) -> 3.6702173 | D35: =$D$4*B35+(1-$D$4)*D34 -> 3.7386423 | E35: =C35-D35 -> -0.068425078 | F35: =AVERAGE(E27:E35) -> -0.035134792 | G35: =E35-F35 -> -0.033290286 | H35: =IF(G35<0,"Hold","Sell") -> Hold
A36: 42055 | B36: 3.8792 | C36: =$C$4*B26+C35*(1-$C$4) -> 3.6675838 | D36: =$D$4*B36+(1-$D$4)*D35 -> 3.749054 | E36: =C36-D36 -> -0.081470181 | F36: =(E36*(2/(10)))+((1-(2/10))*F35) -> -0.044401869 | G36: =E36-F36 -> -0.037068311 | H36: =IF(G36<0,"Hold","Sell") -> Hold
A37: 42058 | B37: 3.8189 | C37: =$C$4*B27+C36*(1-$C$4) -> 3.6754017 | D37: =$D$4*B37+(1-$D$4)*D36 -> 3.7542278 | E37: =C37-D37 -> -0.078826085 | F37: =(E37*(2/(10)))+((1-(2/10))*F36) -> -0.051286713 | G37: =E37-F37 -> -0.027539373 | H37: =IF(G37<0,"Hold","Sell") -> Hold
A38: 42059 | B38: 3.844 | C38: =$C$4*B28+C37*(1-$C$4) -> 3.6897399 | D38: =$D$4*B38+(1-$D$4)*D37 -> 3.7608776 | E38: =C38-D38 -> -0.071137679 | F38: =(E38*(2/(10)))+((1-(2/10))*F37) -> -0.055256906 | G38: =E38-F38 -> -0.015880773 | H38: =IF(G38<0,"Hold","Sell") -> Hold
A39: 42060 | B39: 3.8792 | C39: =$C$4*B29+C38*(1-$C$4) -> 3.7034261 | D39: =$D$4*B39+(1-$D$4)*D38 -> 3.7696422 | E39: =C39-D39 -> -0.066216134 | F39: =(E39*(2/(10)))+((1-(2/10))*F38) -> -0.057448752 | G39: =E39-F39 -> -0.0087673825 | H39: =IF(G39<0,"Hold","Sell") -> Hold
A40: 42061 | B40: 3.8792 | C40: =$C$4*B30+C39*(1-$C$4) -> 3.7150067 | D40: =$D$4*B40+(1-$D$4)*D39 -> 3.7777576 | E40: =C40-D40 -> -0.062750922 | F40: =(E40*(2/(10)))+((1-(2/10))*F39) -> -0.058509186 | G40: =E40-F40 -> -0.0042417362 | H40: =IF(G40<0,"Hold","Sell") -> Hold
...

Sheet OBV
A1: Date | B1: Cours | C1: Cours Ajusté | D1: Qte. Ech. | E1: OBV | F1: OBV Trend Signal | G1: OBV Strength | H1: Price-OBV Alignment
A2: 42006 | B2: 7.21 | C2: 3.6229 | D2: 1246 | E2: =D2 -> 1246
A3: 42009 | B3: 7.36 | C3: 3.6983 | D3: 2070 | E3: =IF(B3>B2, E2+D3, IF(B3<B2, E2-D3, E2)) -> 3316
A4: 42010 | B4: 7.38 | C4: 3.7083 | D4: 2260 | E4: =IF(B4>B3, E3+D4, IF(B4<B3, E3-D4, E3)) -> 5576
A5: 42011 | B5: 7.45 | C5: 3.7435 | D5: 6749 | E5: =IF(B5>B4, E4+D5, IF(B5<B4, E4-D5, E4)) -> 12325
A6: 42012 | B6: 7.4 | C6: 3.7184 | D6: 3435 | E6: =IF(B6>B5, E5+D6, IF(B6<B5, E5-D6, E5)) -> 8890 | H6: =IF(AND(B6>B1, E6>E1), "CONFIRMED BULLISH", IF(AND(B6<B1, E6<E1), "CONFIRMED BEARISH", IF(AND(B6>B1, E6<E1), "BEARISH DIVERGENCE", IF(AND(B6<B1, E6>E1), "BULLISH DIVERGENCE", "NEUTRAL")))) -> CONFIRMED BEARISH
A7: 42013 | B7: 7.4 | C7: 3.7184 | D7: 8780 | E7: =IF(B7>B6, E6+D7, IF(B7<B6, E6-D7, E6)) -> 8890 | F7: =IF(E7>E2,"BULLISH",IF(E7<E2,"BEARISH","NEUTRAL")) -> BULLISH | G7: =IF((E7-E2)/E2 > 0.02, "STRONG", IF((E7-E2)/E2 < -0.02, "WEAK", "NEUTRAL")) -> STRONG | H7: =IF(AND(B7>B2, E7>E2), "CONFIRMED BULLISH", IF(AND(B7<B2, E7<E2), "CONFIRMED BEARISH", IF(AND(B7>B2, E7<E2), "BEARISH DIVERGENCE", IF(AND(B7<B2, E7>E2), "BULLISH DIVERGENCE", "NEUTRAL")))) -> CONFIRMED BULLISH
A8: 42016 | B8: 7.4 | C8: 3.7184 | D8: 3318 | E8: =IF(B8>B7, E7+D8, IF(B8<B7, E7-D8, E7)) -> 8890 | F8: =IF(E8>E3,"BULLISH",IF(E8<E3,"BEARISH","NEUTRAL")) -> BULLISH | G8: =IF((E8-E3)/E3 > 0.02, "STRONG", IF((E8-E3)/E3 < -0.02, "WEAK", "NEUTRAL")) -> STRONG | H8: =IF(AND(B8>B3, E8>E3), "CONFIRMED BULLISH", IF(AND(B8<B3, E8<E3), "CONFIRMED BEARISH", IF(AND(B8>B3, E8<E3), "BEARISH DIVERGENCE", IF(AND(B8<B3, E8>E3), "BULLISH DIVERGENCE", "NEUTRAL")))) -> CONFIRMED BULLISH
A9: 42017 | B9: 7.4 | C9: 3.7184 | D9: 0 | E9: =IF(B9>B8, E8+D9, IF(B9<B8, E8-D9, E8)) -> 8890 | F9: =IF(E9>E4,"BULLISH",IF(E9<E4,"BEARISH","NEUTRAL")) -> BULLISH | G9: =IF((E9-E4)/E4 > 0.02, "STRONG", IF((E9-E4)/E4 < -0.02, "WEAK", "NEUTRAL")) -> STRONG | H9: =IF(AND(B9>B4, E9>E4), "CONFIRMED BULLISH", IF(AND(B9<B4, E9<E4), "CONFIRMED BEARISH", IF(AND(B9>B4, E9<E4), "BEARISH DIVERGENCE", IF(AND(B9<B4, E9>E4), "BULLISH DIVERGENCE", "NEUTRAL")))) -> CONFIRMED BULLISH
A10: 42019 | B10: 7.2 | C10: 3.6179 | D10: 7353 | E10: =IF(B10>B9, E9+D10, IF(B10<B9, E9-D10, E9)) -> 1537 | F10: =IF(E10>E5,"BULLISH",IF(E10<E5,"BEARISH","NEUTRAL")) -> BEARISH | G10: =IF((E10-E5)/E5 > 0.02, "STRONG", IF((E10-E5)/E5 < -0.02, "WEAK", "NEUTRAL")) -> WEAK | H10: =IF(AND(B10>B5, E10>E5), "CONFIRMED BULLISH", IF(AND(B10<B5, E10<E5), "CONFIRMED BEARISH", IF(AND(B10>B5, E10<E5), "BEARISH DIVERGENCE", IF(AND(B10<B5, E10>E5), "BULLISH DIVERGENCE", "NEUTRAL")))) -> CONFIRMED BEARISH
A11: 42020 | B11: 7.39 | C11: 3.7134 | D11: 2615 | E11: =IF(B11>B10, E10+D11, IF(B11<B10, E10-D11, E10)) -> 4152 | F11: =IF(E11>E6,"BULLISH",IF(E11<E6,"BEARISH","NEUTRAL")) -> BEARISH | G11: =IF((E11-E6)/E6 > 0.02, "STRONG", IF((E11-E6)/E6 < -0.02, "WEAK", "NEUTRAL")) -> WEAK | H11: =IF(AND(B11>B6, E11>E6), "CONFIRMED BULLISH", IF(AND(B11<B6, E11<E6), "CONFIRMED BEARISH", IF(AND(B11>B6, E11<E6), "BEARISH DIVERGENCE", IF(AND(B11<B6, E11>E6), "BULLISH DIVERGENCE", "NEUTRAL")))) -> CONFIRMED BEARISH
A12: 42023 | B12: 7.39 | C12: 3.7134 | D12: 320 | E12: =IF(B12>B11, E11+D12, IF(B12<B11, E11-D12, E11)) -> 4152 | F12: =IF(E12>E7,"BULLISH",IF(E12<E7,"BEARISH","NEUTRAL")) -> BEARISH | G12: =IF((E12-E7)/E7 > 0.02, "STRONG", IF((E12-E7)/E7 < -0.02, "WEAK", "NEUTRAL")) -> WEAK | H12: =IF(AND(B12>B7, E12>E7), "CONFIRMED BULLISH", IF(AND(B12<B7, E12<E7), "CONFIRMED BEARISH", IF(AND(B12>B7, E12<E7), "BEARISH DIVERGENCE", IF(AND(B12<B7, E12>E7), "BULLISH DIVERGENCE", "NEUTRAL")))) -> CONFIRMED BEARISH
A13: 42024 | B13: 7.39 | C13: 3.7134 | D13: 0 | E13: =IF(B13>B12, E12+D13, IF(B13<B12, E12-D13, E12)) -> 4152 | F13: =IF(E13>E8,"BULLISH",IF(E13<E8,"BEARISH","NEUTRAL")) -> BEARISH | G13: =IF((E13-E8)/E8 > 0.02, "STRONG", IF((E13-E8)/E8 < -0.02, "WEAK", "NEUTRAL")) -> WEAK | H13: =IF(AND(B13>B8, E13>E8), "CONFIRMED BULLISH", IF(AND(B13<B8, E13<E8), "CONFIRMED BEARISH", IF(AND(B13>B8, E13<E8), "BEARISH DIVERGENCE", IF(AND(B13<B8, E13>E8), "BULLISH DIVERGENCE", "NEUTRAL")))) -> CONFIRMED BEARISH
A14: 42025 | B14: 7.3 | C14: 3.6681 | D14: 3395 | E14: =IF(B14>B13, E13+D14, IF(B14<B13, E13-D14, E13)) -> 757 | F14: =IF(E14>E9,"BULLISH",IF(E14<E9,"BEARISH","NEUTRAL")) -> BEARISH | G14: =IF((E14-E9)/E9 > 0.02, "STRONG", IF((E14-E9)/E9 < -0.02, "WEAK", "NEUTRAL")) -> WEAK | H14: =IF(AND(B14>B9, E14>E9), "CONFIRMED BULLISH", IF(AND(B14<B9, E14<E9), "CONFIRMED BEARISH", IF(AND(B14>B9, E14<E9), "BEARISH DIVERGENCE", IF(AND(B14<B9, E14>E9), "BULLISH DIVERGENCE", "NEUTRAL")))) -> CONFIRMED BEARISH
A15: 42026 | B15: 7.35 | C15: 3.6933 | D15: 1960 | E15: =IF(B15>B14, E14+D15, IF(B15<B14, E14-D15, E14)) -> 2717 | F15: =IF(E15>E10,"BULLISH",IF(E15<E10,"BEARISH","NEUTRAL")) -> BULLISH | G15: =IF((E15-E10)/E10 > 0.02, "STRONG", IF((E15-E10)/E10 < -0.02, "WEAK", "NEUTRAL")) -> STRONG | H15: =IF(AND(B15>B10, E15>E10), "CONFIRMED BULLISH", IF(AND(B15<B10, E15<E10), "CONFIRMED BEARISH", IF(AND(B15>B10, E15<E10), "BEARISH DIVERGENCE", IF(AND(B15<B10, E15>E10), "BULLISH DIVERGENCE", "NEUTRAL")))) -> CONFIRMED BULLISH
A16: 42027 | B16: 7.34 | C16: 3.6882 | D16: 9379 | E16: =IF(B16>B15, E15+D16, IF(B16<B15, E15-D16, E15)) -> -6662 | F16: =IF(E16>E11,"BULLISH",IF(E16<E11,"BEARISH","NEUTRAL")) -> BEARISH | G16: =IF((E16-E11)/E11 > 0.02, "STRONG", IF((E16-E11)/E11 < -0.02, "WEAK", "NEUTRAL")) -> WEAK | H16: =IF(AND(B16>B11, E16>E11), "CONFIRMED BULLISH", IF(AND(B16<B11, E16<E11), "CONFIRMED BEARISH", IF(AND(B16>B11, E16<E11), "BEARISH DIVERGENCE", IF(AND(B16<B11, E16>E11), "BULLISH DIVERGENCE", "NEUTRAL")))) -> CONFIRMED BEARISH
A17: 42030 | B17: 7.34 | C17: 3.6882 | D17: 320 | E17: =IF(B17>B16, E16+D17, IF(B17<B16, E16-D17, E16)) -> -6662 | F17: =IF(E17>E12,"BULLISH",IF(E17<E12,"BEARISH","NEUTRAL")) -> BEARISH | G17: =IF((E17-E12)/E12 > 0.02, "STRONG", IF((E17-E12)/E12 < -0.02, "WEAK", "NEUTRAL")) -> WEAK | H17: =IF(AND(B17>B12, E17>E12), "CONFIRMED BULLISH", IF(AND(B17<B12, E17<E12), "CONFIRMED BEARISH", IF(AND(B17>B12, E17<E12), "BEARISH DIVERGENCE", IF(AND(B17<B12, E17>E12), "BULLISH DIVERGENCE", "NEUTRAL")))) -> CONFIRMED BEARISH
A18: 42031 | B18: 7.15 | C18: 3.5928 | D18: 1817 | E18: =IF(B18>B17, E17+D18, IF(B18<B17, E17-D18, E17)) -> -8479 | F18: =IF(E18>E13,"BULLISH",IF(E18<E13,"BEARISH","NEUTRAL")) -> BEARISH | G18: =IF((E18-E13)/E13 > 0.02, "STRONG", IF((E18-E13)/E13 < -0.02, "WEAK", "NEUTRAL")) -> WEAK | H18: =IF(AND(B18>B13, E18>E13), "CONFIRMED BULLISH", IF(AND(B18<B13, E18<E13), "CONFIRMED BEARISH", IF(AND(B18>B13, E18<E13), "BEARISH DIVERGENCE", IF(AND(B18<B13, E18>E13), "BULLISH DIVERGENCE", "NEUTRAL")))) -> CONFIRMED BEARISH
... A2693: 45930 | B2693: 8.9 | C2693: 8.9 | D2693: 73152 | E2693: =IF(B2693>B2692, E2692+D2693, IF(B2693<B2692, E2692-D2693, E2692)) -> 11929409 | F2693: =IF(E2693>E2688,"BULLISH",IF(E2693<E2688,"BEARISH","NEUTRAL")) -> BULLISH | G2693: =IF((E2693-E2688)/E2688 > 0.02, "STRONG", IF((E2693-E2688)/E2688 < -0.02, "WEAK", "NEUTRAL")) -> NEUTRAL | H2693: =IF(AND(B2693>B2688, E2693>E2688), "CONFIRMED BULLISH", IF(AND(B2693<B2688, E2693<E2688), "CONFIRMED BEARISH", IF(AND(B2693>B2688, E2693<E2688), "BEARISH DIVERGENCE", IF(AND(B2693<B2688, E2693>E2688), "BULLISH DIVERGENCE", "NEUTRAL")))) -> CONFIRMED BULLISH

Sheet Overall Overview
A1: =RSI!A1 -> Date | B1: =RSI!B1 -> Cours Ajusté | C1: =RSI!I1 -> 14-Day RSI | D1: =MACD!E1 -> MACD Line | E1: =MACD!F1 -> Signal Line | F1: ='Moving Avg'!D1 -> Simple Moving Avg (5) | G1: ='Moving Avg'!F1 -> Simple Moving Avg (20) | H1: ='Moving Avg'!G1 -> Simple Moving Avg (50) | I1: ='Moving Avg'!H1 -> Simple Moving Avg (200) | J1: =OBV!F1 -> OBV Trend Signal | K1: =OBV!G1 -> OBV Strength | L1: =OBV!H1 -> Price-OBV Alignment
A2: =RSI!A2 -> 42006 | B2: =RSI!B2 -> 3.6229 | C2: =RSI!I2 -> 0 | D2: =MACD!E2 -> 0 | E2: =MACD!F2 -> 0 | F2: ='Moving Avg'!D2 -> 0 | G2: ='Moving Avg'!F2 -> 0 | H2: ='Moving Avg'!G2 -> 0 | I2: ='Moving Avg'!H2 -> 0 | J2: =OBV!F2 -> 0 | K2: =OBV!G2 -> 0 | L2: =OBV!H2 -> 0
A3: =RSI!A3 -> 42009 | B3: =RSI!B3 -> 3.6983 | C3: =RSI!I3 -> 0 | D3: =MACD!E3 -> 0 | E3: =MACD!F3 -> 0 | F3: ='Moving Avg'!D3 -> 0 | G3: ='Moving Avg'!F3 -> 0 | H3: ='Moving Avg'!G3 -> 0 | I3: ='Moving Avg'!H3 -> 0 | J3: =OBV!F3 -> 0 | K3: =OBV!G3 -> 0 | L3: =OBV!H3 -> 0
A4: =RSI!A4 -> 42010 | B4: =RSI!B4 -> 3.7083 | C4: =RSI!I4 -> 0 | D4: =MACD!E4 -> 0 | E4: =MACD!F4 -> 0 | F4: ='Moving Avg'!D4 -> 0 | G4: ='Moving Avg'!F4 -> 0 | H4: ='Moving Avg'!G4 -> 0 | I4: ='Moving Avg'!H4 -> 0 | J4: =OBV!F4 -> 0 | K4: =OBV!G4 -> 0 | L4: =OBV!H4 -> 0
A5: =RSI!A5 -> 42011 | B5: =RSI!B5 -> 3.7435 | C5: =RSI!I5 -> 0 | D5: =MACD!E5 -> 0 | E5: =MACD!F5 -> 0 | F5: ='Moving Avg'!D5 -> 3.69325 | G5: ='Moving Avg'!F5 -> 0 | H5: ='Moving Avg'!G5 -> 0 | I5: ='Moving Avg'!H5 -> 0 | J5: =OBV!F5 -> 0 | K5: =OBV!G5 -> 0 | L5: =OBV!H5 -> 0
A6: =RSI!A6 -> 42012 | B6: =RSI!B6 -> 3.7184 | C6: =RSI!I6 -> 0 | D6: =MACD!E6 -> 0 | E6: =MACD!F6 -> 0 | F6: ='Moving Avg'!D6 -> 3.69828 | G6: ='Moving Avg'!F6 -> 0 | H6: ='Moving Avg'!G6 -> 0 | I6: ='Moving Avg'!H6 -> 0 | J6: =OBV!F6 -> 0 | K6: =OBV!G6 -> 0 | L6: =OBV!H6 -> CONFIRMED BEARISH
A7: =RSI!A7 -> 42013 | B7: =RSI!B7 -> 3.7184 | C7: =RSI!I7 -> 0 | D7: =MACD!E7 -> 0 | E7: =MACD!F7 -> 0 | F7: ='Moving Avg'!D7 -> 3.71738 | G7: ='Moving Avg'!F7 -> 0 | H7: ='Moving Avg'!G7 -> 0 | I7: ='Moving Avg'!H7 -> 0 | J7: =OBV!F7 -> BULLISH | K7: =OBV!G7 -> STRONG | L7: =OBV!H7 -> CONFIRMED BULLISH
A8: =RSI!A8 -> 42016 | B8: =RSI!B8 -> 3.7184 | C8: =RSI!I8 -> 0 | D8: =MACD!E8 -> 0 | E8: =MACD!F8 -> 0 | F8: ='Moving Avg'!D8 -> 3.7214 | G8: ='Moving Avg'!F8 -> 0 | H8: ='Moving Avg'!G8 -> 0 | I8: ='Moving Avg'!H8 -> 0 | J8: =OBV!F8 -> BULLISH | K8: =OBV!G8 -> STRONG | L8: =OBV!H8 -> CONFIRMED BULLISH
A9: =RSI!A9 -> 42017 | B9: =RSI!B9 -> 3.7184 | C9: =RSI!I9 -> 0 | D9: =MACD!E9 -> 0 | E9: =MACD!F9 -> 0 | F9: ='Moving Avg'!D9 -> 3.72342 | G9: ='Moving Avg'!F9 -> 0 | H9: ='Moving Avg'!G9 -> 0 | I9: ='Moving Avg'!H9 -> 0 | J9: =OBV!F9 -> BULLISH | K9: =OBV!G9 -> STRONG | L9: =OBV!H9 -> CONFIRMED BULLISH
A10: =RSI!A10 -> 42019 | B10: =RSI!B10 -> 3.6179 | C10: =RSI!I10 -> 0 | D10: =MACD!E10 -> 0 | E10: =MACD!F10 -> 0 | F10: ='Moving Avg'!D10 -> 3.6983 | G10: ='Moving Avg'!F10 -> 0 | H10: ='Moving Avg'!G10 -> 0 | I10: ='Moving Avg'!H10 -> 0 | J10: =OBV!F10 -> BEARISH | K10: =OBV!G10 -> WEAK | L10: =OBV!H10 -> CONFIRMED BEARISH
A11: =RSI!A11 -> 42020 | B11: =RSI!B11 -> 3.7134 | C11: =RSI!I11 -> 0 | D11: =MACD!E11 -> 0 | E11: =MACD!F11 -> 0 | F11: ='Moving Avg'!D11 -> 3.6973 | G11: ='Moving Avg'!F11 -> 0 | H11: ='Moving Avg'!G11 -> 0 | I11: ='Moving Avg'!H11 -> 0 | J11: =OBV!F11 -> BEARISH | K11: =OBV!G11 -> WEAK | L11: =OBV!H11 -> CONFIRMED BEARISH
A12: =RSI!A12 -> 42023 | B12: =RSI!B12 -> 3.7134 | C12: =RSI!I12 -> 0 | D12: =MACD!E12 -> 0 | E12: =MACD!F12 -> 0 | F12: ='Moving Avg'!D12 -> 3.6963 | G12: ='Moving Avg'!F12 -> 0 | H12: ='Moving Avg'!G12 -> 0 | I12: ='Moving Avg'!H12 -> 0 | J12: =OBV!F12 -> BEARISH | K12: =OBV!G12 -> WEAK | L12: =OBV!H12 -> CONFIRMED BEARISH
... A2693: =RSI!A2693 -> 45930 | B2693: =RSI!B2693 -> 8.9 | C2693: =RSI!I2693 -> 53.444496 | D2693: =MACD!E2693 -> 0.087231144 | E2693: =MACD!F2693 -> 0.07889905 | F2693: ='Moving Avg'!D2693 -> 8.732 | G2693: ='Moving Avg'!F2693 -> 8.804 | H2693: ='Moving Avg'!G2693 -> 8.952 | I2693: ='Moving Avg'!H2693 -> 8.958912 | J2693: =OBV!F2693 -> BULLISH | K2693: =OBV!G2693 -> NEUTRAL | L2693: =OBV!H2693 -> CONFIRMED BULLISH

Sheet Scoring System
A1: Date | B1: Cours Ajusté | C1: 14-Day RSI | D1: MACD Line | E1: Signal Line | F1: Simple Moving Avg (5) | G1: Simple Moving Avg (20) | H1: Simple Moving Avg (50) | I1: Simple Moving Avg (200) | J1: OBV Trend Signal | K1: OBV Strength | L1: Price-OBV Alignment | M1: RSI Score | N1: MACD Score | O1: SMA Score | P1: OBV Score | Q1: Score Momentum | R1: Score Trend | S1: Volume Score | T1: Score Equal Weights | U1: Overall Score (3C) | V1: Overall Score (4C)
A2: 42006 | B2: 3.6229 | C2: 0 | D2: 0 | E2: 0 | F2: 0 | G2: 0 | H2: 0 | I2: 0 | J2: 0 | K2: 0 | L2: 0 | M2: =IF(C2<30,50, IF(C2>70, 0, 25)) -> 50 | N2: =IF(E2-D2>0.02, 100, IF(E2-D2<0,0,45)) -> 45 | O2: =IF(F2-I2>10,100,IF(F2-I2>5,75, IF(F2-I2>0,50,0))) -> 0 | P2: =IF(L2="confirmed bullish", 34, IF(L2="bullish divergence",17, 0))+IF(J2="bullish",33,IF(J2="bearish",0,16.5))+IF(K2="strong",33,IF(K2="weak",0,16.5)) -> 33 | Q2: =0.35*M2+N2*0.35+O2*0.15+P2*0.15 -> 38.2 | R2: =M2*0.2+N2*0.2+O2*0.35+P2*0.25 -> 27.25 | S2: =M2*0.15+N2*0.15+O2*0.25+P2*0.45 -> 29.1 | T2: =0.25*SUM(M2:P2) -> 32 | U2: =SUM(Q2:S2)/3 -> 31.516667 | V2: =SUM(Q2:T2)/4 -> 31.6375
A3: 42009 | B3: 3.6983 | C3: 0 | D3: 0 | E3: 0 | F3: 0 | G3: 0 | H3: 0 | I3: 0 | J3: 0 | K3: 0 | L3: 0 | M3: =IF(C3<30,50, IF(C3>70, 0, 25)) -> 50 | N3: =IF(E3-D3>0.02, 100, IF(E3-D3<0,0,45)) -> 45 | O3: =IF(F3-I3>10,100,IF(F3-I3>5,75, IF(F3-I3>0,50,0))) -> 0 | P3: =IF(L3="confirmed bullish", 34, IF(L3="bullish divergence",17, 0))+IF(J3="bullish",33,IF(J3="bearish",0,16.5))+IF(K3="strong",33,IF(K3="weak",0,16.5)) -> 33 | Q3: =0.35*M3+N3*0.35+O3*0.15+P3*0.15 -> 38.2 | R3: =M3*0.2+N3*0.2+O3*0.35+P3*0.25 -> 27.25 | S3: =M3*0.15+N3*0.15+O3*0.25+P3*0.45 -> 29.1 | T3: =0.25*SUM(M3:P3) -> 32 | U3: =SUM(Q3:S3)/3 -> 31.516667 | V3: =SUM(Q3:T3)/4 -> 31.6375
A4: 42010 | B4: 3.7083 | C4: 0 | D4: 0 | E4: 0 | F4: 0 | G4: 0 | H4: 0 | I4: 0 | J4: 0 | K4: 0 | L4: 0 | M4: =IF(C4<30,50, IF(C4>70, 0, 25)) -> 50 | N4: =IF(E4-D4>0.02, 100, IF(E4-D4<0,0,45)) -> 45 | O4: =IF(F4-I4>10,100,IF(F4-I4>5,75, IF(F4-I4>0,50,0))) -> 0 | P4: =IF(L4="confirmed bullish", 34, IF(L4="bullish divergence",17, 0))+IF(J4="bullish",33,IF(J4="bearish",0,16.5))+IF(K4="strong",33,IF(K4="weak",0,16.5)) -> 33 | Q4: =0.35*M4+N4*0.35+O4*0.15+P4*0.15 -> 38.2 | R4: =M4*0.2+N4*0.2+O4*0.35+P4*0.25 -> 27.25 | S4: =M4*0.15+N4*0.15+O4*0.25+P4*0.45 -> 29.1 | T4: =0.25*SUM(M4:P4) -> 32 | U4: =SUM(Q4:S4)/3 -> 31.516667 | V4: =SUM(Q4:T4)/4 -> 31.6375
A5: 42011 | B5: 3.7435 | C5: 0 | D5: 0 | E5: 0 | F5: 3.69325 | G5: 0 | H5: 0 | I5: 0 | J5: 0 | K5: 0 | L5: 0 | M5: =IF(C5<30,50, IF(C5>70, 0, 25)) -> 50 | N5: =IF(E5-D5>0.02, 100, IF(E5-D5<0,0,45)) -> 45 | O5: =IF(F5-I5>10,100,IF(F5-I5>5,75, IF(F5-I5>0,50,0))) -> 50 | P5: =IF(L5="confirmed bullish", 34, IF(L5="bullish divergence",17, 0))+IF(J5="bullish",33,IF(J5="bearish",0,16.5))+IF(K5="strong",33,IF(K5="weak",0,16.5)) -> 33 | Q5: =0.35*M5+N5*0.35+O5*0.15+P5*0.15 -> 45.7 | R5: =M5*0.2+N5*0.2+O5*0.35+P5*0.25 -> 44.75 | S5: =M5*0.15+N5*0.15+O5*0.25+P5*0.45 -> 41.6 | T5: =0.25*SUM(M5:P5) -> 44.5 | U5: =SUM(Q5:S5)/3 -> 44.016667 | V5: =SUM(Q5:T5)/4 -> 44.1375
A6: 42012 | B6: 3.7184 | C6: 0 | D6: 0 | E6: 0 | F6: 3.69828 | G6: 0 | H6: 0 | I6: 0 | J6: 0 | K6: 0 | L6: CONFIRMED BEARISH | M6: =IF(C6<30,50, IF(C6>70, 0, 25)) -> 50 | N6: =IF(E6-D6>0.02, 100, IF(E6-D6<0,0,45)) -> 45 | O6: =IF(F6-I6>10,100,IF(F6-I6>5,75, IF(F6-I6>0,50,0))) -> 50 | P6: =IF(L6="confirmed bullish", 34, IF(L6="bullish divergence",17, 0))+IF(J6="bullish",33,IF(J6="bearish",0,16.5))+IF(K6="strong",33,IF(K6="weak",0,16.5)) -> 33 | Q6: =0.35*M6+N6*0.35+O6*0.15+P6*0.15 -> 45.7 | R6: =M6*0.2+N6*0.2+O6*0.35+P6*0.25 -> 44.75 | S6: =M6*0.15+N6*0.15+O6*0.25+P6*0.45 -> 41.6 | T6: =0.25*SUM(M6:P6) -> 44.5 | U6: =SUM(Q6:S6)/3 -> 44.016667 | V6: =SUM(Q6:T6)/4 -> 44.1375
A7: 42013 | B7: 3.7184 | C7: 0 | D7: 0 | E7: 0 | F7: 3.71738 | G7: 0 | H7: 0 | I7: 0 | J7: BULLISH | K7: STRONG | L7: CONFIRMED BULLISH | M7: =IF(C7<30,50, IF(C7>70, 0, 25)) -> 50 | N7: =IF(E7-D7>0.02, 100, IF(E7-D7<0,0,45)) -> 45 | O7: =IF(F7-I7>10,100,IF(F7-I7>5,75, IF(F7-I7>0,50,0))) -> 50 | P7: =IF(L7="confirmed bullish", 34, IF(L7="bullish divergence",17, 0))+IF(J7="bullish",33,IF(J7="bearish",0,16.5))+IF(K7="strong",33,IF(K7="weak",0,16.5)) -> 100 | Q7: =0.35*M7+N7*0.35+O7*0.15+P7*0.15 -> 55.75 | R7: =M7*0.2+N7*0.2+O7*0.35+P7*0.25 -> 61.5 | S7: =M7*0.15+N7*0.15+O7*0.25+P7*0.45 -> 71.75 | T7: =0.25*SUM(M7:P7) -> 61.25 | U7: =SUM(Q7:S7)/3 -> 63 | V7: =SUM(Q7:T7)/4 -> 62.5625
A8: 42016 | B8: 3.7184 | C8: 0 | D8: 0 | E8: 0 | F8: 3.7214 | G8: 0 | H8: 0 | I8: 0 | J8: BULLISH | K8: STRONG | L8: CONFIRMED BULLISH | M8: =IF(C8<30,50, IF(C8>70, 0, 25)) -> 50 | N8: =IF(E8-D8>0.02, 100, IF(E8-D8<0,0,45)) -> 45 | O8: =IF(F8-I8>10,100,IF(F8-I8>5,75, IF(F8-I8>0,50,0))) -> 50 | P8: =IF(L8="confirmed bullish", 34, IF(L8="bullish divergence",17, 0))+IF(J8="bullish",33,IF(J8="bearish",0,16.5))+IF(K8="strong",33,IF(K8="weak",0,16.5)) -> 100 | Q8: =0.35*M8+N8*0.35+O8*0.15+P8*0.15 -> 55.75 | R8: =M8*0.2+N8*0.2+O8*0.35+P8*0.25 -> 61.5 | S8: =M8*0.15+N8*0.15+O8*0.25+P8*0.45 -> 71.75 | T8: =0.25*SUM(M8:P8) -> 61.25 | U8: =SUM(Q8:S8)/3 -> 63 | V8: =SUM(Q8:T8)/4 -> 62.5625
A9: 42017 | B9: 3.7184 | C9: 0 | D9: 0 | E9: 0 | F9: 3.72342 | G9: 0 | H9: 0 | I9: 0 | J9: BULLISH | K9: STRONG | L9: CONFIRMED BULLISH | M9: =IF(C9<30,50, IF(C9>70, 0, 25)) -> 50 | N9: =IF(E9-D9>0.02, 100, IF(E9-D9<0,0,45)) -> 45 | O9: =IF(F9-I9>10,100,IF(F9-I9>5,75, IF(F9-I9>0,50,0))) -> 50 | P9: =IF(L9="confirmed bullish", 34, IF(L9="bullish divergence",17, 0))+IF(J9="bullish",33,IF(J9="bearish",0,16.5))+IF(K9="strong",33,IF(K9="weak",0,16.5)) -> 100 | Q9: =0.35*M9+N9*0.35+O9*0.15+P9*0.15 -> 55.75 | R9: =M9*0.2+N9*0.2+O9*0.35+P9*0.25 -> 61.5 | S9: =M9*0.15+N9*0.15+O9*0.25+P9*0.45 -> 71.75 | T9: =0.25*SUM(M9:P9) -> 61.25 | U9: =SUM(Q9:S9)/3 -> 63 | V9: =SUM(Q9:T9)/4 -> 62.5625
A10: 42019 | B10: 3.6179 | C10: 0 | D10: 0 | E10: 0 | F10: 3.6983 | G10: 0 | H10: 0 | I10: 0 | J10: BEARISH | K10: WEAK | L10: CONFIRMED BEARISH | M10: =IF(C10<30,50, IF(C10>70, 0, 25)) -> 50 | N10: =IF(E10-D10>0.02, 100, IF(E10-D10<0,0,45)) -> 45 | O10: =IF(F10-I10>10,100,IF(F10-I10>5,75, IF(F10-I10>0,50,0))) -> 50 | P10: =IF(L10="confirmed bullish", 34, IF(L10="bullish divergence",17, 0))+IF(J10="bullish",33,IF(J10="bearish",0,16.5))+IF(K10="strong",33,IF(K10="weak",0,16.5)) -> 0 | Q10: =0.35*M10+N10*0.35+O10*0.15+P10*0.15 -> 40.75 | R10: =M10*0.2+N10*0.2+O10*0.35+P10*0.25 -> 36.5 | S10: =M10*0.15+N10*0.15+O10*0.25+P10*0.45 -> 26.75 | T10: =0.25*SUM(M10:P10) -> 36.25 | U10: =SUM(Q10:S10)/3 -> 34.666667 | V10: =SUM(Q10:T10)/4 -> 35.0625
A11: 42020 | B11: 3.7134 | C11: 0 | D11: 0 | E11: 0 | F11: 3.6973 | G11: 0 | H11: 0 | I11: 0 | J11: BEARISH | K11: WEAK | L11: CONFIRMED BEARISH | M11: =IF(C11<30,50, IF(C11>70, 0, 25)) -> 50 | N11: =IF(E11-D11>0.02, 100, IF(E11-D11<0,0,45)) -> 45 | O11: =IF(F11-I11>10,100,IF(F11-I11>5,75, IF(F11-I11>0,50,0))) -> 50 | P11: =IF(L11="confirmed bullish", 34, IF(L11="bullish divergence",17, 0))+IF(J11="bullish",33,IF(J11="bearish",0,16.5))+IF(K11="strong",33,IF(K11="weak",0,16.5)) -> 0 | Q11: =0.35*M11+N11*0.35+O11*0.15+P11*0.15 -> 40.75 | R11: =M11*0.2+N11*0.2+O11*0.35+P11*0.25 -> 36.5 | S11: =M11*0.15+N11*0.15+O11*0.25+P11*0.45 -> 26.75 | T11: =0.25*SUM(M11:P11) -> 36.25 | U11: =SUM(Q11:S11)/3 -> 34.666667 | V11: =SUM(Q11:T11)/4 -> 35.0625
A12: 42023 | B12: 3.7134 | C12: 0 | D12: 0 | E12: 0 | F12: 3.6963 | G12: 0 | H12: 0 | I12: 0 | J12: BEARISH | K12: WEAK | L12: CONFIRMED BEARISH | M12: =IF(C12<30,50, IF(C12>70, 0, 25)) -> 50 | N12: =IF(E12-D12>0.02, 100, IF(E12-D12<0,0,45)) -> 45 | O12: =IF(F12-I12>10,100,IF(F12-I12>5,75, IF(F12-I12>0,50,0))) -> 50 | P12: =IF(L12="confirmed bullish", 34, IF(L12="bullish divergence",17, 0))+IF(J12="bullish",33,IF(J12="bearish",0,16.5))+IF(K12="strong",33,IF(K12="weak",0,16.5)) -> 0 | Q12: =0.35*M12+N12*0.35+O12*0.15+P12*0.15 -> 40.75 | R12: =M12*0.2+N12*0.2+O12*0.35+P12*0.25 -> 36.5 | S12: =M12*0.15+N12*0.15+O12*0.25+P12*0.45 -> 26.75 | T12: =0.25*SUM(M12:P12) -> 36.25 | U12: =SUM(Q12:S12)/3 -> 34.666667 | V12: =SUM(Q12:T12)/4 -> 35.0625
A13: 42024 | B13: 3.7134 | C13: 0 | D13: 0 | E13: 0 | F13: 3.6953 | G13: 0 | H13: 0 | I13: 0 | J13: BEARISH | K13: WEAK | L13: CONFIRMED BEARISH | M13: =IF(C13<30,50, IF(C13>70, 0, 25)) -> 50 | N13: =IF(E13-D13>0.02, 100, IF(E13-D13<0,0,45)) -> 45 | O13: =IF(F13-I13>10,100,IF(F13-I13>5,75, IF(F13-I13>0,50,0))) -> 50 | P13: =IF(L13="confirmed bullish", 34, IF(L13="bullish divergence",17, 0))+IF(J13="bullish",33,IF(J13="bearish",0,16.5))+IF(K13="strong",33,IF(K13="weak",0,16.5)) -> 0 | Q13: =0.35*M13+N13*0.35+O13*0.15+P13*0.15 -> 40.75 | R13: =M13*0.2+N13*0.2+O13*0.35+P13*0.25 -> 36.5 | S13: =M13*0.15+N13*0.15+O13*0.25+P13*0.45 -> 26.75 | T13: =0.25*SUM(M13:P13) -> 36.25 | U13: =SUM(Q13:S13)/3 -> 34.666667 | V13: =SUM(Q13:T13)/4 -> 35.0625
A14: 42025 | B14: 3.6681 | C14: 0 | D14: 0 | E14: 0 | F14: 3.68524 | G14: 0 | H14: 0 | I14: 0 | J14: BEARISH | K14: WEAK | L14: CONFIRMED BEARISH | M14: =IF(C14<30,50, IF(C14>70, 0, 25)) -> 50 | N14: =IF(E14-D14>0.02, 100, IF(E14-D14<0,0,45)) -> 45 | O14: =IF(F14-I14>10,100,IF(F14-I14>5,75, IF(F14-I14>0,50,0))) -> 50 | P14: =IF(L14="confirmed bullish", 34, IF(L14="bullish divergence",17, 0))+IF(J14="bullish",33,IF(J14="bearish",0,16.5))+IF(K14="strong",33,IF(K14="weak",0,16.5)) -> 0 | Q14: =0.35*M14+N14*0.35+O14*0.15+P14*0.15 -> 40.75 | R14: =M14*0.2+N14*0.2+O14*0.35+P14*0.25 -> 36.5 | S14: =M14*0.15+N14*0.15+O14*0.25+P14*0.45 -> 26.75 | T14: =0.25*SUM(M14:P14) -> 36.25 | U14: =SUM(Q14:S14)/3 -> 34.666667 | V14: =SUM(Q14:T14)/4 -> 35.0625
A15: 42026 | B15: 3.6933 | C15: 0 | D15: 0 | E15: 0 | F15: 3.70032 | G15: 0 | H15: 0 | I15: 0 | J15: BULLISH | K15: STRONG | L15: CONFIRMED BULLISH | M15: =IF(C15<30,50, IF(C15>70, 0, 25)) -> 50 | N15: =IF(E15-D15>0.02, 100, IF(E15-D15<0,0,45)) -> 45 | O15: =IF(F15-I15>10,100,IF(F15-I15>5,75, IF(F15-I15>0,50,0))) -> 50 | P15: =IF(L15="confirmed bullish", 34, IF(L15="bullish divergence",17, 0))+IF(J15="bullish",33,IF(J15="bearish",0,16.5))+IF(K15="strong",33,IF(K15="weak",0,16.5)) -> 100 | Q15: =0.35*M15+N15*0.35+O15*0.15+P15*0.15 -> 55.75 | R15: =M15*0.2+N15*0.2+O15*0.35+P15*0.25 -> 61.5 | S15: =M15*0.15+N15*0.15+O15*0.25+P15*0.45 -> 71.75 | T15: =0.25*SUM(M15:P15) -> 61.25 | U15: =SUM(Q15:S15)/3 -> 63 | V15: =SUM(Q15:T15)/4 -> 62.5625
A16: 42027 | B16: 3.6882 | C16: 57.824107 | D16: 0 | E16: 0 | F16: 3.69528 | G16: 0 | H16: 0 | I16: 0 | J16: BEARISH | K16: WEAK | L16: CONFIRMED BEARISH | M16: =IF(C16<30,50, IF(C16>70, 0, 25)) -> 25 | N16: =IF(E16-D16>0.02, 100, IF(E16-D16<0,0,45)) -> 45 | O16: =IF(F16-I16>10,100,IF(F16-I16>5,75, IF(F16-I16>0,50,0))) -> 50 | P16: =IF(L16="confirmed bullish", 34, IF(L16="bullish divergence",17, 0))+IF(J16="bullish",33,IF(J16="bearish",0,16.5))+IF(K16="strong",33,IF(K16="weak",0,16.5)) -> 0 | Q16: =0.35*M16+N16*0.35+O16*0.15+P16*0.15 -> 32 | R16: =M16*0.2+N16*0.2+O16*0.35+P16*0.25 -> 31.5 | S16: =M16*0.15+N16*0.15+O16*0.25+P16*0.45 -> 23 | T16: =0.25*SUM(M16:P16) -> 30 | U16: =SUM(Q16:S16)/3 -> 28.833333 | V16: =SUM(Q16:T16)/4 -> 29.125
A17: 42030 | B17: 3.6882 | C17: 57.824107 | D17: 0 | E17: 0 | F17: 3.69024 | G17: 0 | H17: 0 | I17: 0 | J17: BEARISH | K17: WEAK | L17: CONFIRMED BEARISH | M17: =IF(C17<30,50, IF(C17>70, 0, 25)) -> 25 | N17: =IF(E17-D17>0.02, 100, IF(E17-D17<0,0,45)) -> 45 | O17: =IF(F17-I17>10,100,IF(F17-I17>5,75, IF(F17-I17>0,50,0))) -> 50 | P17: =IF(L17="confirmed bullish", 34, IF(L17="bullish divergence",17, 0))+IF(J17="bullish",33,IF(J17="bearish",0,16.5))+IF(K17="strong",33,IF(K17="weak",0,16.5)) -> 0 | Q17: =0.35*M17+N17*0.35+O17*0.15+P17*0.15 -> 32 | R17: =M17*0.2+N17*0.2+O17*0.35+P17*0.25 -> 31.5 | S17: =M17*0.15+N17*0.15+O17*0.25+P17*0.45 -> 23 | T17: =0.25*SUM(M17:P17) -> 30 | U17: =SUM(Q17:S17)/3 -> 28.833333 | V17: =SUM(Q17:T17)/4 -> 29.125
A18: 42031 | B18: 3.5928 | C18: 45.705828 | D18: 0 | E18: 0 | F18: 3.66612 | G18: 0 | H18: 0 | I18: 0 | J18: BEARISH | K18: WEAK | L18: CONFIRMED BEARISH | M18: =IF(C18<30,50, IF(C18>70, 0, 25)) -> 25 | N18: =IF(E18-D18>0.02, 100, IF(E18-D18<0,0,45)) -> 45 | O18: =IF(F18-I18>10,100,IF(F18-I18>5,75, IF(F18-I18>0,50,0))) -> 50 | P18: =IF(L18="confirmed bullish", 34, IF(L18="bullish divergence",17, 0))+IF(J18="bullish",33,IF(J18="bearish",0,16.5))+IF(K18="strong",33,IF(K18="weak",0,16.5)) -> 0 | Q18: =0.35*M18+N18*0.35+O18*0.15+P18*0.15 -> 32 | R18: =M18*0.2+N18*0.2+O18*0.35+P18*0.25 -> 31.5 | S18: =M18*0.15+N18*0.15+O18*0.25+P18*0.45 -> 23 | T18: =0.25*SUM(M18:P18) -> 30 | U18: =SUM(Q18:S18)/3 -> 28.833333 | V18: =SUM(Q18:T18)/4 -> 29.125
... A2693: 45930 | B2693: 8.9 | C2693: 53.444496 | D2693: 0.087231144 | E2693: 8.2559581e-34 | F2693: 8.732 | G2693: 8.804 | H2693: 8.952 | I2693: 8.958912 | J2693: BULLISH | K2693: NEUTRAL | L2693: CONFIRMED BULLISH | M2693: =IF(C2693<30,50, IF(C2693>70, 0, 25)) -> 25 | N2693: =IF(E2693-D2693>0.02, 100, IF(E2693-D2693<0,0,45)) -> 0 | O2693: =IF(F2693-I2693>10,100,IF(F2693-I2693>5,75, IF(F2693-I2693>0,50,0))) -> 0 | P2693: =IF(L2693="confirmed bullish", 34, IF(L2693="bullish divergence",17, 0))+IF(J2693="bullish",33,IF(J2693="bearish",0,16.5))+IF(K2693="strong",33,IF(K2693="weak",0,16.5)) -> 83.5 | Q2693: =0.35*M2693+N2693*0.35+O2693*0.15+P2693*0.15 -> 21.275 | R2693: =M2693*0.2+N2693*0.2+O2693*0.35+P2693*0.25 -> 25.875 | S2693: =M2693*0.15+N2693*0.15+O2693*0.25+P2693*0.45 -> 41.325 | T2693: =0.25*SUM(M2693:P2693) -> 27.125 | U2693: =SUM(Q2693:S2693)/3 -> 29.491667 | V2693: =SUM(Q2693:T2693)/4 -> 28.9
