Workbook

Sheet TITRES_STAT
B2: Titre : UADH, Du : 31/10/2015, Au : 31/10/2025
B4: Date | C4: Cours | D4: Cours Ajusté | E4: Qte. Ech. | F4: CMP J | G4: Volume | H4: Daily Return
B5: 42310 | C5: 7.7 | D5: 6.695 | E5: 1600
B6: 42311 | C6: 7.68 | D6: 6.6776 | E6: 39800 | H6: =(D6-D5)/D5 -> -0.0025989544 | J6: Business Days | K6: 252
B7: 42312 | C7: 7.67 | D7: 6.6689 | E7: 160 | H7: =(D7-D6)/D6 -> -0.0013028633
B8: 42313 | C8: 7.66 | D8: 6.6602 | E8: 1867 | H8: =(D8-D7)/D7 -> -0.001304563 | J8: Daily Mean | K8: =AVERAGE(H6:H2511) -> -0.00061433667
B9: 42314 | C9: 7.6 | D9: 6.6081 | E9: 1960 | H9: =(D9-D8)/D8 -> -0.0078225879 | J9: Yearly Mean | K9: =K8*K6 -> -0.15481284
B10: 42317 | C10: 7.5 | D10: 6.5211 | E10: 62148 | H10: =(D10-D9)/D9 -> -0.01316566 | J10: Daily Std Deviation | K10: =STDEV(H6:H2511) -> 0.026918471
B11: 42318 | C11: 7.5 | D11: 6.5211 | E11: 486 | H11: =(D11-D10)/D10 -> 0 | J11: Yearly Std Deviation | K11: =K10*SQRT(K6) -> 0.42731748
B12: 42319 | C12: 7.54 | D12: 6.5559 | E12: 217 | H12: =(D12-D11)/D11 -> 0.005336523
B13: 42320 | C13: 7.54 | D13: 6.5559 | E13: 513 | H13: =(D13-D12)/D12 -> 0
B14: 42321 | C14: 7.56 | D14: 6.5733 | E14: 7007 | H14: =(D14-D13)/D13 -> 0.0026540978
B15: 42324 | C15: 7.5 | D15: 6.5211 | E15: 778 | H15: =(D15-D14)/D14 -> -0.0079412167
B16: 42325 | C16: 7.5 | D16: 6.5211 | E16: 1050 | H16: =(D16-D15)/D15 -> 0
B17: 42326 | C17: 7.5 | D17: 6.5211 | E17: 4500 | H17: =(D17-D16)/D16 -> 0
B18: 42327 | C18: 7.5 | D18: 6.5211 | E18: 14063 | H18: =(D18-D17)/D17 -> 0
B19: 42328 | C19: 7.5 | D19: 6.5211 | E19: 1500 | H19: =(D19-D18)/D18 -> 0
B20: 42331 | C20: 7.5 | D20: 6.5211 | E20: 5000 | H20: =(D20-D19)/D19 -> 0
B21: 42332 | C21: 7.5 | D21: 6.5211 | E21: 3564 | H21: =(D21-D20)/D20 -> 0
B22: 42333 | C22: 7.5 | D22: 6.5211 | E22: 1018 | H22: =(D22-D21)/D21 -> 0
B23: 42334 | C23: 7.5 | D23: 6.5211 | E23: 3686 | H23: =(D23-D22)/D22 -> 0
... B842: 43528 | C842: 1.5 | D842: 1.5 | E842: 1 | H842: =(D842-D841)/D841 -> 0
B843: 43529 | C843: 1.46 | D843: 1.46 | E843: 2 | F843: 1.46 | G843: 2.92 | H843: =(D843-D842)/D842 -> -0.026666667
B844: 43530 | C844: 1.5 | D844: 1.5 | E844: 230 | F844: 1.4555 | G844: 334.765 | H844: =(D844-D843)/D843 -> 0.02739726
B845: 43531 | C845: 1.5 | D845: 1.5 | E845: 0 | F845: 0 | G845: 0 | H845: =(D845-D844)/D844 -> 0
B846: 43532 | C846: 1.5 | D846: 1.5 | E846: 0 | F846: 0 | G846: 0 | H846: =(D846-D845)/D845 -> 0
B847: 43535 | C847: 1.49 | D847: 1.49 | E847: 8 | F847: 1.49 | G847: 11.92 | H847: =(D847-D846)/D846 -> -0.0066666667
B848: 43536 | C848: 1.45 | D848: 1.45 | E848: 508 | F848: 1.458 | G848: 740.664 | H848: =(D848-D847)/D847 -> -0.026845638
B849: 43537 | C849: 1.45 | D849: 1.45 | E849: 129 | F849: 1.45 | G849: 187.05 | H849: =(D849-D848)/D848 -> 0
B850: 43538 | C850: 1.41 | D850: 1.41 | E850: 620 | F850: 1.4101 | G850: 874.262 | H850: =(D850-D849)/D849 -> -0.027586207
B851: 43539 | C851: 1.41 | D851: 1.41 | E851: 12349 | F851: 1.4035 | G851: 17331.821 | H851: =(D851-D850)/D850 -> 0
B852: 43542 | C852: 1.37 | D852: 1.37 | E852: 9564 | F852: 1.3702 | G852: 13104.593 | H852: =(D852-D851)/D851 -> -0.028368794
B853: 43543 | C853: 1.41 | D853: 1.41 | E853: 2573 | F853: 1.3628 | G853: 3506.4844 | H853: =(D853-D852)/D852 -> 0.02919708
B854: 43545 | C854: 1.4 | D854: 1.4 | E854: 55 | F854: 1.3545 | G854: 74.4975 | H854: =(D854-D853)/D853 -> -0.0070921986
... B2509: 45958 | C2509: 0.58 | D2509: 0.58 | E2509: 0 | F2509: 0 | G2509: 0 | H2509: =(D2509-D2508)/D2508 -> 0.035714286
B2510: 45959 | C2510: 0.58 | D2510: 0.58 | E2510: 2 | F2510: 0.58 | G2510: 1.16 | H2510: =(D2510-D2509)/D2509 -> 0 | I2510: Number of Shares | J2510: Market Cap | K2510: Average Volume
B2511: 45960 | C2511: 0.58 | D2511: 0.58 | E2511: 840 | F2511: 0.58 | G2511: 487.2 | H2511: =(D2511-D2510)/D2510 -> 0 | I2511: 36953847 | J2511: =I2511*D2511 -> 21433231 | K2511: =SUM(E2307:E2511)/205 -> 7735.9659

Sheet Moving Avg
A1: =TITRES_STAT!B4 -> Date | B1: =TITRES_STAT!D4 -> Cours Ajusté | C1: Daily Change | D1: Simple Moving Avg (5) | E1: Simple Moving Avg (10) | F1: Simple Moving Avg (20) | G1: Simple Moving Avg (50) | H1: Simple Moving Avg (200) | I1: Wheighted Moving Avg | J1: Exp Moving Avg (20) | K1: Exp Moving Avg (50)
A2: =TITRES_STAT!B5 -> 42310 | B2: =TITRES_STAT!D5 -> 6.695 | J2: Alpha= | K2: Alpha=
A3: =TITRES_STAT!B6 -> 42311 | B3: =TITRES_STAT!D6 -> 6.6776 | C3: =B3-B2 -> -0.0174 | J3: (2/(20+1)) | K3: (2/(50+1))
A4: =TITRES_STAT!B7 -> 42312 | B4: =TITRES_STAT!D7 -> 6.6689 | C4: =B4-B3 -> -0.0087 | J4: =2/21 -> 0.095238095 | K4: =2/51 -> 0.039215686
A5: =TITRES_STAT!B8 -> 42313 | B5: =TITRES_STAT!D8 -> 6.6602 | C5: =B5-B4 -> -0.0087 | D5: =AVERAGE(B1:B5) -> 6.675425
A6: =TITRES_STAT!B9 -> 42314 | B6: =TITRES_STAT!D9 -> 6.6081 | C6: =B6-B5 -> -0.0521 | D6: =AVERAGE(B2:B6) -> 6.66196
A7: =TITRES_STAT!B10 -> 42317 | B7: =TITRES_STAT!D10 -> 6.5211 | C7: =B7-B6 -> -0.087 | D7: =AVERAGE(B3:B7) -> 6.62718
A8: =TITRES_STAT!B11 -> 42318 | B8: =TITRES_STAT!D11 -> 6.5211 | C8: =B8-B7 -> 0 | D8: =AVERAGE(B4:B8) -> 6.59588
A9: =TITRES_STAT!B12 -> 42319 | B9: =TITRES_STAT!D12 -> 6.5559 | C9: =B9-B8 -> 0.0348 | D9: =AVERAGE(B5:B9) -> 6.57328
A10: =TITRES_STAT!B13 -> 42320 | B10: =TITRES_STAT!D13 -> 6.5559 | C10: =B10-B9 -> 0 | D10: =AVERAGE(B6:B10) -> 6.55242
A11: =TITRES_STAT!B14 -> 42321 | B11: =TITRES_STAT!D14 -> 6.5733 | C11: =B11-B10 -> 0.0174 | D11: =AVERAGE(B7:B11) -> 6.54546 | E11: =AVERAGE(B2:B11) -> 6.60371
A12: =TITRES_STAT!B15 -> 42324 | B12: =TITRES_STAT!D15 -> 6.5211 | C12: =B12-B11 -> -0.0522 | D12: =AVERAGE(B8:B12) -> 6.54546 | E12: =AVERAGE(B3:B12) -> 6.58632
A13: =TITRES_STAT!B16 -> 42325 | B13: =TITRES_STAT!D16 -> 6.5211 | C13: =B13-B12 -> 0 | D13: =AVERAGE(B9:B13) -> 6.54546 | E13: =AVERAGE(B4:B13) -> 6.57067
A14: =TITRES_STAT!B17 -> 42326 | B14: =TITRES_STAT!D17 -> 6.5211 | C14: =B14-B13 -> 0 | D14: =AVERAGE(B10:B14) -> 6.5385 | E14: =AVERAGE(B5:B14) -> 6.55589
A15: =TITRES_STAT!B18 -> 42327 | B15: =TITRES_STAT!D18 -> 6.5211 | C15: =B15-B14 -> 0 | D15: =AVERAGE(B11:B15) -> 6.53154 | E15: =AVERAGE(B6:B15) -> 6.54198
A16: =TITRES_STAT!B19 -> 42328 | B16: =TITRES_STAT!D19 -> 6.5211 | C16: =B16-B15 -> 0 | D16: =AVERAGE(B12:B16) -> 6.5211 | E16: =AVERAGE(B7:B16) -> 6.53328
A17: =TITRES_STAT!B20 -> 42331 | B17: =TITRES_STAT!D20 -> 6.5211 | C17: =B17-B16 -> 0 | D17: =AVERAGE(B13:B17) -> 6.5211 | E17: =AVERAGE(B8:B17) -> 6.53328
A18: =TITRES_STAT!B21 -> 42332 | B18: =TITRES_STAT!D21 -> 6.5211 | C18: =B18-B17 -> 0 | D18: =AVERAGE(B14:B18) -> 6.5211 | E18: =AVERAGE(B9:B18) -> 6.53328 | I18: {=SUMPRODUCT(B2:B21, (ROW(B2:B21)-ROW(B2)+1)) / (20*21/2)} -> 6.5355538
A19: =TITRES_STAT!B22 -> 42333 | B19: =TITRES_STAT!D22 -> 6.5211 | C19: =B19-B18 -> 0 | D19: =AVERAGE(B15:B19) -> 6.5211 | E19: =AVERAGE(B10:B19) -> 6.5298 | I19: {=SUMPRODUCT(B3:B22, (ROW(B3:B22)-ROW(B3)+1)) / (20*21/2)} -> 6.5390771
A20: =TITRES_STAT!B23 -> 42334 | B20: =TITRES_STAT!D23 -> 6.5211 | C20: =B20-B19 -> 0 | D20: =AVERAGE(B16:B20) -> 6.5211 | E20: =AVERAGE(B11:B20) -> 6.52632 | F20: =AVERAGE(B1:B20) -> 6.5645789 | I20: {=SUMPRODUCT(B4:B23, (ROW(B4:B23)-ROW(B4)+1)) / (20*21/2)} -> 6.5430557 | J20: =F20 -> 6.5645789
A21: =TITRES_STAT!B24 -> 42335 | B21: =TITRES_STAT!D24 -> 6.5211 | C21: =B21-B20 -> 0 | D21: =AVERAGE(B17:B21) -> 6.5211 | E21: =AVERAGE(B12:B21) -> 6.5211 | F21: =AVERAGE(B2:B21) -> 6.562405 | I21: {=SUMPRODUCT(B5:B24, (ROW(B5:B24)-ROW(B5)+1)) / (20*21/2)} -> 6.5382924 | J21: =$J$4*B21+J20*(1-$J$4) -> 6.5604381
A22: =TITRES_STAT!B25 -> 42338 | B22: =TITRES_STAT!D25 -> 6.5994 | C22: =B22-B21 -> 0.0783 | D22: =AVERAGE(B18:B22) -> 6.53676 | E22: =AVERAGE(B13:B22) -> 6.52893 | F22: =AVERAGE(B3:B22) -> 6.557625 | I22: {=SUMPRODUCT(B6:B25, (ROW(B6:B25)-ROW(B6)+1)) / (20*21/2)} -> 6.5268681 | J22: =$J$4*B22+J21*(1-$J$4) -> 6.5641488
A23: =TITRES_STAT!B26 -> 42339 | B23: =TITRES_STAT!D26 -> 6.5994 | C23: =B23-B22 -> 0 | D23: =AVERAGE(B19:B23) -> 6.55242 | E23: =AVERAGE(B14:B23) -> 6.53676 | F23: =AVERAGE(B4:B23) -> 6.553715 | I23: {=SUMPRODUCT(B7:B26, (ROW(B7:B26)-ROW(B7)+1)) / (20*21/2)} -> 6.5008281 | J23: =$J$4*B23+J22*(1-$J$4) -> 6.567506
A24: =TITRES_STAT!B27 -> 42340 | B24: =TITRES_STAT!D27 -> 6.5037 | C24: =B24-B23 -> -0.0957 | D24: =AVERAGE(B20:B24) -> 6.54894 | E24: =AVERAGE(B15:B24) -> 6.53502 | F24: =AVERAGE(B5:B24) -> 6.545455 | I24: {=SUMPRODUCT(B8:B27, (ROW(B8:B27)-ROW(B8)+1)) / (20*21/2)} -> 6.4590538 | J24: =$J$4*B24+J23*(1-$J$4) -> 6.5614293
A25: =TITRES_STAT!B28 -> 42341 | B25: =TITRES_STAT!D28 -> 6.4255 | C25: =B25-B24 -> -0.0782 | D25: =AVERAGE(B21:B25) -> 6.52982 | E25: =AVERAGE(B16:B25) -> 6.52546 | F25: =AVERAGE(B6:B25) -> 6.53372 | I25: {=SUMPRODUCT(B9:B28, (ROW(B9:B28)-ROW(B9)+1)) / (20*21/2)} -> 6.4053148 | J25: =$J$4*B25+J24*(1-$J$4) -> 6.5484836
A26: =TITRES_STAT!B29 -> 42342 | B26: =TITRES_STAT!D29 -> 6.2603 | C26: =B26-B25 -> -0.1652 | D26: =AVERAGE(B22:B26) -> 6.47766 | E26: =AVERAGE(B17:B26) -> 6.49938 | F26: =AVERAGE(B7:B26) -> 6.51633 | I26: {=SUMPRODUCT(B10:B29, (ROW(B10:B29)-ROW(B10)+1)) / (20*21/2)} -> 6.3510767 | J26: =$J$4*B26+J25*(1-$J$4) -> 6.5210376
A27: =TITRES_STAT!B30 -> 42345 | B27: =TITRES_STAT!D30 -> 6.0777 | C27: =B27-B26 -> -0.1826 | D27: =AVERAGE(B23:B27) -> 6.37332 | E27: =AVERAGE(B18:B27) -> 6.45504 | F27: =AVERAGE(B8:B27) -> 6.49416 | I27: {=SUMPRODUCT(B11:B30, (ROW(B11:B30)-ROW(B11)+1)) / (20*21/2)} -> 6.3016424 | J27: =$J$4*B27+J26*(1-$J$4) -> 6.4788149
A28: =TITRES_STAT!B31 -> 42346 | B28: =TITRES_STAT!D31 -> 5.9299 | C28: =B28-B27 -> -0.1478 | D28: =AVERAGE(B24:B28) -> 6.23942 | E28: =AVERAGE(B19:B28) -> 6.39592 | F28: =AVERAGE(B9:B28) -> 6.4646 | I28: {=SUMPRODUCT(B12:B31, (ROW(B12:B31)-ROW(B12)+1)) / (20*21/2)} -> 6.2627195 | J28: =$J$4*B28+J27*(1-$J$4) -> 6.4265373
A29: =TITRES_STAT!B32 -> 42347 | B29: =TITRES_STAT!D32 -> 5.8951 | C29: =B29-B28 -> -0.0348 | D29: =AVERAGE(B25:B29) -> 6.1177 | E29: =AVERAGE(B20:B29) -> 6.33332 | F29: =AVERAGE(B10:B29) -> 6.43156 | I29: {=SUMPRODUCT(B13:B32, (ROW(B13:B32)-ROW(B13)+1)) / (20*21/2)} -> 6.226571 | J29: =$J$4*B29+J28*(1-$J$4) -> 6.3759242
A30: =TITRES_STAT!B33 -> 42348 | B30: =TITRES_STAT!D33 -> 5.9125 | C30: =B30-B29 -> 0.0174 | D30: =AVERAGE(B26:B30) -> 6.0151 | E30: =AVERAGE(B21:B30) -> 6.27246 | F30: =AVERAGE(B11:B30) -> 6.39939 | I30: {=SUMPRODUCT(B14:B33, (ROW(B14:B33)-ROW(B14)+1)) / (20*21/2)} -> 6.1954338 | J30: =$J$4*B30+J29*(1-$J$4) -> 6.3317886
A31: =TITRES_STAT!B34 -> 42349 | B31: =TITRES_STAT!D34 -> 5.9907 | C31: =B31-B30 -> 0.0782 | D31: =AVERAGE(B27:B31) -> 5.96118 | E31: =AVERAGE(B22:B31) -> 6.21942 | F31: =AVERAGE(B12:B31) -> 6.37026 | I31: {=SUMPRODUCT(B15:B34, (ROW(B15:B34)-ROW(B15)+1)) / (20*21/2)} -> 6.1733267 | J31: =$J$4*B31+J30*(1-$J$4) -> 6.299304
A32: =TITRES_STAT!B35 -> 42352 | B32: =TITRES_STAT!D35 -> 5.9907 | C32: =B32-B31 -> 0 | D32: =AVERAGE(B28:B32) -> 5.94378 | E32: =AVERAGE(B23:B32) -> 6.15855 | F32: =AVERAGE(B13:B32) -> 6.34374 | I32: {=SUMPRODUCT(B16:B35, (ROW(B16:B35)-ROW(B16)+1)) / (20*21/2)} -> 6.1764705 | J32: =$J$4*B32+J31*(1-$J$4) -> 6.2699131
... A49: =TITRES_STAT!B52 -> 42377 | B49: =TITRES_STAT!D52 -> 6.0864 | C49: =B49-B48 -> 0.0348 | D49: =AVERAGE(B45:B49) -> 6.08464 | E49: =AVERAGE(B40:B49) -> 6.16289 | F49: =AVERAGE(B30:B49) -> 6.134195 | I49: {=SUMPRODUCT(B33:B52, (ROW(B33:B52)-ROW(B33)+1)) / (20*21/2)} -> 6.1224395 | J49: =$J$4*B49+J48*(1-$J$4) -> 6.1707485
A50: =TITRES_STAT!B53 -> 42380 | B50: =TITRES_STAT!D53 -> 6.0864 | C50: =B50-B49 -> 0 | D50: =AVERAGE(B46:B50) -> 6.07248 | E50: =AVERAGE(B41:B50) -> 6.14637 | F50: =AVERAGE(B31:B50) -> 6.14289 | G50: =AVERAGE(B1:B50) -> 6.3328449 | I50: {=SUMPRODUCT(B34:B53, (ROW(B34:B53)-ROW(B34)+1)) / (20*21/2)} -> 6.1051281 | J50: =$J$4*B50+J49*(1-$J$4) -> 6.1627154 | K50: =G50 -> 6.3328449
A51: =TITRES_STAT!B54 -> 42381 | B51: =TITRES_STAT!D54 -> 6.0864 | C51: =B51-B50 -> 0 | D51: =AVERAGE(B47:B51) -> 6.07248 | E51: =AVERAGE(B42:B51) -> 6.13333 | F51: =AVERAGE(B32:B51) -> 6.147675 | G51: =AVERAGE(B2:B51) -> 6.327916 | I51: {=SUMPRODUCT(B35:B54, (ROW(B35:B54)-ROW(B35)+1)) / (20*21/2)} -> 6.0831033 | J51: =$J$4*B51+J50*(1-$J$4) -> 6.1554472 | K51: =$K$4*B51+(1-$K$4)*K50 -> 6.3231804
A52: =TITRES_STAT!B55 -> 42382 | B52: =TITRES_STAT!D55 -> 5.9646 | C52: =B52-B51 -> -0.1218 | D52: =AVERAGE(B48:B52) -> 6.05508 | E52: =AVERAGE(B43:B52) -> 6.1142 | F52: =AVERAGE(B33:B52) -> 6.14637 | G52: =AVERAGE(B3:B52) -> 6.313308 | I52: {=SUMPRODUCT(B36:B55, (ROW(B36:B55)-ROW(B36)+1)) / (20*21/2)} -> 6.0635638 | J52: =$J$4*B52+J51*(1-$J$4) -> 6.1372713 | K52: =$K$4*B52+(1-$K$4)*K51 -> 6.3091184
A53: =TITRES_STAT!B56 -> 42384 | B53: =TITRES_STAT!D56 -> 5.9646 | C53: =B53-B52 -> 0 | D53: =AVERAGE(B49:B53) -> 6.03768 | E53: =AVERAGE(B44:B53) -> 6.0855 | F53: =AVERAGE(B34:B53) -> 6.14376 | G53: =AVERAGE(B4:B53) -> 6.299048 | I53: {=SUMPRODUCT(B37:B56, (ROW(B37:B56)-ROW(B37)+1)) / (20*21/2)} -> 6.0426143 | J53: =$J$4*B53+J52*(1-$J$4) -> 6.1208264 | K53: =$K$4*B53+(1-$K$4)*K52 -> 6.2956079
A54: =TITRES_STAT!B57 -> 42387 | B54: =TITRES_STAT!D57 -> 5.9125 | C54: =B54-B53 -> -0.0521 | D54: =AVERAGE(B50:B54) -> 6.0029 | E54: =AVERAGE(B45:B54) -> 6.04377 | F54: =AVERAGE(B35:B54) -> 6.135065 | G54: =AVERAGE(B5:B54) -> 6.28392 | I54: {=SUMPRODUCT(B38:B57, (ROW(B38:B57)-ROW(B38)+1)) / (20*21/2)} -> 6.0219119 | J54: =$J$4*B54+J53*(1-$J$4) -> 6.1009858 | K54: =$K$4*B54+(1-$K$4)*K53 -> 6.2805841
A55: =TITRES_STAT!B58 -> 42388 | B55: =TITRES_STAT!D58 -> 5.9299 | C55: =B55-B54 -> 0.0174 | D55: =AVERAGE(B51:B55) -> 5.9716 | E55: =AVERAGE(B46:B55) -> 6.02204 | F55: =AVERAGE(B36:B55) -> 6.11507 | G55: =AVERAGE(B6:B55) -> 6.269314 | I55: {=SUMPRODUCT(B39:B58, (ROW(B39:B58)-ROW(B39)+1)) / (20*21/2)} -> 6.0187648 | J55: =$J$4*B55+J54*(1-$J$4) -> 6.0846919 | K55: =$K$4*B55+(1-$K$4)*K54 -> 6.2668317
A56: =TITRES_STAT!B59 -> 42389 | B56: =TITRES_STAT!D59 -> 5.8951 | C56: =B56-B55 -> -0.0348 | D56: =AVERAGE(B52:B56) -> 5.93334 | E56: =AVERAGE(B47:B56) -> 6.00291 | F56: =AVERAGE(B37:B56) -> 6.095075 | G56: =AVERAGE(B7:B56) -> 6.255054 | I56: {=SUMPRODUCT(B40:B59, (ROW(B40:B59)-ROW(B40)+1)) / (20*21/2)} -> 6.0199676 | J56: =$J$4*B56+J55*(1-$J$4) -> 6.0666355 | K56: =$K$4*B56+(1-$K$4)*K55 -> 6.252254
...

Sheet RSI
A1: =TITRES_STAT!B4 -> Date | B1: =TITRES_STAT!D4 -> Cours Ajusté | C1: Change | D1: Gain | E1: Loss | F1: Avg Gain | G1: Avg Loss | H1: RS | I1: 14-Day RSI
A2: =TITRES_STAT!B5 -> 42310 | B2: =TITRES_STAT!D5 -> 6.695
A3: =TITRES_STAT!B6 -> 42311 | B3: =TITRES_STAT!D6 -> 6.6776 | C3: =B3-B2 -> -0.0174 | D3: =IF(C3>0,C3,0) -> 0 | E3: =IF(C3<0,-C3,0) -> 0.0174
A4: =TITRES_STAT!B7 -> 42312 | B4: =TITRES_STAT!D7 -> 6.6689 | C4: =B4-B3 -> -0.0087 | D4: =IF(C4>0,C4,0) -> 0 | E4: =IF(C4<0,-C4,0) -> 0.0087
A5: =TITRES_STAT!B8 -> 42313 | B5: =TITRES_STAT!D8 -> 6.6602 | C5: =B5-B4 -> -0.0087 | D5: =IF(C5>0,C5,0) -> 0 | E5: =IF(C5<0,-C5,0) -> 0.0087
A6: =TITRES_STAT!B9 -> 42314 | B6: =TITRES_STAT!D9 -> 6.6081 | C6: =B6-B5 -> -0.0521 | D6: =IF(C6>0,C6,0) -> 0 | E6: =IF(C6<0,-C6,0) -> 0.0521
A7: =TITRES_STAT!B10 -> 42317 | B7: =TITRES_STAT!D10 -> 6.5211 | C7: =B7-B6 -> -0.087 | D7: =IF(C7>0,C7,0) -> 0 | E7: =IF(C7<0,-C7,0) -> 0.087
A8: =TITRES_STAT!B11 -> 42318 | B8: =TITRES_STAT!D11 -> 6.5211 | C8: =B8-B7 -> 0 | D8: =IF(C8>0,C8,0) -> 0 | E8: =IF(C8<0,-C8,0) -> 0
A9: =TITRES_STAT!B12 -> 42319 | B9: =TITRES_STAT!D12 -> 6.5559 | C9: =B9-B8 -> 0.0348 | D9: =IF(C9>0,C9,0) -> 0.0348 | E9: =IF(C9<0,-C9,0) -> 0
A10: =TITRES_STAT!B13 -> 42320 | B10: =TITRES_STAT!D13 -> 6.5559 | C10: =B10-B9 -> 0 | D10: =IF(C10>0,C10,0) -> 0 | E10: =IF(C10<0,-C10,0) -> 0
A11: =TITRES_STAT!B14 -> 42321 | B11: =TITRES_STAT!D14 -> 6.5733 | C11: =B11-B10 -> 0.0174 | D11: =IF(C11>0,C11,0) -> 0.0174 | E11: =IF(C11<0,-C11,0) -> 0
A12: =TITRES_STAT!B15 -> 42324 | B12: =TITRES_STAT!D15 -> 6.5211 | C12: =B12-B11 -> -0.0522 | D12: =IF(C12>0,C12,0) -> 0 | E12: =IF(C12<0,-C12,0) -> 0.0522
A13: =TITRES_STAT!B16 -> 42325 | B13: =TITRES_STAT!D16 -> 6.5211 | C13: =B13-B12 -> 0 | D13: =IF(C13>0,C13,0) -> 0 | E13: =IF(C13<0,-C13,0) -> 0
A14: =TITRES_STAT!B17 -> 42326 | B14: =TITRES_STAT!D17 -> 6.5211 | C14: =B14-B13 -> 0 | D14: =IF(C14>0,C14,0) -> 0 | E14: =IF(C14<0,-C14,0) -> 0
A15: =TITRES_STAT!B18 -> 42327 | B15: =TITRES_STAT!D18 -> 6.5211 | C15: =B15-B14 -> 0 | D15: =IF(C15>0,C15,0) -> 0 | E15: =IF(C15<0,-C15,0) -> 0
A16: =TITRES_STAT!B19 -> 42328 | B16: =TITRES_STAT!D19 -> 6.5211 | C16: =B16-B15 -> 0 | D16: =IF(C16>0,C16,0) -> 0 | E16: =IF(C16<0,-C16,0) -> 0 | F16: =(SUM(D3:D16)/14) -> 0.0037285714 | G16: =SUM(E3:E16)/14 -> 0.01615 | H16: =F16/G16 -> 0.2308713 | I16: =IF(G16=0,100,100-(100/(1+H16))) -> 18.756737
A17: =TITRES_STAT!B20 -> 42331 | B17: =TITRES_STAT!D20 -> 6.5211 | C17: =B17-B16 -> 0 | D17: =IF(C17>0,C17,0) -> 0 | E17: =IF(C17<0,-C17,0) -> 0 | F17: =((F16*13)+D17)/14 -> 0.0034622449 | G17: =((G16*13)+E17)/14 -> 0.014996429 | H17: =F17/G17 -> 0.2308713 | I17: =IF(G17=0,100,100-(100/(1+H17))) -> 18.756737
A18: =TITRES_STAT!B21 -> 42332 | B18: =TITRES_STAT!D21 -> 6.5211 | C18: =B18-B17 -> 0 | D18: =IF(C18>0,C18,0) -> 0 | E18: =IF(C18<0,-C18,0) -> 0 | F18: =((F17*13)+D18)/14 -> 0.0032149417 | G18: =((G17*13)+E18)/14 -> 0.013925255 | H18: =F18/G18 -> 0.2308713 | I18: =IF(G18=0,100,100-(100/(1+H18))) -> 18.756737
A19: =TITRES_STAT!B22 -> 42333 | B19: =TITRES_STAT!D22 -> 6.5211 | C19: =B19-B18 -> 0 | D19: =IF(C19>0,C19,0) -> 0 | E19: =IF(C19<0,-C19,0) -> 0 | F19: =((F18*13)+D19)/14 -> 0.002985303 | G19: =((G18*13)+E19)/14 -> 0.012930594 | H19: =F19/G19 -> 0.2308713 | I19: =IF(G19=0,100,100-(100/(1+H19))) -> 18.756737
A20: =TITRES_STAT!B23 -> 42334 | B20: =TITRES_STAT!D23 -> 6.5211 | C20: =B20-B19 -> 0 | D20: =IF(C20>0,C20,0) -> 0 | E20: =IF(C20<0,-C20,0) -> 0 | F20: =((F19*13)+D20)/14 -> 0.0027720671 | G20: =((G19*13)+E20)/14 -> 0.01200698 | H20: =F20/G20 -> 0.2308713 | I20: =IF(G20=0,100,100-(100/(1+H20))) -> 18.756737
A21: =TITRES_STAT!B24 -> 42335 | B21: =TITRES_STAT!D24 -> 6.5211 | C21: =B21-B20 -> 0 | D21: =IF(C21>0,C21,0) -> 0 | E21: =IF(C21<0,-C21,0) -> 0 | F21: =((F20*13)+D21)/14 -> 0.0025740623 | G21: =((G20*13)+E21)/14 -> 0.011149339 | H21: =F21/G21 -> 0.2308713 | I21: =IF(G21=0,100,100-(100/(1+H21))) -> 18.756737
A22: =TITRES_STAT!B25 -> 42338 | B22: =TITRES_STAT!D25 -> 6.5994 | C22: =B22-B21 -> 0.0783 | D22: =IF(C22>0,C22,0) -> 0.0783 | E22: =IF(C22<0,-C22,0) -> 0 | F22: =((F21*13)+D22)/14 -> 0.0079830578 | G22: =((G21*13)+E22)/14 -> 0.010352957 | H22: =F22/G22 -> 0.77108961 | I22: =IF(G22=0,100,100-(100/(1+H22))) -> 43.537583
A23: =TITRES_STAT!B26 -> 42339 | B23: =TITRES_STAT!D26 -> 6.5994 | C23: =B23-B22 -> 0 | D23: =IF(C23>0,C23,0) -> 0 | E23: =IF(C23<0,-C23,0) -> 0 | F23: =((F22*13)+D23)/14 -> 0.0074128394 | G23: =((G22*13)+E23)/14 -> 0.0096134604 | H23: =F23/G23 -> 0.77108961 | I23: =IF(G23=0,100,100-(100/(1+H23))) -> 43.537583
A24: =TITRES_STAT!B27 -> 42340 | B24: =TITRES_STAT!D27 -> 6.5037 | C24: =B24-B23 -> -0.0957 | D24: =IF(C24>0,C24,0) -> 0 | E24: =IF(C24<0,-C24,0) -> 0.0957 | F24: =((F23*13)+D24)/14 -> 0.0068833509 | G24: =((G23*13)+E24)/14 -> 0.015762499 | H24: =F24/G24 -> 0.4366916 | I24: =IF(G24=0,100,100-(100/(1+H24))) -> 30.39564
A25: =TITRES_STAT!B28 -> 42341 | B25: =TITRES_STAT!D28 -> 6.4255 | C25: =B25-B24 -> -0.0782 | D25: =IF(C25>0,C25,0) -> 0 | E25: =IF(C25<0,-C25,0) -> 0.0782 | F25: =((F24*13)+D25)/14 -> 0.006391683 | G25: =((G24*13)+E25)/14 -> 0.02022232 | H25: =F25/G25 -> 0.3160707 | I25: =IF(G25=0,100,100-(100/(1+H25))) -> 24.01624
A26: =TITRES_STAT!B29 -> 42342 | B26: =TITRES_STAT!D29 -> 6.2603 | C26: =B26-B25 -> -0.1652 | D26: =IF(C26>0,C26,0) -> 0 | E26: =IF(C26<0,-C26,0) -> 0.1652 | F26: =((F25*13)+D26)/14 -> 0.0059351342 | G26: =((G25*13)+E26)/14 -> 0.030577869 | H26: =F26/G26 -> 0.19409901 | I26: =IF(G26=0,100,100-(100/(1+H26))) -> 16.254851
A27: =TITRES_STAT!B30 -> 42345 | B27: =TITRES_STAT!D30 -> 6.0777 | C27: =B27-B26 -> -0.1826 | D27: =IF(C27>0,C27,0) -> 0 | E27: =IF(C27<0,-C27,0) -> 0.1826 | F27: =((F26*13)+D27)/14 -> 0.005511196 | G27: =((G26*13)+E27)/14 -> 0.041436593 | H27: =F27/G27 -> 0.13300312 | I27: =IF(G27=0,100,100-(100/(1+H27))) -> 11.73899
A28: =TITRES_STAT!B31 -> 42346 | B28: =TITRES_STAT!D31 -> 5.9299 | C28: =B28-B27 -> -0.1478 | D28: =IF(C28>0,C28,0) -> 0 | E28: =IF(C28<0,-C28,0) -> 0.1478 | F28: =((F27*13)+D28)/14 -> 0.0051175392 | G28: =((G27*13)+E28)/14 -> 0.049033979 | H28: =F28/G28 -> 0.1043672 | I28: =IF(G28=0,100,100-(100/(1+H28))) -> 9.4504076
... A2508: =TITRES_STAT!B2511 -> 45960 | B2508: =TITRES_STAT!D2511 -> 0.58 | C2508: =B2508-B2507 -> 0 | D2508: =IF(C2508>0,C2508,0) -> 0 | E2508: =IF(C2508<0,-C2508,0) -> 0 | F2508: =((F2507*13)+D2508)/14 -> 0.0060795203 | G2508: =((G2507*13)+E2508)/14 -> 0.0053775474 | H2508: =F2508/G2508 -> 1.1305377 | I2508: =IF(G2508=0,100,100-(100/(1+H2508))) -> 53.063493

Sheet MACD
A1: =TITRES_STAT!B4 -> Date | B1: =TITRES_STAT!D4 -> Cours Ajusté | C1: EMA 12-Period | D1: EMA 26-Period | E1: MACD Line | F1: Signal Line | G1: MACD Histogram | H1: Signal
A2: =TITRES_STAT!B5 -> 42310 | B2: =TITRES_STAT!D5 -> 6.695 | C2: Alpha= | D2: Alpha=
A3: =TITRES_STAT!B6 -> 42311 | B3: =TITRES_STAT!D6 -> 6.6776 | C3: (2/12+1) | D3: (2/26+1)
A4: =TITRES_STAT!B7 -> 42312 | B4: =TITRES_STAT!D7 -> 6.6689 | C4: =2/13 -> 0.15384615 | D4: =2/27 -> 0.074074074
A5: =TITRES_STAT!B8 -> 42313 | B5: =TITRES_STAT!D8 -> 6.6602
A6: =TITRES_STAT!B9 -> 42314 | B6: =TITRES_STAT!D9 -> 6.6081
A7: =TITRES_STAT!B10 -> 42317 | B7: =TITRES_STAT!D10 -> 6.5211
A8: =TITRES_STAT!B11 -> 42318 | B8: =TITRES_STAT!D11 -> 6.5211
A9: =TITRES_STAT!B12 -> 42319 | B9: =TITRES_STAT!D12 -> 6.5559
A10: =TITRES_STAT!B13 -> 42320 | B10: =TITRES_STAT!D13 -> 6.5559
A11: =TITRES_STAT!B14 -> 42321 | B11: =TITRES_STAT!D14 -> 6.5733
A12: =TITRES_STAT!B15 -> 42324 | B12: =TITRES_STAT!D15 -> 6.5211
A13: =TITRES_STAT!B16 -> 42325 | B13: =TITRES_STAT!D16 -> 6.5211 | C13: =AVERAGE(B2:B13) -> 6.5899417
A14: =TITRES_STAT!B17 -> 42326 | B14: =TITRES_STAT!D17 -> 6.5211 | C14: =$C$4*B4+C13*(1-$C$4) -> 6.6020891
A15: =TITRES_STAT!B18 -> 42327 | B15: =TITRES_STAT!D18 -> 6.5211 | C15: =$C$4*B5+C14*(1-$C$4) -> 6.6110292
A16: =TITRES_STAT!B19 -> 42328 | B16: =TITRES_STAT!D19 -> 6.5211 | C16: =$C$4*B6+C15*(1-$C$4) -> 6.6105786
A17: =TITRES_STAT!B20 -> 42331 | B17: =TITRES_STAT!D20 -> 6.5211 | C17: =$C$4*B7+C16*(1-$C$4) -> 6.5968127
A18: =TITRES_STAT!B21 -> 42332 | B18: =TITRES_STAT!D21 -> 6.5211 | C18: =$C$4*B8+C17*(1-$C$4) -> 6.5851646
A19: =TITRES_STAT!B22 -> 42333 | B19: =TITRES_STAT!D22 -> 6.5211 | C19: =$C$4*B9+C18*(1-$C$4) -> 6.5806623
A20: =TITRES_STAT!B23 -> 42334 | B20: =TITRES_STAT!D23 -> 6.5211 | C20: =$C$4*B10+C19*(1-$C$4) -> 6.5768527
A21: =TITRES_STAT!B24 -> 42335 | B21: =TITRES_STAT!D24 -> 6.5211 | C21: =$C$4*B11+C20*(1-$C$4) -> 6.5763062
A22: =TITRES_STAT!B25 -> 42338 | B22: =TITRES_STAT!D25 -> 6.5994 | C22: =$C$4*B12+C21*(1-$C$4) -> 6.5678129
A23: =TITRES_STAT!B26 -> 42339 | B23: =TITRES_STAT!D26 -> 6.5994 | C23: =$C$4*B13+C22*(1-$C$4) -> 6.5606263
A24: =TITRES_STAT!B27 -> 42340 | B24: =TITRES_STAT!D27 -> 6.5037 | C24: =$C$4*B14+C23*(1-$C$4) -> 6.5545453
A25: =TITRES_STAT!B28 -> 42341 | B25: =TITRES_STAT!D28 -> 6.4255 | C25: =$C$4*B15+C24*(1-$C$4) -> 6.5493999
A26: =TITRES_STAT!B29 -> 42342 | B26: =TITRES_STAT!D29 -> 6.2603 | C26: =$C$4*B16+C25*(1-$C$4) -> 6.5450461
A27: =TITRES_STAT!B30 -> 42345 | B27: =TITRES_STAT!D30 -> 6.0777 | C27: =$C$4*B17+C26*(1-$C$4) -> 6.5413621 | D27: =AVERAGE(B2:B27) -> 6.5274654 | E27: =C27-D27 -> 0.01389667
A28: =TITRES_STAT!B31 -> 42346 | B28: =TITRES_STAT!D31 -> 5.9299 | C28: =$C$4*B18+C27*(1-$C$4) -> 6.5382448 | D28: =$D$4*B28+(1-$D$4)*D27 -> 6.4832013 | E28: =C28-D28 -> 0.055043533
A29: =TITRES_STAT!B32 -> 42347 | B29: =TITRES_STAT!D32 -> 5.8951 | C29: =$C$4*B19+C28*(1-$C$4) -> 6.5356072 | D29: =$D$4*B29+(1-$D$4)*D28 -> 6.4396382 | E29: =C29-D29 -> 0.095968927
A30: =TITRES_STAT!B33 -> 42348 | B30: =TITRES_STAT!D33 -> 5.9125 | C30: =$C$4*B20+C29*(1-$C$4) -> 6.5333753 | D30: =$D$4*B30+(1-$D$4)*D29 -> 6.4005909 | E30: =C30-D30 -> 0.13278433
A31: =TITRES_STAT!B34 -> 42349 | B31: =TITRES_STAT!D34 -> 5.9907 | C31: =$C$4*B21+C30*(1-$C$4) -> 6.5314868 | D31: =$D$4*B31+(1-$D$4)*D30 -> 6.3702287 | E31: =C31-D31 -> 0.16125812
A32: =TITRES_STAT!B35 -> 42352 | B32: =TITRES_STAT!D35 -> 5.9907 | C32: =$C$4*B22+C31*(1-$C$4) -> 6.541935 | D32: =$D$4*B32+(1-$D$4)*D31 -> 6.3421154 | E32: =C32-D32 -> 0.19981954
A33: =TITRES_STAT!B36 -> 42353 | B33: =TITRES_STAT!D36 -> 6.0168 | C33: =$C$4*B23+C32*(1-$C$4) -> 6.5507757 | D33: =$D$4*B33+(1-$D$4)*D32 -> 6.318018 | E33: =C33-D33 -> 0.23275776
A34: =TITRES_STAT!B37 -> 42354 | B34: =TITRES_STAT!D37 -> 6.0864 | C34: =$C$4*B24+C33*(1-$C$4) -> 6.5435333 | D34: =$D$4*B34+(1-$D$4)*D33 -> 6.3008611 | E34: =C34-D34 -> 0.24267222
A35: =TITRES_STAT!B38 -> 42355 | B35: =TITRES_STAT!D38 -> 6.3298 | C35: =$C$4*B25+C34*(1-$C$4) -> 6.5253743 | D35: =$D$4*B35+(1-$D$4)*D34 -> 6.3030047 | E35: =C35-D35 -> 0.22236963 | F35: =AVERAGE(E27:E35) -> 0.15073008 | G35: =E35-F35 -> 0.071639546 | H35: =IF(G35<0,"Hold","Sell") -> Sell
A36: =TITRES_STAT!B39 -> 42356 | B36: =TITRES_STAT!D39 -> 6.295 | C36: =$C$4*B26+C35*(1-$C$4) -> 6.4845937 | D36: =$D$4*B36+(1-$D$4)*D35 -> 6.3024118 | E36: =C36-D36 -> 0.1821819 | F36: =(E36*(2/(10)))+((1-(2/10))*F35) -> 0.15702045 | G36: =E36-F36 -> 0.025161456 | H36: =IF(G36<0,"Hold","Sell") -> Sell
A37: =TITRES_STAT!B40 -> 42359 | B37: =TITRES_STAT!D40 -> 6.2603 | C37: =$C$4*B27+C36*(1-$C$4) -> 6.4219947 | D37: =$D$4*B37+(1-$D$4)*D36 -> 6.2992924 | E37: =C37-D37 -> 0.12270226 | F37: =(E37*(2/(10)))+((1-(2/10))*F36) -> 0.15015681 | G37: =E37-F37 -> -0.027454545 | H37: =IF(G37<0,"Hold","Sell") -> Hold
A38: =TITRES_STAT!B41 -> 42360 | B38: =TITRES_STAT!D41 -> 6.0864 | C38: =$C$4*B28+C37*(1-$C$4) -> 6.3462878 | D38: =$D$4*B38+(1-$D$4)*D37 -> 6.2835226 | E38: =C38-D38 -> 0.062765202 | F38: =(E38*(2/(10)))+((1-(2/10))*F37) -> 0.13267849 | G38: =E38-F38 -> -0.069913286 | H38: =IF(G38<0,"Hold","Sell") -> Hold
A39: =TITRES_STAT!B42 -> 42361 | B39: =TITRES_STAT!D42 -> 6.0864 | C39: =$C$4*B29+C38*(1-$C$4) -> 6.2768743 | D39: =$D$4*B39+(1-$D$4)*D38 -> 6.2689209 | E39: =C39-D39 -> 0.0079533697 | F39: =(E39*(2/(10)))+((1-(2/10))*F38) -> 0.10773346 | G39: =E39-F39 -> -0.099780095 | H39: =IF(G39<0,"Hold","Sell") -> Hold
A40: =TITRES_STAT!B43 -> 42363 | B40: =TITRES_STAT!D43 -> 6.2516 | C40: =$C$4*B30+C39*(1-$C$4) -> 6.2208167 | D40: =$D$4*B40+(1-$D$4)*D39 -> 6.2676379 | E40: =C40-D40 -> -0.046821181 | F40: =(E40*(2/(10)))+((1-(2/10))*F39) -> 0.076822535 | G40: =E40-F40 -> -0.12364372 | H40: =IF(G40<0,"Hold","Sell") -> Hold
...

Sheet OBV
A1: =TITRES_STAT!B4 -> Date | B1: =TITRES_STAT!C4 -> Cours | C1: =TITRES_STAT!D4 -> Cours Ajusté | D1: =TITRES_STAT!E4 -> Qte. Ech. | E1: OBV | F1: OBV Trend Signal | G1: OBV Strength | H1: Price-OBV Alignment
A2: =TITRES_STAT!B5 -> 42310 | B2: =TITRES_STAT!C5 -> 7.7 | C2: =TITRES_STAT!D5 -> 6.695 | D2: =TITRES_STAT!E5 -> 1600 | E2: =D2 -> 1600
A3: =TITRES_STAT!B6 -> 42311 | B3: =TITRES_STAT!C6 -> 7.68 | C3: =TITRES_STAT!D6 -> 6.6776 | D3: =TITRES_STAT!E6 -> 39800 | E3: =IF(B3>B2, E2+D3, IF(B3<B2, E2-D3, E2)) -> -38200
A4: =TITRES_STAT!B7 -> 42312 | B4: =TITRES_STAT!C7 -> 7.67 | C4: =TITRES_STAT!D7 -> 6.6689 | D4: =TITRES_STAT!E7 -> 160 | E4: =IF(B4>B3, E3+D4, IF(B4<B3, E3-D4, E3)) -> -38360
A5: =TITRES_STAT!B8 -> 42313 | B5: =TITRES_STAT!C8 -> 7.66 | C5: =TITRES_STAT!D8 -> 6.6602 | D5: =TITRES_STAT!E8 -> 1867 | E5: =IF(B5>B4, E4+D5, IF(B5<B4, E4-D5, E4)) -> -40227
A6: =TITRES_STAT!B9 -> 42314 | B6: =TITRES_STAT!C9 -> 7.6 | C6: =TITRES_STAT!D9 -> 6.6081 | D6: =TITRES_STAT!E9 -> 1960 | E6: =IF(B6>B5, E5+D6, IF(B6<B5, E5-D6, E5)) -> -42187 | H6: =IF(AND(B6>B1, E6>E1), "CONFIRMED BULLISH", IF(AND(B6<B1, E6<E1), "CONFIRMED BEARISH", IF(AND(B6>B1, E6<E1), "BEARISH DIVERGENCE", IF(AND(B6<B1, E6>E1), "BULLISH DIVERGENCE", "NEUTRAL")))) -> CONFIRMED BEARISH
A7: =TITRES_STAT!B10 -> 42317 | B7: =TITRES_STAT!C10 -> 7.5 | C7: =TITRES_STAT!D10 -> 6.5211 | D7: =TITRES_STAT!E10 -> 62148 | E7: =IF(B7>B6, E6+D7, IF(B7<B6, E6-D7, E6)) -> -104335 | F7: =IF(E7>E2,"BULLISH",IF(E7<E2,"BEARISH","NEUTRAL")) -> BEARISH | G7: =IF((E7-E2)/E2 > 0.02, "STRONG", IF((E7-E2)/E2 < -0.02, "WEAK", "NEUTRAL")) -> WEAK | H7: =IF(AND(B7>B2, E7>E2), "CONFIRMED BULLISH", IF(AND(B7<B2, E7<E2), "CONFIRMED BEARISH", IF(AND(B7>B2, E7<E2), "BEARISH DIVERGENCE", IF(AND(B7<B2, E7>E2), "BULLISH DIVERGENCE", "NEUTRAL")))) -> CONFIRMED BEARISH
A8: =TITRES_STAT!B11 -> 42318 | B8: =TITRES_STAT!C11 -> 7.5 | C8: =TITRES_STAT!D11 -> 6.5211 | D8: =TITRES_STAT!E11 -> 486 | E8: =IF(B8>B7, E7+D8, IF(B8<B7, E7-D8, E7)) -> -104335 | F8: =IF(E8>E3,"BULLISH",IF(E8<E3,"BEARISH","NEUTRAL")) -> BEARISH | G8: =IF((E8-E3)/E3 > 0.02, "STRONG", IF((E8-E3)/E3 < -0.02, "WEAK", "NEUTRAL")) -> STRONG | H8: =IF(AND(B8>B3, E8>E3), "CONFIRMED BULLISH", IF(AND(B8<B3, E8<E3), "CONFIRMED BEARISH", IF(AND(B8>B3, E8<E3), "BEARISH DIVERGENCE", IF(AND(B8<B3, E8>E3), "BULLISH DIVERGENCE", "NEUTRAL")))) -> CONFIRMED BEARISH
A9: =TITRES_STAT!B12 -> 42319 | B9: =TITRES_STAT!C12 -> 7.54 | C9: =TITRES_STAT!D12 -> 6.5559 | D9: =TITRES_STAT!E12 -> 217 | E9: =IF(B9>B8, E8+D9, IF(B9<B8, E8-D9, E8)) -> -104118 | F9: =IF(E9>E4,"BULLISH",IF(E9<E4,"BEARISH","NEUTRAL")) -> BEARISH | G9: =IF((E9-E4)/E4 > 0.02, "STRONG", IF((E9-E4)/E4 < -0.02, "WEAK", "NEUTRAL")) -> STRONG | H9: =IF(AND(B9>B4, E9>E4), "CONFIRMED BULLISH", IF(AND(B9<B4, E9<E4), "CONFIRMED BEARISH", IF(AND(B9>B4, E9<E4), "BEARISH DIVERGENCE", IF(AND(B9<B4, E9>E4), "BULLISH DIVERGENCE", "NEUTRAL")))) -> CONFIRMED BEARISH
A10: =TITRES_STAT!B13 -> 42320 | B10: =TITRES_STAT!C13 -> 7.54 | C10: =TITRES_STAT!D13 -> 6.5559 | D10: =TITRES_STAT!E13 -> 513 | E10: =IF(B10>B9, E9+D10, IF(B10<B9, E9-D10, E9)) -> -104118 | F10: =IF(E10>E5,"BULLISH",IF(E10<E5,"BEARISH","NEUTRAL")) -> BEARISH | G10: =IF((E10-E5)/E5 > 0.02, "STRONG", IF((E10-E5)/E5 < -0.02, "WEAK", "NEUTRAL")) -> STRONG | H10: =IF(AND(B10>B5, E10>E5), "CONFIRMED BULLISH", IF(AND(B10<B5, E10<E5), "CONFIRMED BEARISH", IF(AND(B10>B5, E10<E5), "BEARISH DIVERGENCE", IF(AND(B10<B5, E10>E5), "BULLISH DIVERGENCE", "NEUTRAL")))) -> CONFIRMED BEARISH
A11: =TITRES_STAT!B14 -> 42321 | B11: =TITRES_STAT!C14 -> 7.56 | C11: =TITRES_STAT!D14 -> 6.5733 | D11: =TITRES_STAT!E14 -> 7007 | E11: =IF(B11>B10, E10+D11, IF(B11<B10, E10-D11, E10)) -> -97111 | F11: =IF(E11>E6,"BULLISH",IF(E11<E6,"BEARISH","NEUTRAL")) -> BEARISH | G11: =IF((E11-E6)/E6 > 0.02, "STRONG", IF((E11-E6)/E6 < -0.02, "WEAK", "NEUTRAL")) -> STRONG | H11: =IF(AND(B11>B6, E11>E6), "CONFIRMED BULLISH", IF(AND(B11<B6, E11<E6), "CONFIRMED BEARISH", IF(AND(B11>B6, E11<E6), "BEARISH DIVERGENCE", IF(AND(B11<B6, E11>E6), "BULLISH DIVERGENCE", "NEUTRAL")))) -> CONFIRMED BEARISH
A12: =TITRES_STAT!B15 -> 42324 | B12: =TITRES_STAT!C15 -> 7.5 | C12: =TITRES_STAT!D15 -> 6.5211 | D12: =TITRES_STAT!E15 -> 778 | E12: =IF(B12>B11, E11+D12, IF(B12<B11, E11-D12, E11)) -> -97889 | F12: =IF(E12>E7,"BULLISH",IF(E12<E7,"BEARISH","NEUTRAL")) -> BULLISH | G12: =IF((E12-E7)/E7 > 0.02, "STRONG", IF((E12-E7)/E7 < -0.02, "WEAK", "NEUTRAL")) -> WEAK | H12: =IF(AND(B12>B7, E12>E7), "CONFIRMED BULLISH", IF(AND(B12<B7, E12<E7), "CONFIRMED BEARISH", IF(AND(B12>B7, E12<E7), "BEARISH DIVERGENCE", IF(AND(B12<B7, E12>E7), "BULLISH DIVERGENCE", "NEUTRAL")))) -> NEUTRAL
A13: =TITRES_STAT!B16 -> 42325 | B13: =TITRES_STAT!C16 -> 7.5 | C13: =TITRES_STAT!D16 -> 6.5211 | D13: =TITRES_STAT!E16 -> 1050 | E13: =IF(B13>B12, E12+D13, IF(B13<B12, E12-D13, E12)) -> -97889 | F13: =IF(E13>E8,"BULLISH",IF(E13<E8,"BEARISH","NEUTRAL")) -> BULLISH | G13: =IF((E13-E8)/E8 > 0.02, "STRONG", IF((E13-E8)/E8 < -0.02, "WEAK", "NEUTRAL")) -> WEAK | H13: =IF(AND(B13>B8, E13>E8), "CONFIRMED BULLISH", IF(AND(B13<B8, E13<E8), "CONFIRMED BEARISH", IF(AND(B13>B8, E13<E8), "BEARISH DIVERGENCE", IF(AND(B13<B8, E13>E8), "BULLISH DIVERGENCE", "NEUTRAL")))) -> NEUTRAL
A14: =TITRES_STAT!B17 -> 42326 | B14: =TITRES_STAT!C17 -> 7.5 | C14: =TITRES_STAT!D17 -> 6.5211 | D14: =TITRES_STAT!E17 -> 4500 | E14: =IF(B14>B13, E13+D14, IF(B14<B13, E13-D14, E13)) -> -97889 | F14: =IF(E14>E9,"BULLISH",IF(E14<E9,"BEARISH","NEUTRAL")) -> BULLISH | G14: =IF((E14-E9)/E9 > 0.02, "STRONG", IF((E14-E9)/E9 < -0.02, "WEAK", "NEUTRAL")) -> WEAK | H14: =IF(AND(B14>B9, E14>E9), "CONFIRMED BULLISH", IF(AND(B14<B9, E14<E9), "CONFIRMED BEARISH", IF(AND(B14>B9, E14<E9), "BEARISH DIVERGENCE", IF(AND(B14<B9, E14>E9), "BULLISH DIVERGENCE", "NEUTRAL")))) -> BULLISH DIVERGENCE
A15: =TITRES_STAT!B18 -> 42327 | B15: =TITRES_STAT!C18 -> 7.5 | C15: =TITRES_STAT!D18 -> 6.5211 | D15: =TITRES_STAT!E18 -> 14063 | E15: =IF(B15>B14, E14+D15, IF(B15<B14, E14-D15, E14)) -> -97889 | F15: =IF(E15>E10,"BULLISH",IF(E15<E10,"BEARISH","NEUTRAL")) -> BULLISH | G15: =IF((E15-E10)/E10 > 0.02, "STRONG", IF((E15-E10)/E10 < -0.02, "WEAK", "NEUTRAL")) -> WEAK | H15: =IF(AND(B15>B10, E15>E10), "CONFIRMED BULLISH", IF(AND(B15<B10, E15<E10), "CONFIRMED BEARISH", IF(AND(B15>B10, E15<E10), "BEARISH DIVERGENCE", IF(AND(B15<B10, E15>E10), "BULLISH DIVERGENCE", "NEUTRAL")))) -> BULLISH DIVERGENCE
A16: =TITRES_STAT!B19 -> 42328 | B16: =TITRES_STAT!C19 -> 7.5 | C16: =TITRES_STAT!D19 -> 6.5211 | D16: =TITRES_STAT!E19 -> 1500 | E16: =IF(B16>B15, E15+D16, IF(B16<B15, E15-D16, E15)) -> -97889 | F16: =IF(E16>E11,"BULLISH",IF(E16<E11,"BEARISH","NEUTRAL")) -> BEARISH | G16: =IF((E16-E11)/E11 > 0.02, "STRONG", IF((E16-E11)/E11 < -0.02, "WEAK", "NEUTRAL")) -> NEUTRAL | H16: =IF(AND(B16>B11, E16>E11), "CONFIRMED BULLISH", IF(AND(B16<B11, E16<E11), "CONFIRMED BEARISH", IF(AND(B16>B11, E16<E11), "BEARISH DIVERGENCE", IF(AND(B16<B11, E16>E11), "BULLISH DIVERGENCE", "NEUTRAL")))) -> CONFIRMED BEARISH
A17: =TITRES_STAT!B20 -> 42331 | B17: =TITRES_STAT!C20 -> 7.5 | C17: =TITRES_STAT!D20 -> 6.5211 | D17: =TITRES_STAT!E20 -> 5000 | E17: =IF(B17>B16, E16+D17, IF(B17<B16, E16-D17, E16)) -> -97889 | F17: =IF(E17>E12,"BULLISH",IF(E17<E12,"BEARISH","NEUTRAL")) -> NEUTRAL | G17: =IF((E17-E12)/E12 > 0.02, "STRONG", IF((E17-E12)/E12 < -0.02, "WEAK", "NEUTRAL")) -> NEUTRAL | H17: =IF(AND(B17>B12, E17>E12), "CONFIRMED BULLISH", IF(AND(B17<B12, E17<E12), "CONFIRMED BEARISH", IF(AND(B17>B12, E17<E12), "BEARISH DIVERGENCE", IF(AND(B17<B12, E17>E12), "BULLISH DIVERGENCE", "NEUTRAL")))) -> NEUTRAL
A18: =TITRES_STAT!B21 -> 42332 | B18: =TITRES_STAT!C21 -> 7.5 | C18: =TITRES_STAT!D21 -> 6.5211 | D18: =TITRES_STAT!E21 -> 3564 | E18: =IF(B18>B17, E17+D18, IF(B18<B17, E17-D18, E17)) -> -97889 | F18: =IF(E18>E13,"BULLISH",IF(E18<E13,"BEARISH","NEUTRAL")) -> NEUTRAL | G18: =IF((E18-E13)/E13 > 0.02, "STRONG", IF((E18-E13)/E13 < -0.02, "WEAK", "NEUTRAL")) -> NEUTRAL | H18: =IF(AND(B18>B13, E18>E13), "CONFIRMED BULLISH", IF(AND(B18<B13, E18<E13), "CONFIRMED BEARISH", IF(AND(B18>B13, E18<E13), "BEARISH DIVERGENCE", IF(AND(B18<B13, E18>E13), "BULLISH DIVERGENCE", "NEUTRAL")))) -> NEUTRAL
... A2508: =TITRES_STAT!B2511 -> 45960 | B2508: =TITRES_STAT!C2511 -> 0.58 | C2508: =TITRES_STAT!D2511 -> 0.58 | D2508: =TITRES_STAT!E2511 -> 840 | E2508: =IF(B2508>B2507, E2507+D2508, IF(B2508<B2507, E2507-D2508, E2507)) -> 4927066 | F2508: =IF(E2508>E2503,"BULLISH",IF(E2508<E2503,"BEARISH","NEUTRAL")) -> NEUTRAL | G2508: =IF((E2508-E2503)/E2503 > 0.02, "STRONG", IF((E2508-E2503)/E2503 < -0.02, "WEAK", "NEUTRAL")) -> NEUTRAL | H2508: =IF(AND(B2508>B2503, E2508>E2503), "CONFIRMED BULLISH", IF(AND(B2508<B2503, E2508<E2503), "CONFIRMED BEARISH", IF(AND(B2508>B2503, E2508<E2503), "BEARISH DIVERGENCE", IF(AND(B2508<B2503, E2508>E2503), "BULLISH DIVERGENCE", "NEUTRAL")))) -> NEUTRAL

Sheet Overall Overview
A1: =RSI!A1 -> Date | B1: =RSI!B1 -> Cours Ajusté | C1: =RSI!I1 -> 14-Day RSI | D1: =MACD!E1 -> MACD Line | E1: =MACD!F1 -> Signal Line | F1: ='Moving Avg'!D1 -> Simple Moving Avg (5) | G1: ='Moving Avg'!F1 -> Simple Moving Avg (20) | H1: ='Moving Avg'!G1 -> Simple Moving Avg (50) | I1: ='Moving Avg'!H1 -> Simple Moving Avg (200) | J1: =OBV!F1 -> OBV Trend Signal | K1: =OBV!G1 -> OBV Strength | L1: =OBV!H1 -> Price-OBV Alignment
A2: =RSI!A2 -> 42310 | B2: =RSI!B2 -> 6.695 | C2: =RSI!I2 -> 0 | D2: =MACD!E2 -> 0 | E2: =MACD!F2 -> 0 | F2: ='Moving Avg'!D2 -> 0 | G2: ='Moving Avg'!F2 -> 0 | H2: ='Moving Avg'!G2 -> 0 | I2: ='Moving Avg'!H2 -> 0 | J2: =OBV!F2 -> 0 | K2: =OBV!G2 -> 0 | L2: =OBV!H2 -> 0
A3: =RSI!A3 -> 42311 | B3: =RSI!B3 -> 6.6776 | C3: =RSI!I3 -> 0 | D3: =MACD!E3 -> 0 | E3: =MACD!F3 -> 0 | F3: ='Moving Avg'!D3 -> 0 | G3: ='Moving Avg'!F3 -> 0 | H3: ='Moving Avg'!G3 -> 0 | I3: ='Moving Avg'!H3 -> 0 | J3: =OBV!F3 -> 0 | K3: =OBV!G3 -> 0 | L3: =OBV!H3 -> 0
A4: =RSI!A4 -> 42312 | B4: =RSI!B4 -> 6.6689 | C4: =RSI!I4 -> 0 | D4: =MACD!E4 -> 0 | E4: =MACD!F4 -> 0 | F4: ='Moving Avg'!D4 -> 0 | G4: ='Moving Avg'!F4 -> 0 | H4: ='Moving Avg'!G4 -> 0 | I4: ='Moving Avg'!H4 -> 0 | J4: =OBV!F4 -> 0 | K4: =OBV!G4 -> 0 | L4: =OBV!H4 -> 0
A5: =RSI!A5 -> 42313 | B5: =RSI!B5 -> 6.6602 | C5: =RSI!I5 -> 0 | D5: =MACD!E5 -> 0 | E5: =MACD!F5 -> 0 | F5: ='Moving Avg'!D5 -> 6.675425 | G5: ='Moving Avg'!F5 -> 0 | H5: ='Moving Avg'!G5 -> 0 | I5: ='Moving Avg'!H5 -> 0 | J5: =OBV!F5 -> 0 | K5: =OBV!G5 -> 0 | L5: =OBV!H5 -> 0
A6: =RSI!A6 -> 42314 | B6: =RSI!B6 -> 6.6081 | C6: =RSI!I6 -> 0 | D6: =MACD!E6 -> 0 | E6: =MACD!F6 -> 0 | F6: ='Moving Avg'!D6 -> 6.66196 | G6: ='Moving Avg'!F6 -> 0 | H6: ='Moving Avg'!G6 -> 0 | I6: ='Moving Avg'!H6 -> 0 | J6: =OBV!F6 -> 0 | K6: =OBV!G6 -> 0 | L6: =OBV!H6 -> CONFIRMED BEARISH
A7: =RSI!A7 -> 42317 | B7: =RSI!B7 -> 6.5211 | C7: =RSI!I7 -> 0 | D7: =MACD!E7 -> 0 | E7: =MACD!F7 -> 0 | F7: ='Moving Avg'!D7 -> 6.62718 | G7: ='Moving Avg'!F7 -> 0 | H7: ='Moving Avg'!G7 -> 0 | I7: ='Moving Avg'!H7 -> 0 | J7: =OBV!F7 -> BEARISH | K7: =OBV!G7 -> WEAK | L7: =OBV!H7 -> CONFIRMED BEARISH
A8: =RSI!A8 -> 42318 | B8: =RSI!B8 -> 6.5211 | C8: =RSI!I8 -> 0 | D8: =MACD!E8 -> 0 | E8: =MACD!F8 -> 0 | F8: ='Moving Avg'!D8 -> 6.59588 | G8: ='Moving Avg'!F8 -> 0 | H8: ='Moving Avg'!G8 -> 0 | I8: ='Moving Avg'!H8 -> 0 | J8: =OBV!F8 -> BEARISH | K8: =OBV!G8 -> STRONG | L8: =OBV!H8 -> CONFIRMED BEARISH
A9: =RSI!A9 -> 42319 | B9: =RSI!B9 -> 6.5559 | C9: =RSI!I9 -> 0 | D9: =MACD!E9 -> 0 | E9: =MACD!F9 -> 0 | F9: ='Moving Avg'!D9 -> 6.57328 | G9: ='Moving Avg'!F9 -> 0 | H9: ='Moving Avg'!G9 -> 0 | I9: ='Moving Avg'!H9 -> 0 | J9: =OBV!F9 -> BEARISH | K9: =OBV!G9 -> STRONG | L9: =OBV!H9 -> CONFIRMED BEARISH
A10: =RSI!A10 -> 42320 | B10: =RSI!B10 -> 6.5559 | C10: =RSI!I10 -> 0 | D10: =MACD!E10 -> 0 | E10: =MACD!F10 -> 0 | F10: ='Moving Avg'!D10 -> 6.55242 | G10: ='Moving Avg'!F10 -> 0 | H10: ='Moving Avg'!G10 -> 0 | I10: ='Moving Avg'!H10 -> 0 | J10: =OBV!F10 -> BEARISH | K10: =OBV!G10 -> STRONG | L10: =OBV!H10 -> CONFIRMED BEARISH
A11: =RSI!A11 -> 42321 | B11: =RSI!B11 -> 6.5733 | C11: =RSI!I11 -> 0 | D11: =MACD!E11 -> 0 | E11: =MACD!F11 -> 0 | F11: ='Moving Avg'!D11 -> 6.54546 | G11: ='Moving Avg'!F11 -> 0 | H11: ='Moving Avg'!G11 -> 0 | I11: ='Moving Avg'!H11 -> 0 | J11: =OBV!F11 -> BEARISH | K11: =OBV!G11 -> STRONG | L11: =OBV!H11 -> CONFIRMED BEARISH
A12: =RSI!A12 -> 42324 | B12: =RSI!B12 -> 6.5211 | C12: =RSI!I12 -> 0 | D12: =MACD!E12 -> 0 | E12: =MACD!F12 -> 0 | F12: ='Moving Avg'!D12 -> 6.54546 | G12: ='Moving Avg'!F12 -> 0 | H12: ='Moving Avg'!G12 -> 0 | I12: ='Moving Avg'!H12 -> 0 | J12: =OBV!F12 -> BULLISH | K12: =OBV!G12 -> WEAK | L12: =OBV!H12 -> NEUTRAL
... A2508: =RSI!A2508 -> 45960 | B2508: =RSI!B2508 -> 0.58 | C2508: =RSI!I2508 -> 53.063493 | D2508: =MACD!E2508 -> 0.0054857536 | E2508: =MACD!F2508 -> 0.0041076881 | F2508: ='Moving Avg'!D2508 -> 0.572 | G2508: ='Moving Avg'!F2508 -> 0.571 | H2508: ='Moving Avg'!G2508 -> 0.575 | I2508: ='Moving Avg'!H2508 -> 0.5167 | J2508: =OBV!F2508 -> NEUTRAL | K2508: =OBV!G2508 -> NEUTRAL | L2508: =OBV!H2508 -> NEUTRAL

Sheet Scoring System
A1: =RSI!A1 -> Date | B1: =RSI!B1 -> Cours Ajusté | C1: =RSI!I1 -> 14-Day RSI | D1: =MACD!E1 -> MACD Line | E1: =MACD!F1 -> Signal Line | F1: ='Moving Avg'!D1 -> Simple Moving Avg (5) | G1: ='Moving Avg'!F1 -> Simple Moving Avg (20) | H1: ='Moving Avg'!G1 -> Simple Moving Avg (50) | I1: ='Moving Avg'!H1 -> Simple Moving Avg (200) | J1: =OBV!F1 -> OBV Trend Signal | K1: =OBV!G1 -> OBV Strength | L1: =OBV!H1 -> Price-OBV Alignment | M1: RSI Score | N1: MACD Score | O1: SMA Score | P1: OBV Score | Q1: Score Momentum | R1: Score Trend | S1: Volume Score | T1: Score Equal Weights | U1: Overall Score (3C) | V1: Overall Score (4C)
A2: =RSI!A2 -> 42310 | B2: =RSI!B2 -> 6.695 | C2: =RSI!I2 -> 0 | D2: =MACD!E2 -> 0 | E2: =MACD!F2 -> 0 | F2: ='Moving Avg'!D2 -> 0 | G2: ='Moving Avg'!F2 -> 0 | H2: ='Moving Avg'!G2 -> 0 | I2: ='Moving Avg'!H2 -> 0 | J2: =OBV!F2 -> 0 | K2: =OBV!G2 -> 0 | L2: =OBV!H2 -> 0 | M2: =IF(C2<30,50, IF(C2>70, 0, 25)) -> 50 | N2: =IF(E2-D2>0.02, 100, IF(E2-D2<0,0,45)) -> 45 | O2: =IF(F2-I2>10,100,IF(F2-I2>5,75, IF(F2-I2>0,50,0))) -> 0 | P2: =IF(L2="confirmed bullish", 34, IF(L2="bullish divergence",17, 0))+IF(J2="bullish",33,IF(J2="bearish",0,16.5))+IF(K2="strong",33,IF(K2="weak",0,16.5)) -> 33 | Q2: =0.35*M2+N2*0.35+O2*0.15+P2*0.15 -> 38.2 | R2: =M2*0.2+N2*0.2+O2*0.35+P2*0.25 -> 27.25 | S2: =M2*0.15+N2*0.15+O2*0.25+P2*0.45 -> 29.1 | T2: =0.25*SUM(M2:P2) -> 32 | U2: =SUM(Q2:S2)/3 -> 31.516667 | V2: =SUM(Q2:T2)/4 -> 31.6375
A3: =RSI!A3 -> 42311 | B3: =RSI!B3 -> 6.6776 | C3: =RSI!I3 -> 0 | D3: =MACD!E3 -> 0 | E3: =MACD!F3 -> 0 | F3: ='Moving Avg'!D3 -> 0 | G3: ='Moving Avg'!F3 -> 0 | H3: ='Moving Avg'!G3 -> 0 | I3: ='Moving Avg'!H3 -> 0 | J3: =OBV!F3 -> 0 | K3: =OBV!G3 -> 0 | L3: =OBV!H3 -> 0 | M3: =IF(C3<30,50, IF(C3>70, 0, 25)) -> 50 | N3: =IF(E3-D3>0.02, 100, IF(E3-D3<0,0,45)) -> 45 | O3: =IF(F3-I3>10,100,IF(F3-I3>5,75, IF(F3-I3>0,50,0))) -> 0 | P3: =IF(L3="confirmed bullish", 34, IF(L3="bullish divergence",17, 0))+IF(J3="bullish",33,IF(J3="bearish",0,16.5))+IF(K3="strong",33,IF(K3="weak",0,16.5)) -> 33 | Q3: =0.35*M3+N3*0.35+O3*0.15+P3*0.15 -> 38.2 | R3: =M3*0.2+N3*0.2+O3*0.35+P3*0.25 -> 27.25 | S3: =M3*0.15+N3*0.15+O3*0.25+P3*0.45 -> 29.1 | T3: =0.25*SUM(M3:P3) -> 32 | U3: =SUM(Q3:S3)/3 -> 31.516667 | V3: =SUM(Q3:T3)/4 -> 31.6375
A4: =RSI!A4 -> 42312 | B4: =RSI!B4 -> 6.6689 | C4: =RSI!I4 -> 0 | D4: =MACD!E4 -> 0 | E4: =MACD!F4 -> 0 | F4: ='Moving Avg'!D4 -> 0 | G4: ='Moving Avg'!F4 -> 0 | H4: ='Moving Avg'!G4 -> 0 | I4: ='Moving Avg'!H4 -> 0 | J4: =OBV!F4 -> 0 | K4: =OBV!G4 -> 0 | L4: =OBV!H4 -> 0 | M4: =IF(C4<30,50, IF(C4>70, 0, 25)) -> 50 | N4: =IF(E4-D4>0.02, 100, IF(E4-D4<0,0,45)) -> 45 | O4: =IF(F4-I4>10,100,IF(F4-I4>5,75, IF(F4-I4>0,50,0))) -> 0 | P4: =IF(L4="confirmed bullish", 34, IF(L4="bullish divergence",17, 0))+IF(J4="bullish",33,IF(J4="bearish",0,16.5))+IF(K4="strong",33,IF(K4="weak",0,16.5)) -> 33 | Q4: =0.35*M4+N4*0.35+O4*0.15+P4*0.15 -> 38.2 | R4: =M4*0.2+N4*0.2+O4*0.35+P4*0.25 -> 27.25 | S4: =M4*0.15+N4*0.15+O4*0.25+P4*0.45 -> 29.1 | T4: =0.25*SUM(M4:P4) -> 32 | U4: =SUM(Q4:S4)/3 -> 31.516667 | V4: =SUM(Q4:T4)/4 -> 31.6375
A5: =RSI!A5 -> 42313 | B5: =RSI!B5 -> 6.6602 | C5: =RSI!I5 -> 0 | D5: =MACD!E5 -> 0 | E5: =MACD!F5 -> 0 | F5: ='Moving Avg'!D5 -> 6.675425 | G5: ='Moving Avg'!F5 -> 0 | H5: ='Moving Avg'!G5 -> 0 | I5: ='Moving Avg'!H5 -> 0 | J5: =OBV!F5 -> 0 | K5: =OBV!G5 -> 0 | L5: =OBV!H5 -> 0 | M5: =IF(C5<30,50, IF(C5>70, 0, 25)) -> 50 | N5: =IF(E5-D5>0.02, 100, IF(E5-D5<0,0,45)) -> 45 | O5: =IF(F5-I5>10,100,IF(F5-I5>5,75, IF(F5-I5>0,50,0))) -> 75 | P5: =IF(L5="confirmed bullish", 34, IF(L5="bullish divergence",17, 0))+IF(J5="bullish",33,IF(J5="bearish",0,16.5))+IF(K5="strong",33,IF(K5="weak",0,16.5)) -> 33 | Q5: =0.35*M5+N5*0.35+O5*0.15+P5*0.15 -> 49.45 | R5: =M5*0.2+N5*0.2+O5*0.35+P5*0.25 -> 53.5 | S5: =M5*0.15+N5*0.15+O5*0.25+P5*0.45 -> 47.85 | T5: =0.25*SUM(M5:P5) -> 50.75 | U5: =SUM(Q5:S5)/3 -> 50.266667 | V5: =SUM(Q5:T5)/4 -> 50.3875
A6: =RSI!A6 -> 42314 | B6: =RSI!B6 -> 6.6081 | C6: =RSI!I6 -> 0 | D6: =MACD!E6 -> 0 | E6: =MACD!F6 -> 0 | F6: ='Moving Avg'!D6 -> 6.66196 | G6: ='Moving Avg'!F6 -> 0 | H6: ='Moving Avg'!G6 -> 0 | I6: ='Moving Avg'!H6 -> 0 | J6: =OBV!F6 -> 0 | K6: =OBV!G6 -> 0 | L6: =OBV!H6 -> CONFIRMED BEARISH | M6: =IF(C6<30,50, IF(C6>70, 0, 25)) -> 50 | N6: =IF(E6-D6>0.02, 100, IF(E6-D6<0,0,45)) -> 45 | O6: =IF(F6-I6>10,100,IF(F6-I6>5,75, IF(F6-I6>0,50,0))) -> 75 | P6: =IF(L6="confirmed bullish", 34, IF(L6="bullish divergence",17, 0))+IF(J6="bullish",33,IF(J6="bearish",0,16.5))+IF(K6="strong",33,IF(K6="weak",0,16.5)) -> 33 | Q6: =0.35*M6+N6*0.35+O6*0.15+P6*0.15 -> 49.45 | R6: =M6*0.2+N6*0.2+O6*0.35+P6*0.25 -> 53.5 | S6: =M6*0.15+N6*0.15+O6*0.25+P6*0.45 -> 47.85 | T6: =0.25*SUM(M6:P6) -> 50.75 | U6: =SUM(Q6:S6)/3 -> 50.266667 | V6: =SUM(Q6:T6)/4 -> 50.3875
A7: =RSI!A7 -> 42317 | B7: =RSI!B7 -> 6.5211 | C7: =RSI!I7 -> 0 | D7: =MACD!E7 -> 0 | E7: =MACD!F7 -> 0 | F7: ='Moving Avg'!D7 -> 6.62718 | G7: ='Moving Avg'!F7 -> 0 | H7: ='Moving Avg'!G7 -> 0 | I7: ='Moving Avg'!H7 -> 0 | J7: =OBV!F7 -> BEARISH | K7: =OBV!G7 -> WEAK | L7: =OBV!H7 -> CONFIRMED BEARISH | M7: =IF(C7<30,50, IF(C7>70, 0, 25)) -> 50 | N7: =IF(E7-D7>0.02, 100, IF(E7-D7<0,0,45)) -> 45 | O7: =IF(F7-I7>10,100,IF(F7-I7>5,75, IF(F7-I7>0,50,0))) -> 75 | P7: =IF(L7="confirmed bullish", 34, IF(L7="bullish divergence",17, 0))+IF(J7="bullish",33,IF(J7="bearish",0,16.5))+IF(K7="strong",33,IF(K7="weak",0,16.5)) -> 0 | Q7: =0.35*M7+N7*0.35+O7*0.15+P7*0.15 -> 44.5 | R7: =M7*0.2+N7*0.2+O7*0.35+P7*0.25 -> 45.25 | S7: =M7*0.15+N7*0.15+O7*0.25+P7*0.45 -> 33 | T7: =0.25*SUM(M7:P7) -> 42.5 | U7: =SUM(Q7:S7)/3 -> 40.916667 | V7: =SUM(Q7:T7)/4 -> 41.3125
A8: =RSI!A8 -> 42318 | B8: =RSI!B8 -> 6.5211 | C8: =RSI!I8 -> 0 | D8: =MACD!E8 -> 0 | E8: =MACD!F8 -> 0 | F8: ='Moving Avg'!D8 -> 6.59588 | G8: ='Moving Avg'!F8 -> 0 | H8: ='Moving Avg'!G8 -> 0 | I8: ='Moving Avg'!H8 -> 0 | J8: =OBV!F8 -> BEARISH | K8: =OBV!G8 -> STRONG | L8: =OBV!H8 -> CONFIRMED BEARISH | M8: =IF(C8<30,50, IF(C8>70, 0, 25)) -> 50 | N8: =IF(E8-D8>0.02, 100, IF(E8-D8<0,0,45)) -> 45 | O8: =IF(F8-I8>10,100,IF(F8-I8>5,75, IF(F8-I8>0,50,0))) -> 75 | P8: =IF(L8="confirmed bullish", 34, IF(L8="bullish divergence",17, 0))+IF(J8="bullish",33,IF(J8="bearish",0,16.5))+IF(K8="strong",33,IF(K8="weak",0,16.5)) -> 33 | Q8: =0.35*M8+N8*0.35+O8*0.15+P8*0.15 -> 49.45 | R8: =M8*0.2+N8*0.2+O8*0.35+P8*0.25 -> 53.5 | S8: =M8*0.15+N8*0.15+O8*0.25+P8*0.45 -> 47.85 | T8: =0.25*SUM(M8:P8) -> 50.75 | U8: =SUM(Q8:S8)/3 -> 50.266667 | V8: =SUM(Q8:T8)/4 -> 50.3875
A9: =RSI!A9 -> 42319 | B9: =RSI!B9 -> 6.5559 | C9: =RSI!I9 -> 0 | D9: =MACD!E9 -> 0 | E9: =MACD!F9 -> 0 | F9: ='Moving Avg'!D9 -> 6.57328 | G9: ='Moving Avg'!F9 -> 0 | H9: ='Moving Avg'!G9 -> 0 | I9: ='Moving Avg'!H9 -> 0 | J9: =OBV!F9 -> BEARISH | K9: =OBV!G9 -> STRONG | L9: =OBV!H9 -> CONFIRMED BEARISH | M9: =IF(C9<30,50, IF(C9>70, 0, 25)) -> 50 | N9: =IF(E9-D9>0.02, 100, IF(E9-D9<0,0,45)) -> 45 | O9: =IF(F9-I9>10,100,IF(F9-I9>5,75, IF(F9-I9>0,50,0))) -> 75 | P9: =IF(L9="confirmed bullish", 34, IF(L9="bullish divergence",17, 0))+IF(J9="bullish",33,IF(J9="bearish",0,16.5))+IF(K9="strong",33,IF(K9="weak",0,16.5)) -> 33 | Q9: =0.35*M9+N9*0.35+O9*0.15+P9*0.15 -> 49.45 | R9: =M9*0.2+N9*0.2+O9*0.35+P9*0.25 -> 53.5 | S9: =M9*0.15+N9*0.15+O9*0.25+P9*0.45 -> 47.85 | T9: =0.25*SUM(M9:P9) -> 50.75 | U9: =SUM(Q9:S9)/3 -> 50.266667 | V9: =SUM(Q9:T9)/4 -> 50.3875
A10: =RSI!A10 -> 42320 | B10: =RSI!B10 -> 6.5559 | C10: =RSI!I10 -> 0 | D10: =MACD!E10 -> 0 | E10: =MACD!F10 -> 0 | F10: ='Moving Avg'!D10 -> 6.55242 | G10: ='Moving Avg'!F10 -> 0 | H10: ='Moving Avg'!G10 -> 0 | I10: ='Moving Avg'!H10 -> 0 | J10: =OBV!F10 -> BEARISH | K10: =OBV!G10 -> STRONG | L10: =OBV!H10 -> CONFIRMED BEARISH | M10: =IF(C10<30,50, IF(C10>70, 0, 25)) -> 50 | N10: =IF(E10-D10>0.02, 100, IF(E10-D10<0,0,45)) -> 45 | O10: =IF(F10-I10>10,100,IF(F10-I10>5,75, IF(F10-I10>0,50,0))) -> 75 | P10: =IF(L10="confirmed bullish", 34, IF(L10="bullish divergence",17, 0))+IF(J10="bullish",33,IF(J10="bearish",0,16.5))+IF(K10="strong",33,IF(K10="weak",0,16.5)) -> 33 | Q10: =0.35*M10+N10*0.35+O10*0.15+P10*0.15 -> 49.45 | R10: =M10*0.2+N10*0.2+O10*0.35+P10*0.25 -> 53.5 | S10: =M10*0.15+N10*0.15+O10*0.25+P10*0.45 -> 47.85 | T10: =0.25*SUM(M10:P10) -> 50.75 | U10: =SUM(Q10:S10)/3 -> 50.266667 | V10: =SUM(Q10:T10)/4 -> 50.3875
A11: =RSI!A11 -> 42321 | B11: =RSI!B11 -> 6.5733 | C11: =RSI!I11 -> 0 | D11: =MACD!E11 -> 0 | E11: =MACD!F11 -> 0 | F11: ='Moving Avg'!D11 -> 6.54546 | G11: ='Moving Avg'!F11 -> 0 | H11: ='Moving Avg'!G11 -> 0 | I11: ='Moving Avg'!H11 -> 0 | J11: =OBV!F11 -> BEARISH | K11: =OBV!G11 -> STRONG | L11: =OBV!H11 -> CONFIRMED BEARISH | M11: =IF(C11<30,50, IF(C11>70, 0, 25)) -> 50 | N11: =IF(E11-D11>0.02, 100, IF(E11-D11<0,0,45)) -> 45 | O11: =IF(F11-I11>10,100,IF(F11-I11>5,75, IF(F11-I11>0,50,0))) -> 75 | P11: =IF(L11="confirmed bullish", 34, IF(L11="bullish divergence",17, 0))+IF(J11="bullish",33,IF(J11="bearish",0,16.5))+IF(K11="strong",33,IF(K11="weak",0,16.5)) -> 33 | Q11: =0.35*M11+N11*0.35+O11*0.15+P11*0.15 -> 49.45 | R11: =M11*0.2+N11*0.2+O11*0.35+P11*0.25 -> 53.5 | S11: =M11*0.15+N11*0.15+O11*0.25+P11*0.45 -> 47.85 | T11: =0.25*SUM(M11:P11) -> 50.75 | U11: =SUM(Q11:S11)/3 -> 50.266667 | V11: =SUM(Q11:T11)/4 -> 50.3875
A12: =RSI!A12 -> 42324 | B12: =RSI!B12 -> 6.5211 | C12: =RSI!I12 -> 0 | D12: =MACD!E12 -> 0 | E12: =MACD!F12 -> 0 | F12: ='Moving Avg'!D12 -> 6.54546 | G12: ='Moving Avg'!F12 -> 0 | H12: ='Moving Avg'!G12 -> 0 | I12: ='Moving Avg'!H12 -> 0 | J12: =OBV!F12 -> BULLISH | K12: =OBV!G12 -> WEAK | L12: =OBV!H12 -> NEUTRAL | M12: =IF(C12<30,50, IF(C12>70, 0, 25)) -> 50 | N12: =IF(E12-D12>0.02, 100, IF(E12-D12<0,0,45)) -> 45 | O12: =IF(F12-I12>10,100,IF(F12-I12>5,75, IF(F12-I12>0,50,0))) -> 75 | P12: =IF(L12="confirmed bullish", 34, IF(L12="bullish divergence",17, 0))+IF(J12="bullish",33,IF(J12="bearish",0,16.5))+IF(K12="strong",33,IF(K12="weak",0,16.5)) -> 33 | Q12: =0.35*M12+N12*0.35+O12*0.15+P12*0.15 -> 49.45 | R12: =M12*0.2+N12*0.2+O12*0.35+P12*0.25 -> 53.5 | S12: =M12*0.15+N12*0.15+O12*0.25+P12*0.45 -> 47.85 | T12: =0.25*SUM(M12:P12) -> 50.75 | U12: =SUM(Q12:S12)/3 -> 50.266667 | V12: =SUM(Q12:T12)/4 -> 50.3875
A13: =RSI!A13 -> 42325 | B13: =RSI!B13 -> 6.5211 | C13: =RSI!I13 -> 0 | D13: =MACD!E13 -> 0 | E13: =MACD!F13 -> 0 | F13: ='Moving Avg'!D13 -> 6.54546 | G13: ='Moving Avg'!F13 -> 0 | H13: ='Moving Avg'!G13 -> 0 | I13: ='Moving Avg'!H13 -> 0 | J13: =OBV!F13 -> BULLISH | K13: =OBV!G13 -> WEAK | L13: =OBV!H13 -> NEUTRAL | M13: =IF(C13<30,50, IF(C13>70, 0, 25)) -> 50 | N13: =IF(E13-D13>0.02, 100, IF(E13-D13<0,0,45)) -> 45 | O13: =IF(F13-I13>10,100,IF(F13-I13>5,75, IF(F13-I13>0,50,0))) -> 75 | P13: =IF(L13="confirmed bullish", 34, IF(L13="bullish divergence",17, 0))+IF(J13="bullish",33,IF(J13="bearish",0,16.5))+IF(K13="strong",33,IF(K13="weak",0,16.5)) -> 33 | Q13: =0.35*M13+N13*0.35+O13*0.15+P13*0.15 -> 49.45 | R13: =M13*0.2+N13*0.2+O13*0.35+P13*0.25 -> 53.5 | S13: =M13*0.15+N13*0.15+O13*0.25+P13*0.45 -> 47.85 | T13: =0.25*SUM(M13:P13) -> 50.75 | U13: =SUM(Q13:S13)/3 -> 50.266667 | V13: =SUM(Q13:T13)/4 -> 50.3875
... A2508: =RSI!A2508 -> 45960 | B2508: =RSI!B2508 -> 0.58 | C2508: =RSI!I2508 -> 53.063493 | D2508: =MACD!E2508 -> 0.0054857536 | E2508: =MACD!F2508 -> 0.0041076881 | F2508: ='Moving Avg'!D2508 -> 0.572 | G2508: ='Moving Avg'!F2508 -> 0.571 | H2508: ='Moving Avg'!G2508 -> 0.575 | I2508: ='Moving Avg'!H2508 -> 0.5167 | J2508: =OBV!F2508 -> NEUTRAL | K2508: =OBV!G2508 -> NEUTRAL | L2508: =OBV!H2508 -> NEUTRAL | M2508: =IF(C2508<30,50, IF(C2508>70, 0, 25)) -> 25 | N2508: =IF(E2508-D2508>0.02, 100, IF(E2508-D2508<0,0,45)) -> 0 | O2508: =IF(F2508-I2508>10,100,IF(F2508-I2508>5,75, IF(F2508-I2508>0,50,0))) -> 50 | P2508: =IF(L2508="confirmed bullish", 34, IF(L2508="bullish divergence",17, 0))+IF(J2508="bullish",33,IF(J2508="bearish",0,16.5))+IF(K2508="strong",33,IF(K2508="weak",0,16.5)) -> 33 | Q2508: =0.35*M2508+N2508*0.35+O2508*0.15+P2508*0.15 -> 21.2 | R2508: =M2508*0.2+N2508*0.2+O2508*0.35+P2508*0.25 -> 30.75 | S2508: =M2508*0.15+N2508*0.15+O2508*0.25+P2508*0.45 -> 31.1 | T2508: =0.25*SUM(M2508:P2508) -> 27 | U2508: =SUM(Q2508:S2508)/3 -> 27.683333 | V2508: =SUM(Q2508:T2508)/4 -> 27.5125
